Workbook
Name AcctCodes: Acc!$A$10:$A$259
Name AcctTbl: Acc!$A$10:$J$259
Name BankTbl: Bnk!$A$10:$G$19
Name BasketTbl: Bsk!$B$10:$F$21
Name GroupTbl: Grp!$A$10:$F$52
Name ListAllCodes: OFFSET(Acc!$A$10,0,0,MAX(COUNTIF(Acc!$D$10:$D$259,"?*"),1),1)
Name ListBanks: OFFSET(Bnk!$B$10,0,0,MAX(COUNTIF(Bnk!$B$10:$B$19,"?*"),1),1)
Name ListBasketOps: OFFSET(Op!$B$24,0,0,MAX(COUNTIF(Op!$B$24:$B$33,"?*"),1),1)
Name ListBaskets: OFFSET(Bsk!$B$10,0,0,MAX(COUNTIF(Bsk!$B$10:$B$21,"?*"),1),1)
Name ListCategories: OFFSET(List!$B$10,0,0,MAX(COUNTIF(List!$B$10:$B$29,"?*"),1),1)
Name ListChequeStatus: OFFSET(List!$G$10,0,0,MAX(COUNTIF(List!$G$10:$G$29,"?*"),1),1)
Name ListColorKeys: OFFSET(List!$P$10,0,0,MAX(COUNTIF(List!$P$10:$P$29,"?*"),1),1)
Name ListDirections: OFFSET(List!$C$10,0,0,MAX(COUNTIF(List!$C$10:$C$29,"?*"),1),1)
Name ListGroups: Grp!$H$10:$H$19
Name ListInclude: OFFSET(List!$H$10,0,0,MAX(COUNTIF(List!$H$10:$H$29,"?*"),1),1)
Name ListManualRoles: OFFSET(List!$I$10,0,0,MAX(COUNTIF(List!$I$10:$I$29,"?*"),1),1)
Name ListOpCategories: OFFSET(List!$L$10,0,0,MAX(COUNTIF(List!$L$10:$L$29,"?*"),1),1)
Name ListOps: OFFSET(Op!$B$10,0,0,MAX(COUNTIF(Op!$B$10:$B$33,"?*"),1),1)
Name ListPartyBasis: OFFSET(List!$O$10,0,0,MAX(COUNTIF(List!$O$10:$O$29,"?*"),1),1)
Name ListPartyTypes: OFFSET(List!$E$10,0,0,MAX(COUNTIF(List!$E$10:$E$29,"?*"),1),1)
Name ListPayMethods: OFFSET(List!$F$10,0,0,MAX(COUNTIF(List!$F$10:$F$29,"?*"),1),1)
Name ListPosEffects: OFFSET(List!$J$10,0,0,MAX(COUNTIF(List!$J$10:$J$29,"?*"),1),1)
Name ListProducts: OFFSET(Prd!$B$10,0,0,MAX(COUNTIF(Prd!$B$10:$B$29,"?*"),1),1)
Name ListReportSheets: OFFSET(List!$N$10,0,0,MAX(COUNTIF(List!$N$10:$N$29,"?*"),1),1)
Name ListSeasons: OFFSET(List!$Q$10,0,0,MAX(COUNTIF(List!$Q$10:$Q$29,"?*"),1),1)
Name ListSides: OFFSET(List!$K$10,0,0,MAX(COUNTIF(List!$K$10:$K$29,"?*"),1),1)
Name ListStatus: OFFSET(List!$M$10,0,0,MAX(COUNTIF(List!$M$10:$M$29,"?*"),1),1)
Name ListSubgroups: OFFSET(Grp!$B$10,0,0,MAX(COUNTIF(Grp!$B$10:$B$52,"?*"),1),1)
Name ListTxnDirections: OFFSET(List!$R$10,0,0,MAX(COUNTIF(List!$R$10:$R$29,"?*"),1),1)
Name ListUnits: OFFSET(List!$A$10,0,0,MAX(COUNTIF(List!$A$10:$A$29,"?*"),1),1)
Name ListYesNo: OFFSET(List!$D$10,0,0,MAX(COUNTIF(List!$D$10:$D$29,"?*"),1),1)
Name OpTbl: Op!$A$10:$S$33
Name ParamTbl: Par!$A$10:$E$21
Name ProductTbl: Prd!$B$10:$D$29
Name ListBankOps: List!$S$10:$S$29
Name ListOtherScalesLabel: List!$T$10:$T$29
Name ListBankNames: List!$U$10:$U$19

Sheet Home
A1: مازندشت — سورتینگ و بسته‌بندی مرکبات | G1: MAZANDASHT · CITRUS SORTING & PACKING
A2: مازندشت · سامانه یکپارچه سورتینگ و بسته‌بندی مرکبات
A3: فایل مادر (INFO) — مرکز تعریف حساب‌ها، عملیات، سبدها، بانک‌ها و پارامترها · نسخه ۰۱ · Excel 2013
A5: حساب‌های تعریف‌شده | C5: عملیات باسکول | E5: انواع سبد | G5: محصولات | I5: بانک‌ها
A6: =COUNTIF(Acc!$D$10:$D$259,"?*") | C6: =COUNTIF(Op!$B$10:$B$33,"?*") | E6: =COUNTIF(Bsk!$B$10:$B$21,"?*") | G6: =COUNTIF(Prd!$B$10:$B$29,"?*") | I6: =COUNTIF(Bnk!$A$10:$A$19,"?*")
A8: ۰۱ | B8: فایل‌های سامانه — روی هر کارت کلیک کنید — همه فایل‌ها باید در یک پوشه باشند
A10: INFO · فایل مادر — همین فایل | C10: ۰۱ ثبت · ثبت روزانه عملیات | E10: ۰۲ گزارش · گزارش‌های مدیریتی | G10: ۰۳ فاکتور · فاکتور چاپی
A11: حساب‌ها، عملیات، سبدها، بانک‌ها، پارامترها | C11: باسکول، سبد، پرداخت‌ها، گزارش جامع | E11: باغداران، بارفروشان، فروشندگان سبد، دفتر کل | G11: صورت‌حساب خریدار/باغدار با تیک انتخاب ردیف
A12: 00_Master.xlsx | C12: 01_Entry.xlsx | E12: 02_Reports.xlsx | G12: 03_Invoice.xlsx
A13: ۰۴ ترازنامه · ترازنامه و حسابرسی | C13: ۰۵ بانک · بانک و چک | E13: ۰۶ بارفروشان · کارت بارفروشان | G13: ۰۷ نمونه · ثبت ساده — نسخه نمونه
A14: تراز ۴ و ۶ ستونه، حسابرسی، ترازبانک | C14: تراکنش بانکی، دفتر چک، مغایرت‌گیری | E14: ریز بار ارسالی و تسویه هر بارفروش | G14: کدگذاری ساده‌شده برای شروع سریع
A15: 04_Balance.xlsx | C15: 05_Bank.xlsx | E15: 06_Buyers.xlsx | G15: 07_Demo.xlsx
A23: ۰۲ | B23: جریان داده — چه کسی از چه کسی می‌خواند — فلش‌ها جهت جریان اطلاعات را نشان می‌دهند
A24: INFO | B24: ← | C24: ۰۱ ثبت | D24: ← | E24: ۰۲ گزارش
A25: تعریف‌ها | C25: ورود اطلاعات | E25: گزارش
A27: ۰۱ ثبت ← INFO | D27: کد و نام حساب‌ها، عملیات و قواعد، وزن سبد، بانک‌ها، پارامترها
A28: ۰۲ گزارش ← ۰۱ ثبت + INFO | D28: ریز باسکول، سبد و پرداخت‌ها؛ نام و گروه از INFO
A29: ۰۳ فاکتور ← ۰۱ ثبت + INFO | D29: مانده و ریز گردش هر حساب؛ تیک انتخاب ردیف
A30: ۰۴ ترازنامه ← ۰۱ ثبت + ۰۲ + ۰۵ | D30: گردش حساب‌ها، بانک‌ها، موجودی سبد و مرکبات
A31: ۰۵ بانک ← INFO + ۰۱ ثبت | D31: بانک‌ها و شماره چک‌ها؛ تطبیق با پرداخت‌ها
A32: ۰۶ بارفروشان ← ۰۱ ثبت + ۰۵ | D32: بار خروجی بارفروش + تسویه‌ها + هزینه باسکول
A34: ۰۳ | B34: قواعد طلایی — هر روز یک بار بخوانید
A35: 1 | B35: کدها را تغییر ندهید؛ عنوان‌ها را آزادانه عوض کنید. سیستم با «کد» کار می‌کند، نه با عنوان.
A36: 2 | B36: ردیف تازه = ردیف خالی بعدی؛ کدها از قبل درج شده‌اند. بین ردیف‌ها ردیف خالی نگذارید.
A37: 3 | B37: برای حذف یک حساب، محتوای سلول‌ها را پاک کنید (Delete)؛ خودِ ردیف را حذف نکنید.
A38: 4 | B38: همه فایل‌ها همیشه در یک پوشه باشند؛ مسیر لینک‌ها نسبی است.
A39: 5 | B39: بعد از هر تغییر در INFO، فایل‌های دیگر را باز کنید و Data ← Edit Links ← Update Values بزنید.
A40: 6 | B40: تاریخ‌ها شمسی با قالب 1405/07/10؛ ساعت با قالب 09:30. اعداد را با ارقام لاتین وارد کنید.
A41: 7 | B41: قبل از هر ماه، از کل پوشه یک نسخه پشتیبان بگیرید (فایل را با تاریخ در نام کپی کنید).
A42: 8 | B42: اگر فرمولی «#NAME?» داد، یعنی فایل INFO بسته یا جابه‌جا شده است؛ ابتدا لینک را Update کنید.
A44: راهنمای کامل سامانه — روی این نوار کلیک کنید
A46: فایل‌های همراه — با یک کلیک باز می‌شوند (مسیر نسبی، همه در همین پوشه)
A47: دفتر ثبت 01_Entry | C47: بانک 02_Bank | E47: گزارش‌ها 03_Report | G47: فاکتورها 04_Inv | I47: تراز 05_Bal
A48: خریداران 06_Buyers | C48: نمونه 07_Demo | E48: داشبورد 08_Dash

Sheet Co
A1: مازندشت — سورتینگ و بسته‌بندی مرکبات | G1: MAZANDASHT · CITRUS SORTING & PACKING
A2: مشخصات شرکت
A3: این مقادیر منبع سرصفحه و گزارش‌های همه فایل‌ها هستند
A5: ۰۱ | B5: اطلاعات هویتی و تماس — ستون‌های زرد قابل ویرایش‌اند
A7: نام کامل شرکت | C7: سورتینگ و بسته‌بندی مرکبات مازندشت | H7: در سرصفحه همه فایل‌ها استفاده می‌شود
A8: برند | C8: مازندشت | H8: نام کوتاه روی فاکتور و گزارش
A9: زمینه فعالیت | C9: سورتینگ، بسته‌بندی و بازرگانی مرکبات
A10: نشانی | C10: باغدشت، بخش مرکزی، شهرستان قائم‌شهر، استان مازندران، ایران
A11: تلفن ثابت | C11: 011-42116449
A12: تلفن همراه | C12: 0911-116-5751
A13: مدیرعامل | C13: قاسم زاهدی تیر
A14: سال مالی | C14: 1405 | H14: برای گزارش‌های ماهانه
A15: شروع سال مالی | C15: 1405/01/01 | H15: تاریخ شمسی
A16: واحد پول | C16: ریال | H16: ریال یا تومان — در همه فرمول‌ها یکسان
A17: یادداشت | C17: این اطلاعات به‌صورت خودکار در سرصفحه فایل‌های دیگر تکرار می‌شود.
A19: ۰۲ | B19: لوگو و سرصفحه — جای لوگو در همه فایل‌ها یکسان است
A20: جای لوگو Insert ← Picture (یکبار در هر فایل) | D20: سرصفحه همه فایل‌ها از همین مشخصات ساخته می‌شود: نام شرکت، نشانی، تلفن و سال مالی. برای تغییر، فقط همین شیت را ویرایش کنید و در فایل‌های دیگر Edit Links → Update Values بزنید. لوگو را می‌توانید در همین کادر درج کنید؛ فایل مادر مرجع ظاهر همه فایل‌هاست.

Sheet Par
A1: مازندشت — سورتینگ و بسته‌بندی مرکبات | B1: MAZANDASHT · CITRUS SORTING & PACKING
A2: پارامترهای محاسباتی
A3: منبع فرمول‌های همه فایل‌ها — مقدار زرد را تغییر دهید، همه‌جا خودکار به‌روز می‌شود
A4: راهنما | B4: ورود دستی | C4: خودکار | D4: ورود | E4: خروج
A5: سال مالی | C5: درصد افت خرید | E5: وزن سبد پیش‌فرض
A6: =IFERROR(VLOOKUP("P04",$A$10:$E$21,3,0),"") | C6: =IFERROR(VLOOKUP("P02",$A$10:$E$21,3,0),0) | E6: =IFERROR(VLOOKUP("P01",$A$10:$E$21,3,0),0)
A8: کد | B8: نام پارامتر | C8: مقدار | D8: واحد | E8: توضیح
A9: Code | B9: Parameter | C9: Value | D9: Unit | E9: Note
A10: P01 | B10: وزن سبد پیش‌فرض | C10: 1.5 | D10: کیلوگرم | E10: اگر نوع سبد انتخاب نشود، وزن تار این عدد است
A11: P02 | B11: درصد افت خرید | C11: 1 | D11: درصد | E11: از وزن خالص خرید مرکبات کسر می‌شود
A12: P03 | B12: واحد رند کردن مبلغ | C12: 1000 | D12: ریال | E12: مبلغ نهایی به نزدیک‌ترین مضرب این عدد رند می‌شود
A13: P04 | B13: سال مالی | C13: 1405 | D13: سال | E13: برای گزارش‌های ماهانه
A14: P05 | B14: حد هشدار موجودی سبد | C14: 100 | D14: عدد | E14: کمتر از این تعداد، هشدار موجودی
A15: P06 | B15: درصد کارمزد پوز | C15: 0 | D15: درصد | E15: در صورت کسر کارمزد از واریزی پوز
A16: P07 | B16: پیش‌شماره فاکتور خرید | C16: خرید- | D16: متن
A17: P08 | B17: پیش‌شماره فاکتور فروش | C17: فروش- | D17: متن
A18: P09 | B18: سقف اعتبار پیش‌فرض بارفروش | C18: 500000000 | D18: ریال | E18: برای هشدار اعتباری
A19: P10 | B19: مهلت چک | C19: 30 | D19: روز
A20: P11 | B20: واحد پول | C20: ریال | D20: متن
A21: P12 | B21: نمایش ردیف‌های صفر در ترازنامه | C21: خیر | D21: بله/خیر

Sheet Grp
A1: مازندشت — سورتینگ و بسته‌بندی مرکبات | F1: MAZANDASHT · CITRUS SORTING & PACKING
A2: گروه‌ها و زیرگروه‌های حساب
A3: هر گروه، پیشوند کد، شیت گزارش و رنگ اختصاصی خود را دارد — منبع کشوهای شیت حساب‌ها
A4: راهنما | B4: ورود دستی | C4: خودکار | D4: ورود | E4: خروج | F4: هشدار | G4: ستون‌های زرد = ورود شما | ستون‌های خاکستری = محاسبه خودکار | روی سرستون‌ها بایستید تا راهنما باز شود
A5: گروه‌های اصلی | D5: زیرگروه‌ها | G5: زیرگروه باغدار | J5: گروه‌های گزارشی
A6: 10 | D6: =COUNTIF($B$10:$B$52,"?*") | G6: =COUNTIF($B$10:$B$52,"سردرختی")+COUNTIF($B$10:$B$52,"انباری") | J6: =SUMPRODUCT(1/COUNTIF($D$10:$D$52,$D$10:$D$52))
A8: گروه اصلی | B8: زیرگروه | C8: پیشوند کد | D8: شیت گزارش | E8: رنگ | F8: توضیح | H8: گروه‌های اصلی (منبع کشو)
A9: Group | B9: Subgroup | C9: Prefix | D9: Report Sheet | E9: Color | F9: Note
A10: باغدار | B10: سردرختی | C10: C | D10: Growers | E10: mint | F10: مرکبات سردرختی تحویل باغ | H10: باغدار
A11: باغدار | B11: انباری | C11: C | D11: Growers | E11: mint | F11: مرکبات تحویل انبار | H11: بارفروش
A12: باغدار | B12: عمده | C12: C | D12: Growers | E12: mint | H12: فروشنده سبد
A13: باغدار | B13: خرده‌فروش | C13: C | D13: Growers | E13: mint | H13: تأمین‌کننده
A14: باغدار | B14: صادراتی | C14: C | D14: Growers | E14: mint | H14: کارمند
A15: باغدار | B15: میدان بار | C15: C | D15: Growers | E15: mint | H15: سایر حساب
A16: بارفروش | B16: میدان بار شهرستان | C16: SL | D16: LoadBuyers | E16: sky | F16: خریدار بار در شهرستان | H16: باسکول دیگران
A17: بارفروش | B17: حجره‌دار | C17: SL | D17: LoadBuyers | E17: sky | H17: دارایی ثابت
A18: بارفروش | B18: صادراتی | C18: SL | D18: LoadBuyers | E18: sky | H18: وام و تسهیلات
A19: بارفروش | B19: واسطه | C19: SL | D19: LoadBuyers | E19: sky | H19: سرمایه و آورده صاحبان
A20: بارفروش | B20: نقدی | C20: SL | D20: LoadBuyers | E20: sky | H20: بانک و صندوق
A21: فروشنده سبد | B21: سبد پلاستیکی | C21: S | D21: BasketSellers | E21: lavender
A22: فروشنده سبد | B22: سبد چوبی | C22: S | D22: BasketSellers | E22: lavender
A23: فروشنده سبد | B23: سبد مقوایی | C23: S | D23: BasketSellers | E23: lavender
A24: فروشنده سبد | B24: سایر | C24: S | D24: BasketSellers | E24: lavender
A25: تأمین‌کننده | B25: مواد بسته‌بندی | C25: S | D25: Suppliers | E25: peach
A26: تأمین‌کننده | B26: واکس و رنگ | C26: S | D26: Suppliers | E26: peach
A27: تأمین‌کننده | B27: حمل‌ونقل | C27: S | D27: Suppliers | E27: peach
A28: تأمین‌کننده | B28: خدمات | C28: S | D28: Suppliers | E28: peach
A29: کارمند | B29: مدیرعامل | C29: E | D29: Staff | E29: sand
A30: کارمند | B30: حسابدار | C30: E | D30: Staff | E30: sand
A31: کارمند | B31: فروشنده | C31: E | D31: Staff | E31: sand
A32: کارمند | B32: انباردار | C32: E | D32: Staff | E32: sand
... A34: کارمند | B34: کارگر | C34: E | D34: Staff | E34: sand
A35: سایر حساب | B35: صندوق | C35: X | D35: Other | E35: grey | F35: حساب معین
A36: سایر حساب | B36: موجودی | C36: X | D36: Other | E36: grey | F36: حساب معین
A37: سایر حساب | B37: درآمد | C37: X | D37: Other | E37: grey | F37: حساب معین
A38: سایر حساب | B38: هزینه | C38: X | D38: Other | E38: grey | F38: حساب معین
A39: سایر حساب | B39: انعام و پاداش | C39: X | D39: Other | E39: grey | F39: طرف حساب انعام مصطفی
A40: سایر حساب | B40: چک پرداختی | C40: X | D40: Other | E40: grey | F40: حساب معین چک‌های در جریان
A41: سایر حساب | B41: حساب واسط | C41: X | D41: Other | E41: grey | F41: حساب معین عملیات متفرقه
A42: سایر حساب | B42: مالیات | C42: X | D42: Other | E42: grey
...

Sheet Acc
A1: مازندشت — سورتینگ و بسته‌بندی مرکبات | I1: MAZANDASHT · CITRUS SORTING & PACKING
A2: دفتر حساب‌ها — همه صاحبان حساب در یک‌جا
A3: باغدار، بارفروش، فروشنده سبد، تأمین‌کننده، کارمند، باسکول دیگران و حساب‌های معین · کدها ثابت‌اند
A4: راهنما | B4: ورود دستی | C4: خودکار | D4: ورود | E4: خروج | F4: هشدار | G4: ستون‌های زرد = ورود شما | ستون‌های خاکستری = محاسبه خودکار | روی سرستون‌ها بایستید تا راهنما باز شود
A5: حساب‌های تعریف‌شده | D5: باغداران | G5: بارفروشان | J5: فروشندگان سبد | M5: مانده بدهکار افتتاحیه
A6: =COUNTIF($D$10:$D$259,"?*") | D6: =COUNTIF($B$10:$B$259,"باغدار") | G6: =COUNTIF($B$10:$B$259,"بارفروش") | J6: =COUNTIF($B$10:$B$259,"فروشنده سبد") | M6: =SUMIF($H$10:$H$259,">0")
A8: کد حساب | B8: گروه (ماهیت) | C8: زیرگروه | D8: نام صاحب حساب | E8: تلفن | F8: همراه | G8: نشانی | H8: مانده اولیه | I8: نوع حساب | J8: فعال | K8: گروه کد (خودکار) | L8: توضیحات | M8: بررسی
A9: Code | B9: Group | C9: Subgroup | D9: Account Holder | E9: Phone | F9: Mobile | G9: Address | H9: Opening | I9: Type | J9: Active | K9: راهنمای باسکول دیگران
A10: C001 | B10: باغدار | C10: عمده | D10: زینب زاهدی | E10: 011-33330001 | F10: 09110000001 | G10: بابل — میدان مرکبات | H10: 0 | I10: طرف حساب | J10: بله | K10: این اشخاص، طرف حساب «باسکول دیگران» هستند: در فایل 02_Bank با نوع «دریافت/پرداخت باسکول دیگران» انتخاب می‌شوند و مانده بدهی هر کدام در شیت Payable همان فایل و در گزارش گروه‌ها (01_Entry ← GRep) دیده می‌شود. برای شخص جدید، نخستین کد خالی BD را پر کنید.
A11: C002 | B11: باغدار | C11: صادراتی | D11: سید عباس موسوی | E11: 011-33330002 | F11: 09110000002 | G11: ساری — شهرک صنعتی | H11: 0 | I11: طرف حساب | J11: بله
A12: C003 | B12: باغدار | C12: خرده‌فروش | D12: حاج احمد عیسی پور | E12: 011-33330003 | F12: 09110000003 | G12: قائم‌شهر — خیابان طالب آملی | H12: 0 | I12: طرف حساب | J12: بله
A13: C004 | B13: باغدار | D13: امید زاهدی | H13: 0 | I13: طرف حساب | J13: بله
A14: C005 | B14: باغدار | D14: بار شخصی قاسم زاهدی | H14: 0 | I14: طرف حساب | J14: بله
A15: C006 | B15: باغدار | D15: هوشنگ عیسی پور | H15: 0 | I15: طرف حساب | J15: بله | K15: =IF($A15="","",IF(LEFT($A15,3)="CAP","سرمایه و آورده صاحبان",IF(LEFT($A15,2)="SL","بارفروش",IF(LEFT($A15,2)="BD","باسکول دیگران",IF(LEFT($A15,1)="C","باغدار",IF(LEFT($A15,1)="S","فروشنده سبد/تأمین‌کننده",IF(LEFT($A15,1)="E","کارمند",IF(LEFT($A15,1)="X","سایر حساب",IF(LEFT($A15,1)="F","دارایی ثابت",IF(LEFT($A15,1)="L","وام و تسهیلات","")))))))))) | M15: =IF(OR($B15="",$A15=""),"",IF(OR($B15=$K15,AND(LEFT($A15,1)="S",OR($B15="فروشنده سبد",$B15="تأمین‌کننده")),AND(LEFT($A15,2)="BD",$B15="باسکول دیگران")),"✓","⚠"))
A16: C007 | B16: باغدار | D16: علی آهنگر | H16: 0 | I16: طرف حساب | J16: بله | K16: =IF($A16="","",IF(LEFT($A16,3)="CAP","سرمایه و آورده صاحبان",IF(LEFT($A16,2)="SL","بارفروش",IF(LEFT($A16,2)="BD","باسکول دیگران",IF(LEFT($A16,1)="C","باغدار",IF(LEFT($A16,1)="S","فروشنده سبد/تأمین‌کننده",IF(LEFT($A16,1)="E","کارمند",IF(LEFT($A16,1)="X","سایر حساب",IF(LEFT($A16,1)="F","دارایی ثابت",IF(LEFT($A16,1)="L","وام و تسهیلات","")))))))))) | M16: =IF(OR($B16="",$A16=""),"",IF(OR($B16=$K16,AND(LEFT($A16,1)="S",OR($B16="فروشنده سبد",$B16="تأمین‌کننده")),AND(LEFT($A16,2)="BD",$B16="باسکول دیگران")),"✓","⚠"))
A17: C008 | B17: باغدار | D17: صفدر مسلمی | H17: 0 | I17: طرف حساب | J17: بله | K17: =IF($A17="","",IF(LEFT($A17,3)="CAP","سرمایه و آورده صاحبان",IF(LEFT($A17,2)="SL","بارفروش",IF(LEFT($A17,2)="BD","باسکول دیگران",IF(LEFT($A17,1)="C","باغدار",IF(LEFT($A17,1)="S","فروشنده سبد/تأمین‌کننده",IF(LEFT($A17,1)="E","کارمند",IF(LEFT($A17,1)="X","سایر حساب",IF(LEFT($A17,1)="F","دارایی ثابت",IF(LEFT($A17,1)="L","وام و تسهیلات","")))))))))) | M17: =IF(OR($B17="",$A17=""),"",IF(OR($B17=$K17,AND(LEFT($A17,1)="S",OR($B17="فروشنده سبد",$B17="تأمین‌کننده")),AND(LEFT($A17,2)="BD",$B17="باسکول دیگران")),"✓","⚠"))
A18: C009 | B18: باغدار | D18: همایون بابایی | H18: 0 | I18: طرف حساب | J18: بله | K18: =IF($A18="","",IF(LEFT($A18,3)="CAP","سرمایه و آورده صاحبان",IF(LEFT($A18,2)="SL","بارفروش",IF(LEFT($A18,2)="BD","باسکول دیگران",IF(LEFT($A18,1)="C","باغدار",IF(LEFT($A18,1)="S","فروشنده سبد/تأمین‌کننده",IF(LEFT($A18,1)="E","کارمند",IF(LEFT($A18,1)="X","سایر حساب",IF(LEFT($A18,1)="F","دارایی ثابت",IF(LEFT($A18,1)="L","وام و تسهیلات","")))))))))) | M18: =IF(OR($B18="",$A18=""),"",IF(OR($B18=$K18,AND(LEFT($A18,1)="S",OR($B18="فروشنده سبد",$B18="تأمین‌کننده")),AND(LEFT($A18,2)="BD",$B18="باسکول دیگران")),"✓","⚠"))
A19: C010 | B19: باغدار | D19: دبیر فرجی | H19: 0 | I19: طرف حساب | J19: بله | K19: =IF($A19="","",IF(LEFT($A19,3)="CAP","سرمایه و آورده صاحبان",IF(LEFT($A19,2)="SL","بارفروش",IF(LEFT($A19,2)="BD","باسکول دیگران",IF(LEFT($A19,1)="C","باغدار",IF(LEFT($A19,1)="S","فروشنده سبد/تأمین‌کننده",IF(LEFT($A19,1)="E","کارمند",IF(LEFT($A19,1)="X","سایر حساب",IF(LEFT($A19,1)="F","دارایی ثابت",IF(LEFT($A19,1)="L","وام و تسهیلات","")))))))))) | M19: =IF(OR($B19="",$A19=""),"",IF(OR($B19=$K19,AND(LEFT($A19,1)="S",OR($B19="فروشنده سبد",$B19="تأمین‌کننده")),AND(LEFT($A19,2)="BD",$B19="باسکول دیگران")),"✓","⚠"))
A20: C011 | B20: باغدار | D20: محمود علیجانی | H20: 0 | I20: طرف حساب | J20: بله | K20: =IF($A20="","",IF(LEFT($A20,3)="CAP","سرمایه و آورده صاحبان",IF(LEFT($A20,2)="SL","بارفروش",IF(LEFT($A20,2)="BD","باسکول دیگران",IF(LEFT($A20,1)="C","باغدار",IF(LEFT($A20,1)="S","فروشنده سبد/تأمین‌کننده",IF(LEFT($A20,1)="E","کارمند",IF(LEFT($A20,1)="X","سایر حساب",IF(LEFT($A20,1)="F","دارایی ثابت",IF(LEFT($A20,1)="L","وام و تسهیلات","")))))))))) | M20: =IF(OR($B20="",$A20=""),"",IF(OR($B20=$K20,AND(LEFT($A20,1)="S",OR($B20="فروشنده سبد",$B20="تأمین‌کننده")),AND(LEFT($A20,2)="BD",$B20="باسکول دیگران")),"✓","⚠"))
A21: C012 | B21: باغدار | D21: افشین بشتکار | H21: 0 | I21: طرف حساب | J21: بله | K21: =IF($A21="","",IF(LEFT($A21,3)="CAP","سرمایه و آورده صاحبان",IF(LEFT($A21,2)="SL","بارفروش",IF(LEFT($A21,2)="BD","باسکول دیگران",IF(LEFT($A21,1)="C","باغدار",IF(LEFT($A21,1)="S","فروشنده سبد/تأمین‌کننده",IF(LEFT($A21,1)="E","کارمند",IF(LEFT($A21,1)="X","سایر حساب",IF(LEFT($A21,1)="F","دارایی ثابت",IF(LEFT($A21,1)="L","وام و تسهیلات","")))))))))) | M21: =IF(OR($B21="",$A21=""),"",IF(OR($B21=$K21,AND(LEFT($A21,1)="S",OR($B21="فروشنده سبد",$B21="تأمین‌کننده")),AND(LEFT($A21,2)="BD",$B21="باسکول دیگران")),"✓","⚠"))
A22: C013 | B22: باغدار | D22: میرقربان موسویان | H22: 0 | I22: طرف حساب | J22: بله | K22: =IF($A22="","",IF(LEFT($A22,3)="CAP","سرمایه و آورده صاحبان",IF(LEFT($A22,2)="SL","بارفروش",IF(LEFT($A22,2)="BD","باسکول دیگران",IF(LEFT($A22,1)="C","باغدار",IF(LEFT($A22,1)="S","فروشنده سبد/تأمین‌کننده",IF(LEFT($A22,1)="E","کارمند",IF(LEFT($A22,1)="X","سایر حساب",IF(LEFT($A22,1)="F","دارایی ثابت",IF(LEFT($A22,1)="L","وام و تسهیلات","")))))))))) | M22: =IF(OR($B22="",$A22=""),"",IF(OR($B22=$K22,AND(LEFT($A22,1)="S",OR($B22="فروشنده سبد",$B22="تأمین‌کننده")),AND(LEFT($A22,2)="BD",$B22="باسکول دیگران")),"✓","⚠"))
A23: C014 | B23: باغدار | D23: باباجانی (تراجیکلا) | H23: 0 | I23: طرف حساب | J23: بله | K23: =IF($A23="","",IF(LEFT($A23,3)="CAP","سرمایه و آورده صاحبان",IF(LEFT($A23,2)="SL","بارفروش",IF(LEFT($A23,2)="BD","باسکول دیگران",IF(LEFT($A23,1)="C","باغدار",IF(LEFT($A23,1)="S","فروشنده سبد/تأمین‌کننده",IF(LEFT($A23,1)="E","کارمند",IF(LEFT($A23,1)="X","سایر حساب",IF(LEFT($A23,1)="F","دارایی ثابت",IF(LEFT($A23,1)="L","وام و تسهیلات","")))))))))) | M23: =IF(OR($B23="",$A23=""),"",IF(OR($B23=$K23,AND(LEFT($A23,1)="S",OR($B23="فروشنده سبد",$B23="تأمین‌کننده")),AND(LEFT($A23,2)="BD",$B23="باسکول دیگران")),"✓","⚠"))
A24: C015 | B24: باغدار | D24: کاظم میرزازاده | H24: 0 | I24: طرف حساب | J24: بله | K24: =IF($A24="","",IF(LEFT($A24,3)="CAP","سرمایه و آورده صاحبان",IF(LEFT($A24,2)="SL","بارفروش",IF(LEFT($A24,2)="BD","باسکول دیگران",IF(LEFT($A24,1)="C","باغدار",IF(LEFT($A24,1)="S","فروشنده سبد/تأمین‌کننده",IF(LEFT($A24,1)="E","کارمند",IF(LEFT($A24,1)="X","سایر حساب",IF(LEFT($A24,1)="F","دارایی ثابت",IF(LEFT($A24,1)="L","وام و تسهیلات","")))))))))) | M24: =IF(OR($B24="",$A24=""),"",IF(OR($B24=$K24,AND(LEFT($A24,1)="S",OR($B24="فروشنده سبد",$B24="تأمین‌کننده")),AND(LEFT($A24,2)="BD",$B24="باسکول دیگران")),"✓","⚠"))
A25: C016 | B25: باغدار | D25: علی جانبرارپور | H25: 0 | I25: طرف حساب | J25: بله | K25: =IF($A25="","",IF(LEFT($A25,3)="CAP","سرمایه و آورده صاحبان",IF(LEFT($A25,2)="SL","بارفروش",IF(LEFT($A25,2)="BD","باسکول دیگران",IF(LEFT($A25,1)="C","باغدار",IF(LEFT($A25,1)="S","فروشنده سبد/تأمین‌کننده",IF(LEFT($A25,1)="E","کارمند",IF(LEFT($A25,1)="X","سایر حساب",IF(LEFT($A25,1)="F","دارایی ثابت",IF(LEFT($A25,1)="L","وام و تسهیلات","")))))))))) | M25: =IF(OR($B25="",$A25=""),"",IF(OR($B25=$K25,AND(LEFT($A25,1)="S",OR($B25="فروشنده سبد",$B25="تأمین‌کننده")),AND(LEFT($A25,2)="BD",$B25="باسکول دیگران")),"✓","⚠"))
A26: C017 | B26: باغدار | D26: لیلا محمودنیا | H26: 0 | I26: طرف حساب | J26: بله | K26: =IF($A26="","",IF(LEFT($A26,3)="CAP","سرمایه و آورده صاحبان",IF(LEFT($A26,2)="SL","بارفروش",IF(LEFT($A26,2)="BD","باسکول دیگران",IF(LEFT($A26,1)="C","باغدار",IF(LEFT($A26,1)="S","فروشنده سبد/تأمین‌کننده",IF(LEFT($A26,1)="E","کارمند",IF(LEFT($A26,1)="X","سایر حساب",IF(LEFT($A26,1)="F","دارایی ثابت",IF(LEFT($A26,1)="L","وام و تسهیلات","")))))))))) | M26: =IF(OR($B26="",$A26=""),"",IF(OR($B26=$K26,AND(LEFT($A26,1)="S",OR($B26="فروشنده سبد",$B26="تأمین‌کننده")),AND(LEFT($A26,2)="BD",$B26="باسکول دیگران")),"✓","⚠"))
... A66: C057 | B66: باغدار | D66: کبری اصغرنیا | H66: 0 | I66: طرف حساب | J66: بله | K66: =IF($A66="","",IF(LEFT($A66,3)="CAP","سرمایه و آورده صاحبان",IF(LEFT($A66,2)="SL","بارفروش",IF(LEFT($A66,2)="BD","باسکول دیگران",IF(LEFT($A66,1)="C","باغدار",IF(LEFT($A66,1)="S","فروشنده سبد/تأمین‌کننده",IF(LEFT($A66,1)="E","کارمند",IF(LEFT($A66,1)="X","سایر حساب",IF(LEFT($A66,1)="F","دارایی ثابت",IF(LEFT($A66,1)="L","وام و تسهیلات","")))))))))) | M66: =IF(OR($B66="",$A66=""),"",IF(OR($B66=$K66,AND(LEFT($A66,1)="S",OR($B66="فروشنده سبد",$B66="تأمین‌کننده")),AND(LEFT($A66,2)="BD",$B66="باسکول دیگران")),"✓","⚠"))
A67: SL001 | B67: بارفروش | C67: میدان بار شهرستان | D67: قم — سید حسین حسینی | F67: 9125528445 | G67: قم، میدان تره‌بار، بلوک ۴، غرفه ۲۲ | H67: 0 | I67: طرف حساب | J67: بله | K67: =IF($A67="","",IF(LEFT($A67,3)="CAP","سرمایه و آورده صاحبان",IF(LEFT($A67,2)="SL","بارفروش",IF(LEFT($A67,2)="BD","باسکول دیگران",IF(LEFT($A67,1)="C","باغدار",IF(LEFT($A67,1)="S","فروشنده سبد/تأمین‌کننده",IF(LEFT($A67,1)="E","کارمند",IF(LEFT($A67,1)="X","سایر حساب",IF(LEFT($A67,1)="F","دارایی ثابت",IF(LEFT($A67,1)="L","وام و تسهیلات","")))))))))) | L67: خریدار بار — فروش خروجی باسکول | M67: =IF(OR($B67="",$A67=""),"",IF(OR($B67=$K67,AND(LEFT($A67,1)="S",OR($B67="فروشنده سبد",$B67="تأمین‌کننده")),AND(LEFT($A67,2)="BD",$B67="باسکول دیگران")),"✓","⚠"))
A68: SL002 | B68: بارفروش | C68: میدان بار شهرستان | D68: مشهد — محمد توکلی | F68: 9154018185 | G68: مشهد، میدان بار سپاد، تالار ۶، حجره ۱۵ | H68: 0 | I68: طرف حساب | J68: بله | K68: =IF($A68="","",IF(LEFT($A68,3)="CAP","سرمایه و آورده صاحبان",IF(LEFT($A68,2)="SL","بارفروش",IF(LEFT($A68,2)="BD","باسکول دیگران",IF(LEFT($A68,1)="C","باغدار",IF(LEFT($A68,1)="S","فروشنده سبد/تأمین‌کننده",IF(LEFT($A68,1)="E","کارمند",IF(LEFT($A68,1)="X","سایر حساب",IF(LEFT($A68,1)="F","دارایی ثابت",IF(LEFT($A68,1)="L","وام و تسهیلات","")))))))))) | L68: خریدار بار — فروش خروجی باسکول | M68: =IF(OR($B68="",$A68=""),"",IF(OR($B68=$K68,AND(LEFT($A68,1)="S",OR($B68="فروشنده سبد",$B68="تأمین‌کننده")),AND(LEFT($A68,2)="BD",$B68="باسکول دیگران")),"✓","⚠"))
A69: SL003 | B69: بارفروش | C69: میدان بار شهرستان | D69: اراک — پوریا خوش‌نمکیان | F69: 9369182495 | G69: اراک، میدان بار، فاز ۲، سالن شهید رجایی، حجره ۶ | H69: 0 | I69: طرف حساب | J69: بله | K69: =IF($A69="","",IF(LEFT($A69,3)="CAP","سرمایه و آورده صاحبان",IF(LEFT($A69,2)="SL","بارفروش",IF(LEFT($A69,2)="BD","باسکول دیگران",IF(LEFT($A69,1)="C","باغدار",IF(LEFT($A69,1)="S","فروشنده سبد/تأمین‌کننده",IF(LEFT($A69,1)="E","کارمند",IF(LEFT($A69,1)="X","سایر حساب",IF(LEFT($A69,1)="F","دارایی ثابت",IF(LEFT($A69,1)="L","وام و تسهیلات","")))))))))) | L69: خریدار بار — فروش خروجی باسکول | M69: =IF(OR($B69="",$A69=""),"",IF(OR($B69=$K69,AND(LEFT($A69,1)="S",OR($B69="فروشنده سبد",$B69="تأمین‌کننده")),AND(LEFT($A69,2)="BD",$B69="باسکول دیگران")),"✓","⚠"))
A70: SL004 | B70: بارفروش | C70: میدان بار شهرستان | D70: تبریز — نورزاده | H70: 0 | I70: طرف حساب | J70: بله | K70: =IF($A70="","",IF(LEFT($A70,3)="CAP","سرمایه و آورده صاحبان",IF(LEFT($A70,2)="SL","بارفروش",IF(LEFT($A70,2)="BD","باسکول دیگران",IF(LEFT($A70,1)="C","باغدار",IF(LEFT($A70,1)="S","فروشنده سبد/تأمین‌کننده",IF(LEFT($A70,1)="E","کارمند",IF(LEFT($A70,1)="X","سایر حساب",IF(LEFT($A70,1)="F","دارایی ثابت",IF(LEFT($A70,1)="L","وام و تسهیلات","")))))))))) | L70: خریدار بار — فروش خروجی باسکول | M70: =IF(OR($B70="",$A70=""),"",IF(OR($B70=$K70,AND(LEFT($A70,1)="S",OR($B70="فروشنده سبد",$B70="تأمین‌کننده")),AND(LEFT($A70,2)="BD",$B70="باسکول دیگران")),"✓","⚠"))
A71: SL005 | B71: بارفروش | C71: میدان بار شهرستان | D71: زنجان — خانی | H71: 0 | I71: طرف حساب | J71: بله | K71: =IF($A71="","",IF(LEFT($A71,3)="CAP","سرمایه و آورده صاحبان",IF(LEFT($A71,2)="SL","بارفروش",IF(LEFT($A71,2)="BD","باسکول دیگران",IF(LEFT($A71,1)="C","باغدار",IF(LEFT($A71,1)="S","فروشنده سبد/تأمین‌کننده",IF(LEFT($A71,1)="E","کارمند",IF(LEFT($A71,1)="X","سایر حساب",IF(LEFT($A71,1)="F","دارایی ثابت",IF(LEFT($A71,1)="L","وام و تسهیلات","")))))))))) | L71: خریدار بار — فروش خروجی باسکول | M71: =IF(OR($B71="",$A71=""),"",IF(OR($B71=$K71,AND(LEFT($A71,1)="S",OR($B71="فروشنده سبد",$B71="تأمین‌کننده")),AND(LEFT($A71,2)="BD",$B71="باسکول دیگران")),"✓","⚠"))
A72: S001 | B72: فروشنده سبد | C72: سبد پلاستیکی | D72: حسن کوچک‌زاده | E72: 011-44440001 | F72: 09110000004 | G72: باغدشت | H72: 0 | I72: طرف حساب | J72: بله | K72: =IF($A72="","",IF(LEFT($A72,3)="CAP","سرمایه و آورده صاحبان",IF(LEFT($A72,2)="SL","بارفروش",IF(LEFT($A72,2)="BD","باسکول دیگران",IF(LEFT($A72,1)="C","باغدار",IF(LEFT($A72,1)="S","فروشنده سبد/تأمین‌کننده",IF(LEFT($A72,1)="E","کارمند",IF(LEFT($A72,1)="X","سایر حساب",IF(LEFT($A72,1)="F","دارایی ثابت",IF(LEFT($A72,1)="L","وام و تسهیلات","")))))))))) | L72: خرید سبد از باغ | M72: =IF(OR($B72="",$A72=""),"",IF(OR($B72=$K72,AND(LEFT($A72,1)="S",OR($B72="فروشنده سبد",$B72="تأمین‌کننده")),AND(LEFT($A72,2)="BD",$B72="باسکول دیگران")),"✓","⚠"))
A73: S002 | B73: فروشنده سبد | C73: سبد پلاستیکی | D73: سید محمد موسویان | E73: 011-44440002 | F73: 09110000005 | G73: قائم‌شهر — میدان بار | H73: 0 | I73: طرف حساب | J73: بله | K73: =IF($A73="","",IF(LEFT($A73,3)="CAP","سرمایه و آورده صاحبان",IF(LEFT($A73,2)="SL","بارفروش",IF(LEFT($A73,2)="BD","باسکول دیگران",IF(LEFT($A73,1)="C","باغدار",IF(LEFT($A73,1)="S","فروشنده سبد/تأمین‌کننده",IF(LEFT($A73,1)="E","کارمند",IF(LEFT($A73,1)="X","سایر حساب",IF(LEFT($A73,1)="F","دارایی ثابت",IF(LEFT($A73,1)="L","وام و تسهیلات","")))))))))) | L73: خرید سبد از میدان بار | M73: =IF(OR($B73="",$A73=""),"",IF(OR($B73=$K73,AND(LEFT($A73,1)="S",OR($B73="فروشنده سبد",$B73="تأمین‌کننده")),AND(LEFT($A73,2)="BD",$B73="باسکول دیگران")),"✓","⚠"))
A74: S003 | B74: فروشنده سبد | C74: سبد پلاستیکی | D74: سید ربیع موسویان | H74: 0 | I74: طرف حساب | J74: بله | K74: =IF($A74="","",IF(LEFT($A74,3)="CAP","سرمایه و آورده صاحبان",IF(LEFT($A74,2)="SL","بارفروش",IF(LEFT($A74,2)="BD","باسکول دیگران",IF(LEFT($A74,1)="C","باغدار",IF(LEFT($A74,1)="S","فروشنده سبد/تأمین‌کننده",IF(LEFT($A74,1)="E","کارمند",IF(LEFT($A74,1)="X","سایر حساب",IF(LEFT($A74,1)="F","دارایی ثابت",IF(LEFT($A74,1)="L","وام و تسهیلات","")))))))))) | M74: =IF(OR($B74="",$A74=""),"",IF(OR($B74=$K74,AND(LEFT($A74,1)="S",OR($B74="فروشنده سبد",$B74="تأمین‌کننده")),AND(LEFT($A74,2)="BD",$B74="باسکول دیگران")),"✓","⚠"))
A75: E001 | B75: کارمند | C75: مدیرعامل | D75: قاسم زاهدی تیر | F75: 09110000010 | G75: قائم‌شهر | H75: 0 | I75: طرف حساب | J75: بله | K75: =IF($A75="","",IF(LEFT($A75,3)="CAP","سرمایه و آورده صاحبان",IF(LEFT($A75,2)="SL","بارفروش",IF(LEFT($A75,2)="BD","باسکول دیگران",IF(LEFT($A75,1)="C","باغدار",IF(LEFT($A75,1)="S","فروشنده سبد/تأمین‌کننده",IF(LEFT($A75,1)="E","کارمند",IF(LEFT($A75,1)="X","سایر حساب",IF(LEFT($A75,1)="F","دارایی ثابت",IF(LEFT($A75,1)="L","وام و تسهیلات","")))))))))) | L75: مدیرعامل شرکت | M75: =IF(OR($B75="",$A75=""),"",IF(OR($B75=$K75,AND(LEFT($A75,1)="S",OR($B75="فروشنده سبد",$B75="تأمین‌کننده")),AND(LEFT($A75,2)="BD",$B75="باسکول دیگران")),"✓","⚠"))
A76: E002 | B76: کارمند | C76: حسابدار | D76: (نام حسابدار) | F76: 09110000011 | G76: قائم‌شهر | H76: 0 | I76: طرف حساب | J76: بله | K76: =IF($A76="","",IF(LEFT($A76,3)="CAP","سرمایه و آورده صاحبان",IF(LEFT($A76,2)="SL","بارفروش",IF(LEFT($A76,2)="BD","باسکول دیگران",IF(LEFT($A76,1)="C","باغدار",IF(LEFT($A76,1)="S","فروشنده سبد/تأمین‌کننده",IF(LEFT($A76,1)="E","کارمند",IF(LEFT($A76,1)="X","سایر حساب",IF(LEFT($A76,1)="F","دارایی ثابت",IF(LEFT($A76,1)="L","وام و تسهیلات","")))))))))) | M76: =IF(OR($B76="",$A76=""),"",IF(OR($B76=$K76,AND(LEFT($A76,1)="S",OR($B76="فروشنده سبد",$B76="تأمین‌کننده")),AND(LEFT($A76,2)="BD",$B76="باسکول دیگران")),"✓","⚠"))
A77: E003 | B77: کارمند | C77: فروشنده | D77: (نام فروشنده ۱) | F77: 09110000012 | G77: قائم‌شهر | H77: 0 | I77: طرف حساب | J77: بله | K77: =IF($A77="","",IF(LEFT($A77,3)="CAP","سرمایه و آورده صاحبان",IF(LEFT($A77,2)="SL","بارفروش",IF(LEFT($A77,2)="BD","باسکول دیگران",IF(LEFT($A77,1)="C","باغدار",IF(LEFT($A77,1)="S","فروشنده سبد/تأمین‌کننده",IF(LEFT($A77,1)="E","کارمند",IF(LEFT($A77,1)="X","سایر حساب",IF(LEFT($A77,1)="F","دارایی ثابت",IF(LEFT($A77,1)="L","وام و تسهیلات","")))))))))) | M77: =IF(OR($B77="",$A77=""),"",IF(OR($B77=$K77,AND(LEFT($A77,1)="S",OR($B77="فروشنده سبد",$B77="تأمین‌کننده")),AND(LEFT($A77,2)="BD",$B77="باسکول دیگران")),"✓","⚠"))
A78: E004 | B78: کارمند | C78: انباردار | D78: (نام انباردار) | F78: 09110000013 | G78: قائم‌شهر | H78: 0 | I78: طرف حساب | J78: بله | K78: =IF($A78="","",IF(LEFT($A78,3)="CAP","سرمایه و آورده صاحبان",IF(LEFT($A78,2)="SL","بارفروش",IF(LEFT($A78,2)="BD","باسکول دیگران",IF(LEFT($A78,1)="C","باغدار",IF(LEFT($A78,1)="S","فروشنده سبد/تأمین‌کننده",IF(LEFT($A78,1)="E","کارمند",IF(LEFT($A78,1)="X","سایر حساب",IF(LEFT($A78,1)="F","دارایی ثابت",IF(LEFT($A78,1)="L","وام و تسهیلات","")))))))))) | M78: =IF(OR($B78="",$A78=""),"",IF(OR($B78=$K78,AND(LEFT($A78,1)="S",OR($B78="فروشنده سبد",$B78="تأمین‌کننده")),AND(LEFT($A78,2)="BD",$B78="باسکول دیگران")),"✓","⚠"))
A79: E005 | B79: کارمند | C79: سرپرست خط | D79: رضا کاظمی (نمونه) | F79: 09110000014 | G79: قائم‌شهر | H79: 0 | I79: طرف حساب | J79: بله | K79: =IF($A79="","",IF(LEFT($A79,3)="CAP","سرمایه و آورده صاحبان",IF(LEFT($A79,2)="SL","بارفروش",IF(LEFT($A79,2)="BD","باسکول دیگران",IF(LEFT($A79,1)="C","باغدار",IF(LEFT($A79,1)="S","فروشنده سبد/تأمین‌کننده",IF(LEFT($A79,1)="E","کارمند",IF(LEFT($A79,1)="X","سایر حساب",IF(LEFT($A79,1)="F","دارایی ثابت",IF(LEFT($A79,1)="L","وام و تسهیلات","")))))))))) | L79: نمونه — گروه سالن ۱ | M79: =IF(OR($B79="",$A79=""),"",IF(OR($B79=$K79,AND(LEFT($A79,1)="S",OR($B79="فروشنده سبد",$B79="تأمین‌کننده")),AND(LEFT($A79,2)="BD",$B79="باسکول دیگران")),"✓","⚠"))
A80: E006 | B80: کارمند | C80: کارگر | D80: علی احمدی (نمونه) | F80: 09110000015 | G80: قائم‌شهر | H80: 0 | I80: طرف حساب | J80: بله | K80: =IF($A80="","",IF(LEFT($A80,3)="CAP","سرمایه و آورده صاحبان",IF(LEFT($A80,2)="SL","بارفروش",IF(LEFT($A80,2)="BD","باسکول دیگران",IF(LEFT($A80,1)="C","باغدار",IF(LEFT($A80,1)="S","فروشنده سبد/تأمین‌کننده",IF(LEFT($A80,1)="E","کارمند",IF(LEFT($A80,1)="X","سایر حساب",IF(LEFT($A80,1)="F","دارایی ثابت",IF(LEFT($A80,1)="L","وام و تسهیلات","")))))))))) | L80: نمونه — گروه سالن ۱ | M80: =IF(OR($B80="",$A80=""),"",IF(OR($B80=$K80,AND(LEFT($A80,1)="S",OR($B80="فروشنده سبد",$B80="تأمین‌کننده")),AND(LEFT($A80,2)="BD",$B80="باسکول دیگران")),"✓","⚠"))
...

Sheet Op
A1: مازندشت — سورتینگ و بسته‌بندی مرکبات | O1: MAZANDASHT · CITRUS SORTING & PACKING
A2: قواعد عملیات — موتور بدهکار/بستانکار سامانه
A3: هر عملیات یک جهت، یک دسته، الزامات و سمت‌های حساب دارد · تغییر این شیت، رفتار همه فایل‌ها را عوض می‌کند
A4: راهنما | B4: ورود دستی | C4: خودکار | D4: ورود | E4: خروج | F4: هشدار | G4: ستون‌های زرد = ورود شما | ستون‌های خاکستری = محاسبه خودکار | روی سرستون‌ها بایستید تا راهنما باز شود
A5: عملیات تعریف‌شده | E5: عملیات فعال | I5: در کشوی باسکول | M5: عملیات سبد | Q5: عملیات پوز
A6: =COUNTIF($B$10:$B$33,"?*") | E6: =COUNTIF($S$10:$S$33,"بله") | I6: =COUNTIF($P$10:$P$33,"بله") | M6: =COUNTIF($B$10:$B$33,"*سبد*") | Q6: =COUNTIF($L$10:$L$33,"بدهکار")+COUNTIF($L$10:$L$33,"بستانکار")
A7: شناسه عملیات | C7: جهت و دسته | E7: الزامات و طرف حساب | I7: حساب معین | K7: مبلغ دستی و پوز | O7: طرف ثابت | P7: نمایش | R7: توضیح / فعال
A8: کد | B8: عنوان عملیات | C8: جهت | D8: دسته | E8: وزن لازم؟ | F8: حساب طرف؟ | G8: مبنای مبلغ طرف | H8: سمت حساب طرف | I8: حساب معین | J8: سمت معین | K8: نقش مبلغ دستی | L8: اثر پوز | M8: بانک پوز | N8: حساب مقابل پوز | O8: حساب طرف ثابت | P8: در باسکول؟ | Q8: رنگ | R8: توضیح و قاعده | S8: فعال
A9: Code | B9: Operation | C9: Direction | D9: Category | E9: Weight? | F9: Party? | G9: Party Basis | H9: Party Side | I9: Ledger | J9: Ledger Side | K9: Manual Role | L9: POS Effect | M9: POS Bank | N9: POS Counter | O9: Fixed Party | P9: In Baskol | Q9: Color | R9: Rule | S9: Active
A10: OP01 | B10: خرید مرکبات | C10: ورود | D10: خرید | E10: بله | F10: بله | G10: وزن | H10: بستانکار | I10: X004 | J10: بدهکار | K10: افزودن | L10: — | P10: بله | Q10: mint | R10: بدهکار: موجودی مرکبات | بستانکار: حساب باغدار. مبلغ ستون «مبلغ دستی» به بستانکاری باغدار اضافه می‌شود (کرایه/سایر). | S10: بله
A11: OP02 | B11: فروش بار (بارفروش) | C11: خروج | D11: فروش | E11: بله | F11: بله | G11: وزن | H11: بدهکار | I11: X006 | J11: بستانکار | K11: پوز | L11: بدهکار | M11: BN02 | N11: X002 | P11: بله | Q11: sky | R11: بدهکار: حساب بارفروش | بستانکار: فروش مرکبات. مبلغ ستون «پوز/دستی» فقط هزینه باسکول است: بدهکار صادرات ۲۰۰۶ / بستانکار درآمد باسکول؛ به حساب بارفروش کاری ندارد. | S11: بله
A12: OP03 | B12: فروش متفرقه / صادراتی | C12: خروج | D12: فروش | E12: بله | F12: بله | G12: وزن | H12: بدهکار | I12: X006 | J12: بستانکار | K12: پوز | L12: بدهکار | M12: BN02 | N12: X002 | P12: بله | Q12: sky | R12: مانند فروش بار؛ برای حجره‌دار و صادراتی. | S12: بله
A13: OP04 | B13: آبگیری | C13: خروج | D13: آبگیری | E13: بله | F13: بله | G13: مبلغ | H13: خودکار | I13: X008 | J13: خودکار | K13: هیچ | L13: — | P13: بله | Q13: lavender | R13: هم وزن و هم مبلغ وارد می‌شود. سمت حساب را خودتان (بدهکار/بستانکار) در ستون «سمت حساب» انتخاب کنید؛ طرف مقابل حساب درآمد آبگیری است. | S13: بله
A14: OP05 | B14: انعام مصطفی | C14: — | D14: انعام | E14: خیر | F14: خیر | G14: مبلغ | H14: بستانکار | I14: BN02 | J14: بدهکار | K14: هیچ | L14: — | O14: X001 | P14: بله | Q14: rose | R14: فقط مبلغ. بدهکار: صادرات ۲۰۰۶ (پوز باسکول) | بستانکار: انعام مصطفی. با هر انتقال/پرداخت به ایشان در شیت Payment تسویه می‌شود. | S14: بله
A15: OP06 | B15: باسکول دیگران | C15: — | D15: باسکول دیگران | E15: خیر | F15: بله | G15: مبلغ | H15: بدهکار | I15: X002 | J15: بستانکار | K15: هیچ | L15: — | P15: بله | Q15: sand | R15: فقط مبلغ. بدهکار: حساب صاحب باسکول دیگر (گروه باسکول دیگران) | بستانکار: درآمد باسکول. | S15: بله
A16: OP07 | B16: درآمد پوز باسکول (بدون طرف) | C16: — | D16: درآمد | E16: خیر | F16: خیر | G16: مبلغ | H16: — | J16: — | K16: پوز | L16: بدهکار | M16: BN02 | N16: X002 | P16: بله | Q16: sand | R16: فقط مبلغ. بدهکار: صادرات ۲۰۰۶ | بستانکار: درآمد باسکول. برای هزینه باسکول نقدی/POS بدون بار. | S16: بله
A17: OP08 | B17: مرجوعی خرید | C17: خروج | D17: خرید | E17: بله | F17: بله | G17: وزن | H17: بدهکار | I17: X004 | J17: بستانکار | K17: افزودن | L17: — | P17: بله | Q17: grey | R17: برگشت بار به باغدار: بدهکار باغدار | بستانکار موجودی مرکبات. | S17: بله
A18: OP09 | B18: مرجوعی فروش | C18: ورود | D18: فروش | E18: بله | F18: بله | G18: وزن | H18: بستانکار | I18: X006 | J18: بدهکار | K18: هیچ | L18: — | P18: بله | Q18: grey | R18: برگشت بار از بارفروش: بستانکار بارفروش | بدهکار فروش مرکبات. | S18: بله
A19: OP10 | B19: ضایعات / افت انبار | C19: خروج | D19: هزینه | E19: بله | F19: بله | G19: وزن | H19: بستانکار | I19: X009 | J19: بدهکار | K19: هیچ | L19: — | O19: X004 | P19: بله | Q19: grey | R19: فقط وزن و فی. طرف حساب ثابت = موجودی مرکبات (بستانکار) | هزینه ضایعات (بدهکار). | S19: بله
A20: OP11 | B20: انتقال بین انبار | C20: خروج | D20: انتقال | E20: بله | F20: خیر | G20: هیچ | H20: — | J20: — | K20: هیچ | L20: — | P20: بله | Q20: teal | R20: فقط برای کنترل فیزیکی؛ سند مالی ندارد. | S20: بله
A21: OP12 | B21: سایر ورود | C21: ورود | D21: سایر | E21: بله | F21: بله | G21: وزن | H21: بستانکار | I21: X011 | J21: بدهکار | K21: افزودن | L21: — | P21: بله | Q21: sand | R21: ورود متفرقه با طرف حساب؛ به حساب واسط می‌رود تا بعداً طبقه‌بندی شود. | S21: بله
A22: OP13 | B22: سایر خروج | C22: خروج | D22: سایر | E22: بله | F22: بله | G22: وزن | H22: بدهکار | I22: X011 | J22: بستانکار | K22: هیچ | L22: — | P22: بله | Q22: sand | R22: خروج متفرقه با طرف حساب؛ به حساب واسط می‌رود. | S22: بله
A23: OP14 | B23: هزینه باسکول نقدی (درآمد) | C23: — | D23: درآمد | E23: خیر | F23: خیر | G23: مبلغ | H23: — | J23: — | K23: پوز | L23: بدهکار | M23: BN02 | N23: X002 | P23: بله | Q23: sand | R23: دریافت هزینه باسکول از مشتری بدون بار؛ بدهکار صادرات ۲۰۰۶ / بستانکار درآمد باسکول. | S23: بله
A24: OP15 | B24: خرید سبد | C24: ورود | D24: خرید | E24: خیر | F24: بله | G24: مبلغ | H24: بستانکار | I24: X005 | J24: بدهکار | K24: هیچ | L24: — | P24: خیر | Q24: lavender | R24: خرید سبد از فروشنده سبد: بدهکار موجودی سبد | بستانکار فروشنده سبد. | S24: بله
A25: OP16 | B25: فروش سبد | C25: خروج | D25: فروش | E25: خیر | F25: بله | G25: مبلغ | H25: بدهکار | I25: X007 | J25: بستانکار | K25: هیچ | L25: — | P25: خیر | Q25: lavender | R25: فروش سبد: بدهکار خریدار | بستانکار درآمد فروش سبد. | S25: بله
A26: OP17 | B26: مرجوعی خرید سبد | C26: خروج | D26: خرید | E26: خیر | F26: بله | G26: مبلغ | H26: بدهکار | I26: X005 | J26: بستانکار | K26: هیچ | L26: — | P26: خیر | Q26: lavender | R26: برگشت سبد به فروشنده: بدهکار فروشنده | بستانکار موجودی سبد. | S26: بله
A27: OP18 | B27: مرجوعی فروش سبد | C27: ورود | D27: فروش | E27: خیر | F27: بله | G27: مبلغ | H27: بستانکار | I27: X007 | J27: بدهکار | K27: هیچ | L27: — | P27: خیر | Q27: lavender | R27: برگشت سبد از خریدار: بستانکار خریدار | بدهکار فروش سبد. | S27: بله
A28: OP19 | B28: انتقال سبد بین انبار | C28: خروج | D28: انتقال | E28: خیر | F28: خیر | G28: هیچ | H28: — | J28: — | K28: هیچ | L28: — | P28: خیر | Q28: grey | R28: فقط شمارش؛ سند مالی ندارد. | S28: بله
A29: OP20
A30: OP21
A31: OP22
A32: OP23
A33: OP24

Sheet Bsk
A1: مازندشت — سورتینگ و بسته‌بندی مرکبات | F1: MAZANDASHT · CITRUS SORTING & PACKING
A2: انواع سبد و ظروف — وزن تار، قیمت و موجودی
A3: وزن تار هر سبد در محاسبه وزن خالص باسکول کسر می‌شود · موجودی با عملیات شیت سبد در فایل ثبت حرکت می‌کند
A4: راهنما | B4: ورود دستی | C4: خودکار | D4: ورود | E4: خروج | F4: هشدار | G4: ستون‌های زرد = ورود شما | ستون‌های خاکستری = محاسبه خودکار | روی سرستون‌ها بایستید تا راهنما باز شود
A5: انواع سبد | D5: مجموع موجودی اولیه | G5: میانگین وزن تار | J5: ارزش موجودی اولیه
A6: =COUNTIF($B$10:$B$21,"?*") | D6: =SUM($G$10:$G$21) | G6: =IFERROR(AVERAGEIF($C$10:$C$21,">0"),0) | J6: =SUM($I$10:$I$21)
A8: کد | B8: نام سبد | C8: وزن تار (kg) | D8: ظرفیت (kg) | E8: قیمت خرید | F8: قیمت فروش | G8: موجودی اولیه | H8: توضیح | I8: ارزش موجودی اولیه | J8: برچسب کشویی
A9: Code | B9: Name | C9: Tare | D9: Capacity | E9: Buy Price | F9: Sell Price | G9: Opening Qty | H9: Note | I9: Opening Value | J9: Label
A10: BK01 | B10: ۶ک مشکی | C10: 1.5 | D10: 6 | E10: 45000 | F10: 55000 | G10: 1200 | I10: =IF($A10="","",$G10*$E10) | J10: =IF($B10="","",$A10&" – "&$B10)
A11: BK02 | B11: درب‌۶ک | C11: 1.5 | D11: 6 | E11: 48000 | F11: 58000 | G11: 400 | I11: =IF($A11="","",$G11*$E11) | J11: =IF($B11="","",$A11&" – "&$B11)
A12: BK03 | B12: ۹ک مشکی | C12: 1.9 | D12: 9 | E12: 62000 | F12: 75000 | G12: 800 | I12: =IF($A12="","",$G12*$E12) | J12: =IF($B12="","",$A12&" – "&$B12)
A13: BK04 | B13: ریلی کوچک آبی | C13: 1.3 | D13: 5 | E13: 40000 | F13: 50000 | G13: 300 | I13: =IF($A13="","",$G13*$E13) | J13: =IF($B13="","",$A13&" – "&$B13)
A14: BK05 | B14: تک‌رج آبی بزرگ | C14: 2 | D14: 10 | E14: 70000 | F14: 85000 | G14: 250 | I14: =IF($A14="","",$G14*$E14) | J14: =IF($B14="","",$A14&" – "&$B14)
A15: BK06 | B15: آبی ۲۵×۲۰ | C15: 1.1 | D15: 4 | E15: 35000 | F15: 45000 | G15: 150 | I15: =IF($A15="","",$G15*$E15) | J15: =IF($B15="","",$A15&" – "&$B15)
A16: BK07 | B16: ۸ک مشکی | C16: 1.8 | D16: 8 | E16: 58000 | F16: 70000 | G16: 200 | I16: =IF($A16="","",$G16*$E16) | J16: =IF($B16="","",$A16&" – "&$B16)
A17: BK08 | C17: 1.5 | D17: 6 | E17: 0 | F17: 0 | G17: 0 | I17: =IF($A17="","",$G17*$E17) | J17: =IF($B17="","",$A17&" – "&$B17)
A18: BK09 | C18: 1.5 | D18: 6 | E18: 0 | F18: 0 | G18: 0 | I18: =IF($A18="","",$G18*$E18) | J18: =IF($B18="","",$A18&" – "&$B18)
A19: BK10 | C19: 1.5 | D19: 6 | E19: 0 | F19: 0 | G19: 0 | I19: =IF($A19="","",$G19*$E19) | J19: =IF($B19="","",$A19&" – "&$B19)
A20: BK11 | C20: 1.5 | D20: 6 | E20: 0 | F20: 0 | G20: 0 | I20: =IF($A20="","",$G20*$E20) | J20: =IF($B20="","",$A20&" – "&$B20)
A21: BK12 | C21: 1.5 | D21: 6 | E21: 0 | F21: 0 | G21: 0 | I21: =IF($A21="","",$G21*$E21) | J21: =IF($B21="","",$A21&" – "&$B21)

Sheet Prd
A1: مازندشت — سورتینگ و بسته‌بندی مرکبات | C1: MAZANDASHT · CITRUS SORTING & PACKING
A2: محصولات — خرید و فروش
A3: برای هر محصول، دسته (نوع مرکبات)، واحد و سبد پیش‌فرض تعریف می‌شود
A4: راهنما | B4: ورود دستی | C4: خودکار | D4: ورود | E4: خروج | F4: هشدار
A5: محصولات | C5: پرتقال | E5: نارنگی | G5: لیمو
A6: =COUNTIF($B$10:$B$29,"?*") | C6: =COUNTIF($C$10:$C$29,"پرتقال") | E6: =COUNTIF($C$10:$C$29,"نارنگی") | G6: =COUNTIF($C$10:$C$29,"لیمو")
A8: کد | B8: نام محصول | C8: دسته / نوع مرکبات | D8: واحد | E8: سبد پیش‌فرض | F8: توضیح | G8: برچسب کشویی
A9: Code | B9: Product | C9: Category | D9: Unit | E9: Default Basket | F9: Note | G9: Label
A10: PB01 | B10: پرتقال تامسون | C10: پرتقال | D10: کیلوگرم | E10: BK03 | F10: خرید از باغ / میدان بار | G10: =IF($B10="","",$B10&" – "&$C10)
A11: PB02 | B11: پرتقال خونی | C11: پرتقال | D11: کیلوگرم | E11: BK03 | G11: =IF($B11="","",$B11&" – "&$C11)
A12: PB03 | B12: پرتقال کاراکارا | C12: پرتقال | D12: کیلوگرم | E12: BK03 | G12: =IF($B12="","",$B12&" – "&$C12)
A13: PB04 | B13: پرتقال بیروتی | C13: پرتقال | D13: کیلوگرم | E13: BK01 | G13: =IF($B13="","",$B13&" – "&$C13)
A14: PB05 | B14: پرتقال یافا | C14: پرتقال | D14: کیلوگرم | E14: BK03 | G14: =IF($B14="","",$B14&" – "&$C14)
A15: PB06 | B15: نارنگی پیچ | C15: نارنگی | D15: کیلوگرم | E15: BK01 | G15: =IF($B15="","",$B15&" – "&$C15)
A16: PB07 | B16: نارنگی ژاپنی | C16: نارنگی | D16: کیلوگرم | E16: BK07 | G16: =IF($B16="","",$B16&" – "&$C16)
A17: PB08 | B17: نارنگی اونشو | C17: نارنگی | D17: کیلوگرم | E17: BK01 | G17: =IF($B17="","",$B17&" – "&$C17)
A18: PB09 | B18: نارنگی یافا | C18: نارنگی | D18: کیلوگرم | E18: BK01 | G18: =IF($B18="","",$B18&" – "&$C18)
A19: PB10 | B19: لیمو شیرین | C19: لیمو | D19: کیلوگرم | E19: BK01 | G19: =IF($B19="","",$B19&" – "&$C19)
A20: PB11 | B20: لیمو ترش | C20: لیمو | D20: کیلوگرم | E20: BK01 | G20: =IF($B20="","",$B20&" – "&$C20)
A21: PB12 | B21: کامکوات | C21: سایر | D21: کیلوگرم | E21: BK04 | G21: =IF($B21="","",$B21&" – "&$C21)
A22: PB13 | B22: گریپ‌فرویت | C22: گریپ‌فرویت | D22: کیلوگرم | E22: BK03 | G22: =IF($B22="","",$B22&" – "&$C22)
... A24: PB15 | B24: نارنج | C24: سایر | D24: کیلوگرم | E24: BK03 | G24: =IF($B24="","",$B24&" – "&$C24)
A25: PB16 | G25: =IF($B25="","",$B25&" – "&$C25)
A26: PB17 | G26: =IF($B26="","",$B26&" – "&$C26)
A27: PB18 | G27: =IF($B27="","",$B27&" – "&$C27)
A28: PB19 | G28: =IF($B28="","",$B28&" – "&$C28)
A29: PB20 | G29: =IF($B29="","",$B29&" – "&$C29)

Sheet Bnk
A1: مازندشت — سورتینگ و بسته‌بندی مرکبات | C1: MAZANDASHT · CITRUS SORTING & PACKING
A2: بانک‌ها و حساب‌های شرکت
A3: کد بانک ثابت است؛ عنوان را آزادانه عوض کنید · پوز باسکول به صادرات ۲۰۰۶ وصل است
A4: راهنما | B4: ورود دستی | C4: خودکار | D4: ورود | E4: خروج | F4: هشدار
A5: بانک‌ها | D5: بانک فعال | G5: مانده اولیه
A6: =COUNTIF($A$10:$A$19,"?*") | D6: =COUNTIF($F$10:$F$19,"بله") | G6: =SUM($C$10:$C$19)
A8: کد بانک | B8: عنوان نمایشی | C8: مانده اولیه | D8: کد حساب معین | E8: شبا | F8: فعال | G8: توضیح
A9: Code | B9: Title | C9: Opening | D9: Ledger | E9: IBAN | F9: Active | G9: Note
A10: BN01 | B10: صادرات ۹۰۰۹ — جاری اصلی | C10: 500000000 | D10: BN01 | F10: بله | G10: حساب جاری اصلی شرکت
A11: BN02 | B11: صادرات ۲۰۰۶ — پوز باسکول | C11: 0 | D11: BN02 | F11: بله | G11: پوز باسکول به این حساب وصل است
A12: BN03 | B12: ملت | C12: 0 | D12: BN03 | F12: بله
A13: BN04 | B13: کشاورزی | C13: 0 | D13: BN04 | F13: بله
A14: BN05 | B14: سپه | C14: 0 | D14: BN05 | F14: بله
A15: BN06 | B15: مهر ایران | C15: 0 | D15: BN06 | F15: بله
A16: BN07 | B16: تجارت | C16: 0 | D16: BN07 | F16: بله
A17: BN08 | B17: پاسارگاد | C17: 0 | D17: BN08 | F17: بله
A18: BN09 | B18: رفاه | C18: 0 | D18: BN09 | F18: بله
A19: BN10 | B19: قرض‌الحسنه | C19: 0 | D19: BN10 | F19: بله

Sheet List
A1: مازندشت — سورتینگ و بسته‌بندی مرکبات | N1: MAZANDASHT · CITRUS SORTING & PACKING
A2: لیست‌های عمومی — منبع کشوهای سامانه
A3: هر ستون یک لیست است؛ مقدار جدید را در ردیف خالی بعدی همان ستون بنویسید
A4: راهنما | B4: ورود دستی | C4: خودکار | D4: ورود | E4: خروج | F4: هشدار | G4: ستون‌های زرد = ورود شما | ستون‌های خاکستری = محاسبه خودکار | روی سرستون‌ها بایستید تا راهنما باز شود
A8: واحد شمارش | B8: دسته مرکبات | C8: جهت | D8: بله / خیر | E8: نوع حساب | F8: روش پرداخت | G8: وضعیت چک | H8: تیک انتخاب | I8: نقش مبلغ دستی | J8: اثر پوز | K8: سمت حساب | L8: دسته عملیات | M8: علامت وضعیت | N8: شیت گزارش | O8: مبنای طرف | P8: کلید رنگ | Q8: فصل | R8: جهت پرداخت | S8: نوع عملیات بانکی | T8: شخص باسکول دیگران | U8: بانک عامل (کد و نام)
A9: Units | B9: Categories | C9: Directions | D9: YesNo | E9: PartyTypes | F9: PayMethods | G9: ChequeStatus | H9: Include | I9: ManualRoles | J9: PosEffects | K9: Sides | L9: OpCategories | M9: StatusMarks | N9: ReportSheets | O9: PartyBasis | P9: ColorKeys | Q9: Seasons | R9: TxnDirections | S9: Bank operations | T9: Other scales | U9: Company banks
A10: کیلوگرم | B10: پرتقال | C10: ورود | D10: بله | E10: طرف حساب | F10: نقد | G10: در جریان | H10: ☑ | I10: افزودن | J10: بدهکار | K10: بدهکار | L10: خرید | M10: ✓ | N10: Growers | O10: وزن | P10: mint | Q10: بهار | R10: پرداخت | S10: دریافت از مشتری | T10: BD001 – باسکول میدان بار (نمونه) | U10: BN01 – صادرات ۹۰۰۹ — جاری اصلی
A11: سبد | B11: نارنگی | C11: خروج | D11: خیر | E11: معین | F11: چک | G11: پاس شده | H11: ☐ | I11: پوز | J11: بستانکار | K11: بستانکار | L11: فروش | M11: ⚠ | N11: LoadBuyers | O11: مبلغ | P11: sky | Q11: تابستان | R11: دریافت | S11: پرداخت به مشتری | T11: BD002 – (بدون نام) | U11: BN02 – صادرات ۲۰۰۶ — پوز باسکول
A12: جعبه | B12: لیمو | C12: — | F12: انتقال بانکی | G12: برگشتی | I12: هیچ | J12: — | K12: خودکار | L12: آبگیری | N12: BasketSellers | O12: هیچ | P12: lavender | Q12: پاییز | S12: دریافت نقدی و واریز به بانک | T12: BD003 – (بدون نام) | U12: BN03 – ملت
A13: تن | B13: گریپ‌فرویت | F13: کارت/پوز | G13: باطل | I13: — | K13: — | L13: انعام | N13: Suppliers | O13: — | P13: rose | Q13: زمستان | S13: پرداخت هزینه | T13: BD004 – (بدون نام) | U13: BN04 – کشاورزی
A14: عدد | B14: سایر | F14: پاس چک | L14: باسکول دیگران | N14: Staff | P14: sand | S14: انتقال داخلی بین بانک‌ها | T14: BD005 – (بدون نام) | U14: BN05 – سپه
A15: ریال | F15: انتقال داخلی | L15: درآمد | N15: Other | P15: grey | S15: پرداخت انعام مصطفی | T15: BD006 – (بدون نام) | U15: BN06 – مهر ایران
L16: هزینه | N16: OtherScales | P16: teal | S16: دریافت هزینه باسکول دیگران | T16: BD007 – (بدون نام) | U16: BN07 – تجارت
L17: انتقال | N17: Assets | P17: peach | S17: پرداخت به باسکول دیگران | T17: BD008 – (بدون نام) | U17: BN08 – پاسارگاد
L18: سایر | N18: Liabilities | S18: واریز پز باسکول (۲۰۰۶) | T18: BD009 – (بدون نام) | U18: BN09 – رفاه
L19: تعدیل | N19: Equity | S19: پاس چک (پرداخت چک) | T19: BD010 – (بدون نام) | U19: BN10 – قرض‌الحسنه
S20: برگشت چک دریافتی | T20: BD011 – (بدون نام)
S21: واریز چک به حساب | T21: BD012 – (بدون نام)
S22: دریافت تسهیلات | T22: BD013 – (بدون نام)
S23: بازپرداخت تسهیلات | T23: BD014 – (بدون نام)
S24: سایر دریافت | T24: BD015 – (بدون نام)
S25: سایر پرداخت | T25: BD016 – (بدون نام)
S26: تسویه دریافت (واسط) | T26: BD017 – (بدون نام)
S27: تسویه پرداخت (واسط) | T27: BD018 – (بدون نام)
T28: BD019 – (بدون نام)
T29: BD020 – (بدون نام)
S32: این سه فهرست، کشوهای فایل 02_Bank را می‌سازند. برای اضافه کردن نوع عملیات بانکی جدید، یک ردیف به ستون S اضافه کنید و در شیت Sync فایل بانک همان ردیف را ادامه دهید.

Sheet Sync
A1: مازندشت — سورتینگ و بسته‌بندی مرکبات | C1: MAZANDASHT · CITRUS SORTING & PACKING
A2: مرجع سریع و قفل‌شده (Sync)
A3: نمای خواندنی از پارامترها، گروه‌ها و بانک‌ها · این شیت فقط مطالعه است
A5: این شیت قفل است و هیچ داده‌ای در آن وارد نمی‌شود؛ مقادیرش زنده از شیت‌های Params، Groups و Banks خوانده می‌شود. برای تغییر هر مقدار، همان شیت اصلی را ویرایش کنید و برگردید — اینجا خودکار به‌روز می‌شود.
H6: نوع عملیات بانکی
A7: ۰۱ | B7: پارامترهای محاسباتی — همان مقادیر شیت Params — پایه همه فرمول‌های مجموعه | H7: دریافت از مشتری | I7: IN | J7: CODE
A8: کد | B8: نام پارامتر | C8: مقدار | D8: واحد | E8: توضیح | F8: شیت منبع | H8: پرداخت به مشتری | I8: OUT | J8: CODE
A9: P01 | B9: =IFERROR(VLOOKUP($A9,Par!$A$10:$E$21,2,0),"") | C9: =IFERROR(VLOOKUP($A9,Par!$A$10:$E$21,3,0),"") | D9: =IFERROR(VLOOKUP($A9,Par!$A$10:$E$21,4,0),"") | E9: =IFERROR(VLOOKUP($A9,Par!$A$10:$E$21,5,0),"") | F9: Params | H9: دریافت نقدی و واریز به بانک | I9: IN | J9: FIXED | K9: X003
A10: P02 | B10: =IFERROR(VLOOKUP($A10,Par!$A$10:$E$21,2,0),"") | C10: =IFERROR(VLOOKUP($A10,Par!$A$10:$E$21,3,0),"") | D10: =IFERROR(VLOOKUP($A10,Par!$A$10:$E$21,4,0),"") | E10: =IFERROR(VLOOKUP($A10,Par!$A$10:$E$21,5,0),"") | F10: Params | H10: پرداخت هزینه | I10: OUT | J10: CODE
A11: P03 | B11: =IFERROR(VLOOKUP($A11,Par!$A$10:$E$21,2,0),"") | C11: =IFERROR(VLOOKUP($A11,Par!$A$10:$E$21,3,0),"") | D11: =IFERROR(VLOOKUP($A11,Par!$A$10:$E$21,4,0),"") | E11: =IFERROR(VLOOKUP($A11,Par!$A$10:$E$21,5,0),"") | F11: Params | H11: انتقال داخلی بین بانک‌ها | I11: TRF | J11: NONE
A12: P04 | B12: =IFERROR(VLOOKUP($A12,Par!$A$10:$E$21,2,0),"") | C12: =IFERROR(VLOOKUP($A12,Par!$A$10:$E$21,3,0),"") | D12: =IFERROR(VLOOKUP($A12,Par!$A$10:$E$21,4,0),"") | E12: =IFERROR(VLOOKUP($A12,Par!$A$10:$E$21,5,0),"") | F12: Params | H12: پرداخت انعام مصطفی | I12: OUT | J12: FIXED | K12: X001
A13: P05 | B13: =IFERROR(VLOOKUP($A13,Par!$A$10:$E$21,2,0),"") | C13: =IFERROR(VLOOKUP($A13,Par!$A$10:$E$21,3,0),"") | D13: =IFERROR(VLOOKUP($A13,Par!$A$10:$E$21,4,0),"") | E13: =IFERROR(VLOOKUP($A13,Par!$A$10:$E$21,5,0),"") | F13: Params | H13: دریافت هزینه باسکول دیگران | I13: IN | J13: PICK
A14: P06 | B14: =IFERROR(VLOOKUP($A14,Par!$A$10:$E$21,2,0),"") | C14: =IFERROR(VLOOKUP($A14,Par!$A$10:$E$21,3,0),"") | D14: =IFERROR(VLOOKUP($A14,Par!$A$10:$E$21,4,0),"") | E14: =IFERROR(VLOOKUP($A14,Par!$A$10:$E$21,5,0),"") | F14: Params | H14: پرداخت به باسکول دیگران | I14: OUT | J14: PICK
A15: P07 | B15: =IFERROR(VLOOKUP($A15,Par!$A$10:$E$21,2,0),"") | C15: =IFERROR(VLOOKUP($A15,Par!$A$10:$E$21,3,0),"") | D15: =IFERROR(VLOOKUP($A15,Par!$A$10:$E$21,4,0),"") | E15: =IFERROR(VLOOKUP($A15,Par!$A$10:$E$21,5,0),"") | F15: Params | H15: واریز پز باسکول (۲۰۰۶) | I15: IN | J15: FIXED | K15: X011
A16: P08 | B16: =IFERROR(VLOOKUP($A16,Par!$A$10:$E$21,2,0),"") | C16: =IFERROR(VLOOKUP($A16,Par!$A$10:$E$21,3,0),"") | D16: =IFERROR(VLOOKUP($A16,Par!$A$10:$E$21,4,0),"") | E16: =IFERROR(VLOOKUP($A16,Par!$A$10:$E$21,5,0),"") | F16: Params | H16: پاس چک (پرداخت چک) | I16: OUT | J16: FIXED | K16: X010
A17: P09 | B17: =IFERROR(VLOOKUP($A17,Par!$A$10:$E$21,2,0),"") | C17: =IFERROR(VLOOKUP($A17,Par!$A$10:$E$21,3,0),"") | D17: =IFERROR(VLOOKUP($A17,Par!$A$10:$E$21,4,0),"") | E17: =IFERROR(VLOOKUP($A17,Par!$A$10:$E$21,5,0),"") | F17: Params | H17: برگشت چک دریافتی | I17: IN | J17: FIXED | K17: X010
A18: P10 | B18: =IFERROR(VLOOKUP($A18,Par!$A$10:$E$21,2,0),"") | C18: =IFERROR(VLOOKUP($A18,Par!$A$10:$E$21,3,0),"") | D18: =IFERROR(VLOOKUP($A18,Par!$A$10:$E$21,4,0),"") | E18: =IFERROR(VLOOKUP($A18,Par!$A$10:$E$21,5,0),"") | F18: Params | H18: واریز چک به حساب | I18: IN | J18: FIXED | K18: X010
A19: P11 | B19: =IFERROR(VLOOKUP($A19,Par!$A$10:$E$21,2,0),"") | C19: =IFERROR(VLOOKUP($A19,Par!$A$10:$E$21,3,0),"") | D19: =IFERROR(VLOOKUP($A19,Par!$A$10:$E$21,4,0),"") | E19: =IFERROR(VLOOKUP($A19,Par!$A$10:$E$21,5,0),"") | F19: Params | H19: دریافت تسهیلات | I19: IN | J19: CODE
A20: P12 | B20: =IFERROR(VLOOKUP($A20,Par!$A$10:$E$21,2,0),"") | C20: =IFERROR(VLOOKUP($A20,Par!$A$10:$E$21,3,0),"") | D20: =IFERROR(VLOOKUP($A20,Par!$A$10:$E$21,4,0),"") | E20: =IFERROR(VLOOKUP($A20,Par!$A$10:$E$21,5,0),"") | F20: Params | H20: بازپرداخت تسهیلات | I20: OUT | J20: CODE
H21: سایر دریافت | I21: IN | J21: CODE
H22: سایر پرداخت | I22: OUT | J22: CODE
A23: ۰۲ | B23: گروه‌های اصلی حساب — تعداد حساب‌های هر گروه، زنده از شیت Accounts | H23: تسویه دریافت (واسط) | I23: IN | J23: FIXED | K23: X011
A24: گروه | B24: تعداد حساب | C24: تعداد زیرگروه | F24: شیت منبع | H24: تسویه پرداخت (واسط) | I24: OUT | J24: FIXED | K24: X011
A25: باغدار | B25: =COUNTIF(Acc!$B$10:$B$259,$A25) | C25: =COUNTIF(Grp!$A$10:$A$52,$A25) | F25: Accounts / Groups
A26: بارفروش | B26: =COUNTIF(Acc!$B$10:$B$259,$A26) | C26: =COUNTIF(Grp!$A$10:$A$52,$A26) | F26: Accounts / Groups
A27: فروشنده سبد | B27: =COUNTIF(Acc!$B$10:$B$259,$A27) | C27: =COUNTIF(Grp!$A$10:$A$52,$A27) | F27: Accounts / Groups
A28: تأمین‌کننده | B28: =COUNTIF(Acc!$B$10:$B$259,$A28) | C28: =COUNTIF(Grp!$A$10:$A$52,$A28) | F28: Accounts / Groups
A29: کارمند | B29: =COUNTIF(Acc!$B$10:$B$259,$A29) | C29: =COUNTIF(Grp!$A$10:$A$52,$A29) | F29: Accounts / Groups
A30: سایر حساب | B30: =COUNTIF(Acc!$B$10:$B$259,$A30) | C30: =COUNTIF(Grp!$A$10:$A$52,$A30) | F30: Accounts / Groups
A31: باسکول دیگران | B31: =COUNTIF(Acc!$B$10:$B$259,$A31) | C31: =COUNTIF(Grp!$A$10:$A$52,$A31) | F31: Accounts / Groups
A32: دارایی ثابت | B32: =COUNTIF(Acc!$B$10:$B$259,$A32) | C32: =COUNTIF(Grp!$A$10:$A$52,$A32) | F32: Accounts / Groups
A33: وام و تسهیلات | B33: =COUNTIF(Acc!$B$10:$B$259,$A33) | C33: =COUNTIF(Grp!$A$10:$A$52,$A33) | F33: Accounts / Groups
A34: سرمایه و آورده صاحبان | B34: =COUNTIF(Acc!$B$10:$B$259,$A34) | C34: =COUNTIF(Grp!$A$10:$A$52,$A34) | F34: Accounts / Groups
A35: بانک و صندوق | B35: =COUNTIF(Acc!$B$10:$B$259,$A35) | C35: =COUNTIF(Grp!$A$10:$A$52,$A35) | F35: Accounts / Groups
A36: جمع | B36: =SUM($B$25:$B$35)
A39: ۰۳ | B39: بانک‌های شرکت — کد بانک ثابت است؛ عنوان را در شیت Banks عوض کنید
A40: کد بانک | B40: عنوان نمایشی | C40: شماره حساب | D40: فعال | E40: شبا | F40: شیت منبع
A41: =Bnk!$A10 | B41: =Bnk!$B10 | C41: =Bnk!$D10 | D41: =Bnk!$F10 | E41: =Bnk!$E10 | F41: Banks
A42: =Bnk!$A11 | B42: =Bnk!$B11 | C42: =Bnk!$D11 | D42: =Bnk!$F11 | E42: =Bnk!$E11 | F42: Banks
A43: =Bnk!$A12 | B43: =Bnk!$B12 | C43: =Bnk!$D12 | D43: =Bnk!$F12 | E43: =Bnk!$E12 | F43: Banks
...

Sheet Help
A1: مازندشت — سورتینگ و بسته‌بندی مرکبات | G1: MAZANDASHT · CITRUS SORTING & PACKING
A2: راهنمای کامل فایل مادر (INFO)
A3: از اینجا شروع کنید — نقشه، قواعد و آموزش گام‌به‌گام سامانه حسابداری مازندشت
A5: این شیت قفل است و فقط برای مطالعه است. همه فایل‌های دیگر از همین فایل خوانده می‌شوند؛ بنابراین ترتیب کار همیشه این است: اول INFO، بعد ثبت، بعد گزارش/فاکتور/ترازنامه. هر بخش را با یک مثال واقعی از عملیات سورتینگ توضیح داده‌ایم.
A7: ۰ | B7: فهرست مطالب — روی هر سطر کلیک کنید
A8: ۱ | B8: این فایل چیست و چرا «مادر» است؟
A9: ۲ | B9: نقشه فایل‌ها و جریان داده
A10: ۳ | B10: قواعد کدگذاری
A11: ۴ | B11: دفتر حساب‌ها (Accounts)
A12: ۵ | B12: گروه‌ها و زیرگروه‌ها
A13: ۶ | B13: عملیات و قواعد بدهکار/بستانکار
A14: ۷ | B14: پارامترهای محاسباتی
A15: ۸ | B15: سبدها و وزن تار
A16: ۹ | B16: محصولات، بانک‌ها و پوز
A17: ۱۰ | B17: افزودن حساب / عملیات جدید — گام‌به‌گام
A18: ۱۱ | B18: همگام‌سازی و Update Links
... A26: ۱ | B26: این فایل چیست و چرا «مادر» است؟
B27: مازندشت یک واحد سورتینگ، بسته‌بندی و بازرگانی مرکبات است. کار روزانه شما سه جنس داده دارد: (۱) بار که با کامیون می‌آید و با باسکول وزن می‌شود، (۲) پول که از بانک و چک و پوز می‌آید و می‌رود، (۳) سبد که خرید و فروش و مرجوعی دارد. اگر هر فایل این داده‌ها را جدا نگه دارد، نام‌ها و کدها به‌سرعت از هم جدا می‌شوند و گزارش‌ها به هم نمی‌خورند. به همین دلیل یک فایل «مادر» داریم که فقط تعریف می‌کند: چه حساب‌هایی داریم، چه عملیاتی انجام می‌شود، هر عملیات چه سمت بدهکار/بستانکاری دارد، وزن هر سبد چقدر است، بانک‌ها کدام‌اند و پارامترهای محاسباتی چه مقادیری دارند.
B28: بقیه فایل‌ها هیچ تعریفی از خودشان ندارند؛ همه‌چیز را از این فایل می‌خوانند. مزیت بزرگ این معماری: اگر فردا یک باغدار جدید اضافه شد یا یک عملیات تازه مثل «آبگیری با هزینه حمل» لازم شد، فقط همین فایل را تغییر می‌دهید و همه گزارش‌ها، فاکتور و ترازنامه خودکار به‌روز می‌شوند. عیبش این است که اگر این فایل جابه‌جا شود یا اسم یک شیت عوض شود، همه فایل‌ها خطا می‌دهند؛ پس قواعد این راهنما را دقیق رعایت کنید.
B29: قانون یک‌خطی: INFO تعریف می‌کند، «ثبت» می‌نویسد، بقیه می‌خوانند و گزارش می‌دهند.
A31: ۲ | B31: نقشه فایل‌ها و جریان داده
B32: ۱) 00_Master.xlsx — همین فایل: حساب‌ها، عملیات، سبدها، محصولات، بانک‌ها، پارامترها و لیست‌ها. ۲) 01_Entry.xlsx — تنها محل نوشتن داده: شیت باسکول (ورود/خروج بار)، شیت سبد (خرید/فروش سبد)، شیت پرداخت (پرداخت و دریافت و چک). ۳) 02_Reports.xlsx — گزارش باغداران، بارفروشان، فروشندگان سبد و دفتر کل. ۴) 03_Invoice.xlsx — فاکتور چاپی با تیک انتخاب ردیف. ۵) 04_Balance.xlsx — ترازنامه ۴ و ۶ ستونه، حسابرسی، ترازبانک. ۶) 05_Bank.xlsx — تراکنش بانکی، دفتر چک و مغایرت‌گیری. ۷) 06_Buyers.xlsx — کارت اختصاصی هر بارفروش. ۸) 07_Demo.xlsx — نسخه ساده‌شده برای شروع و آموزش.
B33: جریان داده یک‌طرفه است: INFO → ثبت → گزارش/فاکتور/ترازنامه. فایل بانک هم از INFO بانک‌ها و از ثبت پرداخت‌ها را می‌خواند تا مغایرت بانکی را نشان دهد. هیچ‌گاه داده را در دو جا وارد نکنید؛ اگر بار در باسکول ثبت شد، همان‌جا می‌ماند و گزارش‌ها از همان می‌خوانند. فایل 07 نمونه هیچ ارتباطی با فایل‌های اصلی ندارد و برای آموزش است؛ داده‌هایش را جدی نگیرید.
B34: همه فایل‌ها باید در یک پوشه باشند. اگر پوشه را جابه‌جا کردید، فایل‌ها را با هم جابه‌جا کنید و لینک‌ها را Update کنید.
A36: ۳ | B36: قواعد کدگذاری
B37: کدها ثابت‌اند و هرگز عوض نمی‌شوند؛ فقط عنوان‌ها آزادند. پیشوند کد، گروه حساب را نشان می‌دهد: C باغدار (مثلاً C001)، SL بارفروش (SL001)، S فروشنده سبد و تأمین‌کننده (S001)، E کارمند (E001)، X حساب معین داخلی (X001)، BD باسکول دیگران (BD001)، F دارایی ثابت (F001)، L وام (L001) و CAP سرمایه (CAP001). عملیات با OP شروع می‌شود (OP01)، سبد با BK (BK01)، محصول با PB (PB01)، پارامتر با P (P01) و بانک با BANK (BN01).
B38: شماره‌ها را دستی جابه‌جا نکنید. برای حساب جدید، اولین ردیف خالی همان گروه را پر کنید؛ کدها از قبل درج شده‌اند. مثلاً باغدار جدید = C058، بارفروش جدید = SL006. اگر کدی را پاک کنید و دوباره بنویسید، گردش قبلی آن حساب از گزارش‌ها حذف می‌شود؛ پس برای حذف یک حساب فقط نام و مشخصاتش را پاک کنید و کد را نگه دارید تا شماره‌ها جابه‌جا نشوند.
B39: کد = هویت؛ عنوان = نمایش. گزارش‌ها و فرمول‌ها همیشه با کد کار می‌کنند.
A41: ۴ | B41: دفتر حساب‌ها (Accounts)
B42: این شیت قلب فایل مادر است. هر ردیف یک صاحب حساب یا یک حساب معین است. ستون «گروه» از ۱۰ گروه اصلی انتخاب می‌شود و ستون «زیرگروه» از شیت Groups می‌آید. ستون «مانده اولیه» علامت‌دار است: عدد مثبت یعنی حساب بدهکار است (از ما طلب دارد) و عدد منفی یعنی بستانکار است (ما به او بدهکاریم). برای باغدار معمولاً بستانکاریم و برای بارفروش بدهکار. جمع جبری مانده‌های اولیه باید با سرمایه و دارایی‌ها بخواند؛ در غیر این صورت ترازنامه افتتاحیه تراز نمی‌شود.
B43: ستون «نوع حساب» دو مقدار دارد: «طرف حساب» برای اشخاص و «معین» برای حساب‌های داخلی مثل صندوق، موجودی مرکبات، فروش، هزینه. ستون «گروه کد (خودکار)» پیشوند کد را ترجمه می‌کند و ستون «بررسی» با ✓/⚠ می‌گوید گروه انتخابی با پیشوند کد سازگار است یا نه. حساب‌های بدون نام در گزارش‌ها و کشوها نمی‌آیند؛ پس برای شروع، فقط ردیف‌هایی را پر کنید که واقعاً استفاده می‌شوند.
B44: مثال: C001 زینب زاهدی، گروه باغدار، زیرگروه عمده، مانده اولیه ۰. وقتی بار تحویل می‌دهد، در باسکول با کد C001 ثبت می‌شود و حسابش بستانکار می‌شود. وقتی پول می‌گیرد، در شیت پرداخت با همان کد ثبت می‌شود و بستانکاری کم می‌شود. مانده نهایی = بستانکاری باسکول − پرداخت‌ها.
B45: جمع بدهکاران و بستانکاران افتتاحیه باید با هم برابر باشد؛ اگر نبود، یک ردیف جا افتاده است.
A47: ۵ | B47: گروه‌ها و زیرگروه‌ها
