Workbook
Name AcctCodes: Sync!$B$10:$B$259
Name AcctTbl: Sync!$B$10:$G$259
Name BankCodes: Sync!$AK$10:$AK$19
Name BankTbl: Sync!$AK$10:$AN$19
Name BasketCodeCol: Sync!$Z$10:$Z$21
Name BasketTbl: Sync!$Y$10:$AF$21
Name GroupTbl: Sync!$AR$10:$AS$51
Name ListAllCodes: OFFSET(Sync!$B$10,0,0,MAX(COUNTIF(Sync!$C$10:$C$259,"?*"),1),1)
Name ListBanks: OFFSET(Sync!$AL$10,0,0,MAX(COUNTIF(Sync!$AL$10:$AL$19,"?*"),1),1)
Name ListBasketOps: OFFSET(Sync!$AW$10,0,0,MAX(COUNTIF(Sync!$AW$10:$AW$14,"?*"),1),1)
Name ListBaskets: OFFSET(Sync!$Y$10,0,0,MAX(COUNTIF(Sync!$Y$10:$Y$21,"?*"),1),1)
Name ListBasketSellerCodes: OFFSET(Sync!$B$72,0,0,MAX(COUNTIF(Sync!$C$72:$C$74,"?*"),1),1)
Name ListBaskolOps: OFFSET(Sync!$AZ$10,0,0,MAX(COUNTIF(Sync!$AZ$10:$AZ$23,"?*"),1),1)
Name ListCategories: OFFSET(Sync!$CB$10,0,0,MAX(COUNTIF(Sync!$CB$10:$CB$29,"?*"),1),1)
Name ListChequeStatus: OFFSET(Sync!$CG$10,0,0,MAX(COUNTIF(Sync!$CG$10:$CG$29,"?*"),1),1)
Name ListColorKeys: OFFSET(Sync!$CP$10,0,0,MAX(COUNTIF(Sync!$CP$10:$CP$29,"?*"),1),1)
Name ListDirections: OFFSET(Sync!$CC$10,0,0,MAX(COUNTIF(Sync!$CC$10:$CC$29,"?*"),1),1)
Name ListGroups: Sync!$AU$10:$AU$19
Name ListGrowerCodes: OFFSET(Sync!$B$10,0,0,MAX(COUNTIF(Sync!$C$10:$C$66,"?*"),1),1)
Name ListInclude: OFFSET(Sync!$CH$10,0,0,MAX(COUNTIF(Sync!$CH$10:$CH$29,"?*"),1),1)
Name ListLoadBuyerCodes: OFFSET(Sync!$B$67,0,0,MAX(COUNTIF(Sync!$C$67:$C$71,"?*"),1),1)
Name ListManualRoles: OFFSET(Sync!$CI$10,0,0,MAX(COUNTIF(Sync!$CI$10:$CI$29,"?*"),1),1)
Name ListOpCategories: OFFSET(Sync!$CL$10,0,0,MAX(COUNTIF(Sync!$CL$10:$CL$29,"?*"),1),1)
Name ListOps: OFFSET(Sync!$I$10,0,0,MAX(COUNTIF(Sync!$I$10:$I$33,"?*"),1),1)
Name ListOtherScaleCodes: Sync!$AX$10:$AX$29
Name ListPartyBasis: OFFSET(Sync!$CO$10,0,0,MAX(COUNTIF(Sync!$CO$10:$CO$29,"?*"),1),1)
Name ListPartyTypes: OFFSET(Sync!$CE$10,0,0,MAX(COUNTIF(Sync!$CE$10:$CE$29,"?*"),1),1)
Name ListPayMethods: OFFSET(Sync!$CF$10,0,0,MAX(COUNTIF(Sync!$CF$10:$CF$29,"?*"),1),1)
Name ListPosEffects: OFFSET(Sync!$CJ$10,0,0,MAX(COUNTIF(Sync!$CJ$10:$CJ$29,"?*"),1),1)
Name ListProducts: OFFSET(Sync!$AH$10,0,0,MAX(COUNTIF(Sync!$AH$10:$AH$29,"?*"),1),1)
Name ListReportSheets: OFFSET(Sync!$CN$10,0,0,MAX(COUNTIF(Sync!$CN$10:$CN$29,"?*"),1),1)
Name ListSeasons: OFFSET(Sync!$CQ$10,0,0,MAX(COUNTIF(Sync!$CQ$10:$CQ$29,"?*"),1),1)
Name ListSides: OFFSET(Sync!$CK$10,0,0,MAX(COUNTIF(Sync!$CK$10:$CK$29,"?*"),1),1)
Name ListStatus: OFFSET(Sync!$CM$10,0,0,MAX(COUNTIF(Sync!$CM$10:$CM$29,"?*"),1),1)
Name ListSubgroups: OFFSET(Sync!$AR$10,0,0,MAX(COUNTIF(Sync!$AS$10:$AS$51,"?*"),1),1)
Name ListTxnDirections: OFFSET(Sync!$CR$10,0,0,MAX(COUNTIF(Sync!$CR$10:$CR$29,"?*"),1),1)
Name ListUnits: OFFSET(Sync!$CA$10,0,0,MAX(COUNTIF(Sync!$CA$10:$CA$29,"?*"),1),1)
Name ListYesNo: OFFSET(Sync!$CD$10,0,0,MAX(COUNTIF(Sync!$CD$10:$CD$29,"?*"),1),1)
Name OpTbl: Sync!$I$10:$W$33
Name ParamTbl: Sync!$AO$10:$AP$21
Name ProductTbl: Sync!$AH$10:$AI$29

Sheet Ov
A1: مازندشت — سورتینگ و بسته‌بندی مرکبات | G1: MAZANDASHT · CITRUS SORTING & PACKING
A2: بانک، چک و مغایرت‌گیری
A3: همه پرداخت‌ها و دریافت‌های ثبت روزانه، به‌اضافه پیگیری چک‌ها · نسخه ۰۲
A9: ۰۱ | B9: خلاصه بانک — جمع دریافت و پرداخت از شیت تراکنش‌ها
A11: تعداد تراکنش | D11: جمع دریافت | G11: جمع پرداخت
A12: =COUNTA(Txn!$B$10:$B$159) -> 0 | D12: =SUM(Txn!$K$10:$K$159) -> 0 | G12: =SUM(Txn!$L$10:$L$159) -> 0
A14: مانده گردش | D14: چک در جریان | G14: چک پاس‌شده
A15: =E11-C11 -> 0 | D15: =COUNTIF(Chq!$J$10:$J$159,"در جریان") -> 0 | G15: =COUNTIF(Chq!$J$10:$J$159,"پاس شده") -> 0
A19: تراکنش‌ها | C19: چک‌ها | E19: مغایرت‌گیری | G19: خلاصه ماهانه
A20: همه پرداخت‌ها و دریافت‌ها با بانک، چک و طرف حساب | C20: شماره چک، سررسید، وضعیت و طرف حساب | E20: مانده دفتر در برابر مانده صورت‌حساب بانک | G20: دریافت و پرداخت هر ماه به تفکیک بانک
A25: این فایل داده‌ای وارد نمی‌کند؛ همه سطرها از «ثبت روزانه» خوانده می‌شود. اگر اعداد صفر بود: Data ← Edit Links ← Update Values.

Sheet Txn
A1: مازندشت — سورتینگ و بسته‌بندی مرکبات | N1: MAZANDASHT · CITRUS SORTING & PACKING
A2: تراکنش‌های بانکی
A3: کپی زنده از شیت پرداخت در ثبت روزانه · دست نزنید؛ در ثبت ویرایش کنید
A4: راهنما | B4: ورود دستی | C4: خودکار | D4: ورود | E4: خروج | F4: هشدار | G4: ستون‌های زرد = ورود شما | ستون‌های خاکستری = محاسبه خودکار | روی سرستون‌ها بایستید تا راهنما باز شود
A5: دریافت | E5: پرداخت | I5: مانده | M5: چک باز | Q5: تعداد
A6: =SUM($M$10:$M$159) -> 0 | E6: =SUM($N$10:$N$159) -> 0 | I6: =$M$7-$N$7 -> 0 | M6: =COUNTIF($K$10:$K$159,"در جریان") -> 0 | Q6: =COUNTA($B$10:$B$159) -> 0
A7: سند | D7: روش و طرف | G7: بانک و چک | J7: مبلغ و وضعیت | M7: دریافت / پرداخت
A8: تاریخ | B8: سند | C8: نوع | D8: روش | E8: کد حساب | F8: نام حساب | G8: گروه | H8: بانک | I8: شماره چک | J8: مبلغ | K8: وضعیت چک | L8: سررسید | M8: دریافت | N8: پرداخت | O8: شرح | P8: منبع
A9: Date | B9: Doc | C9: Type | D9: Method | E9: Account | F9: Name | G9: Group | H9: Bank | I9: Cheque | J9: Amount | K9: Chq status | L9: Due | M9: In | N9: Out | O9: Notes | P9: Source
A10: ='[01_Entry.xlsx]Pay'!B10 -> 1405/07/06 | B10: ='[01_Entry.xlsx]Pay'!C10 -> PV-001 | C10: ='[01_Entry.xlsx]Pay'!D10 -> پرداخت | D10: ='[01_Entry.xlsx]Pay'!E10 -> نقد | E10: ='[01_Entry.xlsx]Pay'!F10 -> C001 | F10: ='[01_Entry.xlsx]Pay'!G10 -> زینب زاهدی | G10: ='[01_Entry.xlsx]Pay'!H10 -> باغدار | H10: ='[01_Entry.xlsx]Pay'!I10 -> empty | ... L10: ='[01_Entry.xlsx]Pay'!M10 | M10: =IF($D10="دریافت",IF($L10="انتقال داخلی",0,$J10),0) -> 0 | N10: =IF($D10="پرداخت",IF($L10="انتقال داخلی",0,$J10),0) -> 0 | O10: ='[01_Entry.xlsx]Pay'!P10 -> علی‌الحساب خرید | P10: =IF($B10="","","ثبت روزانه") -> 0
A11: ='[01_Entry.xlsx]Pay'!B11 -> 1405/07/06 | B11: ='[01_Entry.xlsx]Pay'!C11 -> RV-001 | C11: ='[01_Entry.xlsx]Pay'!D11 -> دریافت | D11: ='[01_Entry.xlsx]Pay'!E11 -> انتقال بانکی | E11: ='[01_Entry.xlsx]Pay'!F11 -> SL001 | F11: ='[01_Entry.xlsx]Pay'!G11 -> قم — سید حسین حسینی | G11: ='[01_Entry.xlsx]Pay'!H11 -> بارفروش | H11: ='[01_Entry.xlsx]Pay'!I11 -> BANK01 | ... L11: ='[01_Entry.xlsx]Pay'!M11 | M11: =IF($D11="دریافت",IF($L11="انتقال داخلی",0,$J11),0) -> 0 | N11: =IF($D11="پرداخت",IF($L11="انتقال داخلی",0,$J11),0) -> 0 | O11: ='[01_Entry.xlsx]Pay'!P11 -> تسویه بار | P11: =IF($B11="","","ثبت روزانه") -> 0
A12: ='[01_Entry.xlsx]Pay'!B12 -> 1405/07/07 | B12: ='[01_Entry.xlsx]Pay'!C12 -> PV-002 | C12: ='[01_Entry.xlsx]Pay'!D12 -> پرداخت | D12: ='[01_Entry.xlsx]Pay'!E12 -> چک | E12: ='[01_Entry.xlsx]Pay'!F12 -> C002 | F12: ='[01_Entry.xlsx]Pay'!G12 -> سید عباس موسوی | G12: ='[01_Entry.xlsx]Pay'!H12 -> باغدار | H12: ='[01_Entry.xlsx]Pay'!I12 -> BANK01 | ... L12: ='[01_Entry.xlsx]Pay'!M12 | M12: =IF($D12="دریافت",IF($L12="انتقال داخلی",0,$J12),0) -> 0 | N12: =IF($D12="پرداخت",IF($L12="انتقال داخلی",0,$J12),0) -> 0 | O12: ='[01_Entry.xlsx]Pay'!P12 -> چک ۳۰ روزه | P12: =IF($B12="","","ثبت روزانه") -> 0
A13: ='[01_Entry.xlsx]Pay'!B13 -> 1405/07/08 | B13: ='[01_Entry.xlsx]Pay'!C13 -> PV-003 | C13: ='[01_Entry.xlsx]Pay'!D13 -> پرداخت | D13: ='[01_Entry.xlsx]Pay'!E13 -> انتقال بانکی | E13: ='[01_Entry.xlsx]Pay'!F13 -> C003 | F13: ='[01_Entry.xlsx]Pay'!G13 -> حاج احمد عیسی پور | G13: ='[01_Entry.xlsx]Pay'!H13 -> باغدار | H13: ='[01_Entry.xlsx]Pay'!I13 -> BANK02 | ... L13: ='[01_Entry.xlsx]Pay'!M13 | M13: =IF($D13="دریافت",IF($L13="انتقال داخلی",0,$J13),0) -> 0 | N13: =IF($D13="پرداخت",IF($L13="انتقال داخلی",0,$J13),0) -> 0 | O13: ='[01_Entry.xlsx]Pay'!P13 -> empty | P13: =IF($B13="","","ثبت روزانه") -> 0
A14: ='[01_Entry.xlsx]Pay'!B14 -> 1405/07/09 | B14: ='[01_Entry.xlsx]Pay'!C14 -> RV-002 | C14: ='[01_Entry.xlsx]Pay'!D14 -> دریافت | D14: ='[01_Entry.xlsx]Pay'!E14 -> کارت/پوز | E14: ='[01_Entry.xlsx]Pay'!F14 -> SL002 | F14: ='[01_Entry.xlsx]Pay'!G14 -> مشهد — محمد توکلی | G14: ='[01_Entry.xlsx]Pay'!H14 -> بارفروش | H14: ='[01_Entry.xlsx]Pay'!I14 -> BANK02 | ... L14: ='[01_Entry.xlsx]Pay'!M14 | M14: =IF($D14="دریافت",IF($L14="انتقال داخلی",0,$J14),0) -> 0 | N14: =IF($D14="پرداخت",IF($L14="انتقال داخلی",0,$J14),0) -> 0 | O14: ='[01_Entry.xlsx]Pay'!P14 -> empty | P14: =IF($B14="","","ثبت روزانه") -> 0
A15: ='[01_Entry.xlsx]Pay'!B15 -> 1405/07/10 | B15: ='[01_Entry.xlsx]Pay'!C15 -> PV-004 | C15: ='[01_Entry.xlsx]Pay'!D15 -> پرداخت | D15: ='[01_Entry.xlsx]Pay'!E15 -> پاس چک | E15: ='[01_Entry.xlsx]Pay'!F15 -> X010 | F15: ='[01_Entry.xlsx]Pay'!G15 -> چک‌های پرداختی (در جریان) | G15: ='[01_Entry.xlsx]Pay'!H15 -> سایر حساب | H15: ='[01_Entry.xlsx]Pay'!I15 -> BANK01 | ... L15: ='[01_Entry.xlsx]Pay'!M15 | M15: =IF($D15="دریافت",IF($L15="انتقال داخلی",0,$J15),0) -> 0 | N15: =IF($D15="پرداخت",IF($L15="انتقال داخلی",0,$J15),0) -> 0 | O15: ='[01_Entry.xlsx]Pay'!P15 -> پاس شدن چک | P15: =IF($B15="","","ثبت روزانه") -> 0
A16: ='[01_Entry.xlsx]Pay'!B16 -> 1405/07/10 | B16: ='[01_Entry.xlsx]Pay'!C16 -> PV-005 | C16: ='[01_Entry.xlsx]Pay'!D16 -> پرداخت | D16: ='[01_Entry.xlsx]Pay'!E16 -> نقد | E16: ='[01_Entry.xlsx]Pay'!F16 -> C006 | F16: ='[01_Entry.xlsx]Pay'!G16 -> هوشنگ عیسی پور | G16: ='[01_Entry.xlsx]Pay'!H16 -> باغدار | H16: ='[01_Entry.xlsx]Pay'!I16 -> empty | ... L16: ='[01_Entry.xlsx]Pay'!M16 | M16: =IF($D16="دریافت",IF($L16="انتقال داخلی",0,$J16),0) -> 0 | N16: =IF($D16="پرداخت",IF($L16="انتقال داخلی",0,$J16),0) -> 0 | O16: ='[01_Entry.xlsx]Pay'!P16 -> empty | P16: =IF($B16="","","ثبت روزانه") -> 0
A17: ='[01_Entry.xlsx]Pay'!B17 -> 1405/07/11 | B17: ='[01_Entry.xlsx]Pay'!C17 -> RV-003 | C17: ='[01_Entry.xlsx]Pay'!D17 -> دریافت | D17: ='[01_Entry.xlsx]Pay'!E17 -> انتقال بانکی | E17: ='[01_Entry.xlsx]Pay'!F17 -> SL001 | F17: ='[01_Entry.xlsx]Pay'!G17 -> قم — سید حسین حسینی | G17: ='[01_Entry.xlsx]Pay'!H17 -> بارفروش | H17: ='[01_Entry.xlsx]Pay'!I17 -> BANK02 | ... L17: ='[01_Entry.xlsx]Pay'!M17 | M17: =IF($D17="دریافت",IF($L17="انتقال داخلی",0,$J17),0) -> 0 | N17: =IF($D17="پرداخت",IF($L17="انتقال داخلی",0,$J17),0) -> 0 | O17: ='[01_Entry.xlsx]Pay'!P17 -> empty | P17: =IF($B17="","","ثبت روزانه") -> 0
A18: ='[01_Entry.xlsx]Pay'!B18 -> 1405/07/11 | B18: ='[01_Entry.xlsx]Pay'!C18 -> PV-006 | C18: ='[01_Entry.xlsx]Pay'!D18 -> پرداخت | D18: ='[01_Entry.xlsx]Pay'!E18 -> نقد | E18: ='[01_Entry.xlsx]Pay'!F18 -> X001 | F18: ='[01_Entry.xlsx]Pay'!G18 -> انعام مصطفی | G18: ='[01_Entry.xlsx]Pay'!H18 -> سایر حساب | H18: ='[01_Entry.xlsx]Pay'!I18 -> empty | ... L18: ='[01_Entry.xlsx]Pay'!M18 | M18: =IF($D18="دریافت",IF($L18="انتقال داخلی",0,$J18),0) -> 0 | N18: =IF($D18="پرداخت",IF($L18="انتقال داخلی",0,$J18),0) -> 0 | O18: ='[01_Entry.xlsx]Pay'!P18 -> تسویه انعام مصطفی | P18: =IF($B18="","","ثبت روزانه") -> 0
A19: ='[01_Entry.xlsx]Pay'!B19 -> 1405/07/12 | B19: ='[01_Entry.xlsx]Pay'!C19 -> PV-007 | C19: ='[01_Entry.xlsx]Pay'!D19 -> پرداخت | D19: ='[01_Entry.xlsx]Pay'!E19 -> انتقال داخلی | E19: ='[01_Entry.xlsx]Pay'!F19 -> BANK02 | F19: ='[01_Entry.xlsx]Pay'!G19 -> کد ناشناخته | G19: ='[01_Entry.xlsx]Pay'!H19 | H19: ='[01_Entry.xlsx]Pay'!I19 -> BANK01 | ... L19: ='[01_Entry.xlsx]Pay'!M19 | M19: =IF($D19="دریافت",IF($L19="انتقال داخلی",0,$J19),0) -> 0 | N19: =IF($D19="پرداخت",IF($L19="انتقال داخلی",0,$J19),0) -> 0 | O19: ='[01_Entry.xlsx]Pay'!P19 -> انتقال بین بانکی | P19: =IF($B19="","","ثبت روزانه") -> 0
A20: ='[01_Entry.xlsx]Pay'!B20 -> 1405/07/07 | B20: ='[01_Entry.xlsx]Pay'!C20 -> PV-008 | C20: ='[01_Entry.xlsx]Pay'!D20 -> پرداخت | D20: ='[01_Entry.xlsx]Pay'!E20 -> چک | E20: ='[01_Entry.xlsx]Pay'!F20 -> C004 | F20: ='[01_Entry.xlsx]Pay'!G20 -> امید زاهدی | G20: ='[01_Entry.xlsx]Pay'!H20 -> باغدار | H20: ='[01_Entry.xlsx]Pay'!I20 -> BANK03 | ... L20: ='[01_Entry.xlsx]Pay'!M20 | M20: =IF($D20="دریافت",IF($L20="انتقال داخلی",0,$J20),0) -> 0 | N20: =IF($D20="پرداخت",IF($L20="انتقال داخلی",0,$J20),0) -> 0 | O20: ='[01_Entry.xlsx]Pay'!P20 -> در جریان | P20: =IF($B20="","","ثبت روزانه") -> 0
A21: ='[01_Entry.xlsx]Pay'!B21 -> 1405/07/12 | B21: ='[01_Entry.xlsx]Pay'!C21 -> RV-004 | C21: ='[01_Entry.xlsx]Pay'!D21 -> دریافت | D21: ='[01_Entry.xlsx]Pay'!E21 -> انتقال بانکی | E21: ='[01_Entry.xlsx]Pay'!F21 -> SL002 | F21: ='[01_Entry.xlsx]Pay'!G21 -> مشهد — محمد توکلی | G21: ='[01_Entry.xlsx]Pay'!H21 -> بارفروش | H21: ='[01_Entry.xlsx]Pay'!I21 -> BANK01 | ... L21: ='[01_Entry.xlsx]Pay'!M21 | M21: =IF($D21="دریافت",IF($L21="انتقال داخلی",0,$J21),0) -> 0 | N21: =IF($D21="پرداخت",IF($L21="انتقال داخلی",0,$J21),0) -> 0 | O21: ='[01_Entry.xlsx]Pay'!P21 -> empty | P21: =IF($B21="","","ثبت روزانه") -> 0
... A159: ='[01_Entry.xlsx]Pay'!B159 -> empty | B159: ='[01_Entry.xlsx]Pay'!C159 -> empty | C159: ='[01_Entry.xlsx]Pay'!D159 -> empty | D159: ='[01_Entry.xlsx]Pay'!E159 -> empty | E159: ='[01_Entry.xlsx]Pay'!F159 -> empty | F159: ='[01_Entry.xlsx]Pay'!G159 | G159: ='[01_Entry.xlsx]Pay'!H159 | H159: ='[01_Entry.xlsx]Pay'!I159 -> empty | ... L159: ='[01_Entry.xlsx]Pay'!M159 | M159: =IF($D159="دریافت",IF($L159="انتقال داخلی",0,$J159),0) -> 0 | N159: =IF($D159="پرداخت",IF($L159="انتقال داخلی",0,$J159),0) -> 0 | O159: ='[01_Entry.xlsx]Pay'!P159 -> empty | P159: =IF($B159="","","ثبت روزانه") -> 0

Sheet Chq
A1: مازندشت — سورتینگ و بسته‌بندی مرکبات | J1: MAZANDASHT · CITRUS SORTING & PACKING
A2: پیگیری چک‌ها
A3: هر سطر یک چک · وضعیت را در ثبت روزانه تغییر دهید (در جریان / پاس شده / برگشتی)
A4: راهنما | B4: ورود دستی | C4: خودکار | D4: ورود | E4: خروج | F4: هشدار | G4: ستون‌های زرد = ورود شما | ستون‌های خاکستری = محاسبه خودکار | روی سرستون‌ها بایستید تا راهنما باز شود
A5: تعداد چک | D5: در جریان | G5: پاس شده | J5: برگشتی | M5: مبلغ در جریان
A6: =COUNTA($C$10:$C$159) -> 0 | D6: =COUNTIF($J$10:$J$159,"در جریان") -> 0 | G6: =COUNTIF($J$10:$J$159,"پاس شده") -> 0 | J6: =COUNTIF($J$10:$J$159,"برگشتی") -> 0 | M6: =SUMIF($J$10:$J$159,"در جریان",$H$10:$H$159) -> 0
A8: تاریخ | B8: سند | C8: شماره چک | D8: نوع | E8: طرف حساب | F8: بانک | G8: سررسید | H8: مبلغ | I8: وضعیت | J8: چند روز مانده | K8: هشدار
A9: Date | B9: Doc | C9: Cheque | D9: Type | E9: Party | F9: Bank | G9: Due | H9: Amount | I9: Status | J9: Days | K9: Alert
A10: ='[01_Entry.xlsx]Pay'!B10 -> 1405/07/06 | B10: ='[01_Entry.xlsx]Pay'!C10 -> PV-001 | C10: ='[01_Entry.xlsx]Pay'!J10 | D10: ='[01_Entry.xlsx]Pay'!D10 -> پرداخت | E10: ='[01_Entry.xlsx]Pay'!F10 -> C001 | F10: ='[01_Entry.xlsx]Pay'!I10 -> empty | G10: ='[01_Entry.xlsx]Pay'!M10 | H10: ='[01_Entry.xlsx]Pay'!K10 -> 150000000 | I10: ='[01_Entry.xlsx]Pay'!L10 -> empty | J10: =IF(OR($C10="",$G10=""),"","—") -> 0 | K10: =IF($C10="","",IF($I10="برگشتی","⚠ برگشت",IF($H10="در جریان","⏳ در جریان","✓"))) -> 0
A11: ='[01_Entry.xlsx]Pay'!B11 -> 1405/07/06 | B11: ='[01_Entry.xlsx]Pay'!C11 -> RV-001 | C11: ='[01_Entry.xlsx]Pay'!J11 | D11: ='[01_Entry.xlsx]Pay'!D11 -> دریافت | E11: ='[01_Entry.xlsx]Pay'!F11 -> SL001 | F11: ='[01_Entry.xlsx]Pay'!I11 -> BANK01 | G11: ='[01_Entry.xlsx]Pay'!M11 | H11: ='[01_Entry.xlsx]Pay'!K11 -> 300000000 | I11: ='[01_Entry.xlsx]Pay'!L11 -> empty | J11: =IF(OR($C11="",$G11=""),"","—") -> 0 | K11: =IF($C11="","",IF($I11="برگشتی","⚠ برگشت",IF($H11="در جریان","⏳ در جریان","✓"))) -> 0
A12: ='[01_Entry.xlsx]Pay'!B12 -> 1405/07/07 | B12: ='[01_Entry.xlsx]Pay'!C12 -> PV-002 | C12: ='[01_Entry.xlsx]Pay'!J12 -> CHQ-1001 | D12: ='[01_Entry.xlsx]Pay'!D12 -> پرداخت | E12: ='[01_Entry.xlsx]Pay'!F12 -> C002 | F12: ='[01_Entry.xlsx]Pay'!I12 -> BANK01 | G12: ='[01_Entry.xlsx]Pay'!M12 | H12: ='[01_Entry.xlsx]Pay'!K12 -> 200000000 | I12: ='[01_Entry.xlsx]Pay'!L12 -> در جریان | J12: =IF(OR($C12="",$G12=""),"","—") -> 0 | K12: =IF($C12="","",IF($I12="برگشتی","⚠ برگشت",IF($H12="در جریان","⏳ در جریان","✓"))) -> 0
A13: ='[01_Entry.xlsx]Pay'!B13 -> 1405/07/08 | B13: ='[01_Entry.xlsx]Pay'!C13 -> PV-003 | C13: ='[01_Entry.xlsx]Pay'!J13 | D13: ='[01_Entry.xlsx]Pay'!D13 -> پرداخت | E13: ='[01_Entry.xlsx]Pay'!F13 -> C003 | F13: ='[01_Entry.xlsx]Pay'!I13 -> BANK02 | G13: ='[01_Entry.xlsx]Pay'!M13 | H13: ='[01_Entry.xlsx]Pay'!K13 -> 80000000 | I13: ='[01_Entry.xlsx]Pay'!L13 -> empty | J13: =IF(OR($C13="",$G13=""),"","—") -> 0 | K13: =IF($C13="","",IF($I13="برگشتی","⚠ برگشت",IF($H13="در جریان","⏳ در جریان","✓"))) -> 0
A14: ='[01_Entry.xlsx]Pay'!B14 -> 1405/07/09 | B14: ='[01_Entry.xlsx]Pay'!C14 -> RV-002 | C14: ='[01_Entry.xlsx]Pay'!J14 | D14: ='[01_Entry.xlsx]Pay'!D14 -> دریافت | E14: ='[01_Entry.xlsx]Pay'!F14 -> SL002 | F14: ='[01_Entry.xlsx]Pay'!I14 -> BANK02 | G14: ='[01_Entry.xlsx]Pay'!M14 | H14: ='[01_Entry.xlsx]Pay'!K14 -> 120000000 | I14: ='[01_Entry.xlsx]Pay'!L14 -> empty | J14: =IF(OR($C14="",$G14=""),"","—") -> 0 | K14: =IF($C14="","",IF($I14="برگشتی","⚠ برگشت",IF($H14="در جریان","⏳ در جریان","✓"))) -> 0
A15: ='[01_Entry.xlsx]Pay'!B15 -> 1405/07/10 | B15: ='[01_Entry.xlsx]Pay'!C15 -> PV-004 | C15: ='[01_Entry.xlsx]Pay'!J15 -> CHQ-1001 | D15: ='[01_Entry.xlsx]Pay'!D15 -> پرداخت | E15: ='[01_Entry.xlsx]Pay'!F15 -> X010 | F15: ='[01_Entry.xlsx]Pay'!I15 -> BANK01 | G15: ='[01_Entry.xlsx]Pay'!M15 | H15: ='[01_Entry.xlsx]Pay'!K15 -> 200000000 | I15: ='[01_Entry.xlsx]Pay'!L15 -> پاس شده | J15: =IF(OR($C15="",$G15=""),"","—") -> 0 | K15: =IF($C15="","",IF($I15="برگشتی","⚠ برگشت",IF($H15="در جریان","⏳ در جریان","✓"))) -> 0
A16: ='[01_Entry.xlsx]Pay'!B16 -> 1405/07/10 | B16: ='[01_Entry.xlsx]Pay'!C16 -> PV-005 | C16: ='[01_Entry.xlsx]Pay'!J16 | D16: ='[01_Entry.xlsx]Pay'!D16 -> پرداخت | E16: ='[01_Entry.xlsx]Pay'!F16 -> C006 | F16: ='[01_Entry.xlsx]Pay'!I16 -> empty | G16: ='[01_Entry.xlsx]Pay'!M16 | H16: ='[01_Entry.xlsx]Pay'!K16 -> 30000000 | I16: ='[01_Entry.xlsx]Pay'!L16 -> empty | J16: =IF(OR($C16="",$G16=""),"","—") -> 0 | K16: =IF($C16="","",IF($I16="برگشتی","⚠ برگشت",IF($H16="در جریان","⏳ در جریان","✓"))) -> 0
A17: ='[01_Entry.xlsx]Pay'!B17 -> 1405/07/11 | B17: ='[01_Entry.xlsx]Pay'!C17 -> RV-003 | C17: ='[01_Entry.xlsx]Pay'!J17 | D17: ='[01_Entry.xlsx]Pay'!D17 -> دریافت | E17: ='[01_Entry.xlsx]Pay'!F17 -> SL001 | F17: ='[01_Entry.xlsx]Pay'!I17 -> BANK02 | G17: ='[01_Entry.xlsx]Pay'!M17 | H17: ='[01_Entry.xlsx]Pay'!K17 -> 100000000 | I17: ='[01_Entry.xlsx]Pay'!L17 -> empty | J17: =IF(OR($C17="",$G17=""),"","—") -> 0 | K17: =IF($C17="","",IF($I17="برگشتی","⚠ برگشت",IF($H17="در جریان","⏳ در جریان","✓"))) -> 0
A18: ='[01_Entry.xlsx]Pay'!B18 -> 1405/07/11 | B18: ='[01_Entry.xlsx]Pay'!C18 -> PV-006 | C18: ='[01_Entry.xlsx]Pay'!J18 | D18: ='[01_Entry.xlsx]Pay'!D18 -> پرداخت | E18: ='[01_Entry.xlsx]Pay'!F18 -> X001 | F18: ='[01_Entry.xlsx]Pay'!I18 -> empty | G18: ='[01_Entry.xlsx]Pay'!M18 | H18: ='[01_Entry.xlsx]Pay'!K18 -> 500000 | I18: ='[01_Entry.xlsx]Pay'!L18 -> empty | J18: =IF(OR($C18="",$G18=""),"","—") -> 0 | K18: =IF($C18="","",IF($I18="برگشتی","⚠ برگشت",IF($H18="در جریان","⏳ در جریان","✓"))) -> 0
A19: ='[01_Entry.xlsx]Pay'!B19 -> 1405/07/12 | B19: ='[01_Entry.xlsx]Pay'!C19 -> PV-007 | C19: ='[01_Entry.xlsx]Pay'!J19 | D19: ='[01_Entry.xlsx]Pay'!D19 -> پرداخت | E19: ='[01_Entry.xlsx]Pay'!F19 -> BANK02 | F19: ='[01_Entry.xlsx]Pay'!I19 -> BANK01 | G19: ='[01_Entry.xlsx]Pay'!M19 | H19: ='[01_Entry.xlsx]Pay'!K19 -> 50000000 | I19: ='[01_Entry.xlsx]Pay'!L19 -> empty | J19: =IF(OR($C19="",$G19=""),"","—") -> 0 | K19: =IF($C19="","",IF($I19="برگشتی","⚠ برگشت",IF($H19="در جریان","⏳ در جریان","✓"))) -> 0
A20: ='[01_Entry.xlsx]Pay'!B20 -> 1405/07/07 | B20: ='[01_Entry.xlsx]Pay'!C20 -> PV-008 | C20: ='[01_Entry.xlsx]Pay'!J20 -> CHQ-1002 | D20: ='[01_Entry.xlsx]Pay'!D20 -> پرداخت | E20: ='[01_Entry.xlsx]Pay'!F20 -> C004 | F20: ='[01_Entry.xlsx]Pay'!I20 -> BANK03 | G20: ='[01_Entry.xlsx]Pay'!M20 | H20: ='[01_Entry.xlsx]Pay'!K20 -> 60000000 | I20: ='[01_Entry.xlsx]Pay'!L20 -> در جریان | J20: =IF(OR($C20="",$G20=""),"","—") -> 0 | K20: =IF($C20="","",IF($I20="برگشتی","⚠ برگشت",IF($H20="در جریان","⏳ در جریان","✓"))) -> 0
A21: ='[01_Entry.xlsx]Pay'!B21 -> 1405/07/12 | B21: ='[01_Entry.xlsx]Pay'!C21 -> RV-004 | C21: ='[01_Entry.xlsx]Pay'!J21 | D21: ='[01_Entry.xlsx]Pay'!D21 -> دریافت | E21: ='[01_Entry.xlsx]Pay'!F21 -> SL002 | F21: ='[01_Entry.xlsx]Pay'!I21 -> BANK01 | G21: ='[01_Entry.xlsx]Pay'!M21 | H21: ='[01_Entry.xlsx]Pay'!K21 -> 50000000 | I21: ='[01_Entry.xlsx]Pay'!L21 -> empty | J21: =IF(OR($C21="",$G21=""),"","—") -> 0 | K21: =IF($C21="","",IF($I21="برگشتی","⚠ برگشت",IF($H21="در جریان","⏳ در جریان","✓"))) -> 0
... A159: ='[01_Entry.xlsx]Pay'!B159 -> empty | B159: ='[01_Entry.xlsx]Pay'!C159 -> empty | C159: ='[01_Entry.xlsx]Pay'!J159 | D159: ='[01_Entry.xlsx]Pay'!D159 -> empty | E159: ='[01_Entry.xlsx]Pay'!F159 -> empty | F159: ='[01_Entry.xlsx]Pay'!I159 -> empty | G159: ='[01_Entry.xlsx]Pay'!M159 | H159: ='[01_Entry.xlsx]Pay'!K159 -> empty | I159: ='[01_Entry.xlsx]Pay'!L159 -> empty | J159: =IF(OR($C159="",$G159=""),"","—") -> 0 | K159: =IF($C159="","",IF($I159="برگشتی","⚠ برگشت",IF($H159="در جریان","⏳ در جریان","✓"))) -> 0

Sheet Rec
A1: مازندشت — سورتینگ و بسته‌بندی مرکبات | E1: MAZANDASHT · CITRUS SORTING & PACKING
A2: مغایرت‌گیری بانکی
A3: مانده دفتر (خودکار) را با مانده واقعی صورت‌حساب بانک مقایسه کنید
A4: راهنما | B4: ورود دستی | C4: خودکار | D4: ورود | E4: خروج | F4: هشدار | G4: ستون‌های زرد = ورود شما | ستون‌های خاکستری = محاسبه خودکار | روی سرستون‌ها بایستید تا راهنما باز شود
A5: جمع مانده دفتر | D5: جمع مانده بانک | G5: مغایرت
A6: =SUM($F$12:$F$21) -> 0 | D6: =SUM($H$12:$H$21) -> 0 | G6: =SUM($F$12:$F$21)-SUM($H$12:$H$21) -> 0
A10: ۰۱ | B10: مانده هر بانک — ستون «مانده بانک» را از صورت‌حساب وارد کنید؛ مغایرت خودکار حساب می‌شود
A11: بانک | B11: کد | C11: مانده اولیه | D11: دریافت | E11: پرداخت | F11: مانده دفتر | G11: مانده بانک (ورود دستی) | H11: مغایرت | I11: وضعیت
A12: صادرات ۹۰۰۹ — جاری اصلی | B12: BANK01 | C12: 500000000 | D12: =SUMIFS(Txn!$M$10:$M$159,Txn!$H$10:$H$159,$B12) -> 0 | E12: =SUMIFS(Txn!$N$10:$N$159,Txn!$H$10:$H$159,$B12) -> 0 | F12: =$C12+$D12-$E12 -> 0 | G12: 0 | H12: =$F12-$G12 -> 0 | I12: =IF(ROUND($H12,0)=0,"✓","⚠") -> 0
A13: صادرات ۲۰۰۶ — پوز باسکول | B13: BANK02 | C13: 0 | D13: =SUMIFS(Txn!$M$10:$M$159,Txn!$H$10:$H$159,$B13) -> 0 | E13: =SUMIFS(Txn!$N$10:$N$159,Txn!$H$10:$H$159,$B13) -> 0 | F13: =$C13+$D13-$E13 -> 0 | G13: 0 | H13: =$F13-$G13 -> 0 | I13: =IF(ROUND($H13,0)=0,"✓","⚠") -> 0
A14: ملت | B14: BANK03 | C14: 0 | D14: =SUMIFS(Txn!$M$10:$M$159,Txn!$H$10:$H$159,$B14) -> 0 | E14: =SUMIFS(Txn!$N$10:$N$159,Txn!$H$10:$H$159,$B14) -> 0 | F14: =$C14+$D14-$E14 -> 0 | G14: 0 | H14: =$F14-$G14 -> 0 | I14: =IF(ROUND($H14,0)=0,"✓","⚠") -> 0
A15: کشاورزی | B15: BANK04 | C15: 0 | D15: =SUMIFS(Txn!$M$10:$M$159,Txn!$H$10:$H$159,$B15) -> 0 | E15: =SUMIFS(Txn!$N$10:$N$159,Txn!$H$10:$H$159,$B15) -> 0 | F15: =$C15+$D15-$E15 -> 0 | G15: 0 | H15: =$F15-$G15 -> 0 | I15: =IF(ROUND($H15,0)=0,"✓","⚠") -> 0
A16: سپه | B16: BANK05 | C16: 0 | D16: =SUMIFS(Txn!$M$10:$M$159,Txn!$H$10:$H$159,$B16) -> 0 | E16: =SUMIFS(Txn!$N$10:$N$159,Txn!$H$10:$H$159,$B16) -> 0 | F16: =$C16+$D16-$E16 -> 0 | G16: 0 | H16: =$F16-$G16 -> 0 | I16: =IF(ROUND($H16,0)=0,"✓","⚠") -> 0
A17: مهر ایران | B17: BANK06 | C17: 0 | D17: =SUMIFS(Txn!$M$10:$M$159,Txn!$H$10:$H$159,$B17) -> 0 | E17: =SUMIFS(Txn!$N$10:$N$159,Txn!$H$10:$H$159,$B17) -> 0 | F17: =$C17+$D17-$E17 -> 0 | G17: 0 | H17: =$F17-$G17 -> 0 | I17: =IF(ROUND($H17,0)=0,"✓","⚠") -> 0
A18: تجارت | B18: BANK07 | C18: 0 | D18: =SUMIFS(Txn!$M$10:$M$159,Txn!$H$10:$H$159,$B18) -> 0 | E18: =SUMIFS(Txn!$N$10:$N$159,Txn!$H$10:$H$159,$B18) -> 0 | F18: =$C18+$D18-$E18 -> 0 | G18: 0 | H18: =$F18-$G18 -> 0 | I18: =IF(ROUND($H18,0)=0,"✓","⚠") -> 0
A19: پاسارگاد | B19: BANK08 | C19: 0 | D19: =SUMIFS(Txn!$M$10:$M$159,Txn!$H$10:$H$159,$B19) -> 0 | E19: =SUMIFS(Txn!$N$10:$N$159,Txn!$H$10:$H$159,$B19) -> 0 | F19: =$C19+$D19-$E19 -> 0 | G19: 0 | H19: =$F19-$G19 -> 0 | I19: =IF(ROUND($H19,0)=0,"✓","⚠") -> 0
A20: رفاه | B20: BANK09 | C20: 0 | D20: =SUMIFS(Txn!$M$10:$M$159,Txn!$H$10:$H$159,$B20) -> 0 | E20: =SUMIFS(Txn!$N$10:$N$159,Txn!$H$10:$H$159,$B20) -> 0 | F20: =$C20+$D20-$E20 -> 0 | G20: 0 | H20: =$F20-$G20 -> 0 | I20: =IF(ROUND($H20,0)=0,"✓","⚠") -> 0
A21: قرض‌الحسنه | B21: BANK10 | C21: 0 | D21: =SUMIFS(Txn!$M$10:$M$159,Txn!$H$10:$H$159,$B21) -> 0 | E21: =SUMIFS(Txn!$N$10:$N$159,Txn!$H$10:$H$159,$B21) -> 0 | F21: =$C21+$D21-$E21 -> 0 | G21: 0 | H21: =$F21-$G21 -> 0 | I21: =IF(ROUND($H21,0)=0,"✓","⚠") -> 0

Sheet Sum
A1: مازندشت — سورتینگ و بسته‌بندی مرکبات | G1: MAZANDASHT · CITRUS SORTING & PACKING
A2: خلاصه ماهانه بانک
A3: دریافت و پرداخت هر ماه شمسی · بر اساس ماه تاریخ سند
A4: راهنما | B4: ورود دستی | C4: خودکار | D4: ورود | E4: خروج | F4: هشدار | G4: ستون‌های زرد = ورود شما | ستون‌های خاکستری = محاسبه خودکار | روی سرستون‌ها بایستید تا راهنما باز شود
A5: جمع دریافت | E5: جمع پرداخت | I5: مانده
A6: =SUM($B$12:$B$23) -> 0 | E6: =SUM($C$12:$C$23) -> 0 | I6: =SUM($B$12:$B$23)-SUM($C$12:$C$23) -> 0
A11: ماه | B11: دریافت | C11: پرداخت | D11: مانده ماه | E11: تعداد تراکنش
A13: 01 | B13: =SUMIFS(Txn!$M$10:$M$159,Txn!$A$10:$A$159,"*/01/*") -> 0 | C13: =SUMIFS(Txn!$N$10:$N$159,Txn!$A$10:$A$159,"*/01/*") -> 0 | D13: =$B13-$C13 -> 0 | E13: =COUNTIF(Txn!$A$10:$A$159,"*/01/*") -> 0
A14: 02 | B14: =SUMIFS(Txn!$M$10:$M$159,Txn!$A$10:$A$159,"*/02/*") -> 0 | C14: =SUMIFS(Txn!$N$10:$N$159,Txn!$A$10:$A$159,"*/02/*") -> 0 | D14: =$B14-$C14 -> 0 | E14: =COUNTIF(Txn!$A$10:$A$159,"*/02/*") -> 0
A15: 03 | B15: =SUMIFS(Txn!$M$10:$M$159,Txn!$A$10:$A$159,"*/03/*") -> 0 | C15: =SUMIFS(Txn!$N$10:$N$159,Txn!$A$10:$A$159,"*/03/*") -> 0 | D15: =$B15-$C15 -> 0 | E15: =COUNTIF(Txn!$A$10:$A$159,"*/03/*") -> 0
A16: 04 | B16: =SUMIFS(Txn!$M$10:$M$159,Txn!$A$10:$A$159,"*/04/*") -> 0 | C16: =SUMIFS(Txn!$N$10:$N$159,Txn!$A$10:$A$159,"*/04/*") -> 0 | D16: =$B16-$C16 -> 0 | E16: =COUNTIF(Txn!$A$10:$A$159,"*/04/*") -> 0
A17: 05 | B17: =SUMIFS(Txn!$M$10:$M$159,Txn!$A$10:$A$159,"*/05/*") -> 0 | C17: =SUMIFS(Txn!$N$10:$N$159,Txn!$A$10:$A$159,"*/05/*") -> 0 | D17: =$B17-$C17 -> 0 | E17: =COUNTIF(Txn!$A$10:$A$159,"*/05/*") -> 0
A18: 06 | B18: =SUMIFS(Txn!$M$10:$M$159,Txn!$A$10:$A$159,"*/06/*") -> 0 | C18: =SUMIFS(Txn!$N$10:$N$159,Txn!$A$10:$A$159,"*/06/*") -> 0 | D18: =$B18-$C18 -> 0 | E18: =COUNTIF(Txn!$A$10:$A$159,"*/06/*") -> 0
A19: 07 | B19: =SUMIFS(Txn!$M$10:$M$159,Txn!$A$10:$A$159,"*/07/*") -> 0 | C19: =SUMIFS(Txn!$N$10:$N$159,Txn!$A$10:$A$159,"*/07/*") -> 0 | D19: =$B19-$C19 -> 0 | E19: =COUNTIF(Txn!$A$10:$A$159,"*/07/*") -> 0
A20: 08 | B20: =SUMIFS(Txn!$M$10:$M$159,Txn!$A$10:$A$159,"*/08/*") -> 0 | C20: =SUMIFS(Txn!$N$10:$N$159,Txn!$A$10:$A$159,"*/08/*") -> 0 | D20: =$B20-$C20 -> 0 | E20: =COUNTIF(Txn!$A$10:$A$159,"*/08/*") -> 0
A21: 09 | B21: =SUMIFS(Txn!$M$10:$M$159,Txn!$A$10:$A$159,"*/09/*") -> 0 | C21: =SUMIFS(Txn!$N$10:$N$159,Txn!$A$10:$A$159,"*/09/*") -> 0 | D21: =$B21-$C21 -> 0 | E21: =COUNTIF(Txn!$A$10:$A$159,"*/09/*") -> 0
A22: 10 | B22: =SUMIFS(Txn!$M$10:$M$159,Txn!$A$10:$A$159,"*/10/*") -> 0 | C22: =SUMIFS(Txn!$N$10:$N$159,Txn!$A$10:$A$159,"*/10/*") -> 0 | D22: =$B22-$C22 -> 0 | E22: =COUNTIF(Txn!$A$10:$A$159,"*/10/*") -> 0
A23: 11 | B23: =SUMIFS(Txn!$M$10:$M$159,Txn!$A$10:$A$159,"*/11/*") -> 0 | C23: =SUMIFS(Txn!$N$10:$N$159,Txn!$A$10:$A$159,"*/11/*") -> 0 | D23: =$B23-$C23 -> 0 | E23: =COUNTIF(Txn!$A$10:$A$159,"*/11/*") -> 0
A24: 12 | B24: =SUMIFS(Txn!$M$10:$M$159,Txn!$A$10:$A$159,"*/12/*") -> 0 | C24: =SUMIFS(Txn!$N$10:$N$159,Txn!$A$10:$A$159,"*/12/*") -> 0 | D24: =$B24-$C24 -> 0 | E24: =COUNTIF(Txn!$A$10:$A$159,"*/12/*") -> 0

Sheet Sync
A1: داده‌های ثابت — کپی کامل از 00_Master.xlsx (بدون وابستگی)
A2: این شیت فقط نمایش است و قفل شده. همه کشوها و فرمول‌ها از همین‌جا می‌خوانند؛ برای تغییر، 00_Master.xlsx را ویرایش کنید و سپس این فایل را (با اسکریپت ساخت یا کپی ستون‌ها) دوباره همگام کنید. هیچ فرمولی به فایل مادر وابسته نیست، پس فایل همیشه سالم باز می‌شود. — این فایل از ثبت روزانه می‌خواند.
A3: MAZANDASHT · INFO MASTER DATA (READ ONLY)
B8: حساب‌ها — کد، نام، گروه، زیرگروه، نوع و مانده اولیه | I8: عملیات — قاعده بدهکار/بستانکار | Y8: سبدها — برچسب، کد، نام، تار، ظرفیت، خرید، فروش، موجودی | AH8: محصولات | AK8: بانک‌ها — کد، عنوان، مانده، حساب معین | AO8: پارامترها | AR8: گروه‌ها و زیرگروه‌ها | AU8: گروه‌های اصلی | AW8: عملیات سبد | AX8: باسکول دیگران | AZ8: عملیات باسکول
B9: ACCOUNTS | I9: OPERATIONS | Y9: BASKETS | AH9: PRODUCTS | AK9: BANKS | AO9: PARAMS | AR9: GROUPS | AU9: GROUP LIST | AW9: BASKET OPS | AX9: OTHER SCALES | AZ9: BASKOL OPS
B10: C001 | C10: زینب زاهدی | D10: باغدار | E10: عمده | F10: طرف حساب | G10: 0 | I10: خرید مرکبات | J10: ورود | K10: خرید | L10: بله | M10: بله | N10: وزن | O10: بستانکار | P10: X004 | Q10: بدهکار | R10: افزودن | S10: — | W10: بله | Y10: BK01 – ۶ک مشکی | Z10: BK01 | AA10: ۶ک مشکی | AB10: 1.5 | AC10: 6 | AD10: 45000 | AE10: 55000 | AF10: 1200 | AH10: پرتقال تامسون | AI10: پرتقال | AK10: BANK01 | AL10: صادرات ۹۰۰۹ — جاری اصلی | AM10: 500000000 | AN10: BN01 | AO10: P01 | AP10: 1.5 | AR10: باغدار | AS10: سردرختی | AU10: باغدار | AW10: خرید سبد | AX10: BD001 | AZ10: خرید مرکبات | CA10: کیلوگرم | CB10: پرتقال | CC10: ورود | CD10: بله | CE10: طرف حساب | CF10: نقد | CG10: در جریان | CH10: ☑ | CI10: افزودن | CJ10: بدهکار | CK10: بدهکار | CL10: خرید | CM10: ✓ | CN10: Growers | CO10: وزن | CP10: mint | CQ10: بهار | CR10: پرداخت
B11: C002 | C11: سید عباس موسوی | D11: باغدار | E11: صادراتی | F11: طرف حساب | G11: 0 | I11: فروش بار (بارفروش) | J11: خروج | K11: فروش | L11: بله | M11: بله | N11: وزن | O11: بدهکار | P11: X006 | Q11: بستانکار | R11: پوز | S11: بدهکار | T11: BANK02 | U11: X002 | W11: بله | Y11: BK02 – درب‌۶ک | Z11: BK02 | AA11: درب‌۶ک | AB11: 1.5 | AC11: 6 | AD11: 48000 | AE11: 58000 | AF11: 400 | AH11: پرتقال خونی | AI11: پرتقال | AK11: BANK02 | AL11: صادرات ۲۰۰۶ — پوز باسکول | AM11: 0 | AN11: BN02 | AO11: P02 | AP11: 1 | AR11: باغدار | AS11: انباری | AU11: بارفروش | AW11: فروش سبد | AX11: BD002 | AZ11: فروش بار (بارفروش) | CA11: سبد | CB11: نارنگی | CC11: خروج | CD11: خیر | CE11: معین | CF11: چک | CG11: پاس شده | CH11: ☐ | CI11: پوز | CJ11: بستانکار | CK11: بستانکار | CL11: فروش | CM11: ⚠ | CN11: LoadBuyers | CO11: مبلغ | CP11: sky | CQ11: تابستان | CR11: دریافت
B12: C003 | C12: حاج احمد عیسی پور | D12: باغدار | E12: خرده‌فروش | F12: طرف حساب | G12: 0 | I12: فروش متفرقه / صادراتی | J12: خروج | K12: فروش | L12: بله | M12: بله | N12: وزن | O12: بدهکار | P12: X006 | Q12: بستانکار | R12: پوز | S12: بدهکار | T12: BANK02 | U12: X002 | W12: بله | Y12: BK03 – ۹ک مشکی | Z12: BK03 | AA12: ۹ک مشکی | AB12: 1.9 | AC12: 9 | AD12: 62000 | AE12: 75000 | AF12: 800 | AH12: پرتقال کاراکارا | AI12: پرتقال | AK12: BANK03 | AL12: ملت | AM12: 0 | AN12: BN03 | AO12: P03 | AP12: 1000 | AR12: باغدار | AS12: عمده | AU12: فروشنده سبد | AW12: مرجوعی خرید سبد | AX12: BD003 | AZ12: فروش متفرقه / صادراتی | CA12: جعبه | CB12: لیمو | CC12: — | CF12: انتقال بانکی | CG12: برگشتی | CI12: هیچ | CJ12: — | CK12: خودکار | CL12: آبگیری | CN12: BasketSellers | CO12: هیچ | CP12: lavender | CQ12: پاییز
B13: C004 | C13: امید زاهدی | D13: باغدار | F13: طرف حساب | G13: 0 | I13: آبگیری | J13: خروج | K13: آبگیری | L13: بله | M13: بله | N13: مبلغ | O13: خودکار | P13: X008 | Q13: خودکار | R13: هیچ | S13: — | W13: بله | Y13: BK04 – ریلی کوچک آبی | Z13: BK04 | AA13: ریلی کوچک آبی | AB13: 1.3 | AC13: 5 | AD13: 40000 | AE13: 50000 | AF13: 300 | AH13: پرتقال بیروتی | AI13: پرتقال | AK13: BANK04 | AL13: کشاورزی | AM13: 0 | AN13: BN04 | AO13: P04 | AP13: 1405 | AR13: باغدار | AS13: خرده‌فروش | AU13: تأمین‌کننده | AW13: مرجوعی فروش سبد | AX13: BD004 | AZ13: آبگیری | CA13: تن | CB13: گریپ‌فرویت | CF13: کارت/پوز | CG13: باطل | CI13: — | CK13: — | CL13: انعام | CN13: Suppliers | CO13: — | CP13: rose | CQ13: زمستان
B14: C005 | C14: بار شخصی قاسم زاهدی | D14: باغدار | F14: طرف حساب | G14: 0 | I14: انعام مصطفی | J14: — | K14: انعام | L14: خیر | M14: خیر | N14: مبلغ | O14: بستانکار | P14: BANK02 | Q14: بدهکار | R14: هیچ | S14: — | V14: X001 | W14: بله | Y14: BK05 – تک‌رج آبی بزرگ | Z14: BK05 | AA14: تک‌رج آبی بزرگ | AB14: 2 | AC14: 10 | AD14: 70000 | AE14: 85000 | AF14: 250 | AH14: پرتقال یافا | AI14: پرتقال | AK14: BANK05 | AL14: سپه | AM14: 0 | AN14: BN05 | AO14: P05 | AP14: 100 | AR14: باغدار | AS14: صادراتی | AU14: کارمند | AW14: انتقال سبد بین انبار | AX14: BD005 | AZ14: انعام مصطفی | CA14: عدد | CB14: سایر | CF14: پاس چک | CL14: باسکول دیگران | CN14: Staff | CP14: sand
B15: C006 | C15: هوشنگ عیسی پور | D15: باغدار | F15: طرف حساب | G15: 0 | I15: باسکول دیگران | J15: — | K15: باسکول دیگران | L15: خیر | M15: بله | N15: مبلغ | O15: بدهکار | P15: X002 | Q15: بستانکار | R15: هیچ | S15: — | W15: بله | Y15: BK06 – آبی ۲۵×۲۰ | Z15: BK06 | AA15: آبی ۲۵×۲۰ | AB15: 1.1 | AC15: 4 | AD15: 35000 | AE15: 45000 | AF15: 150 | AH15: نارنگی پیچ | AI15: نارنگی | AK15: BANK06 | AL15: مهر ایران | AM15: 0 | AN15: BN06 | AO15: P06 | AP15: 0 | AR15: باغدار | AS15: میدان بار | AU15: سایر حساب | AX15: BD006 | AZ15: باسکول دیگران | CA15: ریال | CF15: انتقال داخلی | CL15: درآمد | CN15: Other | CP15: grey
B16: C007 | C16: علی آهنگر | D16: باغدار | F16: طرف حساب | G16: 0 | I16: درآمد پوز باسکول (بدون طرف) | J16: — | K16: درآمد | L16: خیر | M16: خیر | N16: مبلغ | O16: — | Q16: — | R16: پوز | S16: بدهکار | T16: BANK02 | U16: X002 | W16: بله | Y16: BK07 – ۸ک مشکی | Z16: BK07 | AA16: ۸ک مشکی | AB16: 1.8 | AC16: 8 | AD16: 58000 | AE16: 70000 | AF16: 200 | AH16: نارنگی ژاپنی | AI16: نارنگی | AK16: BANK07 | AL16: تجارت | AM16: 0 | AN16: BN07 | AO16: P07 | AP16: خرید- | AR16: بارفروش | AS16: میدان بار شهرستان | AU16: باسکول دیگران | AX16: BD007 | AZ16: درآمد پوز باسکول (بدون طرف) | CL16: هزینه | CN16: OtherScales | CP16: teal
B17: C008 | C17: صفدر مسلمی | D17: باغدار | F17: طرف حساب | G17: 0 | I17: مرجوعی خرید | J17: خروج | K17: خرید | L17: بله | M17: بله | N17: وزن | O17: بدهکار | P17: X004 | Q17: بستانکار | R17: افزودن | S17: — | W17: بله | Y17: BK08 – | Z17: BK08 | AB17: 1.5 | AC17: 6 | AD17: 0 | AE17: 0 | AF17: 0 | AH17: نارنگی اونشو | AI17: نارنگی | AK17: BANK08 | AL17: پاسارگاد | AM17: 0 | AN17: BN08 | AO17: P08 | AP17: فروش- | AR17: بارفروش | AS17: حجره‌دار | AU17: دارایی ثابت | AX17: BD008 | AZ17: مرجوعی خرید | CL17: انتقال | CN17: Assets | CP17: peach
B18: C009 | C18: همایون بابایی | D18: باغدار | F18: طرف حساب | G18: 0 | I18: مرجوعی فروش | J18: ورود | K18: فروش | L18: بله | M18: بله | N18: وزن | O18: بستانکار | P18: X006 | Q18: بدهکار | R18: هیچ | S18: — | W18: بله | Y18: BK09 – | Z18: BK09 | AB18: 1.5 | AC18: 6 | AD18: 0 | AE18: 0 | AF18: 0 | AH18: نارنگی یافا | AI18: نارنگی | AK18: BANK09 | AL18: رفاه | AM18: 0 | AN18: BN09 | AO18: P09 | AP18: 500000000 | AR18: بارفروش | AS18: صادراتی | AU18: وام و تسهیلات | AX18: BD009 | AZ18: مرجوعی فروش | CL18: سایر | CN18: Liabilities
B19: C010 | C19: دبیر فرجی | D19: باغدار | F19: طرف حساب | G19: 0 | I19: ضایعات / افت انبار | J19: خروج | K19: هزینه | L19: بله | M19: بله | N19: وزن | O19: بستانکار | P19: X009 | Q19: بدهکار | R19: هیچ | S19: — | V19: X004 | W19: بله | Y19: BK10 – | Z19: BK10 | AB19: 1.5 | AC19: 6 | AD19: 0 | AE19: 0 | AF19: 0 | AH19: لیمو شیرین | AI19: لیمو | AK19: BANK10 | AL19: قرض‌الحسنه | AM19: 0 | AN19: BN10 | AO19: P10 | AP19: 30 | AR19: بارفروش | AS19: واسطه | AU19: سرمایه و آورده صاحبان | AX19: BD010 | AZ19: ضایعات / افت انبار | CL19: تعدیل | CN19: Equity
B20: C011 | C20: محمود علیجانی | D20: باغدار | F20: طرف حساب | G20: 0 | I20: انتقال بین انبار | J20: خروج | K20: انتقال | L20: بله | M20: خیر | N20: هیچ | O20: — | Q20: — | R20: هیچ | S20: — | W20: بله | Y20: BK11 – | Z20: BK11 | AB20: 1.5 | AC20: 6 | AD20: 0 | AE20: 0 | AF20: 0 | AH20: لیمو ترش | AI20: لیمو | AO20: P11 | AP20: ریال | AR20: بارفروش | AS20: نقدی | AU20: بانک و صندوق | AX20: BD011 | AZ20: انتقال بین انبار
B21: C012 | C21: افشین بشتکار | D21: باغدار | F21: طرف حساب | G21: 0 | I21: سایر ورود | J21: ورود | K21: سایر | L21: بله | M21: بله | N21: وزن | O21: بستانکار | P21: X011 | Q21: بدهکار | R21: افزودن | S21: — | W21: بله | Y21: BK12 – | Z21: BK12 | AB21: 1.5 | AC21: 6 | AD21: 0 | AE21: 0 | AF21: 0 | AH21: کامکوات | AI21: سایر | AO21: P12 | AP21: خیر | AR21: فروشنده سبد | AS21: سبد پلاستیکی | AX21: BD012 | AZ21: سایر ورود
B22: C013 | C22: میرقربان موسویان | D22: باغدار | F22: طرف حساب | G22: 0 | I22: سایر خروج | J22: خروج | K22: سایر | L22: بله | M22: بله | N22: وزن | O22: بدهکار | P22: X011 | Q22: بستانکار | R22: هیچ | S22: — | W22: بله | AH22: گریپ‌فرویت | AI22: گریپ‌فرویت | AR22: فروشنده سبد | AS22: سبد چوبی | AX22: BD013 | AZ22: سایر خروج
B23: C014 | C23: باباجانی (تراجیکلا) | D23: باغدار | F23: طرف حساب | G23: 0 | I23: هزینه باسکول نقدی (درآمد) | J23: — | K23: درآمد | L23: خیر | M23: خیر | N23: مبلغ | O23: — | Q23: — | R23: پوز | S23: بدهکار | T23: BANK02 | U23: X002 | W23: بله | AH23: خرمالو | AI23: سایر | AR23: فروشنده سبد | AS23: سبد مقوایی | AX23: BD014 | AZ23: هزینه باسکول نقدی (درآمد)
B24: C015 | C24: کاظم میرزازاده | D24: باغدار | F24: طرف حساب | G24: 0 | I24: خرید سبد | J24: ورود | K24: خرید | L24: خیر | M24: بله | N24: مبلغ | O24: بستانکار | P24: X005 | Q24: بدهکار | R24: هیچ | S24: — | W24: خیر | AH24: نارنج | AI24: سایر | AR24: فروشنده سبد | AS24: سایر | AX24: BD015
B25: C016 | C25: علی جانبرارپور | D25: باغدار | F25: طرف حساب | G25: 0 | I25: فروش سبد | J25: خروج | K25: فروش | L25: خیر | M25: بله | N25: مبلغ | O25: بدهکار | P25: X007 | Q25: بستانکار | R25: هیچ | S25: — | W25: خیر | AR25: تأمین‌کننده | AS25: مواد بسته‌بندی | AX25: BD016
B26: C017 | C26: لیلا محمودنیا | D26: باغدار | F26: طرف حساب | G26: 0 | I26: مرجوعی خرید سبد | J26: خروج | K26: خرید | L26: خیر | M26: بله | N26: مبلغ | O26: بدهکار | P26: X005 | Q26: بستانکار | R26: هیچ | S26: — | W26: خیر | AR26: تأمین‌کننده | AS26: واکس و رنگ | AX26: BD017
B27: C018 | C27: اسماعیل خانیا | D27: باغدار | F27: طرف حساب | G27: 0 | I27: مرجوعی فروش سبد | J27: ورود | K27: فروش | L27: خیر | M27: بله | N27: مبلغ | O27: بستانکار | P27: X007 | Q27: بدهکار | R27: هیچ | S27: — | W27: خیر | AR27: تأمین‌کننده | AS27: حمل‌ونقل | AX27: BD018
B28: C019 | C28: یوسف یوسف نژاد | D28: باغدار | F28: طرف حساب | G28: 0 | I28: انتقال سبد بین انبار | J28: خروج | K28: انتقال | L28: خیر | M28: خیر | N28: هیچ | O28: — | Q28: — | R28: هیچ | S28: — | W28: خیر | AR28: تأمین‌کننده | AS28: خدمات | AX28: BD019
B29: C020 | C29: علی نوایی | D29: باغدار | F29: طرف حساب | G29: 0 | AR29: کارمند | AS29: مدیرعامل | AX29: BD020
B30: C021 | C30: دومیری | D30: باغدار | F30: طرف حساب | G30: 0 | AR30: کارمند | AS30: حسابدار
B31: C022 | C31: شمسعلی علیجانی | D31: باغدار | F31: طرف حساب | G31: 0 | AR31: کارمند | AS31: فروشنده
B32: C023 | C32: یوسف نیا (موزیج) | D32: باغدار | F32: طرف حساب | G32: 0 | AR32: کارمند | AS32: انباردار
B33: C024 | C33: کاظم ذبیح پور | D33: باغدار | F33: طرف حساب | G33: 0 | AR33: کارمند | AS33: سرپرست خط
B34: C025 | C34: علی غلام رضاپور | D34: باغدار | F34: طرف حساب | G34: 0 | AR34: کارمند | AS34: کارگر
B35: C026 | C35: حسین شکرالله نیا | D35: باغدار | F35: طرف حساب | G35: 0 | AR35: سایر حساب | AS35: صندوق
B36: C027 | C36: سید مهدی حسینی (دوست حاج هوشنگ) | D36: باغدار | F36: طرف حساب | G36: 0 | AR36: سایر حساب | AS36: موجودی
B37: C028 | C37: آقای عزیزی | D37: باغدار | F37: طرف حساب | G37: 0 | AR37: سایر حساب | AS37: درآمد
B38: C029 | C38: آقای حبیبی (بانک صادرات) | D38: باغدار | F38: طرف حساب | G38: 0 | AR38: سایر حساب | AS38: هزینه
B39: C030 | C39: محمد علی اصغرزاده | D39: باغدار | F39: طرف حساب | G39: 0 | AR39: سایر حساب | AS39: انعام و پاداش
B40: C031 | C40: فغان پور | D40: باغدار | F40: طرف حساب | G40: 0 | AR40: سایر حساب | AS40: چک پرداختی
B41: C032 | C41: عباس پور (بهنمیر) | D41: باغدار | F41: طرف حساب | G41: 0 | AR41: سایر حساب | AS41: حساب واسط
... B51: C042 | C51: مغداد طلایی | D51: باغدار | F51: طرف حساب | G51: 0 | AR51: سرمایه و آورده صاحبان | AS51: برداشت سرمایه
B52: C043 | C52: سید عبدالله میراقازاده | D52: باغدار | F52: طرف حساب | G52: 0
B53: C044 | C53: رجب پور | D53: باغدار | F53: طرف حساب | G53: 0
...

Sheet Help
A1: مازندشت — سورتینگ و بسته‌بندی مرکبات | C1: MAZANDASHT · CITRUS SORTING & PACKING
A2: راهنمای فایل بانک
A3: همه چیز درباره گردش بانکی و چک‌ها
A4: راهنما | B4: ورود دستی | C4: خودکار | D4: ورود | E4: خروج | F4: هشدار
B10: • | C10: این فایل چه می‌کند؟
A11: فایل بانک هیچ داده‌ای وارد نمی‌کند. همه تراکنش‌ها و چک‌ها را از فایل «ثبت روزانه» می‌خواند و آن‌ها را به شکل بانکی مرتب می‌کند: دریافت، پرداخت، انتقال بین بانک‌ها، چک در جریان و چک پاس‌شده.
B13: • | C13: چرا اعداد صفر است؟
A14: چون این فایل به 01_Entry.xlsx لینک است. وقتی فایل را باز کردید و پیام «به‌روزرسانی پیوندها» آمد، گزینه Update را بزنید. اگر پیام نیامد: Data ← Edit Links ← Update Values. همه فایل‌ها باید در یک پوشه باشند.
B16: • | C16: شیت‌ها
A17: تراکنش‌ها: کپی زنده از ثبت. چک‌ها: فقط چک‌ها با وضعیت و سررسید. مغایرت‌گیری: مانده دفتر با مانده صورت‌حساب بانک مقایسه می‌شود. خلاصه: جمع ماهانه.
B19: • | C19: وضعیت چک
A20: «در جریان» یعنی چک صادر یا دریافت شده و هنوز پاس نشده. وقتی در ثبت روزانه ردیف «پاس چک» ثبت کنید، وضعیت همان شماره چک را «پاس شده» بگذارید. برای برگشت، «برگشتی».
B22: • | C22: قاعده انتقال داخلی
A23: انتقال بین دو بانک خودمان در گزارش دریافت/پرداخت شمرده نمی‌شود تا جمع بانک‌ها دو برابر نشود؛ فقط در شیت مغایرت‌گیری هر دو بانک با هم دیده می‌شوند.
A27: برای تغییر داده‌ها همیشه به فایل ثبت روزانه برگردید.
