Workbook
Name AcctCodes: Sync!$B$10:$B$259
Name AcctTbl: Sync!$B$10:$G$259
Name BankCodes: Sync!$AK$10:$AK$19
Name BankTbl: Sync!$AK$10:$AN$19
Name BasketCodeCol: Sync!$Z$10:$Z$21
Name BasketTbl: Sync!$Y$10:$AF$21
Name GroupTbl: Sync!$AR$10:$AS$51
Name ListAllCodes: OFFSET(Sync!$B$10,0,0,MAX(COUNTIF(Sync!$C$10:$C$259,"?*"),1),1)
Name ListBasketOps: OFFSET(Sync!$AW$10,0,0,MAX(COUNTIF(Sync!$AW$10:$AW$14,"?*"),1),1)
Name ListBaskets: OFFSET(Sync!$Y$10,0,0,MAX(COUNTIF(Sync!$Y$10:$Y$21,"?*"),1),1)
Name ListBasketSellerCodes: OFFSET(Sync!$B$72,0,0,MAX(COUNTIF(Sync!$C$72:$C$74,"?*"),1),1)
Name ListBaskolOps: OFFSET(Sync!$AZ$10,0,0,MAX(COUNTIF(Sync!$AZ$10:$AZ$23,"?*"),1),1)
Name ListCategories: OFFSET(Sync!$CB$10,0,0,MAX(COUNTIF(Sync!$CB$10:$CB$29,"?*"),1),1)
Name ListChequeStatus: OFFSET(Sync!$CG$10,0,0,MAX(COUNTIF(Sync!$CG$10:$CG$29,"?*"),1),1)
Name ListColorKeys: OFFSET(Sync!$CP$10,0,0,MAX(COUNTIF(Sync!$CP$10:$CP$29,"?*"),1),1)
Name ListDirections: OFFSET(Sync!$CC$10,0,0,MAX(COUNTIF(Sync!$CC$10:$CC$29,"?*"),1),1)
Name ListGroups: Sync!$AU$10:$AU$19
Name ListGrowerCodes: OFFSET(Sync!$B$10,0,0,MAX(COUNTIF(Sync!$C$10:$C$66,"?*"),1),1)
Name ListInclude: OFFSET(Sync!$CH$10,0,0,MAX(COUNTIF(Sync!$CH$10:$CH$29,"?*"),1),1)
Name ListLoadBuyerCodes: OFFSET(Sync!$B$67,0,0,MAX(COUNTIF(Sync!$C$67:$C$71,"?*"),1),1)
Name ListManualRoles: OFFSET(Sync!$CI$10,0,0,MAX(COUNTIF(Sync!$CI$10:$CI$29,"?*"),1),1)
Name ListOpCategories: OFFSET(Sync!$CL$10,0,0,MAX(COUNTIF(Sync!$CL$10:$CL$29,"?*"),1),1)
Name ListOps: OFFSET(Sync!$I$10,0,0,MAX(COUNTIF(Sync!$I$10:$I$33,"?*"),1),1)
Name ListOtherScaleCodes: Sync!$AX$10:$AX$29
Name ListPartyBasis: OFFSET(Sync!$CO$10,0,0,MAX(COUNTIF(Sync!$CO$10:$CO$29,"?*"),1),1)
Name ListPartyTypes: OFFSET(Sync!$CE$10,0,0,MAX(COUNTIF(Sync!$CE$10:$CE$29,"?*"),1),1)
Name ListPayMethods: OFFSET(Sync!$CF$10,0,0,MAX(COUNTIF(Sync!$CF$10:$CF$29,"?*"),1),1)
Name ListPosEffects: OFFSET(Sync!$CJ$10,0,0,MAX(COUNTIF(Sync!$CJ$10:$CJ$29,"?*"),1),1)
Name ListProducts: OFFSET(Sync!$AH$10,0,0,MAX(COUNTIF(Sync!$AH$10:$AH$29,"?*"),1),1)
Name ListReportSheets: OFFSET(Sync!$CN$10,0,0,MAX(COUNTIF(Sync!$CN$10:$CN$29,"?*"),1),1)
Name ListSeasons: OFFSET(Sync!$CQ$10,0,0,MAX(COUNTIF(Sync!$CQ$10:$CQ$29,"?*"),1),1)
Name ListSides: OFFSET(Sync!$CK$10,0,0,MAX(COUNTIF(Sync!$CK$10:$CK$29,"?*"),1),1)
Name ListStatus: OFFSET(Sync!$CM$10,0,0,MAX(COUNTIF(Sync!$CM$10:$CM$29,"?*"),1),1)
Name ListSubgroups: OFFSET(Sync!$AR$10,0,0,MAX(COUNTIF(Sync!$AS$10:$AS$51,"?*"),1),1)
Name ListTxnDirections: OFFSET(Sync!$CR$10,0,0,MAX(COUNTIF(Sync!$CR$10:$CR$29,"?*"),1),1)
Name ListUnits: OFFSET(Sync!$CA$10,0,0,MAX(COUNTIF(Sync!$CA$10:$CA$29,"?*"),1),1)
Name ListYesNo: OFFSET(Sync!$CD$10,0,0,MAX(COUNTIF(Sync!$CD$10:$CD$29,"?*"),1),1)
Name OpTbl: Sync!$I$10:$W$33
Name ParamTbl: Sync!$AO$10:$AP$21
Name ProductTbl: Sync!$AH$10:$AI$29
Name ListBanks: Sync!$AK$10:$AK$19

Sheet Home
A1: مازندشت — سورتینگ و بسته‌بندی مرکبات | G1: MAZANDASHT · CITRUS SORTING & PACKING
A2: ثبت روزانه — باسکول، سبد و پرداخت
A3: تنها فایل ورود داده · همه گزارش‌ها و ترازنامه‌ها از همین‌جا می‌خوانند · نسخه ۰۱
A5: توزین‌های ثبت‌شده | C5: جمع خالص ورود (kg) | E5: جمع خالص خروج (kg) | G5: جمع مبالغ (ریال) | I5: وضعیت تراز
A6: =COUNTA(Scale!$B$10:$B$309) | C6: =SUMIF(Scale!$F$10:$F$309,"ورود",Scale!$N$10:$N$309) | E6: =SUMIF(Scale!$F$10:$F$309,"خروج",Scale!$N$10:$N$309) | G6: =SUM(Book!$K$10:$K$1808) | I6: =IF(ROUND(SUM(Book!$L$10:$L$1808)-SUM(Book!$M$10:$M$1808),0)=0,"✓ تراز","⚠ ناتراز")
A8: ۰۱ | B8: شیت‌های این فایل — روی هر کارت کلیک کنید
A9: باسکول | D9: سبد | G9: پرداخت
A10: ثبت ورود/خروج بار، خرید باغدار، فروش بارفروش، آبگیری، انعام و باسکول دیگران | D10: خرید، فروش و مرجوعی سبد به‌همراه موجودی خودکار | G10: پرداخت و دریافت نقدی/بانکی/چک، پاس چک و انتقال داخلی
A12: دفتر معین | D12: خلاصه | G12: راهنما
A13: همه گردش‌های طرف حساب‌ها یک‌جا — منبع گزارش‌ها | D13: تراز دفتر، گردش گروه‌ها، موجودی سبد و آمار ماهانه | G13: آموزش کامل این فایل و قواعد بدهکار/بستانکار
A18: ۰۲ | B18: شروع سریع — پنج گام — هر روز همین ترتیب را برو
A19: ۱ | B19: اول INFO را باز کنید و اگر حساب/عملیات جدیدی دارید اضافه کنید؛ بعد Update Links.
A20: ۲ | B20: در شیت باسکول، نوع عملیات را انتخاب کنید؛ جهت، نام و گروه خودکار می‌آید.
A21: ۳ | B21: وزن باسکول، تعداد سبد و فی را وارد کنید؛ وزن خالص و مبلغ خودکار محاسبه می‌شود.
A22: ۴ | B22: پول‌ها را در شیت پرداخت ثبت کنید (نقد، بانک، چک، پاس چک).
A23: ۵ | B23: شیت خلاصه را ببینید؛ اگر تراز سبز بود، گزارش/فاکتور/ترازنامه را باز کنید.
A25: ۰۳ | B25: رنگ‌ها و معنی آن‌ها
A26: خرید مرکبات | C26: فروش بار | E26: آبگیری | G26: انعام مصطفی
A27: باسکول دیگران | C27: مرجوعی/ضایعات | E27: درآمد پوز | G27: ⚠ ناتراز
A30: این فایل هیچ تعریفی از خودش ندارد: کد حساب‌ها، عملیات، وزن سبد و پارامترها همه از INFO می‌آیند. اگر فایلی را جابه‌جا کردید، هر دو فایل را با هم جابه‌جا کنید و در Excel: Data ← Edit Links ← Update Values.
A31: باز کردن فایل مادر INFO
A33: ۰۴ | B33: فایل‌های دیگر مجموعه — همه در همین پوشه · داده‌ها از همین فایل خوانده می‌شود
A34: بانک · 02_Bank.xlsx | D34: گزارش · 03_Report.xlsx | G34: فاکتور · 04_Inv.xlsx
A35: تراکنش بانکی، چک، مغایرت‌گیری | D35: صورت‌حساب باغدار و بارفروش | G35: تیک زدن سطرها و چاپ فاکتور
A36: ترازنامه · 05_Bal.xlsx | D36: بارفروشان · 06_Buyers.xlsx | G36: نمونه · 07_Demo.xlsx
A37: تراز ۴ و ۶ ستونی و کنترل | D37: ریز بار، ماهانه و مانده | G37: نمونه ساده برای یادگیری
A39: شیت POS · کنترل روزانه پز باسکول در برابر واریزی روز بعد به حساب ۲۰۰۶ صادرات؛ اگر تراز نباشد، هشدار ⚠ می‌دهد.
A40: قاعده جدید: هر مبلغی که برای خروج بار ثبت شود درآمد باسکول است و به ۲۰۰۶ می‌رود؛ برای فروش متفرقه، ستون «کد حساب / مقصد وجه» همان حسابی است که پول به آن واریز شده.

Sheet Scale
A1: مازندشت — سورتینگ و بسته‌بندی مرکبات | P1: MAZANDASHT · CITRUS SORTING & PACKING
A2: دفتر باسکول — ثبت ورود و خروج بار
A3: هر ردیف یک توزین · ابتدا نوع عملیات، بعد کد حساب، وزن، تعداد سبد و فی · ستون‌های خاکستری خودکارند
A4: راهنما | B4: ورود دستی | C4: خودکار | D4: ورود | E4: خروج | F4: هشدار | G4: ستون‌های زرد = ورود شما | ستون‌های خاکستری = محاسبه خودکار | روی سرستون‌ها بایستید تا راهنما باز شود
A5: تعداد توزین | E5: جمع خالص ورود (kg) | I5: جمع خالص خروج (kg) | M5: جمع مبالغ (ریال) | Q5: ردیف‌های ناتراز
A6: =COUNTA($B$10:$B$309) | E6: =SUMIF($F$10:$F$309,"ورود",$N$10:$N$309) | I6: =SUMIF($F$10:$F$309,"خروج",$N$10:$N$309) | M6: =SUM($P$10:$P$309) | Q6: =COUNTIF($AI$10:$AI$309,"⚠")
A7: ردیف | B7: تاریخ و سند | E7: عملیات | G7: طرف حساب | J7: بار و وزن | P7: مبلغ | R7: سمت / وضعیت / توضیح
A8: ردیف | B8: تاریخ | C8: ساعت | D8: شماره سند | E8: نوع عملیات | F8: جهت | G8: کد حساب / مقصد وجه | H8: نام حساب | I8: گروه | J8: محصول | K8: سبد | L8: وزن باسکول | M8: تعداد سبد | N8: وزن خالص | O8: فی خرید | P8: مبلغ محاسبه | Q8: مبلغ پوز/باسکول (درآمد) | R8: سمت حساب | S8: وضعیت | T8: توضیحات
A9: No. | B9: Date | C9: Time | D9: Doc | E9: Operation | F9: Direction | G9: Account / Money-to | H9: Account Name | I9: Group | J9: Product | K9: Basket | L9: Scale kg | M9: Baskets | N9: Net kg | O9: Price | P9: Amount | Q9: POS / Fee amount | R9: Side | S9: Status | T9: Notes
A10: =IF($B10="","",COUNTA($B$10:$B10)) | B10: 1405/07/01 | C10: 07:45 | D10: BS-001 | E10: خرید مرکبات | F10: =IF($E10="","",IFERROR(VLOOKUP($E10,OpTbl,2,0),"")) | G10: C001 | H10: =IF($U10="","",IFERROR(VLOOKUP($U10,AcctTbl,2,0),"کد ناشناخته")) | I10: =IF($U10="","",IFERROR(VLOOKUP($U10,AcctTbl,3,0),"")) | J10: نارنگی پیچ | K10: BK03 – ۹ک مشکی | L10: 2290 | M10: 139 | N10: =IF(OR($E10="",$L10=""),"",IFERROR(($L10-IF($M10="",0,$M10)*IFERROR(VLOOKUP($K10,BasketTbl,4,0),IFERROR(INDEX(BasketTbl,MATCH($K10,BasketCodeCol,0),4),VLOOKUP("P01",ParamTbl,2,0))))*(1-IF(VLOOKUP($E10,OpTbl,3,0)="خرید",VLOOKUP("P02",ParamTbl,2,0),0)/100),"")) | O10: 32000 | P10: =IF(OR($E10="",$L10=""),"",IFERROR(IF(VLOOKUP($E10,OpTbl,6,0)="وزن",ROUND($N10*$O10,-3),IF(VLOOKUP($E10,OpTbl,6,0)="مبلغ",ROUND($L10*$O10,-3),0)),"")) | Q10: 0 | S10: =IF($E10="","",IF($AI10="⚠","⚠ ناتراز",IF(AND(IFERROR(VLOOKUP($E10,OpTbl,4,0),"")="بله",$L10=""),"⚠ وزن",IF(AND(IFERROR(VLOOKUP($E10,OpTbl,5,0),"")="بله",$U10=""),"⚠ حساب",IF(AND(IFERROR(VLOOKUP($E10,OpTbl,6,0),"")="مبلغ",$Q10=""),"⚠ مبلغ","✓"))))) | U10: =IF($E10="","",IFERROR(IF(VLOOKUP($E10,OpTbl,14,0)<>"",VLOOKUP($E10,OpTbl,14,0),$G10),"")) | V10: =IF(OR($AJ10="",$AJ10=0,$AL10<>"بدهکار"),"",$AJ10) | W10: =IF(OR($AJ10="",$AJ10=0,$AL10<>"بستانکار"),"",$AJ10) | X10: =IF($E10="","",IFERROR(VLOOKUP($E10,OpTbl,8,0),"")) | Y10: =IF(OR($X10="",$AJ10="",$AJ10=0,$AM10<>"بدهکار"),"",$AJ10) | Z10: =IF(OR($X10="",$AJ10="",$AJ10=0,$AM10<>"بستانکار"),"",$AJ10) | AA10: =IF(OR($E10="",$AN10="—",$AN10=""),"",IFERROR(VLOOKUP($E10,OpTbl,12,0),"")) | AB10: =IF(OR($AA10="",$Q10="",$Q10=0,$AN10<>"بدهکار"),"",$Q10) | AC10: =IF(OR($AA10="",$Q10="",$Q10=0,$AN10<>"بستانکار"),"",$Q10) | AD10: =IF($AA10="","",IFERROR(VLOOKUP($E10,OpTbl,13,0),"")) | AE10: =IF(OR($AD10="",$Q10="",$Q10=0,$AN10<>"بستانکار"),"",$Q10) | AF10: =IF(OR($AD10="",$Q10="",$Q10=0,$AN10<>"بدهکار"),"",$Q10) | AG10: =SUM($V10,$Y10,$AB10,$AE10) | AH10: =SUM($W10,$Z10,$AC10,$AF10) | AI10: =IF($E10="","",IF(ROUND($AG10-$AH10,0)=0,"✓","⚠")) | AJ10: =IF(OR($E10="",$U10=""),"",IFERROR(IF(VLOOKUP($E10,OpTbl,6,0)="وزن",IF($P10="",0,$P10),IF(VLOOKUP($E10,OpTbl,6,0)="مبلغ",IF(AND($Q10<>"",$Q10<>0),$Q10,$P10),0))+IF(VLOOKUP($E10,OpTbl,10,0)="افزودن",IF($Q10="",0,$Q10),0),0)) | AK10: =IF($E10="","",IFERROR(VLOOKUP($E10,OpTbl,10,0),"")) | AL10: =IF(OR($E10="",$U10=""),"",IFERROR(IF(VLOOKUP($E10,OpTbl,7,0)="خودکار",$R10,VLOOKUP($E10,OpTbl,7,0)),"")) | AM10: =IF(OR($E10="",$X10=""),"",IFERROR(IF(VLOOKUP($E10,OpTbl,9,0)="خودکار",IF($AL10="بدهکار","بستانکار",IF($AL10="بستانکار","بدهکار","")),VLOOKUP($E10,OpTbl,9,0)),"")) | AN10: =IF($E10="","",IFERROR(VLOOKUP($E10,OpTbl,11,0),"")) | AO10: =IF($B10="","",MID($B10,6,2)) | AP10: =IF($B10="",0,1)
A11: =IF($B11="","",COUNTA($B$10:$B11)) | B11: 1405/07/01 | C11: 09:10 | D11: BS-002 | E11: خرید مرکبات | F11: =IF($E11="","",IFERROR(VLOOKUP($E11,OpTbl,2,0),"")) | G11: C003 | H11: =IF($U11="","",IFERROR(VLOOKUP($U11,AcctTbl,2,0),"کد ناشناخته")) | I11: =IF($U11="","",IFERROR(VLOOKUP($U11,AcctTbl,3,0),"")) | J11: پرتقال تامسون | K11: BK01 – ۶ک مشکی | L11: 910 | M11: 53 | N11: =IF(OR($E11="",$L11=""),"",IFERROR(($L11-IF($M11="",0,$M11)*IFERROR(VLOOKUP($K11,BasketTbl,4,0),IFERROR(INDEX(BasketTbl,MATCH($K11,BasketCodeCol,0),4),VLOOKUP("P01",ParamTbl,2,0))))*(1-IF(VLOOKUP($E11,OpTbl,3,0)="خرید",VLOOKUP("P02",ParamTbl,2,0),0)/100),"")) | O11: 35000 | P11: =IF(OR($E11="",$L11=""),"",IFERROR(IF(VLOOKUP($E11,OpTbl,6,0)="وزن",ROUND($N11*$O11,-3),IF(VLOOKUP($E11,OpTbl,6,0)="مبلغ",ROUND($L11*$O11,-3),0)),"")) | Q11: 0 | S11: =IF($E11="","",IF($AI11="⚠","⚠ ناتراز",IF(AND(IFERROR(VLOOKUP($E11,OpTbl,4,0),"")="بله",$L11=""),"⚠ وزن",IF(AND(IFERROR(VLOOKUP($E11,OpTbl,5,0),"")="بله",$U11=""),"⚠ حساب",IF(AND(IFERROR(VLOOKUP($E11,OpTbl,6,0),"")="مبلغ",$Q11=""),"⚠ مبلغ","✓"))))) | U11: =IF($E11="","",IFERROR(IF(VLOOKUP($E11,OpTbl,14,0)<>"",VLOOKUP($E11,OpTbl,14,0),$G11),"")) | V11: =IF(OR($AJ11="",$AJ11=0,$AL11<>"بدهکار"),"",$AJ11) | W11: =IF(OR($AJ11="",$AJ11=0,$AL11<>"بستانکار"),"",$AJ11) | X11: =IF($E11="","",IFERROR(VLOOKUP($E11,OpTbl,8,0),"")) | Y11: =IF(OR($X11="",$AJ11="",$AJ11=0,$AM11<>"بدهکار"),"",$AJ11) | Z11: =IF(OR($X11="",$AJ11="",$AJ11=0,$AM11<>"بستانکار"),"",$AJ11) | AA11: =IF(OR($E11="",$AN11="—",$AN11=""),"",IFERROR(VLOOKUP($E11,OpTbl,12,0),"")) | AB11: =IF(OR($AA11="",$Q11="",$Q11=0,$AN11<>"بدهکار"),"",$Q11) | AC11: =IF(OR($AA11="",$Q11="",$Q11=0,$AN11<>"بستانکار"),"",$Q11) | AD11: =IF($AA11="","",IFERROR(VLOOKUP($E11,OpTbl,13,0),"")) | AE11: =IF(OR($AD11="",$Q11="",$Q11=0,$AN11<>"بستانکار"),"",$Q11) | AF11: =IF(OR($AD11="",$Q11="",$Q11=0,$AN11<>"بدهکار"),"",$Q11) | AG11: =SUM($V11,$Y11,$AB11,$AE11) | AH11: =SUM($W11,$Z11,$AC11,$AF11) | AI11: =IF($E11="","",IF(ROUND($AG11-$AH11,0)=0,"✓","⚠")) | AJ11: =IF(OR($E11="",$U11=""),"",IFERROR(IF(VLOOKUP($E11,OpTbl,6,0)="وزن",IF($P11="",0,$P11),IF(VLOOKUP($E11,OpTbl,6,0)="مبلغ",IF(AND($Q11<>"",$Q11<>0),$Q11,$P11),0))+IF(VLOOKUP($E11,OpTbl,10,0)="افزودن",IF($Q11="",0,$Q11),0),0)) | AK11: =IF($E11="","",IFERROR(VLOOKUP($E11,OpTbl,10,0),"")) | AL11: =IF(OR($E11="",$U11=""),"",IFERROR(IF(VLOOKUP($E11,OpTbl,7,0)="خودکار",$R11,VLOOKUP($E11,OpTbl,7,0)),"")) | AM11: =IF(OR($E11="",$X11=""),"",IFERROR(IF(VLOOKUP($E11,OpTbl,9,0)="خودکار",IF($AL11="بدهکار","بستانکار",IF($AL11="بستانکار","بدهکار","")),VLOOKUP($E11,OpTbl,9,0)),"")) | AN11: =IF($E11="","",IFERROR(VLOOKUP($E11,OpTbl,11,0),"")) | AO11: =IF($B11="","",MID($B11,6,2)) | AP11: =IF($B11="",0,1)
A12: =IF($B12="","",COUNTA($B$10:$B12)) | B12: 1405/07/02 | C12: 08:20 | D12: BS-003 | E12: خرید مرکبات | F12: =IF($E12="","",IFERROR(VLOOKUP($E12,OpTbl,2,0),"")) | G12: C006 | H12: =IF($U12="","",IFERROR(VLOOKUP($U12,AcctTbl,2,0),"کد ناشناخته")) | I12: =IF($U12="","",IFERROR(VLOOKUP($U12,AcctTbl,3,0),"")) | J12: نارنگی اونشو | K12: BK01 – ۶ک مشکی | L12: 1385 | M12: 85 | N12: =IF(OR($E12="",$L12=""),"",IFERROR(($L12-IF($M12="",0,$M12)*IFERROR(VLOOKUP($K12,BasketTbl,4,0),IFERROR(INDEX(BasketTbl,MATCH($K12,BasketCodeCol,0),4),VLOOKUP("P01",ParamTbl,2,0))))*(1-IF(VLOOKUP($E12,OpTbl,3,0)="خرید",VLOOKUP("P02",ParamTbl,2,0),0)/100),"")) | O12: 30000 | P12: =IF(OR($E12="",$L12=""),"",IFERROR(IF(VLOOKUP($E12,OpTbl,6,0)="وزن",ROUND($N12*$O12,-3),IF(VLOOKUP($E12,OpTbl,6,0)="مبلغ",ROUND($L12*$O12,-3),0)),"")) | Q12: 500000 | S12: =IF($E12="","",IF($AI12="⚠","⚠ ناتراز",IF(AND(IFERROR(VLOOKUP($E12,OpTbl,4,0),"")="بله",$L12=""),"⚠ وزن",IF(AND(IFERROR(VLOOKUP($E12,OpTbl,5,0),"")="بله",$U12=""),"⚠ حساب",IF(AND(IFERROR(VLOOKUP($E12,OpTbl,6,0),"")="مبلغ",$Q12=""),"⚠ مبلغ","✓"))))) | T12: کرایه حمل ۵۰۰٬۰۰۰ | U12: =IF($E12="","",IFERROR(IF(VLOOKUP($E12,OpTbl,14,0)<>"",VLOOKUP($E12,OpTbl,14,0),$G12),"")) | V12: =IF(OR($AJ12="",$AJ12=0,$AL12<>"بدهکار"),"",$AJ12) | W12: =IF(OR($AJ12="",$AJ12=0,$AL12<>"بستانکار"),"",$AJ12) | X12: =IF($E12="","",IFERROR(VLOOKUP($E12,OpTbl,8,0),"")) | Y12: =IF(OR($X12="",$AJ12="",$AJ12=0,$AM12<>"بدهکار"),"",$AJ12) | Z12: =IF(OR($X12="",$AJ12="",$AJ12=0,$AM12<>"بستانکار"),"",$AJ12) | AA12: =IF(OR($E12="",$AN12="—",$AN12=""),"",IFERROR(VLOOKUP($E12,OpTbl,12,0),"")) | AB12: =IF(OR($AA12="",$Q12="",$Q12=0,$AN12<>"بدهکار"),"",$Q12) | AC12: =IF(OR($AA12="",$Q12="",$Q12=0,$AN12<>"بستانکار"),"",$Q12) | AD12: =IF($AA12="","",IFERROR(VLOOKUP($E12,OpTbl,13,0),"")) | AE12: =IF(OR($AD12="",$Q12="",$Q12=0,$AN12<>"بستانکار"),"",$Q12) | AF12: =IF(OR($AD12="",$Q12="",$Q12=0,$AN12<>"بدهکار"),"",$Q12) | AG12: =SUM($V12,$Y12,$AB12,$AE12) | AH12: =SUM($W12,$Z12,$AC12,$AF12) | AI12: =IF($E12="","",IF(ROUND($AG12-$AH12,0)=0,"✓","⚠")) | AJ12: =IF(OR($E12="",$U12=""),"",IFERROR(IF(VLOOKUP($E12,OpTbl,6,0)="وزن",IF($P12="",0,$P12),IF(VLOOKUP($E12,OpTbl,6,0)="مبلغ",IF(AND($Q12<>"",$Q12<>0),$Q12,$P12),0))+IF(VLOOKUP($E12,OpTbl,10,0)="افزودن",IF($Q12="",0,$Q12),0),0)) | AK12: =IF($E12="","",IFERROR(VLOOKUP($E12,OpTbl,10,0),"")) | AL12: =IF(OR($E12="",$U12=""),"",IFERROR(IF(VLOOKUP($E12,OpTbl,7,0)="خودکار",$R12,VLOOKUP($E12,OpTbl,7,0)),"")) | AM12: =IF(OR($E12="",$X12=""),"",IFERROR(IF(VLOOKUP($E12,OpTbl,9,0)="خودکار",IF($AL12="بدهکار","بستانکار",IF($AL12="بستانکار","بدهکار","")),VLOOKUP($E12,OpTbl,9,0)),"")) | AN12: =IF($E12="","",IFERROR(VLOOKUP($E12,OpTbl,11,0),"")) | AO12: =IF($B12="","",MID($B12,6,2)) | AP12: =IF($B12="",0,1)
A13: =IF($B13="","",COUNTA($B$10:$B13)) | B13: 1405/07/02 | C13: 11:30 | D13: BS-004 | E13: خرید مرکبات | F13: =IF($E13="","",IFERROR(VLOOKUP($E13,OpTbl,2,0),"")) | G13: C002 | H13: =IF($U13="","",IFERROR(VLOOKUP($U13,AcctTbl,2,0),"کد ناشناخته")) | I13: =IF($U13="","",IFERROR(VLOOKUP($U13,AcctTbl,3,0),"")) | J13: پرتقال خونی | K13: BK03 – ۹ک مشکی | L13: 605 | M13: 36 | N13: =IF(OR($E13="",$L13=""),"",IFERROR(($L13-IF($M13="",0,$M13)*IFERROR(VLOOKUP($K13,BasketTbl,4,0),IFERROR(INDEX(BasketTbl,MATCH($K13,BasketCodeCol,0),4),VLOOKUP("P01",ParamTbl,2,0))))*(1-IF(VLOOKUP($E13,OpTbl,3,0)="خرید",VLOOKUP("P02",ParamTbl,2,0),0)/100),"")) | O13: 38000 | P13: =IF(OR($E13="",$L13=""),"",IFERROR(IF(VLOOKUP($E13,OpTbl,6,0)="وزن",ROUND($N13*$O13,-3),IF(VLOOKUP($E13,OpTbl,6,0)="مبلغ",ROUND($L13*$O13,-3),0)),"")) | Q13: 0 | S13: =IF($E13="","",IF($AI13="⚠","⚠ ناتراز",IF(AND(IFERROR(VLOOKUP($E13,OpTbl,4,0),"")="بله",$L13=""),"⚠ وزن",IF(AND(IFERROR(VLOOKUP($E13,OpTbl,5,0),"")="بله",$U13=""),"⚠ حساب",IF(AND(IFERROR(VLOOKUP($E13,OpTbl,6,0),"")="مبلغ",$Q13=""),"⚠ مبلغ","✓"))))) | U13: =IF($E13="","",IFERROR(IF(VLOOKUP($E13,OpTbl,14,0)<>"",VLOOKUP($E13,OpTbl,14,0),$G13),"")) | V13: =IF(OR($AJ13="",$AJ13=0,$AL13<>"بدهکار"),"",$AJ13) | W13: =IF(OR($AJ13="",$AJ13=0,$AL13<>"بستانکار"),"",$AJ13) | X13: =IF($E13="","",IFERROR(VLOOKUP($E13,OpTbl,8,0),"")) | Y13: =IF(OR($X13="",$AJ13="",$AJ13=0,$AM13<>"بدهکار"),"",$AJ13) | Z13: =IF(OR($X13="",$AJ13="",$AJ13=0,$AM13<>"بستانکار"),"",$AJ13) | AA13: =IF(OR($E13="",$AN13="—",$AN13=""),"",IFERROR(VLOOKUP($E13,OpTbl,12,0),"")) | AB13: =IF(OR($AA13="",$Q13="",$Q13=0,$AN13<>"بدهکار"),"",$Q13) | AC13: =IF(OR($AA13="",$Q13="",$Q13=0,$AN13<>"بستانکار"),"",$Q13) | AD13: =IF($AA13="","",IFERROR(VLOOKUP($E13,OpTbl,13,0),"")) | AE13: =IF(OR($AD13="",$Q13="",$Q13=0,$AN13<>"بستانکار"),"",$Q13) | AF13: =IF(OR($AD13="",$Q13="",$Q13=0,$AN13<>"بدهکار"),"",$Q13) | AG13: =SUM($V13,$Y13,$AB13,$AE13) | AH13: =SUM($W13,$Z13,$AC13,$AF13) | AI13: =IF($E13="","",IF(ROUND($AG13-$AH13,0)=0,"✓","⚠")) | AJ13: =IF(OR($E13="",$U13=""),"",IFERROR(IF(VLOOKUP($E13,OpTbl,6,0)="وزن",IF($P13="",0,$P13),IF(VLOOKUP($E13,OpTbl,6,0)="مبلغ",IF(AND($Q13<>"",$Q13<>0),$Q13,$P13),0))+IF(VLOOKUP($E13,OpTbl,10,0)="افزودن",IF($Q13="",0,$Q13),0),0)) | AK13: =IF($E13="","",IFERROR(VLOOKUP($E13,OpTbl,10,0),"")) | AL13: =IF(OR($E13="",$U13=""),"",IFERROR(IF(VLOOKUP($E13,OpTbl,7,0)="خودکار",$R13,VLOOKUP($E13,OpTbl,7,0)),"")) | AM13: =IF(OR($E13="",$X13=""),"",IFERROR(IF(VLOOKUP($E13,OpTbl,9,0)="خودکار",IF($AL13="بدهکار","بستانکار",IF($AL13="بستانکار","بدهکار","")),VLOOKUP($E13,OpTbl,9,0)),"")) | AN13: =IF($E13="","",IFERROR(VLOOKUP($E13,OpTbl,11,0),"")) | AO13: =IF($B13="","",MID($B13,6,2)) | AP13: =IF($B13="",0,1)
A14: =IF($B14="","",COUNTA($B$10:$B14)) | B14: 1405/07/03 | C14: 07:50 | D14: BS-005 | E14: خرید مرکبات | F14: =IF($E14="","",IFERROR(VLOOKUP($E14,OpTbl,2,0),"")) | G14: C008 | H14: =IF($U14="","",IFERROR(VLOOKUP($U14,AcctTbl,2,0),"کد ناشناخته")) | I14: =IF($U14="","",IFERROR(VLOOKUP($U14,AcctTbl,3,0),"")) | J14: نارنگی ژاپنی | K14: BK07 – ۸ک مشکی | L14: 1762 | M14: 108 | N14: =IF(OR($E14="",$L14=""),"",IFERROR(($L14-IF($M14="",0,$M14)*IFERROR(VLOOKUP($K14,BasketTbl,4,0),IFERROR(INDEX(BasketTbl,MATCH($K14,BasketCodeCol,0),4),VLOOKUP("P01",ParamTbl,2,0))))*(1-IF(VLOOKUP($E14,OpTbl,3,0)="خرید",VLOOKUP("P02",ParamTbl,2,0),0)/100),"")) | O14: 31000 | P14: =IF(OR($E14="",$L14=""),"",IFERROR(IF(VLOOKUP($E14,OpTbl,6,0)="وزن",ROUND($N14*$O14,-3),IF(VLOOKUP($E14,OpTbl,6,0)="مبلغ",ROUND($L14*$O14,-3),0)),"")) | Q14: 0 | S14: =IF($E14="","",IF($AI14="⚠","⚠ ناتراز",IF(AND(IFERROR(VLOOKUP($E14,OpTbl,4,0),"")="بله",$L14=""),"⚠ وزن",IF(AND(IFERROR(VLOOKUP($E14,OpTbl,5,0),"")="بله",$U14=""),"⚠ حساب",IF(AND(IFERROR(VLOOKUP($E14,OpTbl,6,0),"")="مبلغ",$Q14=""),"⚠ مبلغ","✓"))))) | U14: =IF($E14="","",IFERROR(IF(VLOOKUP($E14,OpTbl,14,0)<>"",VLOOKUP($E14,OpTbl,14,0),$G14),"")) | V14: =IF(OR($AJ14="",$AJ14=0,$AL14<>"بدهکار"),"",$AJ14) | W14: =IF(OR($AJ14="",$AJ14=0,$AL14<>"بستانکار"),"",$AJ14) | X14: =IF($E14="","",IFERROR(VLOOKUP($E14,OpTbl,8,0),"")) | Y14: =IF(OR($X14="",$AJ14="",$AJ14=0,$AM14<>"بدهکار"),"",$AJ14) | Z14: =IF(OR($X14="",$AJ14="",$AJ14=0,$AM14<>"بستانکار"),"",$AJ14) | AA14: =IF(OR($E14="",$AN14="—",$AN14=""),"",IFERROR(VLOOKUP($E14,OpTbl,12,0),"")) | AB14: =IF(OR($AA14="",$Q14="",$Q14=0,$AN14<>"بدهکار"),"",$Q14) | AC14: =IF(OR($AA14="",$Q14="",$Q14=0,$AN14<>"بستانکار"),"",$Q14) | AD14: =IF($AA14="","",IFERROR(VLOOKUP($E14,OpTbl,13,0),"")) | AE14: =IF(OR($AD14="",$Q14="",$Q14=0,$AN14<>"بستانکار"),"",$Q14) | AF14: =IF(OR($AD14="",$Q14="",$Q14=0,$AN14<>"بدهکار"),"",$Q14) | AG14: =SUM($V14,$Y14,$AB14,$AE14) | AH14: =SUM($W14,$Z14,$AC14,$AF14) | AI14: =IF($E14="","",IF(ROUND($AG14-$AH14,0)=0,"✓","⚠")) | AJ14: =IF(OR($E14="",$U14=""),"",IFERROR(IF(VLOOKUP($E14,OpTbl,6,0)="وزن",IF($P14="",0,$P14),IF(VLOOKUP($E14,OpTbl,6,0)="مبلغ",IF(AND($Q14<>"",$Q14<>0),$Q14,$P14),0))+IF(VLOOKUP($E14,OpTbl,10,0)="افزودن",IF($Q14="",0,$Q14),0),0)) | AK14: =IF($E14="","",IFERROR(VLOOKUP($E14,OpTbl,10,0),"")) | AL14: =IF(OR($E14="",$U14=""),"",IFERROR(IF(VLOOKUP($E14,OpTbl,7,0)="خودکار",$R14,VLOOKUP($E14,OpTbl,7,0)),"")) | AM14: =IF(OR($E14="",$X14=""),"",IFERROR(IF(VLOOKUP($E14,OpTbl,9,0)="خودکار",IF($AL14="بدهکار","بستانکار",IF($AL14="بستانکار","بدهکار","")),VLOOKUP($E14,OpTbl,9,0)),"")) | AN14: =IF($E14="","",IFERROR(VLOOKUP($E14,OpTbl,11,0),"")) | AO14: =IF($B14="","",MID($B14,6,2)) | AP14: =IF($B14="",0,1)
A15: =IF($B15="","",COUNTA($B$10:$B15)) | B15: 1405/07/03 | C15: 10:15 | D15: BS-006 | E15: فروش بار (بارفروش) | F15: =IF($E15="","",IFERROR(VLOOKUP($E15,OpTbl,2,0),"")) | G15: SL001 | H15: =IF($U15="","",IFERROR(VLOOKUP($U15,AcctTbl,2,0),"کد ناشناخته")) | I15: =IF($U15="","",IFERROR(VLOOKUP($U15,AcctTbl,3,0),"")) | J15: پرتقال تامسون | K15: BK03 – ۹ک مشکی | L15: 2500 | M15: 0 | N15: =IF(OR($E15="",$L15=""),"",IFERROR(($L15-IF($M15="",0,$M15)*IFERROR(VLOOKUP($K15,BasketTbl,4,0),IFERROR(INDEX(BasketTbl,MATCH($K15,BasketCodeCol,0),4),VLOOKUP("P01",ParamTbl,2,0))))*(1-IF(VLOOKUP($E15,OpTbl,3,0)="خرید",VLOOKUP("P02",ParamTbl,2,0),0)/100),"")) | O15: 58000 | P15: =IF(OR($E15="",$L15=""),"",IFERROR(IF(VLOOKUP($E15,OpTbl,6,0)="وزن",ROUND($N15*$O15,-3),IF(VLOOKUP($E15,OpTbl,6,0)="مبلغ",ROUND($L15*$O15,-3),0)),"")) | Q15: 120000 | S15: =IF($E15="","",IF($AI15="⚠","⚠ ناتراز",IF(AND(IFERROR(VLOOKUP($E15,OpTbl,4,0),"")="بله",$L15=""),"⚠ وزن",IF(AND(IFERROR(VLOOKUP($E15,OpTbl,5,0),"")="بله",$U15=""),"⚠ حساب",IF(AND(IFERROR(VLOOKUP($E15,OpTbl,6,0),"")="مبلغ",$Q15=""),"⚠ مبلغ","✓"))))) | T15: هزینه باسکول پوز | U15: =IF($E15="","",IFERROR(IF(VLOOKUP($E15,OpTbl,14,0)<>"",VLOOKUP($E15,OpTbl,14,0),$G15),"")) | V15: =IF(OR($AJ15="",$AJ15=0,$AL15<>"بدهکار"),"",$AJ15) | W15: =IF(OR($AJ15="",$AJ15=0,$AL15<>"بستانکار"),"",$AJ15) | X15: =IF($E15="","",IFERROR(VLOOKUP($E15,OpTbl,8,0),"")) | Y15: =IF(OR($X15="",$AJ15="",$AJ15=0,$AM15<>"بدهکار"),"",$AJ15) | Z15: =IF(OR($X15="",$AJ15="",$AJ15=0,$AM15<>"بستانکار"),"",$AJ15) | AA15: =IF(OR($E15="",$AN15="—",$AN15=""),"",IFERROR(VLOOKUP($E15,OpTbl,12,0),"")) | AB15: =IF(OR($AA15="",$Q15="",$Q15=0,$AN15<>"بدهکار"),"",$Q15) | AC15: =IF(OR($AA15="",$Q15="",$Q15=0,$AN15<>"بستانکار"),"",$Q15) | AD15: =IF($AA15="","",IFERROR(VLOOKUP($E15,OpTbl,13,0),"")) | AE15: =IF(OR($AD15="",$Q15="",$Q15=0,$AN15<>"بستانکار"),"",$Q15) | AF15: =IF(OR($AD15="",$Q15="",$Q15=0,$AN15<>"بدهکار"),"",$Q15) | AG15: =SUM($V15,$Y15,$AB15,$AE15) | AH15: =SUM($W15,$Z15,$AC15,$AF15) | AI15: =IF($E15="","",IF(ROUND($AG15-$AH15,0)=0,"✓","⚠")) | AJ15: =IF(OR($E15="",$U15=""),"",IFERROR(IF(VLOOKUP($E15,OpTbl,6,0)="وزن",IF($P15="",0,$P15),IF(VLOOKUP($E15,OpTbl,6,0)="مبلغ",IF(AND($Q15<>"",$Q15<>0),$Q15,$P15),0))+IF(VLOOKUP($E15,OpTbl,10,0)="افزودن",IF($Q15="",0,$Q15),0),0)) | AK15: =IF($E15="","",IFERROR(VLOOKUP($E15,OpTbl,10,0),"")) | AL15: =IF(OR($E15="",$U15=""),"",IFERROR(IF(VLOOKUP($E15,OpTbl,7,0)="خودکار",$R15,VLOOKUP($E15,OpTbl,7,0)),"")) | AM15: =IF(OR($E15="",$X15=""),"",IFERROR(IF(VLOOKUP($E15,OpTbl,9,0)="خودکار",IF($AL15="بدهکار","بستانکار",IF($AL15="بستانکار","بدهکار","")),VLOOKUP($E15,OpTbl,9,0)),"")) | AN15: =IF($E15="","",IFERROR(VLOOKUP($E15,OpTbl,11,0),"")) | AO15: =IF($B15="","",MID($B15,6,2)) | AP15: =IF($B15="",0,1)
A16: =IF($B16="","",COUNTA($B$10:$B16)) | B16: 1405/07/04 | C16: 09:00 | D16: BS-007 | E16: خرید مرکبات | F16: =IF($E16="","",IFERROR(VLOOKUP($E16,OpTbl,2,0),"")) | G16: C004 | H16: =IF($U16="","",IFERROR(VLOOKUP($U16,AcctTbl,2,0),"کد ناشناخته")) | I16: =IF($U16="","",IFERROR(VLOOKUP($U16,AcctTbl,3,0),"")) | J16: نارنگی پیچ | K16: BK01 – ۶ک مشکی | L16: 640 | M16: 38 | N16: =IF(OR($E16="",$L16=""),"",IFERROR(($L16-IF($M16="",0,$M16)*IFERROR(VLOOKUP($K16,BasketTbl,4,0),IFERROR(INDEX(BasketTbl,MATCH($K16,BasketCodeCol,0),4),VLOOKUP("P01",ParamTbl,2,0))))*(1-IF(VLOOKUP($E16,OpTbl,3,0)="خرید",VLOOKUP("P02",ParamTbl,2,0),0)/100),"")) | O16: 33000 | P16: =IF(OR($E16="",$L16=""),"",IFERROR(IF(VLOOKUP($E16,OpTbl,6,0)="وزن",ROUND($N16*$O16,-3),IF(VLOOKUP($E16,OpTbl,6,0)="مبلغ",ROUND($L16*$O16,-3),0)),"")) | Q16: 0 | S16: =IF($E16="","",IF($AI16="⚠","⚠ ناتراز",IF(AND(IFERROR(VLOOKUP($E16,OpTbl,4,0),"")="بله",$L16=""),"⚠ وزن",IF(AND(IFERROR(VLOOKUP($E16,OpTbl,5,0),"")="بله",$U16=""),"⚠ حساب",IF(AND(IFERROR(VLOOKUP($E16,OpTbl,6,0),"")="مبلغ",$Q16=""),"⚠ مبلغ","✓"))))) | U16: =IF($E16="","",IFERROR(IF(VLOOKUP($E16,OpTbl,14,0)<>"",VLOOKUP($E16,OpTbl,14,0),$G16),"")) | V16: =IF(OR($AJ16="",$AJ16=0,$AL16<>"بدهکار"),"",$AJ16) | W16: =IF(OR($AJ16="",$AJ16=0,$AL16<>"بستانکار"),"",$AJ16) | X16: =IF($E16="","",IFERROR(VLOOKUP($E16,OpTbl,8,0),"")) | Y16: =IF(OR($X16="",$AJ16="",$AJ16=0,$AM16<>"بدهکار"),"",$AJ16) | Z16: =IF(OR($X16="",$AJ16="",$AJ16=0,$AM16<>"بستانکار"),"",$AJ16) | AA16: =IF(OR($E16="",$AN16="—",$AN16=""),"",IFERROR(VLOOKUP($E16,OpTbl,12,0),"")) | AB16: =IF(OR($AA16="",$Q16="",$Q16=0,$AN16<>"بدهکار"),"",$Q16) | AC16: =IF(OR($AA16="",$Q16="",$Q16=0,$AN16<>"بستانکار"),"",$Q16) | AD16: =IF($AA16="","",IFERROR(VLOOKUP($E16,OpTbl,13,0),"")) | AE16: =IF(OR($AD16="",$Q16="",$Q16=0,$AN16<>"بستانکار"),"",$Q16) | AF16: =IF(OR($AD16="",$Q16="",$Q16=0,$AN16<>"بدهکار"),"",$Q16) | AG16: =SUM($V16,$Y16,$AB16,$AE16) | AH16: =SUM($W16,$Z16,$AC16,$AF16) | AI16: =IF($E16="","",IF(ROUND($AG16-$AH16,0)=0,"✓","⚠")) | AJ16: =IF(OR($E16="",$U16=""),"",IFERROR(IF(VLOOKUP($E16,OpTbl,6,0)="وزن",IF($P16="",0,$P16),IF(VLOOKUP($E16,OpTbl,6,0)="مبلغ",IF(AND($Q16<>"",$Q16<>0),$Q16,$P16),0))+IF(VLOOKUP($E16,OpTbl,10,0)="افزودن",IF($Q16="",0,$Q16),0),0)) | AK16: =IF($E16="","",IFERROR(VLOOKUP($E16,OpTbl,10,0),"")) | AL16: =IF(OR($E16="",$U16=""),"",IFERROR(IF(VLOOKUP($E16,OpTbl,7,0)="خودکار",$R16,VLOOKUP($E16,OpTbl,7,0)),"")) | AM16: =IF(OR($E16="",$X16=""),"",IFERROR(IF(VLOOKUP($E16,OpTbl,9,0)="خودکار",IF($AL16="بدهکار","بستانکار",IF($AL16="بستانکار","بدهکار","")),VLOOKUP($E16,OpTbl,9,0)),"")) | AN16: =IF($E16="","",IFERROR(VLOOKUP($E16,OpTbl,11,0),"")) | AO16: =IF($B16="","",MID($B16,6,2)) | AP16: =IF($B16="",0,1)
A17: =IF($B17="","",COUNTA($B$10:$B17)) | B17: 1405/07/04 | C17: 13:20 | D17: BS-008 | E17: فروش بار (بارفروش) | F17: =IF($E17="","",IFERROR(VLOOKUP($E17,OpTbl,2,0),"")) | G17: SL002 | H17: =IF($U17="","",IFERROR(VLOOKUP($U17,AcctTbl,2,0),"کد ناشناخته")) | I17: =IF($U17="","",IFERROR(VLOOKUP($U17,AcctTbl,3,0),"")) | J17: نارنگی اونشو | K17: BK03 – ۹ک مشکی | L17: 1800 | M17: 0 | N17: =IF(OR($E17="",$L17=""),"",IFERROR(($L17-IF($M17="",0,$M17)*IFERROR(VLOOKUP($K17,BasketTbl,4,0),IFERROR(INDEX(BasketTbl,MATCH($K17,BasketCodeCol,0),4),VLOOKUP("P01",ParamTbl,2,0))))*(1-IF(VLOOKUP($E17,OpTbl,3,0)="خرید",VLOOKUP("P02",ParamTbl,2,0),0)/100),"")) | O17: 52000 | P17: =IF(OR($E17="",$L17=""),"",IFERROR(IF(VLOOKUP($E17,OpTbl,6,0)="وزن",ROUND($N17*$O17,-3),IF(VLOOKUP($E17,OpTbl,6,0)="مبلغ",ROUND($L17*$O17,-3),0)),"")) | Q17: 90000 | S17: =IF($E17="","",IF($AI17="⚠","⚠ ناتراز",IF(AND(IFERROR(VLOOKUP($E17,OpTbl,4,0),"")="بله",$L17=""),"⚠ وزن",IF(AND(IFERROR(VLOOKUP($E17,OpTbl,5,0),"")="بله",$U17=""),"⚠ حساب",IF(AND(IFERROR(VLOOKUP($E17,OpTbl,6,0),"")="مبلغ",$Q17=""),"⚠ مبلغ","✓"))))) | T17: هزینه باسکول پوز | U17: =IF($E17="","",IFERROR(IF(VLOOKUP($E17,OpTbl,14,0)<>"",VLOOKUP($E17,OpTbl,14,0),$G17),"")) | V17: =IF(OR($AJ17="",$AJ17=0,$AL17<>"بدهکار"),"",$AJ17) | W17: =IF(OR($AJ17="",$AJ17=0,$AL17<>"بستانکار"),"",$AJ17) | X17: =IF($E17="","",IFERROR(VLOOKUP($E17,OpTbl,8,0),"")) | Y17: =IF(OR($X17="",$AJ17="",$AJ17=0,$AM17<>"بدهکار"),"",$AJ17) | Z17: =IF(OR($X17="",$AJ17="",$AJ17=0,$AM17<>"بستانکار"),"",$AJ17) | AA17: =IF(OR($E17="",$AN17="—",$AN17=""),"",IFERROR(VLOOKUP($E17,OpTbl,12,0),"")) | AB17: =IF(OR($AA17="",$Q17="",$Q17=0,$AN17<>"بدهکار"),"",$Q17) | AC17: =IF(OR($AA17="",$Q17="",$Q17=0,$AN17<>"بستانکار"),"",$Q17) | AD17: =IF($AA17="","",IFERROR(VLOOKUP($E17,OpTbl,13,0),"")) | AE17: =IF(OR($AD17="",$Q17="",$Q17=0,$AN17<>"بستانکار"),"",$Q17) | AF17: =IF(OR($AD17="",$Q17="",$Q17=0,$AN17<>"بدهکار"),"",$Q17) | AG17: =SUM($V17,$Y17,$AB17,$AE17) | AH17: =SUM($W17,$Z17,$AC17,$AF17) | AI17: =IF($E17="","",IF(ROUND($AG17-$AH17,0)=0,"✓","⚠")) | AJ17: =IF(OR($E17="",$U17=""),"",IFERROR(IF(VLOOKUP($E17,OpTbl,6,0)="وزن",IF($P17="",0,$P17),IF(VLOOKUP($E17,OpTbl,6,0)="مبلغ",IF(AND($Q17<>"",$Q17<>0),$Q17,$P17),0))+IF(VLOOKUP($E17,OpTbl,10,0)="افزودن",IF($Q17="",0,$Q17),0),0)) | AK17: =IF($E17="","",IFERROR(VLOOKUP($E17,OpTbl,10,0),"")) | AL17: =IF(OR($E17="",$U17=""),"",IFERROR(IF(VLOOKUP($E17,OpTbl,7,0)="خودکار",$R17,VLOOKUP($E17,OpTbl,7,0)),"")) | AM17: =IF(OR($E17="",$X17=""),"",IFERROR(IF(VLOOKUP($E17,OpTbl,9,0)="خودکار",IF($AL17="بدهکار","بستانکار",IF($AL17="بستانکار","بدهکار","")),VLOOKUP($E17,OpTbl,9,0)),"")) | AN17: =IF($E17="","",IFERROR(VLOOKUP($E17,OpTbl,11,0),"")) | AO17: =IF($B17="","",MID($B17,6,2)) | AP17: =IF($B17="",0,1)
A18: =IF($B18="","",COUNTA($B$10:$B18)) | B18: 1405/07/05 | C18: 08:05 | D18: BS-009 | E18: آبگیری | F18: =IF($E18="","",IFERROR(VLOOKUP($E18,OpTbl,2,0),"")) | G18: C007 | H18: =IF($U18="","",IFERROR(VLOOKUP($U18,AcctTbl,2,0),"کد ناشناخته")) | I18: =IF($U18="","",IFERROR(VLOOKUP($U18,AcctTbl,3,0),"")) | J18: نارنگی پیچ | K18: BK01 – ۶ک مشکی | L18: 800 | M18: 0 | N18: =IF(OR($E18="",$L18=""),"",IFERROR(($L18-IF($M18="",0,$M18)*IFERROR(VLOOKUP($K18,BasketTbl,4,0),IFERROR(INDEX(BasketTbl,MATCH($K18,BasketCodeCol,0),4),VLOOKUP("P01",ParamTbl,2,0))))*(1-IF(VLOOKUP($E18,OpTbl,3,0)="خرید",VLOOKUP("P02",ParamTbl,2,0),0)/100),"")) | O18: 0 | P18: =IF(OR($E18="",$L18=""),"",IFERROR(IF(VLOOKUP($E18,OpTbl,6,0)="وزن",ROUND($N18*$O18,-3),IF(VLOOKUP($E18,OpTbl,6,0)="مبلغ",ROUND($L18*$O18,-3),0)),"")) | Q18: 12000000 | R18: بستانکار | S18: =IF($E18="","",IF($AI18="⚠","⚠ ناتراز",IF(AND(IFERROR(VLOOKUP($E18,OpTbl,4,0),"")="بله",$L18=""),"⚠ وزن",IF(AND(IFERROR(VLOOKUP($E18,OpTbl,5,0),"")="بله",$U18=""),"⚠ حساب",IF(AND(IFERROR(VLOOKUP($E18,OpTbl,6,0),"")="مبلغ",$Q18=""),"⚠ مبلغ","✓"))))) | T18: آبگیری — طرف حساب بستانکار | U18: =IF($E18="","",IFERROR(IF(VLOOKUP($E18,OpTbl,14,0)<>"",VLOOKUP($E18,OpTbl,14,0),$G18),"")) | V18: =IF(OR($AJ18="",$AJ18=0,$AL18<>"بدهکار"),"",$AJ18) | W18: =IF(OR($AJ18="",$AJ18=0,$AL18<>"بستانکار"),"",$AJ18) | X18: =IF($E18="","",IFERROR(VLOOKUP($E18,OpTbl,8,0),"")) | Y18: =IF(OR($X18="",$AJ18="",$AJ18=0,$AM18<>"بدهکار"),"",$AJ18) | Z18: =IF(OR($X18="",$AJ18="",$AJ18=0,$AM18<>"بستانکار"),"",$AJ18) | AA18: =IF(OR($E18="",$AN18="—",$AN18=""),"",IFERROR(VLOOKUP($E18,OpTbl,12,0),"")) | AB18: =IF(OR($AA18="",$Q18="",$Q18=0,$AN18<>"بدهکار"),"",$Q18) | AC18: =IF(OR($AA18="",$Q18="",$Q18=0,$AN18<>"بستانکار"),"",$Q18) | AD18: =IF($AA18="","",IFERROR(VLOOKUP($E18,OpTbl,13,0),"")) | AE18: =IF(OR($AD18="",$Q18="",$Q18=0,$AN18<>"بستانکار"),"",$Q18) | AF18: =IF(OR($AD18="",$Q18="",$Q18=0,$AN18<>"بدهکار"),"",$Q18) | AG18: =SUM($V18,$Y18,$AB18,$AE18) | AH18: =SUM($W18,$Z18,$AC18,$AF18) | AI18: =IF($E18="","",IF(ROUND($AG18-$AH18,0)=0,"✓","⚠")) | AJ18: =IF(OR($E18="",$U18=""),"",IFERROR(IF(VLOOKUP($E18,OpTbl,6,0)="وزن",IF($P18="",0,$P18),IF(VLOOKUP($E18,OpTbl,6,0)="مبلغ",IF(AND($Q18<>"",$Q18<>0),$Q18,$P18),0))+IF(VLOOKUP($E18,OpTbl,10,0)="افزودن",IF($Q18="",0,$Q18),0),0)) | AK18: =IF($E18="","",IFERROR(VLOOKUP($E18,OpTbl,10,0),"")) | AL18: =IF(OR($E18="",$U18=""),"",IFERROR(IF(VLOOKUP($E18,OpTbl,7,0)="خودکار",$R18,VLOOKUP($E18,OpTbl,7,0)),"")) | AM18: =IF(OR($E18="",$X18=""),"",IFERROR(IF(VLOOKUP($E18,OpTbl,9,0)="خودکار",IF($AL18="بدهکار","بستانکار",IF($AL18="بستانکار","بدهکار","")),VLOOKUP($E18,OpTbl,9,0)),"")) | AN18: =IF($E18="","",IFERROR(VLOOKUP($E18,OpTbl,11,0),"")) | AO18: =IF($B18="","",MID($B18,6,2)) | AP18: =IF($B18="",0,1)
A19: =IF($B19="","",COUNTA($B$10:$B19)) | B19: 1405/07/05 | C19: 10:40 | D19: BS-010 | E19: انعام مصطفی | F19: =IF($E19="","",IFERROR(VLOOKUP($E19,OpTbl,2,0),"")) | H19: =IF($U19="","",IFERROR(VLOOKUP($U19,AcctTbl,2,0),"کد ناشناخته")) | I19: =IF($U19="","",IFERROR(VLOOKUP($U19,AcctTbl,3,0),"")) | L19: 0 | M19: 0 | N19: =IF(OR($E19="",$L19=""),"",IFERROR(($L19-IF($M19="",0,$M19)*IFERROR(VLOOKUP($K19,BasketTbl,4,0),IFERROR(INDEX(BasketTbl,MATCH($K19,BasketCodeCol,0),4),VLOOKUP("P01",ParamTbl,2,0))))*(1-IF(VLOOKUP($E19,OpTbl,3,0)="خرید",VLOOKUP("P02",ParamTbl,2,0),0)/100),"")) | O19: 0 | P19: =IF(OR($E19="",$L19=""),"",IFERROR(IF(VLOOKUP($E19,OpTbl,6,0)="وزن",ROUND($N19*$O19,-3),IF(VLOOKUP($E19,OpTbl,6,0)="مبلغ",ROUND($L19*$O19,-3),0)),"")) | Q19: 500000 | S19: =IF($E19="","",IF($AI19="⚠","⚠ ناتراز",IF(AND(IFERROR(VLOOKUP($E19,OpTbl,4,0),"")="بله",$L19=""),"⚠ وزن",IF(AND(IFERROR(VLOOKUP($E19,OpTbl,5,0),"")="بله",$U19=""),"⚠ حساب",IF(AND(IFERROR(VLOOKUP($E19,OpTbl,6,0),"")="مبلغ",$Q19=""),"⚠ مبلغ","✓"))))) | T19: انعام از پوز باسکول | U19: =IF($E19="","",IFERROR(IF(VLOOKUP($E19,OpTbl,14,0)<>"",VLOOKUP($E19,OpTbl,14,0),$G19),"")) | V19: =IF(OR($AJ19="",$AJ19=0,$AL19<>"بدهکار"),"",$AJ19) | W19: =IF(OR($AJ19="",$AJ19=0,$AL19<>"بستانکار"),"",$AJ19) | X19: =IF($E19="","",IFERROR(VLOOKUP($E19,OpTbl,8,0),"")) | Y19: =IF(OR($X19="",$AJ19="",$AJ19=0,$AM19<>"بدهکار"),"",$AJ19) | Z19: =IF(OR($X19="",$AJ19="",$AJ19=0,$AM19<>"بستانکار"),"",$AJ19) | AA19: =IF(OR($E19="",$AN19="—",$AN19=""),"",IFERROR(VLOOKUP($E19,OpTbl,12,0),"")) | AB19: =IF(OR($AA19="",$Q19="",$Q19=0,$AN19<>"بدهکار"),"",$Q19) | AC19: =IF(OR($AA19="",$Q19="",$Q19=0,$AN19<>"بستانکار"),"",$Q19) | AD19: =IF($AA19="","",IFERROR(VLOOKUP($E19,OpTbl,13,0),"")) | AE19: =IF(OR($AD19="",$Q19="",$Q19=0,$AN19<>"بستانکار"),"",$Q19) | AF19: =IF(OR($AD19="",$Q19="",$Q19=0,$AN19<>"بدهکار"),"",$Q19) | AG19: =SUM($V19,$Y19,$AB19,$AE19) | AH19: =SUM($W19,$Z19,$AC19,$AF19) | AI19: =IF($E19="","",IF(ROUND($AG19-$AH19,0)=0,"✓","⚠")) | AJ19: =IF(OR($E19="",$U19=""),"",IFERROR(IF(VLOOKUP($E19,OpTbl,6,0)="وزن",IF($P19="",0,$P19),IF(VLOOKUP($E19,OpTbl,6,0)="مبلغ",IF(AND($Q19<>"",$Q19<>0),$Q19,$P19),0))+IF(VLOOKUP($E19,OpTbl,10,0)="افزودن",IF($Q19="",0,$Q19),0),0)) | AK19: =IF($E19="","",IFERROR(VLOOKUP($E19,OpTbl,10,0),"")) | AL19: =IF(OR($E19="",$U19=""),"",IFERROR(IF(VLOOKUP($E19,OpTbl,7,0)="خودکار",$R19,VLOOKUP($E19,OpTbl,7,0)),"")) | AM19: =IF(OR($E19="",$X19=""),"",IFERROR(IF(VLOOKUP($E19,OpTbl,9,0)="خودکار",IF($AL19="بدهکار","بستانکار",IF($AL19="بستانکار","بدهکار","")),VLOOKUP($E19,OpTbl,9,0)),"")) | AN19: =IF($E19="","",IFERROR(VLOOKUP($E19,OpTbl,11,0),"")) | AO19: =IF($B19="","",MID($B19,6,2)) | AP19: =IF($B19="",0,1)
A20: =IF($B20="","",COUNTA($B$10:$B20)) | B20: 1405/07/06 | C20: 09:15 | D20: BS-011 | E20: باسکول دیگران | F20: =IF($E20="","",IFERROR(VLOOKUP($E20,OpTbl,2,0),"")) | G20: BD001 | H20: =IF($U20="","",IFERROR(VLOOKUP($U20,AcctTbl,2,0),"کد ناشناخته")) | I20: =IF($U20="","",IFERROR(VLOOKUP($U20,AcctTbl,3,0),"")) | L20: 0 | M20: 0 | N20: =IF(OR($E20="",$L20=""),"",IFERROR(($L20-IF($M20="",0,$M20)*IFERROR(VLOOKUP($K20,BasketTbl,4,0),IFERROR(INDEX(BasketTbl,MATCH($K20,BasketCodeCol,0),4),VLOOKUP("P01",ParamTbl,2,0))))*(1-IF(VLOOKUP($E20,OpTbl,3,0)="خرید",VLOOKUP("P02",ParamTbl,2,0),0)/100),"")) | O20: 0 | P20: =IF(OR($E20="",$L20=""),"",IFERROR(IF(VLOOKUP($E20,OpTbl,6,0)="وزن",ROUND($N20*$O20,-3),IF(VLOOKUP($E20,OpTbl,6,0)="مبلغ",ROUND($L20*$O20,-3),0)),"")) | Q20: 150000 | S20: =IF($E20="","",IF($AI20="⚠","⚠ ناتراز",IF(AND(IFERROR(VLOOKUP($E20,OpTbl,4,0),"")="بله",$L20=""),"⚠ وزن",IF(AND(IFERROR(VLOOKUP($E20,OpTbl,5,0),"")="بله",$U20=""),"⚠ حساب",IF(AND(IFERROR(VLOOKUP($E20,OpTbl,6,0),"")="مبلغ",$Q20=""),"⚠ مبلغ","✓"))))) | T20: هزینه باسکول مهمان | U20: =IF($E20="","",IFERROR(IF(VLOOKUP($E20,OpTbl,14,0)<>"",VLOOKUP($E20,OpTbl,14,0),$G20),"")) | V20: =IF(OR($AJ20="",$AJ20=0,$AL20<>"بدهکار"),"",$AJ20) | W20: =IF(OR($AJ20="",$AJ20=0,$AL20<>"بستانکار"),"",$AJ20) | X20: =IF($E20="","",IFERROR(VLOOKUP($E20,OpTbl,8,0),"")) | Y20: =IF(OR($X20="",$AJ20="",$AJ20=0,$AM20<>"بدهکار"),"",$AJ20) | Z20: =IF(OR($X20="",$AJ20="",$AJ20=0,$AM20<>"بستانکار"),"",$AJ20) | AA20: =IF(OR($E20="",$AN20="—",$AN20=""),"",IFERROR(VLOOKUP($E20,OpTbl,12,0),"")) | AB20: =IF(OR($AA20="",$Q20="",$Q20=0,$AN20<>"بدهکار"),"",$Q20) | AC20: =IF(OR($AA20="",$Q20="",$Q20=0,$AN20<>"بستانکار"),"",$Q20) | AD20: =IF($AA20="","",IFERROR(VLOOKUP($E20,OpTbl,13,0),"")) | AE20: =IF(OR($AD20="",$Q20="",$Q20=0,$AN20<>"بستانکار"),"",$Q20) | AF20: =IF(OR($AD20="",$Q20="",$Q20=0,$AN20<>"بدهکار"),"",$Q20) | AG20: =SUM($V20,$Y20,$AB20,$AE20) | AH20: =SUM($W20,$Z20,$AC20,$AF20) | AI20: =IF($E20="","",IF(ROUND($AG20-$AH20,0)=0,"✓","⚠")) | AJ20: =IF(OR($E20="",$U20=""),"",IFERROR(IF(VLOOKUP($E20,OpTbl,6,0)="وزن",IF($P20="",0,$P20),IF(VLOOKUP($E20,OpTbl,6,0)="مبلغ",IF(AND($Q20<>"",$Q20<>0),$Q20,$P20),0))+IF(VLOOKUP($E20,OpTbl,10,0)="افزودن",IF($Q20="",0,$Q20),0),0)) | AK20: =IF($E20="","",IFERROR(VLOOKUP($E20,OpTbl,10,0),"")) | AL20: =IF(OR($E20="",$U20=""),"",IFERROR(IF(VLOOKUP($E20,OpTbl,7,0)="خودکار",$R20,VLOOKUP($E20,OpTbl,7,0)),"")) | AM20: =IF(OR($E20="",$X20=""),"",IFERROR(IF(VLOOKUP($E20,OpTbl,9,0)="خودکار",IF($AL20="بدهکار","بستانکار",IF($AL20="بستانکار","بدهکار","")),VLOOKUP($E20,OpTbl,9,0)),"")) | AN20: =IF($E20="","",IFERROR(VLOOKUP($E20,OpTbl,11,0),"")) | AO20: =IF($B20="","",MID($B20,6,2)) | AP20: =IF($B20="",0,1)
A21: =IF($B21="","",COUNTA($B$10:$B21)) | B21: 1405/07/06 | C21: 12:00 | D21: BS-012 | E21: خرید مرکبات | F21: =IF($E21="","",IFERROR(VLOOKUP($E21,OpTbl,2,0),"")) | G21: C005 | H21: =IF($U21="","",IFERROR(VLOOKUP($U21,AcctTbl,2,0),"کد ناشناخته")) | I21: =IF($U21="","",IFERROR(VLOOKUP($U21,AcctTbl,3,0),"")) | J21: پرتقال یافا | K21: BK03 – ۹ک مشکی | L21: 3200 | M21: 195 | N21: =IF(OR($E21="",$L21=""),"",IFERROR(($L21-IF($M21="",0,$M21)*IFERROR(VLOOKUP($K21,BasketTbl,4,0),IFERROR(INDEX(BasketTbl,MATCH($K21,BasketCodeCol,0),4),VLOOKUP("P01",ParamTbl,2,0))))*(1-IF(VLOOKUP($E21,OpTbl,3,0)="خرید",VLOOKUP("P02",ParamTbl,2,0),0)/100),"")) | O21: 29000 | P21: =IF(OR($E21="",$L21=""),"",IFERROR(IF(VLOOKUP($E21,OpTbl,6,0)="وزن",ROUND($N21*$O21,-3),IF(VLOOKUP($E21,OpTbl,6,0)="مبلغ",ROUND($L21*$O21,-3),0)),"")) | Q21: 0 | S21: =IF($E21="","",IF($AI21="⚠","⚠ ناتراز",IF(AND(IFERROR(VLOOKUP($E21,OpTbl,4,0),"")="بله",$L21=""),"⚠ وزن",IF(AND(IFERROR(VLOOKUP($E21,OpTbl,5,0),"")="بله",$U21=""),"⚠ حساب",IF(AND(IFERROR(VLOOKUP($E21,OpTbl,6,0),"")="مبلغ",$Q21=""),"⚠ مبلغ","✓"))))) | U21: =IF($E21="","",IFERROR(IF(VLOOKUP($E21,OpTbl,14,0)<>"",VLOOKUP($E21,OpTbl,14,0),$G21),"")) | V21: =IF(OR($AJ21="",$AJ21=0,$AL21<>"بدهکار"),"",$AJ21) | W21: =IF(OR($AJ21="",$AJ21=0,$AL21<>"بستانکار"),"",$AJ21) | X21: =IF($E21="","",IFERROR(VLOOKUP($E21,OpTbl,8,0),"")) | Y21: =IF(OR($X21="",$AJ21="",$AJ21=0,$AM21<>"بدهکار"),"",$AJ21) | Z21: =IF(OR($X21="",$AJ21="",$AJ21=0,$AM21<>"بستانکار"),"",$AJ21) | AA21: =IF(OR($E21="",$AN21="—",$AN21=""),"",IFERROR(VLOOKUP($E21,OpTbl,12,0),"")) | AB21: =IF(OR($AA21="",$Q21="",$Q21=0,$AN21<>"بدهکار"),"",$Q21) | AC21: =IF(OR($AA21="",$Q21="",$Q21=0,$AN21<>"بستانکار"),"",$Q21) | AD21: =IF($AA21="","",IFERROR(VLOOKUP($E21,OpTbl,13,0),"")) | AE21: =IF(OR($AD21="",$Q21="",$Q21=0,$AN21<>"بستانکار"),"",$Q21) | AF21: =IF(OR($AD21="",$Q21="",$Q21=0,$AN21<>"بدهکار"),"",$Q21) | AG21: =SUM($V21,$Y21,$AB21,$AE21) | AH21: =SUM($W21,$Z21,$AC21,$AF21) | AI21: =IF($E21="","",IF(ROUND($AG21-$AH21,0)=0,"✓","⚠")) | AJ21: =IF(OR($E21="",$U21=""),"",IFERROR(IF(VLOOKUP($E21,OpTbl,6,0)="وزن",IF($P21="",0,$P21),IF(VLOOKUP($E21,OpTbl,6,0)="مبلغ",IF(AND($Q21<>"",$Q21<>0),$Q21,$P21),0))+IF(VLOOKUP($E21,OpTbl,10,0)="افزودن",IF($Q21="",0,$Q21),0),0)) | AK21: =IF($E21="","",IFERROR(VLOOKUP($E21,OpTbl,10,0),"")) | AL21: =IF(OR($E21="",$U21=""),"",IFERROR(IF(VLOOKUP($E21,OpTbl,7,0)="خودکار",$R21,VLOOKUP($E21,OpTbl,7,0)),"")) | AM21: =IF(OR($E21="",$X21=""),"",IFERROR(IF(VLOOKUP($E21,OpTbl,9,0)="خودکار",IF($AL21="بدهکار","بستانکار",IF($AL21="بستانکار","بدهکار","")),VLOOKUP($E21,OpTbl,9,0)),"")) | AN21: =IF($E21="","",IFERROR(VLOOKUP($E21,OpTbl,11,0),"")) | AO21: =IF($B21="","",MID($B21,6,2)) | AP21: =IF($B21="",0,1)
A22: =IF($B22="","",COUNTA($B$10:$B22)) | B22: 1405/07/07 | C22: 08:30 | D22: BS-013 | E22: مرجوعی خرید | F22: =IF($E22="","",IFERROR(VLOOKUP($E22,OpTbl,2,0),"")) | G22: C001 | H22: =IF($U22="","",IFERROR(VLOOKUP($U22,AcctTbl,2,0),"کد ناشناخته")) | I22: =IF($U22="","",IFERROR(VLOOKUP($U22,AcctTbl,3,0),"")) | J22: نارنگی پیچ | K22: BK01 – ۶ک مشکی | L22: 220 | M22: 12 | N22: =IF(OR($E22="",$L22=""),"",IFERROR(($L22-IF($M22="",0,$M22)*IFERROR(VLOOKUP($K22,BasketTbl,4,0),IFERROR(INDEX(BasketTbl,MATCH($K22,BasketCodeCol,0),4),VLOOKUP("P01",ParamTbl,2,0))))*(1-IF(VLOOKUP($E22,OpTbl,3,0)="خرید",VLOOKUP("P02",ParamTbl,2,0),0)/100),"")) | O22: 32000 | P22: =IF(OR($E22="",$L22=""),"",IFERROR(IF(VLOOKUP($E22,OpTbl,6,0)="وزن",ROUND($N22*$O22,-3),IF(VLOOKUP($E22,OpTbl,6,0)="مبلغ",ROUND($L22*$O22,-3),0)),"")) | Q22: 0 | S22: =IF($E22="","",IF($AI22="⚠","⚠ ناتراز",IF(AND(IFERROR(VLOOKUP($E22,OpTbl,4,0),"")="بله",$L22=""),"⚠ وزن",IF(AND(IFERROR(VLOOKUP($E22,OpTbl,5,0),"")="بله",$U22=""),"⚠ حساب",IF(AND(IFERROR(VLOOKUP($E22,OpTbl,6,0),"")="مبلغ",$Q22=""),"⚠ مبلغ","✓"))))) | T22: برگشت ۱۲ سبد | U22: =IF($E22="","",IFERROR(IF(VLOOKUP($E22,OpTbl,14,0)<>"",VLOOKUP($E22,OpTbl,14,0),$G22),"")) | V22: =IF(OR($AJ22="",$AJ22=0,$AL22<>"بدهکار"),"",$AJ22) | W22: =IF(OR($AJ22="",$AJ22=0,$AL22<>"بستانکار"),"",$AJ22) | X22: =IF($E22="","",IFERROR(VLOOKUP($E22,OpTbl,8,0),"")) | Y22: =IF(OR($X22="",$AJ22="",$AJ22=0,$AM22<>"بدهکار"),"",$AJ22) | Z22: =IF(OR($X22="",$AJ22="",$AJ22=0,$AM22<>"بستانکار"),"",$AJ22) | AA22: =IF(OR($E22="",$AN22="—",$AN22=""),"",IFERROR(VLOOKUP($E22,OpTbl,12,0),"")) | AB22: =IF(OR($AA22="",$Q22="",$Q22=0,$AN22<>"بدهکار"),"",$Q22) | AC22: =IF(OR($AA22="",$Q22="",$Q22=0,$AN22<>"بستانکار"),"",$Q22) | AD22: =IF($AA22="","",IFERROR(VLOOKUP($E22,OpTbl,13,0),"")) | AE22: =IF(OR($AD22="",$Q22="",$Q22=0,$AN22<>"بستانکار"),"",$Q22) | AF22: =IF(OR($AD22="",$Q22="",$Q22=0,$AN22<>"بدهکار"),"",$Q22) | AG22: =SUM($V22,$Y22,$AB22,$AE22) | AH22: =SUM($W22,$Z22,$AC22,$AF22) | AI22: =IF($E22="","",IF(ROUND($AG22-$AH22,0)=0,"✓","⚠")) | AJ22: =IF(OR($E22="",$U22=""),"",IFERROR(IF(VLOOKUP($E22,OpTbl,6,0)="وزن",IF($P22="",0,$P22),IF(VLOOKUP($E22,OpTbl,6,0)="مبلغ",IF(AND($Q22<>"",$Q22<>0),$Q22,$P22),0))+IF(VLOOKUP($E22,OpTbl,10,0)="افزودن",IF($Q22="",0,$Q22),0),0)) | AK22: =IF($E22="","",IFERROR(VLOOKUP($E22,OpTbl,10,0),"")) | AL22: =IF(OR($E22="",$U22=""),"",IFERROR(IF(VLOOKUP($E22,OpTbl,7,0)="خودکار",$R22,VLOOKUP($E22,OpTbl,7,0)),"")) | AM22: =IF(OR($E22="",$X22=""),"",IFERROR(IF(VLOOKUP($E22,OpTbl,9,0)="خودکار",IF($AL22="بدهکار","بستانکار",IF($AL22="بستانکار","بدهکار","")),VLOOKUP($E22,OpTbl,9,0)),"")) | AN22: =IF($E22="","",IFERROR(VLOOKUP($E22,OpTbl,11,0),"")) | AO22: =IF($B22="","",MID($B22,6,2)) | AP22: =IF($B22="",0,1)
A23: =IF($B23="","",COUNTA($B$10:$B23)) | B23: 1405/07/08 | C23: 09:50 | D23: BS-014 | E23: خرید مرکبات | F23: =IF($E23="","",IFERROR(VLOOKUP($E23,OpTbl,2,0),"")) | G23: C009 | H23: =IF($U23="","",IFERROR(VLOOKUP($U23,AcctTbl,2,0),"کد ناشناخته")) | I23: =IF($U23="","",IFERROR(VLOOKUP($U23,AcctTbl,3,0),"")) | J23: نارنگی ژاپنی | K23: BK07 – ۸ک مشکی | L23: 1450 | M23: 92 | N23: =IF(OR($E23="",$L23=""),"",IFERROR(($L23-IF($M23="",0,$M23)*IFERROR(VLOOKUP($K23,BasketTbl,4,0),IFERROR(INDEX(BasketTbl,MATCH($K23,BasketCodeCol,0),4),VLOOKUP("P01",ParamTbl,2,0))))*(1-IF(VLOOKUP($E23,OpTbl,3,0)="خرید",VLOOKUP("P02",ParamTbl,2,0),0)/100),"")) | O23: 30500 | P23: =IF(OR($E23="",$L23=""),"",IFERROR(IF(VLOOKUP($E23,OpTbl,6,0)="وزن",ROUND($N23*$O23,-3),IF(VLOOKUP($E23,OpTbl,6,0)="مبلغ",ROUND($L23*$O23,-3),0)),"")) | Q23: 0 | S23: =IF($E23="","",IF($AI23="⚠","⚠ ناتراز",IF(AND(IFERROR(VLOOKUP($E23,OpTbl,4,0),"")="بله",$L23=""),"⚠ وزن",IF(AND(IFERROR(VLOOKUP($E23,OpTbl,5,0),"")="بله",$U23=""),"⚠ حساب",IF(AND(IFERROR(VLOOKUP($E23,OpTbl,6,0),"")="مبلغ",$Q23=""),"⚠ مبلغ","✓"))))) | U23: =IF($E23="","",IFERROR(IF(VLOOKUP($E23,OpTbl,14,0)<>"",VLOOKUP($E23,OpTbl,14,0),$G23),"")) | V23: =IF(OR($AJ23="",$AJ23=0,$AL23<>"بدهکار"),"",$AJ23) | W23: =IF(OR($AJ23="",$AJ23=0,$AL23<>"بستانکار"),"",$AJ23) | X23: =IF($E23="","",IFERROR(VLOOKUP($E23,OpTbl,8,0),"")) | Y23: =IF(OR($X23="",$AJ23="",$AJ23=0,$AM23<>"بدهکار"),"",$AJ23) | Z23: =IF(OR($X23="",$AJ23="",$AJ23=0,$AM23<>"بستانکار"),"",$AJ23) | AA23: =IF(OR($E23="",$AN23="—",$AN23=""),"",IFERROR(VLOOKUP($E23,OpTbl,12,0),"")) | AB23: =IF(OR($AA23="",$Q23="",$Q23=0,$AN23<>"بدهکار"),"",$Q23) | AC23: =IF(OR($AA23="",$Q23="",$Q23=0,$AN23<>"بستانکار"),"",$Q23) | AD23: =IF($AA23="","",IFERROR(VLOOKUP($E23,OpTbl,13,0),"")) | AE23: =IF(OR($AD23="",$Q23="",$Q23=0,$AN23<>"بستانکار"),"",$Q23) | AF23: =IF(OR($AD23="",$Q23="",$Q23=0,$AN23<>"بدهکار"),"",$Q23) | AG23: =SUM($V23,$Y23,$AB23,$AE23) | AH23: =SUM($W23,$Z23,$AC23,$AF23) | AI23: =IF($E23="","",IF(ROUND($AG23-$AH23,0)=0,"✓","⚠")) | AJ23: =IF(OR($E23="",$U23=""),"",IFERROR(IF(VLOOKUP($E23,OpTbl,6,0)="وزن",IF($P23="",0,$P23),IF(VLOOKUP($E23,OpTbl,6,0)="مبلغ",IF(AND($Q23<>"",$Q23<>0),$Q23,$P23),0))+IF(VLOOKUP($E23,OpTbl,10,0)="افزودن",IF($Q23="",0,$Q23),0),0)) | AK23: =IF($E23="","",IFERROR(VLOOKUP($E23,OpTbl,10,0),"")) | AL23: =IF(OR($E23="",$U23=""),"",IFERROR(IF(VLOOKUP($E23,OpTbl,7,0)="خودکار",$R23,VLOOKUP($E23,OpTbl,7,0)),"")) | AM23: =IF(OR($E23="",$X23=""),"",IFERROR(IF(VLOOKUP($E23,OpTbl,9,0)="خودکار",IF($AL23="بدهکار","بستانکار",IF($AL23="بستانکار","بدهکار","")),VLOOKUP($E23,OpTbl,9,0)),"")) | AN23: =IF($E23="","",IFERROR(VLOOKUP($E23,OpTbl,11,0),"")) | AO23: =IF($B23="","",MID($B23,6,2)) | AP23: =IF($B23="",0,1)
A24: =IF($B24="","",COUNTA($B$10:$B24)) | B24: 1405/07/09 | C24: 11:10 | D24: BS-015 | E24: فروش بار (بارفروش) | F24: =IF($E24="","",IFERROR(VLOOKUP($E24,OpTbl,2,0),"")) | G24: SL001 | H24: =IF($U24="","",IFERROR(VLOOKUP($U24,AcctTbl,2,0),"کد ناشناخته")) | I24: =IF($U24="","",IFERROR(VLOOKUP($U24,AcctTbl,3,0),"")) | J24: پرتقال تامسون | K24: BK03 – ۹ک مشکی | L24: 1600 | M24: 0 | N24: =IF(OR($E24="",$L24=""),"",IFERROR(($L24-IF($M24="",0,$M24)*IFERROR(VLOOKUP($K24,BasketTbl,4,0),IFERROR(INDEX(BasketTbl,MATCH($K24,BasketCodeCol,0),4),VLOOKUP("P01",ParamTbl,2,0))))*(1-IF(VLOOKUP($E24,OpTbl,3,0)="خرید",VLOOKUP("P02",ParamTbl,2,0),0)/100),"")) | O24: 60000 | P24: =IF(OR($E24="",$L24=""),"",IFERROR(IF(VLOOKUP($E24,OpTbl,6,0)="وزن",ROUND($N24*$O24,-3),IF(VLOOKUP($E24,OpTbl,6,0)="مبلغ",ROUND($L24*$O24,-3),0)),"")) | Q24: 80000 | S24: =IF($E24="","",IF($AI24="⚠","⚠ ناتراز",IF(AND(IFERROR(VLOOKUP($E24,OpTbl,4,0),"")="بله",$L24=""),"⚠ وزن",IF(AND(IFERROR(VLOOKUP($E24,OpTbl,5,0),"")="بله",$U24=""),"⚠ حساب",IF(AND(IFERROR(VLOOKUP($E24,OpTbl,6,0),"")="مبلغ",$Q24=""),"⚠ مبلغ","✓"))))) | T24: هزینه باسکول پوز | U24: =IF($E24="","",IFERROR(IF(VLOOKUP($E24,OpTbl,14,0)<>"",VLOOKUP($E24,OpTbl,14,0),$G24),"")) | V24: =IF(OR($AJ24="",$AJ24=0,$AL24<>"بدهکار"),"",$AJ24) | W24: =IF(OR($AJ24="",$AJ24=0,$AL24<>"بستانکار"),"",$AJ24) | X24: =IF($E24="","",IFERROR(VLOOKUP($E24,OpTbl,8,0),"")) | Y24: =IF(OR($X24="",$AJ24="",$AJ24=0,$AM24<>"بدهکار"),"",$AJ24) | Z24: =IF(OR($X24="",$AJ24="",$AJ24=0,$AM24<>"بستانکار"),"",$AJ24) | AA24: =IF(OR($E24="",$AN24="—",$AN24=""),"",IFERROR(VLOOKUP($E24,OpTbl,12,0),"")) | AB24: =IF(OR($AA24="",$Q24="",$Q24=0,$AN24<>"بدهکار"),"",$Q24) | AC24: =IF(OR($AA24="",$Q24="",$Q24=0,$AN24<>"بستانکار"),"",$Q24) | AD24: =IF($AA24="","",IFERROR(VLOOKUP($E24,OpTbl,13,0),"")) | AE24: =IF(OR($AD24="",$Q24="",$Q24=0,$AN24<>"بستانکار"),"",$Q24) | AF24: =IF(OR($AD24="",$Q24="",$Q24=0,$AN24<>"بدهکار"),"",$Q24) | AG24: =SUM($V24,$Y24,$AB24,$AE24) | AH24: =SUM($W24,$Z24,$AC24,$AF24) | AI24: =IF($E24="","",IF(ROUND($AG24-$AH24,0)=0,"✓","⚠")) | AJ24: =IF(OR($E24="",$U24=""),"",IFERROR(IF(VLOOKUP($E24,OpTbl,6,0)="وزن",IF($P24="",0,$P24),IF(VLOOKUP($E24,OpTbl,6,0)="مبلغ",IF(AND($Q24<>"",$Q24<>0),$Q24,$P24),0))+IF(VLOOKUP($E24,OpTbl,10,0)="افزودن",IF($Q24="",0,$Q24),0),0)) | AK24: =IF($E24="","",IFERROR(VLOOKUP($E24,OpTbl,10,0),"")) | AL24: =IF(OR($E24="",$U24=""),"",IFERROR(IF(VLOOKUP($E24,OpTbl,7,0)="خودکار",$R24,VLOOKUP($E24,OpTbl,7,0)),"")) | AM24: =IF(OR($E24="",$X24=""),"",IFERROR(IF(VLOOKUP($E24,OpTbl,9,0)="خودکار",IF($AL24="بدهکار","بستانکار",IF($AL24="بستانکار","بدهکار","")),VLOOKUP($E24,OpTbl,9,0)),"")) | AN24: =IF($E24="","",IFERROR(VLOOKUP($E24,OpTbl,11,0),"")) | AO24: =IF($B24="","",MID($B24,6,2)) | AP24: =IF($B24="",0,1)
A25: =IF($B25="","",COUNTA($B$10:$B25)) | B25: 1405/07/10 | C25: 07:30 | D25: BS-016 | E25: خرید مرکبات | F25: =IF($E25="","",IFERROR(VLOOKUP($E25,OpTbl,2,0),"")) | G25: C010 | H25: =IF($U25="","",IFERROR(VLOOKUP($U25,AcctTbl,2,0),"کد ناشناخته")) | I25: =IF($U25="","",IFERROR(VLOOKUP($U25,AcctTbl,3,0),"")) | J25: پرتقال کاراکارا | K25: BK03 – ۹ک مشکی | L25: 950 | M25: 58 | N25: =IF(OR($E25="",$L25=""),"",IFERROR(($L25-IF($M25="",0,$M25)*IFERROR(VLOOKUP($K25,BasketTbl,4,0),IFERROR(INDEX(BasketTbl,MATCH($K25,BasketCodeCol,0),4),VLOOKUP("P01",ParamTbl,2,0))))*(1-IF(VLOOKUP($E25,OpTbl,3,0)="خرید",VLOOKUP("P02",ParamTbl,2,0),0)/100),"")) | O25: 36000 | P25: =IF(OR($E25="",$L25=""),"",IFERROR(IF(VLOOKUP($E25,OpTbl,6,0)="وزن",ROUND($N25*$O25,-3),IF(VLOOKUP($E25,OpTbl,6,0)="مبلغ",ROUND($L25*$O25,-3),0)),"")) | Q25: 0 | S25: =IF($E25="","",IF($AI25="⚠","⚠ ناتراز",IF(AND(IFERROR(VLOOKUP($E25,OpTbl,4,0),"")="بله",$L25=""),"⚠ وزن",IF(AND(IFERROR(VLOOKUP($E25,OpTbl,5,0),"")="بله",$U25=""),"⚠ حساب",IF(AND(IFERROR(VLOOKUP($E25,OpTbl,6,0),"")="مبلغ",$Q25=""),"⚠ مبلغ","✓"))))) | U25: =IF($E25="","",IFERROR(IF(VLOOKUP($E25,OpTbl,14,0)<>"",VLOOKUP($E25,OpTbl,14,0),$G25),"")) | V25: =IF(OR($AJ25="",$AJ25=0,$AL25<>"بدهکار"),"",$AJ25) | W25: =IF(OR($AJ25="",$AJ25=0,$AL25<>"بستانکار"),"",$AJ25) | X25: =IF($E25="","",IFERROR(VLOOKUP($E25,OpTbl,8,0),"")) | Y25: =IF(OR($X25="",$AJ25="",$AJ25=0,$AM25<>"بدهکار"),"",$AJ25) | Z25: =IF(OR($X25="",$AJ25="",$AJ25=0,$AM25<>"بستانکار"),"",$AJ25) | AA25: =IF(OR($E25="",$AN25="—",$AN25=""),"",IFERROR(VLOOKUP($E25,OpTbl,12,0),"")) | AB25: =IF(OR($AA25="",$Q25="",$Q25=0,$AN25<>"بدهکار"),"",$Q25) | AC25: =IF(OR($AA25="",$Q25="",$Q25=0,$AN25<>"بستانکار"),"",$Q25) | AD25: =IF($AA25="","",IFERROR(VLOOKUP($E25,OpTbl,13,0),"")) | AE25: =IF(OR($AD25="",$Q25="",$Q25=0,$AN25<>"بستانکار"),"",$Q25) | AF25: =IF(OR($AD25="",$Q25="",$Q25=0,$AN25<>"بدهکار"),"",$Q25) | AG25: =SUM($V25,$Y25,$AB25,$AE25) | AH25: =SUM($W25,$Z25,$AC25,$AF25) | AI25: =IF($E25="","",IF(ROUND($AG25-$AH25,0)=0,"✓","⚠")) | AJ25: =IF(OR($E25="",$U25=""),"",IFERROR(IF(VLOOKUP($E25,OpTbl,6,0)="وزن",IF($P25="",0,$P25),IF(VLOOKUP($E25,OpTbl,6,0)="مبلغ",IF(AND($Q25<>"",$Q25<>0),$Q25,$P25),0))+IF(VLOOKUP($E25,OpTbl,10,0)="افزودن",IF($Q25="",0,$Q25),0),0)) | AK25: =IF($E25="","",IFERROR(VLOOKUP($E25,OpTbl,10,0),"")) | AL25: =IF(OR($E25="",$U25=""),"",IFERROR(IF(VLOOKUP($E25,OpTbl,7,0)="خودکار",$R25,VLOOKUP($E25,OpTbl,7,0)),"")) | AM25: =IF(OR($E25="",$X25=""),"",IFERROR(IF(VLOOKUP($E25,OpTbl,9,0)="خودکار",IF($AL25="بدهکار","بستانکار",IF($AL25="بستانکار","بدهکار","")),VLOOKUP($E25,OpTbl,9,0)),"")) | AN25: =IF($E25="","",IFERROR(VLOOKUP($E25,OpTbl,11,0),"")) | AO25: =IF($B25="","",MID($B25,6,2)) | AP25: =IF($B25="",0,1)
A26: =IF($B26="","",COUNTA($B$10:$B26)) | B26: 1405/07/11 | C26: 10:05 | D26: BS-017 | E26: درآمد پوز باسکول (بدون طرف) | F26: =IF($E26="","",IFERROR(VLOOKUP($E26,OpTbl,2,0),"")) | H26: =IF($U26="","",IFERROR(VLOOKUP($U26,AcctTbl,2,0),"کد ناشناخته")) | I26: =IF($U26="","",IFERROR(VLOOKUP($U26,AcctTbl,3,0),"")) | L26: 0 | M26: 0 | N26: =IF(OR($E26="",$L26=""),"",IFERROR(($L26-IF($M26="",0,$M26)*IFERROR(VLOOKUP($K26,BasketTbl,4,0),IFERROR(INDEX(BasketTbl,MATCH($K26,BasketCodeCol,0),4),VLOOKUP("P01",ParamTbl,2,0))))*(1-IF(VLOOKUP($E26,OpTbl,3,0)="خرید",VLOOKUP("P02",ParamTbl,2,0),0)/100),"")) | O26: 0 | P26: =IF(OR($E26="",$L26=""),"",IFERROR(IF(VLOOKUP($E26,OpTbl,6,0)="وزن",ROUND($N26*$O26,-3),IF(VLOOKUP($E26,OpTbl,6,0)="مبلغ",ROUND($L26*$O26,-3),0)),"")) | Q26: 300000 | S26: =IF($E26="","",IF($AI26="⚠","⚠ ناتراز",IF(AND(IFERROR(VLOOKUP($E26,OpTbl,4,0),"")="بله",$L26=""),"⚠ وزن",IF(AND(IFERROR(VLOOKUP($E26,OpTbl,5,0),"")="بله",$U26=""),"⚠ حساب",IF(AND(IFERROR(VLOOKUP($E26,OpTbl,6,0),"")="مبلغ",$Q26=""),"⚠ مبلغ","✓"))))) | T26: هزینه باسکول نقدی | U26: =IF($E26="","",IFERROR(IF(VLOOKUP($E26,OpTbl,14,0)<>"",VLOOKUP($E26,OpTbl,14,0),$G26),"")) | V26: =IF(OR($AJ26="",$AJ26=0,$AL26<>"بدهکار"),"",$AJ26) | W26: =IF(OR($AJ26="",$AJ26=0,$AL26<>"بستانکار"),"",$AJ26) | X26: =IF($E26="","",IFERROR(VLOOKUP($E26,OpTbl,8,0),"")) | Y26: =IF(OR($X26="",$AJ26="",$AJ26=0,$AM26<>"بدهکار"),"",$AJ26) | Z26: =IF(OR($X26="",$AJ26="",$AJ26=0,$AM26<>"بستانکار"),"",$AJ26) | AA26: =IF(OR($E26="",$AN26="—",$AN26=""),"",IFERROR(VLOOKUP($E26,OpTbl,12,0),"")) | AB26: =IF(OR($AA26="",$Q26="",$Q26=0,$AN26<>"بدهکار"),"",$Q26) | AC26: =IF(OR($AA26="",$Q26="",$Q26=0,$AN26<>"بستانکار"),"",$Q26) | AD26: =IF($AA26="","",IFERROR(VLOOKUP($E26,OpTbl,13,0),"")) | AE26: =IF(OR($AD26="",$Q26="",$Q26=0,$AN26<>"بستانکار"),"",$Q26) | AF26: =IF(OR($AD26="",$Q26="",$Q26=0,$AN26<>"بدهکار"),"",$Q26) | AG26: =SUM($V26,$Y26,$AB26,$AE26) | AH26: =SUM($W26,$Z26,$AC26,$AF26) | AI26: =IF($E26="","",IF(ROUND($AG26-$AH26,0)=0,"✓","⚠")) | AJ26: =IF(OR($E26="",$U26=""),"",IFERROR(IF(VLOOKUP($E26,OpTbl,6,0)="وزن",IF($P26="",0,$P26),IF(VLOOKUP($E26,OpTbl,6,0)="مبلغ",IF(AND($Q26<>"",$Q26<>0),$Q26,$P26),0))+IF(VLOOKUP($E26,OpTbl,10,0)="افزودن",IF($Q26="",0,$Q26),0),0)) | AK26: =IF($E26="","",IFERROR(VLOOKUP($E26,OpTbl,10,0),"")) | AL26: =IF(OR($E26="",$U26=""),"",IFERROR(IF(VLOOKUP($E26,OpTbl,7,0)="خودکار",$R26,VLOOKUP($E26,OpTbl,7,0)),"")) | AM26: =IF(OR($E26="",$X26=""),"",IFERROR(IF(VLOOKUP($E26,OpTbl,9,0)="خودکار",IF($AL26="بدهکار","بستانکار",IF($AL26="بستانکار","بدهکار","")),VLOOKUP($E26,OpTbl,9,0)),"")) | AN26: =IF($E26="","",IFERROR(VLOOKUP($E26,OpTbl,11,0),"")) | AO26: =IF($B26="","",MID($B26,6,2)) | AP26: =IF($B26="",0,1)
A27: =IF($B27="","",COUNTA($B$10:$B27)) | B27: 1405/07/12 | C27: 08:45 | D27: BS-018 | E27: خرید مرکبات | F27: =IF($E27="","",IFERROR(VLOOKUP($E27,OpTbl,2,0),"")) | G27: C011 | H27: =IF($U27="","",IFERROR(VLOOKUP($U27,AcctTbl,2,0),"کد ناشناخته")) | I27: =IF($U27="","",IFERROR(VLOOKUP($U27,AcctTbl,3,0),"")) | J27: پرتقال بیروتی | K27: BK01 – ۶ک مشکی | L27: 1200 | M27: 72 | N27: =IF(OR($E27="",$L27=""),"",IFERROR(($L27-IF($M27="",0,$M27)*IFERROR(VLOOKUP($K27,BasketTbl,4,0),IFERROR(INDEX(BasketTbl,MATCH($K27,BasketCodeCol,0),4),VLOOKUP("P01",ParamTbl,2,0))))*(1-IF(VLOOKUP($E27,OpTbl,3,0)="خرید",VLOOKUP("P02",ParamTbl,2,0),0)/100),"")) | O27: 34000 | P27: =IF(OR($E27="",$L27=""),"",IFERROR(IF(VLOOKUP($E27,OpTbl,6,0)="وزن",ROUND($N27*$O27,-3),IF(VLOOKUP($E27,OpTbl,6,0)="مبلغ",ROUND($L27*$O27,-3),0)),"")) | Q27: 0 | S27: =IF($E27="","",IF($AI27="⚠","⚠ ناتراز",IF(AND(IFERROR(VLOOKUP($E27,OpTbl,4,0),"")="بله",$L27=""),"⚠ وزن",IF(AND(IFERROR(VLOOKUP($E27,OpTbl,5,0),"")="بله",$U27=""),"⚠ حساب",IF(AND(IFERROR(VLOOKUP($E27,OpTbl,6,0),"")="مبلغ",$Q27=""),"⚠ مبلغ","✓"))))) | U27: =IF($E27="","",IFERROR(IF(VLOOKUP($E27,OpTbl,14,0)<>"",VLOOKUP($E27,OpTbl,14,0),$G27),"")) | V27: =IF(OR($AJ27="",$AJ27=0,$AL27<>"بدهکار"),"",$AJ27) | W27: =IF(OR($AJ27="",$AJ27=0,$AL27<>"بستانکار"),"",$AJ27) | X27: =IF($E27="","",IFERROR(VLOOKUP($E27,OpTbl,8,0),"")) | Y27: =IF(OR($X27="",$AJ27="",$AJ27=0,$AM27<>"بدهکار"),"",$AJ27) | Z27: =IF(OR($X27="",$AJ27="",$AJ27=0,$AM27<>"بستانکار"),"",$AJ27) | AA27: =IF(OR($E27="",$AN27="—",$AN27=""),"",IFERROR(VLOOKUP($E27,OpTbl,12,0),"")) | AB27: =IF(OR($AA27="",$Q27="",$Q27=0,$AN27<>"بدهکار"),"",$Q27) | AC27: =IF(OR($AA27="",$Q27="",$Q27=0,$AN27<>"بستانکار"),"",$Q27) | AD27: =IF($AA27="","",IFERROR(VLOOKUP($E27,OpTbl,13,0),"")) | AE27: =IF(OR($AD27="",$Q27="",$Q27=0,$AN27<>"بستانکار"),"",$Q27) | AF27: =IF(OR($AD27="",$Q27="",$Q27=0,$AN27<>"بدهکار"),"",$Q27) | AG27: =SUM($V27,$Y27,$AB27,$AE27) | AH27: =SUM($W27,$Z27,$AC27,$AF27) | AI27: =IF($E27="","",IF(ROUND($AG27-$AH27,0)=0,"✓","⚠")) | AJ27: =IF(OR($E27="",$U27=""),"",IFERROR(IF(VLOOKUP($E27,OpTbl,6,0)="وزن",IF($P27="",0,$P27),IF(VLOOKUP($E27,OpTbl,6,0)="مبلغ",IF(AND($Q27<>"",$Q27<>0),$Q27,$P27),0))+IF(VLOOKUP($E27,OpTbl,10,0)="افزودن",IF($Q27="",0,$Q27),0),0)) | AK27: =IF($E27="","",IFERROR(VLOOKUP($E27,OpTbl,10,0),"")) | AL27: =IF(OR($E27="",$U27=""),"",IFERROR(IF(VLOOKUP($E27,OpTbl,7,0)="خودکار",$R27,VLOOKUP($E27,OpTbl,7,0)),"")) | AM27: =IF(OR($E27="",$X27=""),"",IFERROR(IF(VLOOKUP($E27,OpTbl,9,0)="خودکار",IF($AL27="بدهکار","بستانکار",IF($AL27="بستانکار","بدهکار","")),VLOOKUP($E27,OpTbl,9,0)),"")) | AN27: =IF($E27="","",IFERROR(VLOOKUP($E27,OpTbl,11,0),"")) | AO27: =IF($B27="","",MID($B27,6,2)) | AP27: =IF($B27="",0,1)
A28: =IF($B28="","",COUNTA($B$10:$B28)) | F28: =IF($E28="","",IFERROR(VLOOKUP($E28,OpTbl,2,0),"")) | H28: =IF($U28="","",IFERROR(VLOOKUP($U28,AcctTbl,2,0),"کد ناشناخته")) | I28: =IF($U28="","",IFERROR(VLOOKUP($U28,AcctTbl,3,0),"")) | N28: =IF(OR($E28="",$L28=""),"",IFERROR(($L28-IF($M28="",0,$M28)*IFERROR(VLOOKUP($K28,BasketTbl,4,0),IFERROR(INDEX(BasketTbl,MATCH($K28,BasketCodeCol,0),4),VLOOKUP("P01",ParamTbl,2,0))))*(1-IF(VLOOKUP($E28,OpTbl,3,0)="خرید",VLOOKUP("P02",ParamTbl,2,0),0)/100),"")) | P28: =IF(OR($E28="",$L28=""),"",IFERROR(IF(VLOOKUP($E28,OpTbl,6,0)="وزن",ROUND($N28*$O28,-3),IF(VLOOKUP($E28,OpTbl,6,0)="مبلغ",ROUND($L28*$O28,-3),0)),"")) | S28: =IF($E28="","",IF($AI28="⚠","⚠ ناتراز",IF(AND(IFERROR(VLOOKUP($E28,OpTbl,4,0),"")="بله",$L28=""),"⚠ وزن",IF(AND(IFERROR(VLOOKUP($E28,OpTbl,5,0),"")="بله",$U28=""),"⚠ حساب",IF(AND(IFERROR(VLOOKUP($E28,OpTbl,6,0),"")="مبلغ",$Q28=""),"⚠ مبلغ","✓"))))) | U28: =IF($E28="","",IFERROR(IF(VLOOKUP($E28,OpTbl,14,0)<>"",VLOOKUP($E28,OpTbl,14,0),$G28),"")) | V28: =IF(OR($AJ28="",$AJ28=0,$AL28<>"بدهکار"),"",$AJ28) | W28: =IF(OR($AJ28="",$AJ28=0,$AL28<>"بستانکار"),"",$AJ28) | X28: =IF($E28="","",IFERROR(VLOOKUP($E28,OpTbl,8,0),"")) | Y28: =IF(OR($X28="",$AJ28="",$AJ28=0,$AM28<>"بدهکار"),"",$AJ28) | Z28: =IF(OR($X28="",$AJ28="",$AJ28=0,$AM28<>"بستانکار"),"",$AJ28) | AA28: =IF(OR($E28="",$AN28="—",$AN28=""),"",IFERROR(VLOOKUP($E28,OpTbl,12,0),"")) | AB28: =IF(OR($AA28="",$Q28="",$Q28=0,$AN28<>"بدهکار"),"",$Q28) | AC28: =IF(OR($AA28="",$Q28="",$Q28=0,$AN28<>"بستانکار"),"",$Q28) | AD28: =IF($AA28="","",IFERROR(VLOOKUP($E28,OpTbl,13,0),"")) | AE28: =IF(OR($AD28="",$Q28="",$Q28=0,$AN28<>"بستانکار"),"",$Q28) | AF28: =IF(OR($AD28="",$Q28="",$Q28=0,$AN28<>"بدهکار"),"",$Q28) | AG28: =SUM($V28,$Y28,$AB28,$AE28) | AH28: =SUM($W28,$Z28,$AC28,$AF28) | AI28: =IF($E28="","",IF(ROUND($AG28-$AH28,0)=0,"✓","⚠")) | AJ28: =IF(OR($E28="",$U28=""),"",IFERROR(IF(VLOOKUP($E28,OpTbl,6,0)="وزن",IF($P28="",0,$P28),IF(VLOOKUP($E28,OpTbl,6,0)="مبلغ",IF(AND($Q28<>"",$Q28<>0),$Q28,$P28),0))+IF(VLOOKUP($E28,OpTbl,10,0)="افزودن",IF($Q28="",0,$Q28),0),0)) | AK28: =IF($E28="","",IFERROR(VLOOKUP($E28,OpTbl,10,0),"")) | AL28: =IF(OR($E28="",$U28=""),"",IFERROR(IF(VLOOKUP($E28,OpTbl,7,0)="خودکار",$R28,VLOOKUP($E28,OpTbl,7,0)),"")) | AM28: =IF(OR($E28="",$X28=""),"",IFERROR(IF(VLOOKUP($E28,OpTbl,9,0)="خودکار",IF($AL28="بدهکار","بستانکار",IF($AL28="بستانکار","بدهکار","")),VLOOKUP($E28,OpTbl,9,0)),"")) | AN28: =IF($E28="","",IFERROR(VLOOKUP($E28,OpTbl,11,0),"")) | AO28: =IF($B28="","",MID($B28,6,2)) | AP28: =IF($B28="",0,1)
