Workbook
Name AcctTbl: Sync!$H$10:$L$259
Name BankAccts: Sync!$D$10:$D$19
Name BankOpTbl: Sync!$N$10:$S$27
Name BankTbl: Sync!$A$10:$F$19
Name ListAllCodes: Sync!$H$10:$H$259
Name ListBankOps: Sync!$N$10:$N$27
Name ListBanks: Sync!$A$10:$A$19
Name ListChequeStatus: Sync!$U$10:$U$13
Name ListChequeTypes: Sync!$X$10:$X$11
Name ListGroups: Sync!$W$10:$W$33
Name ListOtherScales: Sync!$V$10:$V$29
Name ListPayMethods: Sync!$T$10:$T$14

Sheet Home
A2: مازندشت · سورتینگ و بسته‌بندی مرکبات · MAZANDASHT · CITRUS SORTING & PACKING
A3: فایل تراکنش‌های بانکی
A4: ثبت، کنترل و تحلیل گردش حساب‌های شرکت · همه کشوها از فایل مادر تعریف شده‌اند
A7: تراکنش‌ها | D7: دریافت | F7: پرداخت | H7: مانده بانک‌ها
A8: =COUNTA(Txn!$B$13:$B$152) -> 0 | D8: =SUM(Txn!$O$13:$O$152) -> 0 | F8: =SUM(Txn!$P$13:$P$152) -> 0 | H8: =SUM(Sum!$E$12:$E$21) -> 0
A9: شیت‌های این فایل روی هر کارت کلیک کنید | H9: ۰۱
A10: تراکنش‌ها Txn | D10: مانده بانک‌ها Sum | G10: جریان نقدی Flow
A11: ثبت تراکنش با کشوی بانک، کد طرف حساب و انتقال داخلی | D11: مانده هر حساب + نمودار مقایسه بانک‌ها | G11: دریافت/پرداخت ماهانه با نمودار ترکیبی
A13: تحلیل Anal | D13: کارت/پوز Card | G13: چک‌ها Chq
A14: بر پایه نوع عملیات، روش پرداخت و طرف حساب | D14: کارت‌به‌کارت و پز باسکول به تفکیک بانک | G14: سررسید، وضعیت و مبلغ چک‌های دریافتی/پرداختی
A22: گردش کار روزانه پنج گام ساده | H22: ۰۲
A23: ۱ | B23: صورت‌حساب بانک را باز کنید؛ هر ردیف را در شیت Txn ثبت کنید.
A24: ۲ | B24: نوع عملیات را انتخاب کنید؛ جهت بدهکار/بستانکار خودکار تعیین می‌شود.
A25: ۳ | B25: بانک عامل را از کشو بزنید و کد طرف حساب را تایپ کنید (نام خودکار می‌آید).
A26: ۴ | B26: اگر پول بین دو حساب خودمان جابه‌جا شده، «انتقال داخلی» را بزنید و بانک مقصد را هم انتخاب کنید.
A27: ۵ | B27: آخر روز شیت Sum و Card را ببینید؛ اگر همه ردیف‌ها ✓ بودند، فایل‌های گزارش را باز کنید.
A29: قاعده طلایی: هر بانکی که در فهرست بانک‌های شرکت نیست، اجازه ثبت ندارد. اگر حساب جدیدی باز کردید، اول آن را در فایل مادر (شیت Bnk) اضافه کنید و بعد این فایل را باز کنید.

Sheet Txn
A2: مازندشت · سورتینگ و بسته‌بندی مرکبات · MAZANDASHT · CITRUS SORTING & PACKING
A3: تراکنش‌های بانکی — ثبت، کنترل و ردیابی
A4: بانک عامل را از کشو انتخاب کنید · کد طرف حساب را تایپ کنید · انتقال داخلی: بانک مبدأ و مقصد
A7: تعداد تراکنش | E7: جمع دریافت | I7: جمع پرداخت | M7: مانده جریان | Q7: ردیف‌های ناقص
A8: =COUNTA($B$13:$B$152) -> 0 | E8: =SUM($O$13:$O$152) -> 0 | I8: =SUM($P$13:$P$152) -> 0 | M8: =SUM($O$13:$O$152)-SUM($P$13:$P$152) -> 0 | Q8: =COUNTIF($S$13:$S$152,"⚠*") -> 0
A9: بانک عامل همیشه از فهرست بانک‌های شرکت انتخاب می‌شود. ستون‌های خاکستری خودکارند و دست نزنید. برای انتقال داخلی، بانک مقصد را هم انتخاب کنید تا پول از یک حساب کم و به حساب دیگر اضافه شود.
A11: دفتر تراکنش‌ها هر ردیف یک تراکنش بانکی | S11: ۰۱
A12: ردیف No. | B12: تاریخ Date | C12: شماره سند Doc | D12: نوع عملیات Operation | E12: بانک عامل Company bank | F12: بانک مقصد Destination | G12: روش Method | H12: کد طرف حساب Party code | I12: نام طرف حساب Party name | J12: گروه Group | K12: شرح Description | L12: شماره پیگیری / چک Ref / Cheque | M12: مبلغ (ریال) Amount | N12: شخص باسکول دیگران Other scale | O12: بدهکار بانک Bank Dr | P12: بستانکار بانک Bank Cr | Q12: بدهکار طرف Party Dr | R12: بستانکار طرف Party Cr | S12: وضعیت Status | T12: یادداشت Note
A13: =IF($B13="","",COUNTA($B$13:$B13)) -> 0 | B13: 1405/07/03 | C13: JB-BS-006 | D13: واریز پز باسکول (۲۰۰۶) | E13: BN02 | G13: کارت/پوز | I13: =IF($H13="","",IFERROR(VLOOKUP($H13,AcctTbl,2,0),"کد ناشناخته")) -> 0 | J13: =IF($H13="","",IFERROR(VLOOKUP($H13,AcctTbl,3,0),"")) -> 0 | K13: پوز باسکول — فروش بار (بارفروش) | L13: JB-BS-006 | M13: 120000 | O13: =IF($B13="",0,IF($U13="IN",N($M13),0)) -> 0 | P13: =IF($B13="",0,IF(OR($U13="OUT",$U13="TRF"),N($M13),0)) -> 0 | Q13: =IF($B13="",0,IF(OR($U13="OUT",$U13="TRF"),N($M13),0)) -> 0 | R13: =IF($B13="",0,IF($U13="IN",N($M13),0)) -> 0 | S13: =IF($B13="","",IF($M13="","⚠ مبلغ",IF($E13="","⚠ بانک عامل",IF(AND($U13="TRF",$F13=""),"⚠ بانک مقصد",IF(AND($V13<>"NONE",$V13<>"",$Z13=""),"⚠ طرف حساب","✓"))))) -> 0 | U13: =IFERROR(VLOOKUP($D13,BankOpTbl,2,0),"") -> 0 | V13: =IFERROR(VLOOKUP($D13,BankOpTbl,3,0),"") -> 0 | W13: =IFERROR(VLOOKUP($D13,BankOpTbl,4,0),"") -> 0 | X13: =IF($E13="","",IFERROR(VLOOKUP($E13,BankTbl,4,0),"")) -> 0 | Y13: =IF($F13="","",IFERROR(VLOOKUP($F13,BankTbl,4,0),"")) -> 0 | Z13: =IF($B13="","",IF($V13="PICK",LEFT($N13,5),IF($V13="FIXED",$W13,IF($V13="CODE",$H13,"")))) -> 0
A14: =IF($B14="","",COUNTA($B$13:$B14)) -> 0 | B14: 1405/07/04 | C14: JB-BS-008 | D14: واریز پز باسکول (۲۰۰۶) | E14: BN02 | G14: کارت/پوز | I14: =IF($H14="","",IFERROR(VLOOKUP($H14,AcctTbl,2,0),"کد ناشناخته")) -> 0 | J14: =IF($H14="","",IFERROR(VLOOKUP($H14,AcctTbl,3,0),"")) -> 0 | K14: پوز باسکول — فروش بار (بارفروش) | L14: JB-BS-008 | M14: 90000 | O14: =IF($B14="",0,IF($U14="IN",N($M14),0)) -> 0 | P14: =IF($B14="",0,IF(OR($U14="OUT",$U14="TRF"),N($M14),0)) -> 0 | Q14: =IF($B14="",0,IF(OR($U14="OUT",$U14="TRF"),N($M14),0)) -> 0 | R14: =IF($B14="",0,IF($U14="IN",N($M14),0)) -> 0 | S14: =IF($B14="","",IF($M14="","⚠ مبلغ",IF($E14="","⚠ بانک عامل",IF(AND($U14="TRF",$F14=""),"⚠ بانک مقصد",IF(AND($V14<>"NONE",$V14<>"",$Z14=""),"⚠ طرف حساب","✓"))))) -> 0 | U14: =IFERROR(VLOOKUP($D14,BankOpTbl,2,0),"") -> 0 | V14: =IFERROR(VLOOKUP($D14,BankOpTbl,3,0),"") -> 0 | W14: =IFERROR(VLOOKUP($D14,BankOpTbl,4,0),"") -> 0 | X14: =IF($E14="","",IFERROR(VLOOKUP($E14,BankTbl,4,0),"")) -> 0 | Y14: =IF($F14="","",IFERROR(VLOOKUP($F14,BankTbl,4,0),"")) -> 0 | Z14: =IF($B14="","",IF($V14="PICK",LEFT($N14,5),IF($V14="FIXED",$W14,IF($V14="CODE",$H14,"")))) -> 0
A15: =IF($B15="","",COUNTA($B$13:$B15)) -> 0 | B15: 1405/07/05 | C15: JB-BS-010 | D15: تسویه پرداخت (واسط) | E15: BN02 | G15: انتقال بانکی | I15: =IF($H15="","",IFERROR(VLOOKUP($H15,AcctTbl,2,0),"کد ناشناخته")) -> 0 | J15: =IF($H15="","",IFERROR(VLOOKUP($H15,AcctTbl,3,0),"")) -> 0 | K15: انعام از پوز باسکول | L15: JB-BS-010 | M15: 500000 | O15: =IF($B15="",0,IF($U15="IN",N($M15),0)) -> 0 | P15: =IF($B15="",0,IF(OR($U15="OUT",$U15="TRF"),N($M15),0)) -> 0 | Q15: =IF($B15="",0,IF(OR($U15="OUT",$U15="TRF"),N($M15),0)) -> 0 | R15: =IF($B15="",0,IF($U15="IN",N($M15),0)) -> 0 | S15: =IF($B15="","",IF($M15="","⚠ مبلغ",IF($E15="","⚠ بانک عامل",IF(AND($U15="TRF",$F15=""),"⚠ بانک مقصد",IF(AND($V15<>"NONE",$V15<>"",$Z15=""),"⚠ طرف حساب","✓"))))) -> 0 | U15: =IFERROR(VLOOKUP($D15,BankOpTbl,2,0),"") -> 0 | V15: =IFERROR(VLOOKUP($D15,BankOpTbl,3,0),"") -> 0 | W15: =IFERROR(VLOOKUP($D15,BankOpTbl,4,0),"") -> 0 | X15: =IF($E15="","",IFERROR(VLOOKUP($E15,BankTbl,4,0),"")) -> 0 | Y15: =IF($F15="","",IFERROR(VLOOKUP($F15,BankTbl,4,0),"")) -> 0 | Z15: =IF($B15="","",IF($V15="PICK",LEFT($N15,5),IF($V15="FIXED",$W15,IF($V15="CODE",$H15,"")))) -> 0
A16: =IF($B16="","",COUNTA($B$13:$B16)) -> 0 | B16: 1405/07/06 | C16: JB-RV-001 | D16: تسویه دریافت (واسط) | E16: BN01 | G16: انتقال بانکی | I16: =IF($H16="","",IFERROR(VLOOKUP($H16,AcctTbl,2,0),"کد ناشناخته")) -> 0 | J16: =IF($H16="","",IFERROR(VLOOKUP($H16,AcctTbl,3,0),"")) -> 0 | K16: تسویه بار | L16: JB-RV-001 | M16: 300000000 | O16: =IF($B16="",0,IF($U16="IN",N($M16),0)) -> 0 | P16: =IF($B16="",0,IF(OR($U16="OUT",$U16="TRF"),N($M16),0)) -> 0 | Q16: =IF($B16="",0,IF(OR($U16="OUT",$U16="TRF"),N($M16),0)) -> 0 | R16: =IF($B16="",0,IF($U16="IN",N($M16),0)) -> 0 | S16: =IF($B16="","",IF($M16="","⚠ مبلغ",IF($E16="","⚠ بانک عامل",IF(AND($U16="TRF",$F16=""),"⚠ بانک مقصد",IF(AND($V16<>"NONE",$V16<>"",$Z16=""),"⚠ طرف حساب","✓"))))) -> 0 | U16: =IFERROR(VLOOKUP($D16,BankOpTbl,2,0),"") -> 0 | V16: =IFERROR(VLOOKUP($D16,BankOpTbl,3,0),"") -> 0 | W16: =IFERROR(VLOOKUP($D16,BankOpTbl,4,0),"") -> 0 | X16: =IF($E16="","",IFERROR(VLOOKUP($E16,BankTbl,4,0),"")) -> 0 | Y16: =IF($F16="","",IFERROR(VLOOKUP($F16,BankTbl,4,0),"")) -> 0 | Z16: =IF($B16="","",IF($V16="PICK",LEFT($N16,5),IF($V16="FIXED",$W16,IF($V16="CODE",$H16,"")))) -> 0
A17: =IF($B17="","",COUNTA($B$13:$B17)) -> 0 | B17: 1405/07/08 | C17: JB-PV-003 | D17: تسویه پرداخت (واسط) | E17: BN02 | G17: انتقال بانکی | I17: =IF($H17="","",IFERROR(VLOOKUP($H17,AcctTbl,2,0),"کد ناشناخته")) -> 0 | J17: =IF($H17="","",IFERROR(VLOOKUP($H17,AcctTbl,3,0),"")) -> 0 | K17: پرداخت از واسط | L17: JB-PV-003 | M17: 80000000 | O17: =IF($B17="",0,IF($U17="IN",N($M17),0)) -> 0 | P17: =IF($B17="",0,IF(OR($U17="OUT",$U17="TRF"),N($M17),0)) -> 0 | Q17: =IF($B17="",0,IF(OR($U17="OUT",$U17="TRF"),N($M17),0)) -> 0 | R17: =IF($B17="",0,IF($U17="IN",N($M17),0)) -> 0 | S17: =IF($B17="","",IF($M17="","⚠ مبلغ",IF($E17="","⚠ بانک عامل",IF(AND($U17="TRF",$F17=""),"⚠ بانک مقصد",IF(AND($V17<>"NONE",$V17<>"",$Z17=""),"⚠ طرف حساب","✓"))))) -> 0 | U17: =IFERROR(VLOOKUP($D17,BankOpTbl,2,0),"") -> 0 | V17: =IFERROR(VLOOKUP($D17,BankOpTbl,3,0),"") -> 0 | W17: =IFERROR(VLOOKUP($D17,BankOpTbl,4,0),"") -> 0 | X17: =IF($E17="","",IFERROR(VLOOKUP($E17,BankTbl,4,0),"")) -> 0 | Y17: =IF($F17="","",IFERROR(VLOOKUP($F17,BankTbl,4,0),"")) -> 0 | Z17: =IF($B17="","",IF($V17="PICK",LEFT($N17,5),IF($V17="FIXED",$W17,IF($V17="CODE",$H17,"")))) -> 0
A18: =IF($B18="","",COUNTA($B$13:$B18)) -> 0 | B18: 1405/07/09 | C18: JB-RV-002 | D18: تسویه دریافت (واسط) | E18: BN02 | G18: انتقال بانکی | I18: =IF($H18="","",IFERROR(VLOOKUP($H18,AcctTbl,2,0),"کد ناشناخته")) -> 0 | J18: =IF($H18="","",IFERROR(VLOOKUP($H18,AcctTbl,3,0),"")) -> 0 | K18: واریز از واسط | L18: JB-RV-002 | M18: 120000000 | O18: =IF($B18="",0,IF($U18="IN",N($M18),0)) -> 0 | P18: =IF($B18="",0,IF(OR($U18="OUT",$U18="TRF"),N($M18),0)) -> 0 | Q18: =IF($B18="",0,IF(OR($U18="OUT",$U18="TRF"),N($M18),0)) -> 0 | R18: =IF($B18="",0,IF($U18="IN",N($M18),0)) -> 0 | S18: =IF($B18="","",IF($M18="","⚠ مبلغ",IF($E18="","⚠ بانک عامل",IF(AND($U18="TRF",$F18=""),"⚠ بانک مقصد",IF(AND($V18<>"NONE",$V18<>"",$Z18=""),"⚠ طرف حساب","✓"))))) -> 0 | U18: =IFERROR(VLOOKUP($D18,BankOpTbl,2,0),"") -> 0 | V18: =IFERROR(VLOOKUP($D18,BankOpTbl,3,0),"") -> 0 | W18: =IFERROR(VLOOKUP($D18,BankOpTbl,4,0),"") -> 0 | X18: =IF($E18="","",IFERROR(VLOOKUP($E18,BankTbl,4,0),"")) -> 0 | Y18: =IF($F18="","",IFERROR(VLOOKUP($F18,BankTbl,4,0),"")) -> 0 | Z18: =IF($B18="","",IF($V18="PICK",LEFT($N18,5),IF($V18="FIXED",$W18,IF($V18="CODE",$H18,"")))) -> 0
A19: =IF($B19="","",COUNTA($B$13:$B19)) -> 0 | B19: 1405/07/09 | C19: JB-BS-015 | D19: واریز پز باسکول (۲۰۰۶) | E19: BN02 | G19: کارت/پوز | I19: =IF($H19="","",IFERROR(VLOOKUP($H19,AcctTbl,2,0),"کد ناشناخته")) -> 0 | J19: =IF($H19="","",IFERROR(VLOOKUP($H19,AcctTbl,3,0),"")) -> 0 | K19: پوز باسکول — فروش بار (بارفروش) | L19: JB-BS-015 | M19: 80000 | O19: =IF($B19="",0,IF($U19="IN",N($M19),0)) -> 0 | P19: =IF($B19="",0,IF(OR($U19="OUT",$U19="TRF"),N($M19),0)) -> 0 | Q19: =IF($B19="",0,IF(OR($U19="OUT",$U19="TRF"),N($M19),0)) -> 0 | R19: =IF($B19="",0,IF($U19="IN",N($M19),0)) -> 0 | S19: =IF($B19="","",IF($M19="","⚠ مبلغ",IF($E19="","⚠ بانک عامل",IF(AND($U19="TRF",$F19=""),"⚠ بانک مقصد",IF(AND($V19<>"NONE",$V19<>"",$Z19=""),"⚠ طرف حساب","✓"))))) -> 0 | U19: =IFERROR(VLOOKUP($D19,BankOpTbl,2,0),"") -> 0 | V19: =IFERROR(VLOOKUP($D19,BankOpTbl,3,0),"") -> 0 | W19: =IFERROR(VLOOKUP($D19,BankOpTbl,4,0),"") -> 0 | X19: =IF($E19="","",IFERROR(VLOOKUP($E19,BankTbl,4,0),"")) -> 0 | Y19: =IF($F19="","",IFERROR(VLOOKUP($F19,BankTbl,4,0),"")) -> 0 | Z19: =IF($B19="","",IF($V19="PICK",LEFT($N19,5),IF($V19="FIXED",$W19,IF($V19="CODE",$H19,"")))) -> 0
A20: =IF($B20="","",COUNTA($B$13:$B20)) -> 0 | B20: 1405/07/10 | C20: JB-PV-004 | D20: تسویه پرداخت (واسط) | E20: BN01 | G20: انتقال بانکی | I20: =IF($H20="","",IFERROR(VLOOKUP($H20,AcctTbl,2,0),"کد ناشناخته")) -> 0 | J20: =IF($H20="","",IFERROR(VLOOKUP($H20,AcctTbl,3,0),"")) -> 0 | K20: پاس شدن چک | L20: JB-PV-004 | M20: 200000000 | O20: =IF($B20="",0,IF($U20="IN",N($M20),0)) -> 0 | P20: =IF($B20="",0,IF(OR($U20="OUT",$U20="TRF"),N($M20),0)) -> 0 | Q20: =IF($B20="",0,IF(OR($U20="OUT",$U20="TRF"),N($M20),0)) -> 0 | R20: =IF($B20="",0,IF($U20="IN",N($M20),0)) -> 0 | S20: =IF($B20="","",IF($M20="","⚠ مبلغ",IF($E20="","⚠ بانک عامل",IF(AND($U20="TRF",$F20=""),"⚠ بانک مقصد",IF(AND($V20<>"NONE",$V20<>"",$Z20=""),"⚠ طرف حساب","✓"))))) -> 0 | U20: =IFERROR(VLOOKUP($D20,BankOpTbl,2,0),"") -> 0 | V20: =IFERROR(VLOOKUP($D20,BankOpTbl,3,0),"") -> 0 | W20: =IFERROR(VLOOKUP($D20,BankOpTbl,4,0),"") -> 0 | X20: =IF($E20="","",IFERROR(VLOOKUP($E20,BankTbl,4,0),"")) -> 0 | Y20: =IF($F20="","",IFERROR(VLOOKUP($F20,BankTbl,4,0),"")) -> 0 | Z20: =IF($B20="","",IF($V20="PICK",LEFT($N20,5),IF($V20="FIXED",$W20,IF($V20="CODE",$H20,"")))) -> 0
A21: =IF($B21="","",COUNTA($B$13:$B21)) -> 0 | B21: 1405/07/11 | C21: JB-RV-003 | D21: تسویه دریافت (واسط) | E21: BN02 | G21: انتقال بانکی | I21: =IF($H21="","",IFERROR(VLOOKUP($H21,AcctTbl,2,0),"کد ناشناخته")) -> 0 | J21: =IF($H21="","",IFERROR(VLOOKUP($H21,AcctTbl,3,0),"")) -> 0 | K21: واریز از واسط | L21: JB-RV-003 | M21: 100000000 | O21: =IF($B21="",0,IF($U21="IN",N($M21),0)) -> 0 | P21: =IF($B21="",0,IF(OR($U21="OUT",$U21="TRF"),N($M21),0)) -> 0 | Q21: =IF($B21="",0,IF(OR($U21="OUT",$U21="TRF"),N($M21),0)) -> 0 | R21: =IF($B21="",0,IF($U21="IN",N($M21),0)) -> 0 | S21: =IF($B21="","",IF($M21="","⚠ مبلغ",IF($E21="","⚠ بانک عامل",IF(AND($U21="TRF",$F21=""),"⚠ بانک مقصد",IF(AND($V21<>"NONE",$V21<>"",$Z21=""),"⚠ طرف حساب","✓"))))) -> 0 | U21: =IFERROR(VLOOKUP($D21,BankOpTbl,2,0),"") -> 0 | V21: =IFERROR(VLOOKUP($D21,BankOpTbl,3,0),"") -> 0 | W21: =IFERROR(VLOOKUP($D21,BankOpTbl,4,0),"") -> 0 | X21: =IF($E21="","",IFERROR(VLOOKUP($E21,BankTbl,4,0),"")) -> 0 | Y21: =IF($F21="","",IFERROR(VLOOKUP($F21,BankTbl,4,0),"")) -> 0 | Z21: =IF($B21="","",IF($V21="PICK",LEFT($N21,5),IF($V21="FIXED",$W21,IF($V21="CODE",$H21,"")))) -> 0
A22: =IF($B22="","",COUNTA($B$13:$B22)) -> 0 | B22: 1405/07/11 | C22: JB-BS-017 | D22: واریز پز باسکول (۲۰۰۶) | E22: BN02 | G22: کارت/پوز | I22: =IF($H22="","",IFERROR(VLOOKUP($H22,AcctTbl,2,0),"کد ناشناخته")) -> 0 | J22: =IF($H22="","",IFERROR(VLOOKUP($H22,AcctTbl,3,0),"")) -> 0 | K22: پوز باسکول — درآمد پوز باسکول (بدون طرف) | L22: JB-BS-017 | M22: 300000 | O22: =IF($B22="",0,IF($U22="IN",N($M22),0)) -> 0 | P22: =IF($B22="",0,IF(OR($U22="OUT",$U22="TRF"),N($M22),0)) -> 0 | Q22: =IF($B22="",0,IF(OR($U22="OUT",$U22="TRF"),N($M22),0)) -> 0 | R22: =IF($B22="",0,IF($U22="IN",N($M22),0)) -> 0 | S22: =IF($B22="","",IF($M22="","⚠ مبلغ",IF($E22="","⚠ بانک عامل",IF(AND($U22="TRF",$F22=""),"⚠ بانک مقصد",IF(AND($V22<>"NONE",$V22<>"",$Z22=""),"⚠ طرف حساب","✓"))))) -> 0 | U22: =IFERROR(VLOOKUP($D22,BankOpTbl,2,0),"") -> 0 | V22: =IFERROR(VLOOKUP($D22,BankOpTbl,3,0),"") -> 0 | W22: =IFERROR(VLOOKUP($D22,BankOpTbl,4,0),"") -> 0 | X22: =IF($E22="","",IFERROR(VLOOKUP($E22,BankTbl,4,0),"")) -> 0 | Y22: =IF($F22="","",IFERROR(VLOOKUP($F22,BankTbl,4,0),"")) -> 0 | Z22: =IF($B22="","",IF($V22="PICK",LEFT($N22,5),IF($V22="FIXED",$W22,IF($V22="CODE",$H22,"")))) -> 0
A23: =IF($B23="","",COUNTA($B$13:$B23)) -> 0 | B23: 1405/07/12 | C23: JB-RV-004 | D23: تسویه دریافت (واسط) | E23: BN01 | G23: انتقال بانکی | I23: =IF($H23="","",IFERROR(VLOOKUP($H23,AcctTbl,2,0),"کد ناشناخته")) -> 0 | J23: =IF($H23="","",IFERROR(VLOOKUP($H23,AcctTbl,3,0),"")) -> 0 | K23: واریز از واسط | L23: JB-RV-004 | M23: 50000000 | O23: =IF($B23="",0,IF($U23="IN",N($M23),0)) -> 0 | P23: =IF($B23="",0,IF(OR($U23="OUT",$U23="TRF"),N($M23),0)) -> 0 | Q23: =IF($B23="",0,IF(OR($U23="OUT",$U23="TRF"),N($M23),0)) -> 0 | R23: =IF($B23="",0,IF($U23="IN",N($M23),0)) -> 0 | S23: =IF($B23="","",IF($M23="","⚠ مبلغ",IF($E23="","⚠ بانک عامل",IF(AND($U23="TRF",$F23=""),"⚠ بانک مقصد",IF(AND($V23<>"NONE",$V23<>"",$Z23=""),"⚠ طرف حساب","✓"))))) -> 0 | U23: =IFERROR(VLOOKUP($D23,BankOpTbl,2,0),"") -> 0 | V23: =IFERROR(VLOOKUP($D23,BankOpTbl,3,0),"") -> 0 | W23: =IFERROR(VLOOKUP($D23,BankOpTbl,4,0),"") -> 0 | X23: =IF($E23="","",IFERROR(VLOOKUP($E23,BankTbl,4,0),"")) -> 0 | Y23: =IF($F23="","",IFERROR(VLOOKUP($F23,BankTbl,4,0),"")) -> 0 | Z23: =IF($B23="","",IF($V23="PICK",LEFT($N23,5),IF($V23="FIXED",$W23,IF($V23="CODE",$H23,"")))) -> 0
A24: =IF($B24="","",COUNTA($B$13:$B24)) -> 0 | B24: 1405/07/13 | C24: TB-901 | D24: انتقال داخلی بین بانک‌ها | E24: BN01 | F24: BN03 | G24: انتقال بانکی | I24: =IF($H24="","",IFERROR(VLOOKUP($H24,AcctTbl,2,0),"کد ناشناخته")) -> 0 | J24: =IF($H24="","",IFERROR(VLOOKUP($H24,AcctTbl,3,0),"")) -> 0 | K24: انتقال به حساب ملت | L24: TR-9001 | M24: 50000000 | O24: =IF($B24="",0,IF($U24="IN",N($M24),0)) -> 0 | P24: =IF($B24="",0,IF(OR($U24="OUT",$U24="TRF"),N($M24),0)) -> 0 | Q24: =IF($B24="",0,IF(OR($U24="OUT",$U24="TRF"),N($M24),0)) -> 0 | R24: =IF($B24="",0,IF($U24="IN",N($M24),0)) -> 0 | S24: =IF($B24="","",IF($M24="","⚠ مبلغ",IF($E24="","⚠ بانک عامل",IF(AND($U24="TRF",$F24=""),"⚠ بانک مقصد",IF(AND($V24<>"NONE",$V24<>"",$Z24=""),"⚠ طرف حساب","✓"))))) -> 0 | U24: =IFERROR(VLOOKUP($D24,BankOpTbl,2,0),"") -> 0 | V24: =IFERROR(VLOOKUP($D24,BankOpTbl,3,0),"") -> 0 | W24: =IFERROR(VLOOKUP($D24,BankOpTbl,4,0),"") -> 0 | X24: =IF($E24="","",IFERROR(VLOOKUP($E24,BankTbl,4,0),"")) -> 0 | Y24: =IF($F24="","",IFERROR(VLOOKUP($F24,BankTbl,4,0),"")) -> 0 | Z24: =IF($B24="","",IF($V24="PICK",LEFT($N24,5),IF($V24="FIXED",$W24,IF($V24="CODE",$H24,"")))) -> 0
A25: =IF($B25="","",COUNTA($B$13:$B25)) -> 0 | I25: =IF($H25="","",IFERROR(VLOOKUP($H25,AcctTbl,2,0),"کد ناشناخته")) -> 0 | J25: =IF($H25="","",IFERROR(VLOOKUP($H25,AcctTbl,3,0),"")) -> 0 | O25: =IF($B25="",0,IF($U25="IN",N($M25),0)) -> 0 | P25: =IF($B25="",0,IF(OR($U25="OUT",$U25="TRF"),N($M25),0)) -> 0 | Q25: =IF($B25="",0,IF(OR($U25="OUT",$U25="TRF"),N($M25),0)) -> 0 | R25: =IF($B25="",0,IF($U25="IN",N($M25),0)) -> 0 | S25: =IF($B25="","",IF($M25="","⚠ مبلغ",IF($E25="","⚠ بانک عامل",IF(AND($U25="TRF",$F25=""),"⚠ بانک مقصد",IF(AND($V25<>"NONE",$V25<>"",$Z25=""),"⚠ طرف حساب","✓"))))) -> 0 | U25: =IFERROR(VLOOKUP($D25,BankOpTbl,2,0),"") -> 0 | V25: =IFERROR(VLOOKUP($D25,BankOpTbl,3,0),"") -> 0 | W25: =IFERROR(VLOOKUP($D25,BankOpTbl,4,0),"") -> 0 | X25: =IF($E25="","",IFERROR(VLOOKUP($E25,BankTbl,4,0),"")) -> 0 | Y25: =IF($F25="","",IFERROR(VLOOKUP($F25,BankTbl,4,0),"")) -> 0 | Z25: =IF($B25="","",IF($V25="PICK",LEFT($N25,5),IF($V25="FIXED",$W25,IF($V25="CODE",$H25,"")))) -> 0
A26: =IF($B26="","",COUNTA($B$13:$B26)) -> 0 | I26: =IF($H26="","",IFERROR(VLOOKUP($H26,AcctTbl,2,0),"کد ناشناخته")) -> 0 | J26: =IF($H26="","",IFERROR(VLOOKUP($H26,AcctTbl,3,0),"")) -> 0 | O26: =IF($B26="",0,IF($U26="IN",N($M26),0)) -> 0 | P26: =IF($B26="",0,IF(OR($U26="OUT",$U26="TRF"),N($M26),0)) -> 0 | Q26: =IF($B26="",0,IF(OR($U26="OUT",$U26="TRF"),N($M26),0)) -> 0 | R26: =IF($B26="",0,IF($U26="IN",N($M26),0)) -> 0 | S26: =IF($B26="","",IF($M26="","⚠ مبلغ",IF($E26="","⚠ بانک عامل",IF(AND($U26="TRF",$F26=""),"⚠ بانک مقصد",IF(AND($V26<>"NONE",$V26<>"",$Z26=""),"⚠ طرف حساب","✓"))))) -> 0 | U26: =IFERROR(VLOOKUP($D26,BankOpTbl,2,0),"") -> 0 | V26: =IFERROR(VLOOKUP($D26,BankOpTbl,3,0),"") -> 0 | W26: =IFERROR(VLOOKUP($D26,BankOpTbl,4,0),"") -> 0 | X26: =IF($E26="","",IFERROR(VLOOKUP($E26,BankTbl,4,0),"")) -> 0 | Y26: =IF($F26="","",IFERROR(VLOOKUP($F26,BankTbl,4,0),"")) -> 0 | Z26: =IF($B26="","",IF($V26="PICK",LEFT($N26,5),IF($V26="FIXED",$W26,IF($V26="CODE",$H26,"")))) -> 0
A27: =IF($B27="","",COUNTA($B$13:$B27)) -> 0 | I27: =IF($H27="","",IFERROR(VLOOKUP($H27,AcctTbl,2,0),"کد ناشناخته")) -> 0 | J27: =IF($H27="","",IFERROR(VLOOKUP($H27,AcctTbl,3,0),"")) -> 0 | O27: =IF($B27="",0,IF($U27="IN",N($M27),0)) -> 0 | P27: =IF($B27="",0,IF(OR($U27="OUT",$U27="TRF"),N($M27),0)) -> 0 | Q27: =IF($B27="",0,IF(OR($U27="OUT",$U27="TRF"),N($M27),0)) -> 0 | R27: =IF($B27="",0,IF($U27="IN",N($M27),0)) -> 0 | S27: =IF($B27="","",IF($M27="","⚠ مبلغ",IF($E27="","⚠ بانک عامل",IF(AND($U27="TRF",$F27=""),"⚠ بانک مقصد",IF(AND($V27<>"NONE",$V27<>"",$Z27=""),"⚠ طرف حساب","✓"))))) -> 0 | U27: =IFERROR(VLOOKUP($D27,BankOpTbl,2,0),"") -> 0 | V27: =IFERROR(VLOOKUP($D27,BankOpTbl,3,0),"") -> 0 | W27: =IFERROR(VLOOKUP($D27,BankOpTbl,4,0),"") -> 0 | X27: =IF($E27="","",IFERROR(VLOOKUP($E27,BankTbl,4,0),"")) -> 0 | Y27: =IF($F27="","",IFERROR(VLOOKUP($F27,BankTbl,4,0),"")) -> 0 | Z27: =IF($B27="","",IF($V27="PICK",LEFT($N27,5),IF($V27="FIXED",$W27,IF($V27="CODE",$H27,"")))) -> 0
A28: =IF($B28="","",COUNTA($B$13:$B28)) -> 0 | I28: =IF($H28="","",IFERROR(VLOOKUP($H28,AcctTbl,2,0),"کد ناشناخته")) -> 0 | J28: =IF($H28="","",IFERROR(VLOOKUP($H28,AcctTbl,3,0),"")) -> 0 | O28: =IF($B28="",0,IF($U28="IN",N($M28),0)) -> 0 | P28: =IF($B28="",0,IF(OR($U28="OUT",$U28="TRF"),N($M28),0)) -> 0 | Q28: =IF($B28="",0,IF(OR($U28="OUT",$U28="TRF"),N($M28),0)) -> 0 | R28: =IF($B28="",0,IF($U28="IN",N($M28),0)) -> 0 | S28: =IF($B28="","",IF($M28="","⚠ مبلغ",IF($E28="","⚠ بانک عامل",IF(AND($U28="TRF",$F28=""),"⚠ بانک مقصد",IF(AND($V28<>"NONE",$V28<>"",$Z28=""),"⚠ طرف حساب","✓"))))) -> 0 | U28: =IFERROR(VLOOKUP($D28,BankOpTbl,2,0),"") -> 0 | V28: =IFERROR(VLOOKUP($D28,BankOpTbl,3,0),"") -> 0 | W28: =IFERROR(VLOOKUP($D28,BankOpTbl,4,0),"") -> 0 | X28: =IF($E28="","",IFERROR(VLOOKUP($E28,BankTbl,4,0),"")) -> 0 | Y28: =IF($F28="","",IFERROR(VLOOKUP($F28,BankTbl,4,0),"")) -> 0 | Z28: =IF($B28="","",IF($V28="PICK",LEFT($N28,5),IF($V28="FIXED",$W28,IF($V28="CODE",$H28,"")))) -> 0
A29: =IF($B29="","",COUNTA($B$13:$B29)) -> 0 | I29: =IF($H29="","",IFERROR(VLOOKUP($H29,AcctTbl,2,0),"کد ناشناخته")) -> 0 | J29: =IF($H29="","",IFERROR(VLOOKUP($H29,AcctTbl,3,0),"")) -> 0 | O29: =IF($B29="",0,IF($U29="IN",N($M29),0)) -> 0 | P29: =IF($B29="",0,IF(OR($U29="OUT",$U29="TRF"),N($M29),0)) -> 0 | Q29: =IF($B29="",0,IF(OR($U29="OUT",$U29="TRF"),N($M29),0)) -> 0 | R29: =IF($B29="",0,IF($U29="IN",N($M29),0)) -> 0 | S29: =IF($B29="","",IF($M29="","⚠ مبلغ",IF($E29="","⚠ بانک عامل",IF(AND($U29="TRF",$F29=""),"⚠ بانک مقصد",IF(AND($V29<>"NONE",$V29<>"",$Z29=""),"⚠ طرف حساب","✓"))))) -> 0 | U29: =IFERROR(VLOOKUP($D29,BankOpTbl,2,0),"") -> 0 | V29: =IFERROR(VLOOKUP($D29,BankOpTbl,3,0),"") -> 0 | W29: =IFERROR(VLOOKUP($D29,BankOpTbl,4,0),"") -> 0 | X29: =IF($E29="","",IFERROR(VLOOKUP($E29,BankTbl,4,0),"")) -> 0 | Y29: =IF($F29="","",IFERROR(VLOOKUP($F29,BankTbl,4,0),"")) -> 0 | Z29: =IF($B29="","",IF($V29="PICK",LEFT($N29,5),IF($V29="FIXED",$W29,IF($V29="CODE",$H29,"")))) -> 0
A30: =IF($B30="","",COUNTA($B$13:$B30)) -> 0 | I30: =IF($H30="","",IFERROR(VLOOKUP($H30,AcctTbl,2,0),"کد ناشناخته")) -> 0 | J30: =IF($H30="","",IFERROR(VLOOKUP($H30,AcctTbl,3,0),"")) -> 0 | O30: =IF($B30="",0,IF($U30="IN",N($M30),0)) -> 0 | P30: =IF($B30="",0,IF(OR($U30="OUT",$U30="TRF"),N($M30),0)) -> 0 | Q30: =IF($B30="",0,IF(OR($U30="OUT",$U30="TRF"),N($M30),0)) -> 0 | R30: =IF($B30="",0,IF($U30="IN",N($M30),0)) -> 0 | S30: =IF($B30="","",IF($M30="","⚠ مبلغ",IF($E30="","⚠ بانک عامل",IF(AND($U30="TRF",$F30=""),"⚠ بانک مقصد",IF(AND($V30<>"NONE",$V30<>"",$Z30=""),"⚠ طرف حساب","✓"))))) -> 0 | U30: =IFERROR(VLOOKUP($D30,BankOpTbl,2,0),"") -> 0 | V30: =IFERROR(VLOOKUP($D30,BankOpTbl,3,0),"") -> 0 | W30: =IFERROR(VLOOKUP($D30,BankOpTbl,4,0),"") -> 0 | X30: =IF($E30="","",IFERROR(VLOOKUP($E30,BankTbl,4,0),"")) -> 0 | Y30: =IF($F30="","",IFERROR(VLOOKUP($F30,BankTbl,4,0),"")) -> 0 | Z30: =IF($B30="","",IF($V30="PICK",LEFT($N30,5),IF($V30="FIXED",$W30,IF($V30="CODE",$H30,"")))) -> 0
A31: =IF($B31="","",COUNTA($B$13:$B31)) -> 0 | I31: =IF($H31="","",IFERROR(VLOOKUP($H31,AcctTbl,2,0),"کد ناشناخته")) -> 0 | J31: =IF($H31="","",IFERROR(VLOOKUP($H31,AcctTbl,3,0),"")) -> 0 | O31: =IF($B31="",0,IF($U31="IN",N($M31),0)) -> 0 | P31: =IF($B31="",0,IF(OR($U31="OUT",$U31="TRF"),N($M31),0)) -> 0 | Q31: =IF($B31="",0,IF(OR($U31="OUT",$U31="TRF"),N($M31),0)) -> 0 | R31: =IF($B31="",0,IF($U31="IN",N($M31),0)) -> 0 | S31: =IF($B31="","",IF($M31="","⚠ مبلغ",IF($E31="","⚠ بانک عامل",IF(AND($U31="TRF",$F31=""),"⚠ بانک مقصد",IF(AND($V31<>"NONE",$V31<>"",$Z31=""),"⚠ طرف حساب","✓"))))) -> 0 | U31: =IFERROR(VLOOKUP($D31,BankOpTbl,2,0),"") -> 0 | V31: =IFERROR(VLOOKUP($D31,BankOpTbl,3,0),"") -> 0 | W31: =IFERROR(VLOOKUP($D31,BankOpTbl,4,0),"") -> 0 | X31: =IF($E31="","",IFERROR(VLOOKUP($E31,BankTbl,4,0),"")) -> 0 | Y31: =IF($F31="","",IFERROR(VLOOKUP($F31,BankTbl,4,0),"")) -> 0 | Z31: =IF($B31="","",IF($V31="PICK",LEFT($N31,5),IF($V31="FIXED",$W31,IF($V31="CODE",$H31,"")))) -> 0
A32: =IF($B32="","",COUNTA($B$13:$B32)) -> 0 | I32: =IF($H32="","",IFERROR(VLOOKUP($H32,AcctTbl,2,0),"کد ناشناخته")) -> 0 | J32: =IF($H32="","",IFERROR(VLOOKUP($H32,AcctTbl,3,0),"")) -> 0 | O32: =IF($B32="",0,IF($U32="IN",N($M32),0)) -> 0 | P32: =IF($B32="",0,IF(OR($U32="OUT",$U32="TRF"),N($M32),0)) -> 0 | Q32: =IF($B32="",0,IF(OR($U32="OUT",$U32="TRF"),N($M32),0)) -> 0 | R32: =IF($B32="",0,IF($U32="IN",N($M32),0)) -> 0 | S32: =IF($B32="","",IF($M32="","⚠ مبلغ",IF($E32="","⚠ بانک عامل",IF(AND($U32="TRF",$F32=""),"⚠ بانک مقصد",IF(AND($V32<>"NONE",$V32<>"",$Z32=""),"⚠ طرف حساب","✓"))))) -> 0 | U32: =IFERROR(VLOOKUP($D32,BankOpTbl,2,0),"") -> 0 | V32: =IFERROR(VLOOKUP($D32,BankOpTbl,3,0),"") -> 0 | W32: =IFERROR(VLOOKUP($D32,BankOpTbl,4,0),"") -> 0 | X32: =IF($E32="","",IFERROR(VLOOKUP($E32,BankTbl,4,0),"")) -> 0 | Y32: =IF($F32="","",IFERROR(VLOOKUP($F32,BankTbl,4,0),"")) -> 0 | Z32: =IF($B32="","",IF($V32="PICK",LEFT($N32,5),IF($V32="FIXED",$W32,IF($V32="CODE",$H32,"")))) -> 0
A33: =IF($B33="","",COUNTA($B$13:$B33)) -> 0 | I33: =IF($H33="","",IFERROR(VLOOKUP($H33,AcctTbl,2,0),"کد ناشناخته")) -> 0 | J33: =IF($H33="","",IFERROR(VLOOKUP($H33,AcctTbl,3,0),"")) -> 0 | O33: =IF($B33="",0,IF($U33="IN",N($M33),0)) -> 0 | P33: =IF($B33="",0,IF(OR($U33="OUT",$U33="TRF"),N($M33),0)) -> 0 | Q33: =IF($B33="",0,IF(OR($U33="OUT",$U33="TRF"),N($M33),0)) -> 0 | R33: =IF($B33="",0,IF($U33="IN",N($M33),0)) -> 0 | S33: =IF($B33="","",IF($M33="","⚠ مبلغ",IF($E33="","⚠ بانک عامل",IF(AND($U33="TRF",$F33=""),"⚠ بانک مقصد",IF(AND($V33<>"NONE",$V33<>"",$Z33=""),"⚠ طرف حساب","✓"))))) -> 0 | U33: =IFERROR(VLOOKUP($D33,BankOpTbl,2,0),"") -> 0 | V33: =IFERROR(VLOOKUP($D33,BankOpTbl,3,0),"") -> 0 | W33: =IFERROR(VLOOKUP($D33,BankOpTbl,4,0),"") -> 0 | X33: =IF($E33="","",IFERROR(VLOOKUP($E33,BankTbl,4,0),"")) -> 0 | Y33: =IF($F33="","",IFERROR(VLOOKUP($F33,BankTbl,4,0),"")) -> 0 | Z33: =IF($B33="","",IF($V33="PICK",LEFT($N33,5),IF($V33="FIXED",$W33,IF($V33="CODE",$H33,"")))) -> 0
A34: =IF($B34="","",COUNTA($B$13:$B34)) -> 0 | I34: =IF($H34="","",IFERROR(VLOOKUP($H34,AcctTbl,2,0),"کد ناشناخته")) -> 0 | J34: =IF($H34="","",IFERROR(VLOOKUP($H34,AcctTbl,3,0),"")) -> 0 | O34: =IF($B34="",0,IF($U34="IN",N($M34),0)) -> 0 | P34: =IF($B34="",0,IF(OR($U34="OUT",$U34="TRF"),N($M34),0)) -> 0 | Q34: =IF($B34="",0,IF(OR($U34="OUT",$U34="TRF"),N($M34),0)) -> 0 | R34: =IF($B34="",0,IF($U34="IN",N($M34),0)) -> 0 | S34: =IF($B34="","",IF($M34="","⚠ مبلغ",IF($E34="","⚠ بانک عامل",IF(AND($U34="TRF",$F34=""),"⚠ بانک مقصد",IF(AND($V34<>"NONE",$V34<>"",$Z34=""),"⚠ طرف حساب","✓"))))) -> 0 | U34: =IFERROR(VLOOKUP($D34,BankOpTbl,2,0),"") -> 0 | V34: =IFERROR(VLOOKUP($D34,BankOpTbl,3,0),"") -> 0 | W34: =IFERROR(VLOOKUP($D34,BankOpTbl,4,0),"") -> 0 | X34: =IF($E34="","",IFERROR(VLOOKUP($E34,BankTbl,4,0),"")) -> 0 | Y34: =IF($F34="","",IFERROR(VLOOKUP($F34,BankTbl,4,0),"")) -> 0 | Z34: =IF($B34="","",IF($V34="PICK",LEFT($N34,5),IF($V34="FIXED",$W34,IF($V34="CODE",$H34,"")))) -> 0
A35: =IF($B35="","",COUNTA($B$13:$B35)) -> 0 | I35: =IF($H35="","",IFERROR(VLOOKUP($H35,AcctTbl,2,0),"کد ناشناخته")) -> 0 | J35: =IF($H35="","",IFERROR(VLOOKUP($H35,AcctTbl,3,0),"")) -> 0 | O35: =IF($B35="",0,IF($U35="IN",N($M35),0)) -> 0 | P35: =IF($B35="",0,IF(OR($U35="OUT",$U35="TRF"),N($M35),0)) -> 0 | Q35: =IF($B35="",0,IF(OR($U35="OUT",$U35="TRF"),N($M35),0)) -> 0 | R35: =IF($B35="",0,IF($U35="IN",N($M35),0)) -> 0 | S35: =IF($B35="","",IF($M35="","⚠ مبلغ",IF($E35="","⚠ بانک عامل",IF(AND($U35="TRF",$F35=""),"⚠ بانک مقصد",IF(AND($V35<>"NONE",$V35<>"",$Z35=""),"⚠ طرف حساب","✓"))))) -> 0 | U35: =IFERROR(VLOOKUP($D35,BankOpTbl,2,0),"") -> 0 | V35: =IFERROR(VLOOKUP($D35,BankOpTbl,3,0),"") -> 0 | W35: =IFERROR(VLOOKUP($D35,BankOpTbl,4,0),"") -> 0 | X35: =IF($E35="","",IFERROR(VLOOKUP($E35,BankTbl,4,0),"")) -> 0 | Y35: =IF($F35="","",IFERROR(VLOOKUP($F35,BankTbl,4,0),"")) -> 0 | Z35: =IF($B35="","",IF($V35="PICK",LEFT($N35,5),IF($V35="FIXED",$W35,IF($V35="CODE",$H35,"")))) -> 0
A36: =IF($B36="","",COUNTA($B$13:$B36)) -> 0 | I36: =IF($H36="","",IFERROR(VLOOKUP($H36,AcctTbl,2,0),"کد ناشناخته")) -> 0 | J36: =IF($H36="","",IFERROR(VLOOKUP($H36,AcctTbl,3,0),"")) -> 0 | O36: =IF($B36="",0,IF($U36="IN",N($M36),0)) -> 0 | P36: =IF($B36="",0,IF(OR($U36="OUT",$U36="TRF"),N($M36),0)) -> 0 | Q36: =IF($B36="",0,IF(OR($U36="OUT",$U36="TRF"),N($M36),0)) -> 0 | R36: =IF($B36="",0,IF($U36="IN",N($M36),0)) -> 0 | S36: =IF($B36="","",IF($M36="","⚠ مبلغ",IF($E36="","⚠ بانک عامل",IF(AND($U36="TRF",$F36=""),"⚠ بانک مقصد",IF(AND($V36<>"NONE",$V36<>"",$Z36=""),"⚠ طرف حساب","✓"))))) -> 0 | U36: =IFERROR(VLOOKUP($D36,BankOpTbl,2,0),"") -> 0 | V36: =IFERROR(VLOOKUP($D36,BankOpTbl,3,0),"") -> 0 | W36: =IFERROR(VLOOKUP($D36,BankOpTbl,4,0),"") -> 0 | X36: =IF($E36="","",IFERROR(VLOOKUP($E36,BankTbl,4,0),"")) -> 0 | Y36: =IF($F36="","",IFERROR(VLOOKUP($F36,BankTbl,4,0),"")) -> 0 | Z36: =IF($B36="","",IF($V36="PICK",LEFT($N36,5),IF($V36="FIXED",$W36,IF($V36="CODE",$H36,"")))) -> 0
... A152: =IF($B152="","",COUNTA($B$13:$B152)) -> 0 | I152: =IF($H152="","",IFERROR(VLOOKUP($H152,AcctTbl,2,0),"کد ناشناخته")) -> 0 | J152: =IF($H152="","",IFERROR(VLOOKUP($H152,AcctTbl,3,0),"")) -> 0 | O152: =IF($B152="",0,IF($U152="IN",N($M152),0)) -> 0 | P152: =IF($B152="",0,IF(OR($U152="OUT",$U152="TRF"),N($M152),0)) -> 0 | Q152: =IF($B152="",0,IF(OR($U152="OUT",$U152="TRF"),N($M152),0)) -> 0 | R152: =IF($B152="",0,IF($U152="IN",N($M152),0)) -> 0 | S152: =IF($B152="","",IF($M152="","⚠ مبلغ",IF($E152="","⚠ بانک عامل",IF(AND($U152="TRF",$F152=""),"⚠ بانک مقصد",IF(AND($V152<>"NONE",$V152<>"",$Z152=""),"⚠ طرف حساب","✓"))))) -> 0 | U152: =IFERROR(VLOOKUP($D152,BankOpTbl,2,0),"") -> 0 | V152: =IFERROR(VLOOKUP($D152,BankOpTbl,3,0),"") -> 0 | W152: =IFERROR(VLOOKUP($D152,BankOpTbl,4,0),"") -> 0 | X152: =IF($E152="","",IFERROR(VLOOKUP($E152,BankTbl,4,0),"")) -> 0 | Y152: =IF($F152="","",IFERROR(VLOOKUP($F152,BankTbl,4,0),"")) -> 0 | Z152: =IF($B152="","",IF($V152="PICK",LEFT($N152,5),IF($V152="FIXED",$W152,IF($V152="CODE",$H152,"")))) -> 0
A153: جمع کل | O153: =SUM(O12:O151) -> 0 | P153: =SUM(P12:P151) -> 0 | Q153: =SUM(Q12:Q151) -> 0 | R153: =SUM(R12:R151) -> 0 | S153: =IF(COUNTIF($S$13:$S$152,"⚠*")=0,"✓ تراز","⚠ بررسی") -> 0

Sheet Post
A9: تاریخ | B9: سند | C9: منبع | D9: کد حساب | E9: نام حساب | F9: گروه | G9: عملیات | H9: بانک | I9: بدهکار | J9: بستانکار | K9: ماه | L9: شرح | N9: بانک؟
A13: =IF(Txn!$B13="","",Txn!$B13) -> 0 | B13: =IF(Txn!$B13="","",Txn!$C13) -> 0 | C13: =IF(Txn!$B13="","","تراکنش بانکی") -> 0 | D13: =IF(Txn!$B13="","",IF(Txn!$X13="","",Txn!$X13)) -> 0 | E13: =IF($D13="","",IFERROR(VLOOKUP($D13,AcctTbl,2,0),"")) -> 0 | F13: =IF($D13="","",IFERROR(VLOOKUP($D13,AcctTbl,3,0),"")) -> 0 | G13: =IF(Txn!$B13="","",Txn!$D13) -> 0 | H13: =IF(Txn!$B13="","",Txn!$E13) -> 0 | I13: =IF(Txn!$B13="",0,Txn!$O13) -> 0 | J13: =IF(Txn!$B13="",0,Txn!$P13) -> 0 | K13: =IF($A13="","",IFERROR(VALUE(MID($A13,6,2)),"")) -> 0 | L13: =IF(Txn!$K13="","",Txn!$K13) -> 0 | N13: =IF($D13="",0,COUNTIF(BankAccts,$D13)) -> 0
A14: =IF(Txn!$B13="","",Txn!$B13) -> 0 | B14: =IF(Txn!$B13="","",Txn!$C13) -> 0 | C14: =IF(Txn!$B13="","","تراکنش بانکی") -> 0 | D14: =IF(Txn!$B13="","",IF(IF(Txn!$U13="TRF",Txn!$Y13,Txn!$Z13)="","",IF(Txn!$U13="TRF",Txn!$Y13,Txn!$Z13))) -> 0 | E14: =IF($D14="","",IFERROR(VLOOKUP($D14,AcctTbl,2,0),"")) -> 0 | F14: =IF($D14="","",IFERROR(VLOOKUP($D14,AcctTbl,3,0),"")) -> 0 | G14: =IF(Txn!$B13="","",Txn!$D13) -> 0 | H14: =IF(Txn!$B13="","",Txn!$E13) -> 0 | I14: =IF(Txn!$B13="",0,Txn!$Q13) -> 0 | J14: =IF(Txn!$B13="",0,Txn!$R13) -> 0 | K14: =IF($A14="","",IFERROR(VALUE(MID($A14,6,2)),"")) -> 0 | L14: =IF(Txn!$K13="","","طرف مقابل — "&Txn!$K13) -> 0 | N14: =IF($D14="",0,COUNTIF(BankAccts,$D14)) -> 0
A15: =IF(Txn!$B14="","",Txn!$B14) -> 0 | B15: =IF(Txn!$B14="","",Txn!$C14) -> 0 | C15: =IF(Txn!$B14="","","تراکنش بانکی") -> 0 | D15: =IF(Txn!$B14="","",IF(Txn!$X14="","",Txn!$X14)) -> 0 | E15: =IF($D15="","",IFERROR(VLOOKUP($D15,AcctTbl,2,0),"")) -> 0 | F15: =IF($D15="","",IFERROR(VLOOKUP($D15,AcctTbl,3,0),"")) -> 0 | G15: =IF(Txn!$B14="","",Txn!$D14) -> 0 | H15: =IF(Txn!$B14="","",Txn!$E14) -> 0 | I15: =IF(Txn!$B14="",0,Txn!$O14) -> 0 | J15: =IF(Txn!$B14="",0,Txn!$P14) -> 0 | K15: =IF($A15="","",IFERROR(VALUE(MID($A15,6,2)),"")) -> 0 | L15: =IF(Txn!$K14="","",Txn!$K14) -> 0 | N15: =IF($D15="",0,COUNTIF(BankAccts,$D15)) -> 0
A16: =IF(Txn!$B14="","",Txn!$B14) -> 0 | B16: =IF(Txn!$B14="","",Txn!$C14) -> 0 | C16: =IF(Txn!$B14="","","تراکنش بانکی") -> 0 | D16: =IF(Txn!$B14="","",IF(IF(Txn!$U14="TRF",Txn!$Y14,Txn!$Z14)="","",IF(Txn!$U14="TRF",Txn!$Y14,Txn!$Z14))) -> 0 | E16: =IF($D16="","",IFERROR(VLOOKUP($D16,AcctTbl,2,0),"")) -> 0 | F16: =IF($D16="","",IFERROR(VLOOKUP($D16,AcctTbl,3,0),"")) -> 0 | G16: =IF(Txn!$B14="","",Txn!$D14) -> 0 | H16: =IF(Txn!$B14="","",Txn!$E14) -> 0 | I16: =IF(Txn!$B14="",0,Txn!$Q14) -> 0 | J16: =IF(Txn!$B14="",0,Txn!$R14) -> 0 | K16: =IF($A16="","",IFERROR(VALUE(MID($A16,6,2)),"")) -> 0 | L16: =IF(Txn!$K14="","","طرف مقابل — "&Txn!$K14) -> 0 | N16: =IF($D16="",0,COUNTIF(BankAccts,$D16)) -> 0
A17: =IF(Txn!$B15="","",Txn!$B15) -> 0 | B17: =IF(Txn!$B15="","",Txn!$C15) -> 0 | C17: =IF(Txn!$B15="","","تراکنش بانکی") -> 0 | D17: =IF(Txn!$B15="","",IF(Txn!$X15="","",Txn!$X15)) -> 0 | E17: =IF($D17="","",IFERROR(VLOOKUP($D17,AcctTbl,2,0),"")) -> 0 | F17: =IF($D17="","",IFERROR(VLOOKUP($D17,AcctTbl,3,0),"")) -> 0 | G17: =IF(Txn!$B15="","",Txn!$D15) -> 0 | H17: =IF(Txn!$B15="","",Txn!$E15) -> 0 | I17: =IF(Txn!$B15="",0,Txn!$O15) -> 0 | J17: =IF(Txn!$B15="",0,Txn!$P15) -> 0 | K17: =IF($A17="","",IFERROR(VALUE(MID($A17,6,2)),"")) -> 0 | L17: =IF(Txn!$K15="","",Txn!$K15) -> 0 | N17: =IF($D17="",0,COUNTIF(BankAccts,$D17)) -> 0
A18: =IF(Txn!$B15="","",Txn!$B15) -> 0 | B18: =IF(Txn!$B15="","",Txn!$C15) -> 0 | C18: =IF(Txn!$B15="","","تراکنش بانکی") -> 0 | D18: =IF(Txn!$B15="","",IF(IF(Txn!$U15="TRF",Txn!$Y15,Txn!$Z15)="","",IF(Txn!$U15="TRF",Txn!$Y15,Txn!$Z15))) -> 0 | E18: =IF($D18="","",IFERROR(VLOOKUP($D18,AcctTbl,2,0),"")) -> 0 | F18: =IF($D18="","",IFERROR(VLOOKUP($D18,AcctTbl,3,0),"")) -> 0 | G18: =IF(Txn!$B15="","",Txn!$D15) -> 0 | H18: =IF(Txn!$B15="","",Txn!$E15) -> 0 | I18: =IF(Txn!$B15="",0,Txn!$Q15) -> 0 | J18: =IF(Txn!$B15="",0,Txn!$R15) -> 0 | K18: =IF($A18="","",IFERROR(VALUE(MID($A18,6,2)),"")) -> 0 | L18: =IF(Txn!$K15="","","طرف مقابل — "&Txn!$K15) -> 0 | N18: =IF($D18="",0,COUNTIF(BankAccts,$D18)) -> 0
A19: =IF(Txn!$B16="","",Txn!$B16) -> 0 | B19: =IF(Txn!$B16="","",Txn!$C16) -> 0 | C19: =IF(Txn!$B16="","","تراکنش بانکی") -> 0 | D19: =IF(Txn!$B16="","",IF(Txn!$X16="","",Txn!$X16)) -> 0 | E19: =IF($D19="","",IFERROR(VLOOKUP($D19,AcctTbl,2,0),"")) -> 0 | F19: =IF($D19="","",IFERROR(VLOOKUP($D19,AcctTbl,3,0),"")) -> 0 | G19: =IF(Txn!$B16="","",Txn!$D16) -> 0 | H19: =IF(Txn!$B16="","",Txn!$E16) -> 0 | I19: =IF(Txn!$B16="",0,Txn!$O16) -> 0 | J19: =IF(Txn!$B16="",0,Txn!$P16) -> 0 | K19: =IF($A19="","",IFERROR(VALUE(MID($A19,6,2)),"")) -> 0 | L19: =IF(Txn!$K16="","",Txn!$K16) -> 0 | N19: =IF($D19="",0,COUNTIF(BankAccts,$D19)) -> 0
A20: =IF(Txn!$B16="","",Txn!$B16) -> 0 | B20: =IF(Txn!$B16="","",Txn!$C16) -> 0 | C20: =IF(Txn!$B16="","","تراکنش بانکی") -> 0 | D20: =IF(Txn!$B16="","",IF(IF(Txn!$U16="TRF",Txn!$Y16,Txn!$Z16)="","",IF(Txn!$U16="TRF",Txn!$Y16,Txn!$Z16))) -> 0 | E20: =IF($D20="","",IFERROR(VLOOKUP($D20,AcctTbl,2,0),"")) -> 0 | F20: =IF($D20="","",IFERROR(VLOOKUP($D20,AcctTbl,3,0),"")) -> 0 | G20: =IF(Txn!$B16="","",Txn!$D16) -> 0 | H20: =IF(Txn!$B16="","",Txn!$E16) -> 0 | I20: =IF(Txn!$B16="",0,Txn!$Q16) -> 0 | J20: =IF(Txn!$B16="",0,Txn!$R16) -> 0 | K20: =IF($A20="","",IFERROR(VALUE(MID($A20,6,2)),"")) -> 0 | L20: =IF(Txn!$K16="","","طرف مقابل — "&Txn!$K16) -> 0 | N20: =IF($D20="",0,COUNTIF(BankAccts,$D20)) -> 0
A21: =IF(Txn!$B17="","",Txn!$B17) -> 0 | B21: =IF(Txn!$B17="","",Txn!$C17) -> 0 | C21: =IF(Txn!$B17="","","تراکنش بانکی") -> 0 | D21: =IF(Txn!$B17="","",IF(Txn!$X17="","",Txn!$X17)) -> 0 | E21: =IF($D21="","",IFERROR(VLOOKUP($D21,AcctTbl,2,0),"")) -> 0 | F21: =IF($D21="","",IFERROR(VLOOKUP($D21,AcctTbl,3,0),"")) -> 0 | G21: =IF(Txn!$B17="","",Txn!$D17) -> 0 | H21: =IF(Txn!$B17="","",Txn!$E17) -> 0 | I21: =IF(Txn!$B17="",0,Txn!$O17) -> 0 | J21: =IF(Txn!$B17="",0,Txn!$P17) -> 0 | K21: =IF($A21="","",IFERROR(VALUE(MID($A21,6,2)),"")) -> 0 | L21: =IF(Txn!$K17="","",Txn!$K17) -> 0 | N21: =IF($D21="",0,COUNTIF(BankAccts,$D21)) -> 0
A22: =IF(Txn!$B17="","",Txn!$B17) -> 0 | B22: =IF(Txn!$B17="","",Txn!$C17) -> 0 | C22: =IF(Txn!$B17="","","تراکنش بانکی") -> 0 | D22: =IF(Txn!$B17="","",IF(IF(Txn!$U17="TRF",Txn!$Y17,Txn!$Z17)="","",IF(Txn!$U17="TRF",Txn!$Y17,Txn!$Z17))) -> 0 | E22: =IF($D22="","",IFERROR(VLOOKUP($D22,AcctTbl,2,0),"")) -> 0 | F22: =IF($D22="","",IFERROR(VLOOKUP($D22,AcctTbl,3,0),"")) -> 0 | G22: =IF(Txn!$B17="","",Txn!$D17) -> 0 | H22: =IF(Txn!$B17="","",Txn!$E17) -> 0 | I22: =IF(Txn!$B17="",0,Txn!$Q17) -> 0 | J22: =IF(Txn!$B17="",0,Txn!$R17) -> 0 | K22: =IF($A22="","",IFERROR(VALUE(MID($A22,6,2)),"")) -> 0 | L22: =IF(Txn!$K17="","","طرف مقابل — "&Txn!$K17) -> 0 | N22: =IF($D22="",0,COUNTIF(BankAccts,$D22)) -> 0
A23: =IF(Txn!$B18="","",Txn!$B18) -> 0 | B23: =IF(Txn!$B18="","",Txn!$C18) -> 0 | C23: =IF(Txn!$B18="","","تراکنش بانکی") -> 0 | D23: =IF(Txn!$B18="","",IF(Txn!$X18="","",Txn!$X18)) -> 0 | E23: =IF($D23="","",IFERROR(VLOOKUP($D23,AcctTbl,2,0),"")) -> 0 | F23: =IF($D23="","",IFERROR(VLOOKUP($D23,AcctTbl,3,0),"")) -> 0 | G23: =IF(Txn!$B18="","",Txn!$D18) -> 0 | H23: =IF(Txn!$B18="","",Txn!$E18) -> 0 | I23: =IF(Txn!$B18="",0,Txn!$O18) -> 0 | J23: =IF(Txn!$B18="",0,Txn!$P18) -> 0 | K23: =IF($A23="","",IFERROR(VALUE(MID($A23,6,2)),"")) -> 0 | L23: =IF(Txn!$K18="","",Txn!$K18) -> 0 | N23: =IF($D23="",0,COUNTIF(BankAccts,$D23)) -> 0
A24: =IF(Txn!$B18="","",Txn!$B18) -> 0 | B24: =IF(Txn!$B18="","",Txn!$C18) -> 0 | C24: =IF(Txn!$B18="","","تراکنش بانکی") -> 0 | D24: =IF(Txn!$B18="","",IF(IF(Txn!$U18="TRF",Txn!$Y18,Txn!$Z18)="","",IF(Txn!$U18="TRF",Txn!$Y18,Txn!$Z18))) -> 0 | E24: =IF($D24="","",IFERROR(VLOOKUP($D24,AcctTbl,2,0),"")) -> 0 | F24: =IF($D24="","",IFERROR(VLOOKUP($D24,AcctTbl,3,0),"")) -> 0 | G24: =IF(Txn!$B18="","",Txn!$D18) -> 0 | H24: =IF(Txn!$B18="","",Txn!$E18) -> 0 | I24: =IF(Txn!$B18="",0,Txn!$Q18) -> 0 | J24: =IF(Txn!$B18="",0,Txn!$R18) -> 0 | K24: =IF($A24="","",IFERROR(VALUE(MID($A24,6,2)),"")) -> 0 | L24: =IF(Txn!$K18="","","طرف مقابل — "&Txn!$K18) -> 0 | N24: =IF($D24="",0,COUNTIF(BankAccts,$D24)) -> 0
A25: =IF(Txn!$B19="","",Txn!$B19) -> 0 | B25: =IF(Txn!$B19="","",Txn!$C19) -> 0 | C25: =IF(Txn!$B19="","","تراکنش بانکی") -> 0 | D25: =IF(Txn!$B19="","",IF(Txn!$X19="","",Txn!$X19)) -> 0 | E25: =IF($D25="","",IFERROR(VLOOKUP($D25,AcctTbl,2,0),"")) -> 0 | F25: =IF($D25="","",IFERROR(VLOOKUP($D25,AcctTbl,3,0),"")) -> 0 | G25: =IF(Txn!$B19="","",Txn!$D19) -> 0 | H25: =IF(Txn!$B19="","",Txn!$E19) -> 0 | I25: =IF(Txn!$B19="",0,Txn!$O19) -> 0 | J25: =IF(Txn!$B19="",0,Txn!$P19) -> 0 | K25: =IF($A25="","",IFERROR(VALUE(MID($A25,6,2)),"")) -> 0 | L25: =IF(Txn!$K19="","",Txn!$K19) -> 0 | N25: =IF($D25="",0,COUNTIF(BankAccts,$D25)) -> 0
A26: =IF(Txn!$B19="","",Txn!$B19) -> 0 | B26: =IF(Txn!$B19="","",Txn!$C19) -> 0 | C26: =IF(Txn!$B19="","","تراکنش بانکی") -> 0 | D26: =IF(Txn!$B19="","",IF(IF(Txn!$U19="TRF",Txn!$Y19,Txn!$Z19)="","",IF(Txn!$U19="TRF",Txn!$Y19,Txn!$Z19))) -> 0 | E26: =IF($D26="","",IFERROR(VLOOKUP($D26,AcctTbl,2,0),"")) -> 0 | F26: =IF($D26="","",IFERROR(VLOOKUP($D26,AcctTbl,3,0),"")) -> 0 | G26: =IF(Txn!$B19="","",Txn!$D19) -> 0 | H26: =IF(Txn!$B19="","",Txn!$E19) -> 0 | I26: =IF(Txn!$B19="",0,Txn!$Q19) -> 0 | J26: =IF(Txn!$B19="",0,Txn!$R19) -> 0 | K26: =IF($A26="","",IFERROR(VALUE(MID($A26,6,2)),"")) -> 0 | L26: =IF(Txn!$K19="","","طرف مقابل — "&Txn!$K19) -> 0 | N26: =IF($D26="",0,COUNTIF(BankAccts,$D26)) -> 0
A27: =IF(Txn!$B20="","",Txn!$B20) -> 0 | B27: =IF(Txn!$B20="","",Txn!$C20) -> 0 | C27: =IF(Txn!$B20="","","تراکنش بانکی") -> 0 | D27: =IF(Txn!$B20="","",IF(Txn!$X20="","",Txn!$X20)) -> 0 | E27: =IF($D27="","",IFERROR(VLOOKUP($D27,AcctTbl,2,0),"")) -> 0 | F27: =IF($D27="","",IFERROR(VLOOKUP($D27,AcctTbl,3,0),"")) -> 0 | G27: =IF(Txn!$B20="","",Txn!$D20) -> 0 | H27: =IF(Txn!$B20="","",Txn!$E20) -> 0 | I27: =IF(Txn!$B20="",0,Txn!$O20) -> 0 | J27: =IF(Txn!$B20="",0,Txn!$P20) -> 0 | K27: =IF($A27="","",IFERROR(VALUE(MID($A27,6,2)),"")) -> 0 | L27: =IF(Txn!$K20="","",Txn!$K20) -> 0 | N27: =IF($D27="",0,COUNTIF(BankAccts,$D27)) -> 0
A28: =IF(Txn!$B20="","",Txn!$B20) -> 0 | B28: =IF(Txn!$B20="","",Txn!$C20) -> 0 | C28: =IF(Txn!$B20="","","تراکنش بانکی") -> 0 | D28: =IF(Txn!$B20="","",IF(IF(Txn!$U20="TRF",Txn!$Y20,Txn!$Z20)="","",IF(Txn!$U20="TRF",Txn!$Y20,Txn!$Z20))) -> 0 | E28: =IF($D28="","",IFERROR(VLOOKUP($D28,AcctTbl,2,0),"")) -> 0 | F28: =IF($D28="","",IFERROR(VLOOKUP($D28,AcctTbl,3,0),"")) -> 0 | G28: =IF(Txn!$B20="","",Txn!$D20) -> 0 | H28: =IF(Txn!$B20="","",Txn!$E20) -> 0 | I28: =IF(Txn!$B20="",0,Txn!$Q20) -> 0 | J28: =IF(Txn!$B20="",0,Txn!$R20) -> 0 | K28: =IF($A28="","",IFERROR(VALUE(MID($A28,6,2)),"")) -> 0 | L28: =IF(Txn!$K20="","","طرف مقابل — "&Txn!$K20) -> 0 | N28: =IF($D28="",0,COUNTIF(BankAccts,$D28)) -> 0
A29: =IF(Txn!$B21="","",Txn!$B21) -> 0 | B29: =IF(Txn!$B21="","",Txn!$C21) -> 0 | C29: =IF(Txn!$B21="","","تراکنش بانکی") -> 0 | D29: =IF(Txn!$B21="","",IF(Txn!$X21="","",Txn!$X21)) -> 0 | E29: =IF($D29="","",IFERROR(VLOOKUP($D29,AcctTbl,2,0),"")) -> 0 | F29: =IF($D29="","",IFERROR(VLOOKUP($D29,AcctTbl,3,0),"")) -> 0 | G29: =IF(Txn!$B21="","",Txn!$D21) -> 0 | H29: =IF(Txn!$B21="","",Txn!$E21) -> 0 | I29: =IF(Txn!$B21="",0,Txn!$O21) -> 0 | J29: =IF(Txn!$B21="",0,Txn!$P21) -> 0 | K29: =IF($A29="","",IFERROR(VALUE(MID($A29,6,2)),"")) -> 0 | L29: =IF(Txn!$K21="","",Txn!$K21) -> 0 | N29: =IF($D29="",0,COUNTIF(BankAccts,$D29)) -> 0
A30: =IF(Txn!$B21="","",Txn!$B21) -> 0 | B30: =IF(Txn!$B21="","",Txn!$C21) -> 0 | C30: =IF(Txn!$B21="","","تراکنش بانکی") -> 0 | D30: =IF(Txn!$B21="","",IF(IF(Txn!$U21="TRF",Txn!$Y21,Txn!$Z21)="","",IF(Txn!$U21="TRF",Txn!$Y21,Txn!$Z21))) -> 0 | E30: =IF($D30="","",IFERROR(VLOOKUP($D30,AcctTbl,2,0),"")) -> 0 | F30: =IF($D30="","",IFERROR(VLOOKUP($D30,AcctTbl,3,0),"")) -> 0 | G30: =IF(Txn!$B21="","",Txn!$D21) -> 0 | H30: =IF(Txn!$B21="","",Txn!$E21) -> 0 | I30: =IF(Txn!$B21="",0,Txn!$Q21) -> 0 | J30: =IF(Txn!$B21="",0,Txn!$R21) -> 0 | K30: =IF($A30="","",IFERROR(VALUE(MID($A30,6,2)),"")) -> 0 | L30: =IF(Txn!$K21="","","طرف مقابل — "&Txn!$K21) -> 0 | N30: =IF($D30="",0,COUNTIF(BankAccts,$D30)) -> 0
A31: =IF(Txn!$B22="","",Txn!$B22) -> 0 | B31: =IF(Txn!$B22="","",Txn!$C22) -> 0 | C31: =IF(Txn!$B22="","","تراکنش بانکی") -> 0 | D31: =IF(Txn!$B22="","",IF(Txn!$X22="","",Txn!$X22)) -> 0 | E31: =IF($D31="","",IFERROR(VLOOKUP($D31,AcctTbl,2,0),"")) -> 0 | F31: =IF($D31="","",IFERROR(VLOOKUP($D31,AcctTbl,3,0),"")) -> 0 | G31: =IF(Txn!$B22="","",Txn!$D22) -> 0 | H31: =IF(Txn!$B22="","",Txn!$E22) -> 0 | I31: =IF(Txn!$B22="",0,Txn!$O22) -> 0 | J31: =IF(Txn!$B22="",0,Txn!$P22) -> 0 | K31: =IF($A31="","",IFERROR(VALUE(MID($A31,6,2)),"")) -> 0 | L31: =IF(Txn!$K22="","",Txn!$K22) -> 0 | N31: =IF($D31="",0,COUNTIF(BankAccts,$D31)) -> 0
A32: =IF(Txn!$B22="","",Txn!$B22) -> 0 | B32: =IF(Txn!$B22="","",Txn!$C22) -> 0 | C32: =IF(Txn!$B22="","","تراکنش بانکی") -> 0 | D32: =IF(Txn!$B22="","",IF(IF(Txn!$U22="TRF",Txn!$Y22,Txn!$Z22)="","",IF(Txn!$U22="TRF",Txn!$Y22,Txn!$Z22))) -> 0 | E32: =IF($D32="","",IFERROR(VLOOKUP($D32,AcctTbl,2,0),"")) -> 0 | F32: =IF($D32="","",IFERROR(VLOOKUP($D32,AcctTbl,3,0),"")) -> 0 | G32: =IF(Txn!$B22="","",Txn!$D22) -> 0 | H32: =IF(Txn!$B22="","",Txn!$E22) -> 0 | I32: =IF(Txn!$B22="",0,Txn!$Q22) -> 0 | J32: =IF(Txn!$B22="",0,Txn!$R22) -> 0 | K32: =IF($A32="","",IFERROR(VALUE(MID($A32,6,2)),"")) -> 0 | L32: =IF(Txn!$K22="","","طرف مقابل — "&Txn!$K22) -> 0 | N32: =IF($D32="",0,COUNTIF(BankAccts,$D32)) -> 0
A33: =IF(Txn!$B23="","",Txn!$B23) -> 0 | B33: =IF(Txn!$B23="","",Txn!$C23) -> 0 | C33: =IF(Txn!$B23="","","تراکنش بانکی") -> 0 | D33: =IF(Txn!$B23="","",IF(Txn!$X23="","",Txn!$X23)) -> 0 | E33: =IF($D33="","",IFERROR(VLOOKUP($D33,AcctTbl,2,0),"")) -> 0 | F33: =IF($D33="","",IFERROR(VLOOKUP($D33,AcctTbl,3,0),"")) -> 0 | G33: =IF(Txn!$B23="","",Txn!$D23) -> 0 | H33: =IF(Txn!$B23="","",Txn!$E23) -> 0 | I33: =IF(Txn!$B23="",0,Txn!$O23) -> 0 | J33: =IF(Txn!$B23="",0,Txn!$P23) -> 0 | K33: =IF($A33="","",IFERROR(VALUE(MID($A33,6,2)),"")) -> 0 | L33: =IF(Txn!$K23="","",Txn!$K23) -> 0 | N33: =IF($D33="",0,COUNTIF(BankAccts,$D33)) -> 0
A34: =IF(Txn!$B23="","",Txn!$B23) -> 0 | B34: =IF(Txn!$B23="","",Txn!$C23) -> 0 | C34: =IF(Txn!$B23="","","تراکنش بانکی") -> 0 | D34: =IF(Txn!$B23="","",IF(IF(Txn!$U23="TRF",Txn!$Y23,Txn!$Z23)="","",IF(Txn!$U23="TRF",Txn!$Y23,Txn!$Z23))) -> 0 | E34: =IF($D34="","",IFERROR(VLOOKUP($D34,AcctTbl,2,0),"")) -> 0 | F34: =IF($D34="","",IFERROR(VLOOKUP($D34,AcctTbl,3,0),"")) -> 0 | G34: =IF(Txn!$B23="","",Txn!$D23) -> 0 | H34: =IF(Txn!$B23="","",Txn!$E23) -> 0 | I34: =IF(Txn!$B23="",0,Txn!$Q23) -> 0 | J34: =IF(Txn!$B23="",0,Txn!$R23) -> 0 | K34: =IF($A34="","",IFERROR(VALUE(MID($A34,6,2)),"")) -> 0 | L34: =IF(Txn!$K23="","","طرف مقابل — "&Txn!$K23) -> 0 | N34: =IF($D34="",0,COUNTIF(BankAccts,$D34)) -> 0
A35: =IF(Txn!$B24="","",Txn!$B24) -> 0 | B35: =IF(Txn!$B24="","",Txn!$C24) -> 0 | C35: =IF(Txn!$B24="","","تراکنش بانکی") -> 0 | D35: =IF(Txn!$B24="","",IF(Txn!$X24="","",Txn!$X24)) -> 0 | E35: =IF($D35="","",IFERROR(VLOOKUP($D35,AcctTbl,2,0),"")) -> 0 | F35: =IF($D35="","",IFERROR(VLOOKUP($D35,AcctTbl,3,0),"")) -> 0 | G35: =IF(Txn!$B24="","",Txn!$D24) -> 0 | H35: =IF(Txn!$B24="","",Txn!$E24) -> 0 | I35: =IF(Txn!$B24="",0,Txn!$O24) -> 0 | J35: =IF(Txn!$B24="",0,Txn!$P24) -> 0 | K35: =IF($A35="","",IFERROR(VALUE(MID($A35,6,2)),"")) -> 0 | L35: =IF(Txn!$K24="","",Txn!$K24) -> 0 | N35: =IF($D35="",0,COUNTIF(BankAccts,$D35)) -> 0
A36: =IF(Txn!$B24="","",Txn!$B24) -> 0 | B36: =IF(Txn!$B24="","",Txn!$C24) -> 0 | C36: =IF(Txn!$B24="","","تراکنش بانکی") -> 0 | D36: =IF(Txn!$B24="","",IF(IF(Txn!$U24="TRF",Txn!$Y24,Txn!$Z24)="","",IF(Txn!$U24="TRF",Txn!$Y24,Txn!$Z24))) -> 0 | E36: =IF($D36="","",IFERROR(VLOOKUP($D36,AcctTbl,2,0),"")) -> 0 | F36: =IF($D36="","",IFERROR(VLOOKUP($D36,AcctTbl,3,0),"")) -> 0 | G36: =IF(Txn!$B24="","",Txn!$D24) -> 0 | H36: =IF(Txn!$B24="","",Txn!$E24) -> 0 | I36: =IF(Txn!$B24="",0,Txn!$Q24) -> 0 | J36: =IF(Txn!$B24="",0,Txn!$R24) -> 0 | K36: =IF($A36="","",IFERROR(VALUE(MID($A36,6,2)),"")) -> 0 | L36: =IF(Txn!$K24="","","طرف مقابل — "&Txn!$K24) -> 0 | N36: =IF($D36="",0,COUNTIF(BankAccts,$D36)) -> 0
A37: =IF(Txn!$B25="","",Txn!$B25) -> 0 | B37: =IF(Txn!$B25="","",Txn!$C25) -> 0 | C37: =IF(Txn!$B25="","","تراکنش بانکی") -> 0 | D37: =IF(Txn!$B25="","",IF(Txn!$X25="","",Txn!$X25)) -> 0 | E37: =IF($D37="","",IFERROR(VLOOKUP($D37,AcctTbl,2,0),"")) -> 0 | F37: =IF($D37="","",IFERROR(VLOOKUP($D37,AcctTbl,3,0),"")) -> 0 | G37: =IF(Txn!$B25="","",Txn!$D25) -> 0 | H37: =IF(Txn!$B25="","",Txn!$E25) -> 0 | I37: =IF(Txn!$B25="",0,Txn!$O25) -> 0 | J37: =IF(Txn!$B25="",0,Txn!$P25) -> 0 | K37: =IF($A37="","",IFERROR(VALUE(MID($A37,6,2)),"")) -> 0 | L37: =IF(Txn!$K25="","",Txn!$K25) -> 0 | N37: =IF($D37="",0,COUNTIF(BankAccts,$D37)) -> 0
A38: =IF(Txn!$B25="","",Txn!$B25) -> 0 | B38: =IF(Txn!$B25="","",Txn!$C25) -> 0 | C38: =IF(Txn!$B25="","","تراکنش بانکی") -> 0 | D38: =IF(Txn!$B25="","",IF(IF(Txn!$U25="TRF",Txn!$Y25,Txn!$Z25)="","",IF(Txn!$U25="TRF",Txn!$Y25,Txn!$Z25))) -> 0 | E38: =IF($D38="","",IFERROR(VLOOKUP($D38,AcctTbl,2,0),"")) -> 0 | F38: =IF($D38="","",IFERROR(VLOOKUP($D38,AcctTbl,3,0),"")) -> 0 | G38: =IF(Txn!$B25="","",Txn!$D25) -> 0 | H38: =IF(Txn!$B25="","",Txn!$E25) -> 0 | I38: =IF(Txn!$B25="",0,Txn!$Q25) -> 0 | J38: =IF(Txn!$B25="",0,Txn!$R25) -> 0 | K38: =IF($A38="","",IFERROR(VALUE(MID($A38,6,2)),"")) -> 0 | L38: =IF(Txn!$K25="","","طرف مقابل — "&Txn!$K25) -> 0 | N38: =IF($D38="",0,COUNTIF(BankAccts,$D38)) -> 0
A39: =IF(Txn!$B26="","",Txn!$B26) -> 0 | B39: =IF(Txn!$B26="","",Txn!$C26) -> 0 | C39: =IF(Txn!$B26="","","تراکنش بانکی") -> 0 | D39: =IF(Txn!$B26="","",IF(Txn!$X26="","",Txn!$X26)) -> 0 | E39: =IF($D39="","",IFERROR(VLOOKUP($D39,AcctTbl,2,0),"")) -> 0 | F39: =IF($D39="","",IFERROR(VLOOKUP($D39,AcctTbl,3,0),"")) -> 0 | G39: =IF(Txn!$B26="","",Txn!$D26) -> 0 | H39: =IF(Txn!$B26="","",Txn!$E26) -> 0 | I39: =IF(Txn!$B26="",0,Txn!$O26) -> 0 | J39: =IF(Txn!$B26="",0,Txn!$P26) -> 0 | K39: =IF($A39="","",IFERROR(VALUE(MID($A39,6,2)),"")) -> 0 | L39: =IF(Txn!$K26="","",Txn!$K26) -> 0 | N39: =IF($D39="",0,COUNTIF(BankAccts,$D39)) -> 0
A40: =IF(Txn!$B26="","",Txn!$B26) -> 0 | B40: =IF(Txn!$B26="","",Txn!$C26) -> 0 | C40: =IF(Txn!$B26="","","تراکنش بانکی") -> 0 | D40: =IF(Txn!$B26="","",IF(IF(Txn!$U26="TRF",Txn!$Y26,Txn!$Z26)="","",IF(Txn!$U26="TRF",Txn!$Y26,Txn!$Z26))) -> 0 | E40: =IF($D40="","",IFERROR(VLOOKUP($D40,AcctTbl,2,0),"")) -> 0 | F40: =IF($D40="","",IFERROR(VLOOKUP($D40,AcctTbl,3,0),"")) -> 0 | G40: =IF(Txn!$B26="","",Txn!$D26) -> 0 | H40: =IF(Txn!$B26="","",Txn!$E26) -> 0 | I40: =IF(Txn!$B26="",0,Txn!$Q26) -> 0 | J40: =IF(Txn!$B26="",0,Txn!$R26) -> 0 | K40: =IF($A40="","",IFERROR(VALUE(MID($A40,6,2)),"")) -> 0 | L40: =IF(Txn!$K26="","","طرف مقابل — "&Txn!$K26) -> 0 | N40: =IF($D40="",0,COUNTIF(BankAccts,$D40)) -> 0
A41: =IF(Txn!$B27="","",Txn!$B27) -> 0 | B41: =IF(Txn!$B27="","",Txn!$C27) -> 0 | C41: =IF(Txn!$B27="","","تراکنش بانکی") -> 0 | D41: =IF(Txn!$B27="","",IF(Txn!$X27="","",Txn!$X27)) -> 0 | E41: =IF($D41="","",IFERROR(VLOOKUP($D41,AcctTbl,2,0),"")) -> 0 | F41: =IF($D41="","",IFERROR(VLOOKUP($D41,AcctTbl,3,0),"")) -> 0 | G41: =IF(Txn!$B27="","",Txn!$D27) -> 0 | H41: =IF(Txn!$B27="","",Txn!$E27) -> 0 | I41: =IF(Txn!$B27="",0,Txn!$O27) -> 0 | J41: =IF(Txn!$B27="",0,Txn!$P27) -> 0 | K41: =IF($A41="","",IFERROR(VALUE(MID($A41,6,2)),"")) -> 0 | L41: =IF(Txn!$K27="","",Txn!$K27) -> 0 | N41: =IF($D41="",0,COUNTIF(BankAccts,$D41)) -> 0
A42: =IF(Txn!$B27="","",Txn!$B27) -> 0 | B42: =IF(Txn!$B27="","",Txn!$C27) -> 0 | C42: =IF(Txn!$B27="","","تراکنش بانکی") -> 0 | D42: =IF(Txn!$B27="","",IF(IF(Txn!$U27="TRF",Txn!$Y27,Txn!$Z27)="","",IF(Txn!$U27="TRF",Txn!$Y27,Txn!$Z27))) -> 0 | E42: =IF($D42="","",IFERROR(VLOOKUP($D42,AcctTbl,2,0),"")) -> 0 | F42: =IF($D42="","",IFERROR(VLOOKUP($D42,AcctTbl,3,0),"")) -> 0 | G42: =IF(Txn!$B27="","",Txn!$D27) -> 0 | H42: =IF(Txn!$B27="","",Txn!$E27) -> 0 | I42: =IF(Txn!$B27="",0,Txn!$Q27) -> 0 | J42: =IF(Txn!$B27="",0,Txn!$R27) -> 0 | K42: =IF($A42="","",IFERROR(VALUE(MID($A42,6,2)),"")) -> 0 | L42: =IF(Txn!$K27="","","طرف مقابل — "&Txn!$K27) -> 0 | N42: =IF($D42="",0,COUNTIF(BankAccts,$D42)) -> 0
A43: =IF(Txn!$B28="","",Txn!$B28) -> 0 | B43: =IF(Txn!$B28="","",Txn!$C28) -> 0 | C43: =IF(Txn!$B28="","","تراکنش بانکی") -> 0 | D43: =IF(Txn!$B28="","",IF(Txn!$X28="","",Txn!$X28)) -> 0 | E43: =IF($D43="","",IFERROR(VLOOKUP($D43,AcctTbl,2,0),"")) -> 0 | F43: =IF($D43="","",IFERROR(VLOOKUP($D43,AcctTbl,3,0),"")) -> 0 | G43: =IF(Txn!$B28="","",Txn!$D28) -> 0 | H43: =IF(Txn!$B28="","",Txn!$E28) -> 0 | I43: =IF(Txn!$B28="",0,Txn!$O28) -> 0 | J43: =IF(Txn!$B28="",0,Txn!$P28) -> 0 | K43: =IF($A43="","",IFERROR(VALUE(MID($A43,6,2)),"")) -> 0 | L43: =IF(Txn!$K28="","",Txn!$K28) -> 0 | N43: =IF($D43="",0,COUNTIF(BankAccts,$D43)) -> 0
A44: =IF(Txn!$B28="","",Txn!$B28) -> 0 | B44: =IF(Txn!$B28="","",Txn!$C28) -> 0 | C44: =IF(Txn!$B28="","","تراکنش بانکی") -> 0 | D44: =IF(Txn!$B28="","",IF(IF(Txn!$U28="TRF",Txn!$Y28,Txn!$Z28)="","",IF(Txn!$U28="TRF",Txn!$Y28,Txn!$Z28))) -> 0 | E44: =IF($D44="","",IFERROR(VLOOKUP($D44,AcctTbl,2,0),"")) -> 0 | F44: =IF($D44="","",IFERROR(VLOOKUP($D44,AcctTbl,3,0),"")) -> 0 | G44: =IF(Txn!$B28="","",Txn!$D28) -> 0 | H44: =IF(Txn!$B28="","",Txn!$E28) -> 0 | I44: =IF(Txn!$B28="",0,Txn!$Q28) -> 0 | J44: =IF(Txn!$B28="",0,Txn!$R28) -> 0 | K44: =IF($A44="","",IFERROR(VALUE(MID($A44,6,2)),"")) -> 0 | L44: =IF(Txn!$K28="","","طرف مقابل — "&Txn!$K28) -> 0 | N44: =IF($D44="",0,COUNTIF(BankAccts,$D44)) -> 0
A45: =IF(Txn!$B29="","",Txn!$B29) -> 0 | B45: =IF(Txn!$B29="","",Txn!$C29) -> 0 | C45: =IF(Txn!$B29="","","تراکنش بانکی") -> 0 | D45: =IF(Txn!$B29="","",IF(Txn!$X29="","",Txn!$X29)) -> 0 | E45: =IF($D45="","",IFERROR(VLOOKUP($D45,AcctTbl,2,0),"")) -> 0 | F45: =IF($D45="","",IFERROR(VLOOKUP($D45,AcctTbl,3,0),"")) -> 0 | G45: =IF(Txn!$B29="","",Txn!$D29) -> 0 | H45: =IF(Txn!$B29="","",Txn!$E29) -> 0 | I45: =IF(Txn!$B29="",0,Txn!$O29) -> 0 | J45: =IF(Txn!$B29="",0,Txn!$P29) -> 0 | K45: =IF($A45="","",IFERROR(VALUE(MID($A45,6,2)),"")) -> 0 | L45: =IF(Txn!$K29="","",Txn!$K29) -> 0 | N45: =IF($D45="",0,COUNTIF(BankAccts,$D45)) -> 0
A46: =IF(Txn!$B29="","",Txn!$B29) -> 0 | B46: =IF(Txn!$B29="","",Txn!$C29) -> 0 | C46: =IF(Txn!$B29="","","تراکنش بانکی") -> 0 | D46: =IF(Txn!$B29="","",IF(IF(Txn!$U29="TRF",Txn!$Y29,Txn!$Z29)="","",IF(Txn!$U29="TRF",Txn!$Y29,Txn!$Z29))) -> 0 | E46: =IF($D46="","",IFERROR(VLOOKUP($D46,AcctTbl,2,0),"")) -> 0 | F46: =IF($D46="","",IFERROR(VLOOKUP($D46,AcctTbl,3,0),"")) -> 0 | G46: =IF(Txn!$B29="","",Txn!$D29) -> 0 | H46: =IF(Txn!$B29="","",Txn!$E29) -> 0 | I46: =IF(Txn!$B29="",0,Txn!$Q29) -> 0 | J46: =IF(Txn!$B29="",0,Txn!$R29) -> 0 | K46: =IF($A46="","",IFERROR(VALUE(MID($A46,6,2)),"")) -> 0 | L46: =IF(Txn!$K29="","","طرف مقابل — "&Txn!$K29) -> 0 | N46: =IF($D46="",0,COUNTIF(BankAccts,$D46)) -> 0
A47: =IF(Txn!$B30="","",Txn!$B30) -> 0 | B47: =IF(Txn!$B30="","",Txn!$C30) -> 0 | C47: =IF(Txn!$B30="","","تراکنش بانکی") -> 0 | D47: =IF(Txn!$B30="","",IF(Txn!$X30="","",Txn!$X30)) -> 0 | E47: =IF($D47="","",IFERROR(VLOOKUP($D47,AcctTbl,2,0),"")) -> 0 | F47: =IF($D47="","",IFERROR(VLOOKUP($D47,AcctTbl,3,0),"")) -> 0 | G47: =IF(Txn!$B30="","",Txn!$D30) -> 0 | H47: =IF(Txn!$B30="","",Txn!$E30) -> 0 | I47: =IF(Txn!$B30="",0,Txn!$O30) -> 0 | J47: =IF(Txn!$B30="",0,Txn!$P30) -> 0 | K47: =IF($A47="","",IFERROR(VALUE(MID($A47,6,2)),"")) -> 0 | L47: =IF(Txn!$K30="","",Txn!$K30) -> 0 | N47: =IF($D47="",0,COUNTIF(BankAccts,$D47)) -> 0
A48: =IF(Txn!$B30="","",Txn!$B30) -> 0 | B48: =IF(Txn!$B30="","",Txn!$C30) -> 0 | C48: =IF(Txn!$B30="","","تراکنش بانکی") -> 0 | D48: =IF(Txn!$B30="","",IF(IF(Txn!$U30="TRF",Txn!$Y30,Txn!$Z30)="","",IF(Txn!$U30="TRF",Txn!$Y30,Txn!$Z30))) -> 0 | E48: =IF($D48="","",IFERROR(VLOOKUP($D48,AcctTbl,2,0),"")) -> 0 | F48: =IF($D48="","",IFERROR(VLOOKUP($D48,AcctTbl,3,0),"")) -> 0 | G48: =IF(Txn!$B30="","",Txn!$D30) -> 0 | H48: =IF(Txn!$B30="","",Txn!$E30) -> 0 | I48: =IF(Txn!$B30="",0,Txn!$Q30) -> 0 | J48: =IF(Txn!$B30="",0,Txn!$R30) -> 0 | K48: =IF($A48="","",IFERROR(VALUE(MID($A48,6,2)),"")) -> 0 | L48: =IF(Txn!$K30="","","طرف مقابل — "&Txn!$K30) -> 0 | N48: =IF($D48="",0,COUNTIF(BankAccts,$D48)) -> 0
A49: =IF(Txn!$B31="","",Txn!$B31) -> 0 | B49: =IF(Txn!$B31="","",Txn!$C31) -> 0 | C49: =IF(Txn!$B31="","","تراکنش بانکی") -> 0 | D49: =IF(Txn!$B31="","",IF(Txn!$X31="","",Txn!$X31)) -> 0 | E49: =IF($D49="","",IFERROR(VLOOKUP($D49,AcctTbl,2,0),"")) -> 0 | F49: =IF($D49="","",IFERROR(VLOOKUP($D49,AcctTbl,3,0),"")) -> 0 | G49: =IF(Txn!$B31="","",Txn!$D31) -> 0 | H49: =IF(Txn!$B31="","",Txn!$E31) -> 0 | I49: =IF(Txn!$B31="",0,Txn!$O31) -> 0 | J49: =IF(Txn!$B31="",0,Txn!$P31) -> 0 | K49: =IF($A49="","",IFERROR(VALUE(MID($A49,6,2)),"")) -> 0 | L49: =IF(Txn!$K31="","",Txn!$K31) -> 0 | N49: =IF($D49="",0,COUNTIF(BankAccts,$D49)) -> 0
A50: =IF(Txn!$B31="","",Txn!$B31) -> 0 | B50: =IF(Txn!$B31="","",Txn!$C31) -> 0 | C50: =IF(Txn!$B31="","","تراکنش بانکی") -> 0 | D50: =IF(Txn!$B31="","",IF(IF(Txn!$U31="TRF",Txn!$Y31,Txn!$Z31)="","",IF(Txn!$U31="TRF",Txn!$Y31,Txn!$Z31))) -> 0 | E50: =IF($D50="","",IFERROR(VLOOKUP($D50,AcctTbl,2,0),"")) -> 0 | F50: =IF($D50="","",IFERROR(VLOOKUP($D50,AcctTbl,3,0),"")) -> 0 | G50: =IF(Txn!$B31="","",Txn!$D31) -> 0 | H50: =IF(Txn!$B31="","",Txn!$E31) -> 0 | I50: =IF(Txn!$B31="",0,Txn!$Q31) -> 0 | J50: =IF(Txn!$B31="",0,Txn!$R31) -> 0 | K50: =IF($A50="","",IFERROR(VALUE(MID($A50,6,2)),"")) -> 0 | L50: =IF(Txn!$K31="","","طرف مقابل — "&Txn!$K31) -> 0 | N50: =IF($D50="",0,COUNTIF(BankAccts,$D50)) -> 0
A51: =IF(Txn!$B32="","",Txn!$B32) -> 0 | B51: =IF(Txn!$B32="","",Txn!$C32) -> 0 | C51: =IF(Txn!$B32="","","تراکنش بانکی") -> 0 | D51: =IF(Txn!$B32="","",IF(Txn!$X32="","",Txn!$X32)) -> 0 | E51: =IF($D51="","",IFERROR(VLOOKUP($D51,AcctTbl,2,0),"")) -> 0 | F51: =IF($D51="","",IFERROR(VLOOKUP($D51,AcctTbl,3,0),"")) -> 0 | G51: =IF(Txn!$B32="","",Txn!$D32) -> 0 | H51: =IF(Txn!$B32="","",Txn!$E32) -> 0 | I51: =IF(Txn!$B32="",0,Txn!$O32) -> 0 | J51: =IF(Txn!$B32="",0,Txn!$P32) -> 0 | K51: =IF($A51="","",IFERROR(VALUE(MID($A51,6,2)),"")) -> 0 | L51: =IF(Txn!$K32="","",Txn!$K32) -> 0 | N51: =IF($D51="",0,COUNTIF(BankAccts,$D51)) -> 0
...

Sheet Sum
A2: مازندشت · سورتینگ و بسته‌بندی مرکبات · MAZANDASHT · CITRUS SORTING & PACKING
A3: مانده و گردش حساب‌های بانکی
A4: مانده هر بانک = مانده اولیه + دریافت‌ها − پرداخت‌ها · همه از دفتر تراکنش‌ها
A7: جمع مانده بانک‌ها | C7: جمع دریافت | E7: جمع پرداخت | G7: خالص جریان
A8: =SUM($F$12:$F$21) -> 0 | C8: =SUM($C$12:$C$21) -> 0 | E8: =SUM($D$12:$D$21) -> 0 | G8: =$C$22-$D$22 -> 0
A10: وضعیت هر بانک به ترتیب مانده | G10: ۰۱
A11: بانک | B11: مانده اولیه | C11: دریافت | D11: پرداخت | E11: مانده فعلی | F11: سهم | G11: شماره حساب | H11: یادداشت
A12: =INDEX(BankTbl,1,2) -> 0 | B12: =INDEX(BankTbl,1,3) -> 0 | C12: =SUMIFS(Post!$I$13:$I$292,Post!$D$13:$D$292,$G12) -> 0 | D12: =SUMIFS(Post!$J$13:$J$292,Post!$D$13:$D$292,$G12) -> 0 | E12: =$B12+$C12-$D12 -> 0 | F12: =IFERROR($E12/SUM($E$12:$E$21),0) -> 0 | G12: =INDEX(BankTbl,1,4) -> 0 | H12: =INDEX(BankTbl,1,6) -> 0
A13: =INDEX(BankTbl,2,2) -> 0 | B13: =INDEX(BankTbl,2,3) -> 0 | C13: =SUMIFS(Post!$I$13:$I$292,Post!$D$13:$D$292,$G13) -> 0 | D13: =SUMIFS(Post!$J$13:$J$292,Post!$D$13:$D$292,$G13) -> 0 | E13: =$B13+$C13-$D13 -> 0 | F13: =IFERROR($E13/SUM($E$12:$E$21),0) -> 0 | G13: =INDEX(BankTbl,2,4) -> 0 | H13: =INDEX(BankTbl,2,6) -> 0
A14: =INDEX(BankTbl,3,2) -> 0 | B14: =INDEX(BankTbl,3,3) -> 0 | C14: =SUMIFS(Post!$I$13:$I$292,Post!$D$13:$D$292,$G14) -> 0 | D14: =SUMIFS(Post!$J$13:$J$292,Post!$D$13:$D$292,$G14) -> 0 | E14: =$B14+$C14-$D14 -> 0 | F14: =IFERROR($E14/SUM($E$12:$E$21),0) -> 0 | G14: =INDEX(BankTbl,3,4) -> 0 | H14: =INDEX(BankTbl,3,6) -> 0
A15: =INDEX(BankTbl,4,2) -> 0 | B15: =INDEX(BankTbl,4,3) -> 0 | C15: =SUMIFS(Post!$I$13:$I$292,Post!$D$13:$D$292,$G15) -> 0 | D15: =SUMIFS(Post!$J$13:$J$292,Post!$D$13:$D$292,$G15) -> 0 | E15: =$B15+$C15-$D15 -> 0 | F15: =IFERROR($E15/SUM($E$12:$E$21),0) -> 0 | G15: =INDEX(BankTbl,4,4) -> 0 | H15: =INDEX(BankTbl,4,6) -> 0
A16: =INDEX(BankTbl,5,2) -> 0 | B16: =INDEX(BankTbl,5,3) -> 0 | C16: =SUMIFS(Post!$I$13:$I$292,Post!$D$13:$D$292,$G16) -> 0 | D16: =SUMIFS(Post!$J$13:$J$292,Post!$D$13:$D$292,$G16) -> 0 | E16: =$B16+$C16-$D16 -> 0 | F16: =IFERROR($E16/SUM($E$12:$E$21),0) -> 0 | G16: =INDEX(BankTbl,5,4) -> 0 | H16: =INDEX(BankTbl,5,6) -> 0
A17: =INDEX(BankTbl,6,2) -> 0 | B17: =INDEX(BankTbl,6,3) -> 0 | C17: =SUMIFS(Post!$I$13:$I$292,Post!$D$13:$D$292,$G17) -> 0 | D17: =SUMIFS(Post!$J$13:$J$292,Post!$D$13:$D$292,$G17) -> 0 | E17: =$B17+$C17-$D17 -> 0 | F17: =IFERROR($E17/SUM($E$12:$E$21),0) -> 0 | G17: =INDEX(BankTbl,6,4) -> 0 | H17: =INDEX(BankTbl,6,6) -> 0
A18: =INDEX(BankTbl,7,2) -> 0 | B18: =INDEX(BankTbl,7,3) -> 0 | C18: =SUMIFS(Post!$I$13:$I$292,Post!$D$13:$D$292,$G18) -> 0 | D18: =SUMIFS(Post!$J$13:$J$292,Post!$D$13:$D$292,$G18) -> 0 | E18: =$B18+$C18-$D18 -> 0 | F18: =IFERROR($E18/SUM($E$12:$E$21),0) -> 0 | G18: =INDEX(BankTbl,7,4) -> 0 | H18: =INDEX(BankTbl,7,6) -> 0
A19: =INDEX(BankTbl,8,2) -> 0 | B19: =INDEX(BankTbl,8,3) -> 0 | C19: =SUMIFS(Post!$I$13:$I$292,Post!$D$13:$D$292,$G19) -> 0 | D19: =SUMIFS(Post!$J$13:$J$292,Post!$D$13:$D$292,$G19) -> 0 | E19: =$B19+$C19-$D19 -> 0 | F19: =IFERROR($E19/SUM($E$12:$E$21),0) -> 0 | G19: =INDEX(BankTbl,8,4) -> 0 | H19: =INDEX(BankTbl,8,6) -> 0
A20: =INDEX(BankTbl,9,2) -> 0 | B20: =INDEX(BankTbl,9,3) -> 0 | C20: =SUMIFS(Post!$I$13:$I$292,Post!$D$13:$D$292,$G20) -> 0 | D20: =SUMIFS(Post!$J$13:$J$292,Post!$D$13:$D$292,$G20) -> 0 | E20: =$B20+$C20-$D20 -> 0 | F20: =IFERROR($E20/SUM($E$12:$E$21),0) -> 0 | G20: =INDEX(BankTbl,9,4) -> 0 | H20: =INDEX(BankTbl,9,6) -> 0
