Workbook

Sheet Dash
A2: مازندشت · سورتینگ و بسته‌بندی مرکبات · MAZANDASHT · CITRUS SORTING & PACKING
A3: داشبورد مدیریتی مازندشت
A4: یک نگاه به وزن، مبلغ، بانک، پز و طرف حساب‌ها · همه اعداد از ثبت روزانه و فایل بانک
A7: کل وزن (kg) | C7: کل مبلغ | E7: جمع بدهکار | G7: اختلاف پز
A8: =Time!A8 -> 0 | C8: =Time!C8 -> 0 | E8: =Time!E8 -> 0 | G8: =Pos!G8 -> 0
A9: روند ماهانه — وزن و مبلغ از دفتر ثبت روزانه | G9: ۰۱
A10: ماه | B10: وزن (kg) | C10: مبلغ
A11: =Time!$A$13 -> 0 | B11: =Time!$C$13 -> 0 | C11: =Time!$D$13 -> 0
A12: =Time!$A$14 -> 0 | B12: =Time!$C$14 -> 0 | C12: =Time!$D$14 -> 0
A13: =Time!$A$15 -> 0 | B13: =Time!$C$15 -> 0 | C13: =Time!$D$15 -> 0
A14: =Time!$A$16 -> 0 | B14: =Time!$C$16 -> 0 | C14: =Time!$D$16 -> 0
A15: =Time!$A$17 -> 0 | B15: =Time!$C$17 -> 0 | C15: =Time!$D$17 -> 0
A16: =Time!$A$18 -> 0 | B16: =Time!$C$18 -> 0 | C16: =Time!$D$18 -> 0
A17: =Time!$A$19 -> 0 | B17: =Time!$C$19 -> 0 | C17: =Time!$D$19 -> 0
A18: =Time!$A$20 -> 0 | B18: =Time!$C$20 -> 0 | C18: =Time!$D$20 -> 0
A19: =Time!$A$21 -> 0 | B19: =Time!$C$21 -> 0 | C19: =Time!$D$21 -> 0
A20: =Time!$A$22 -> 0 | B20: =Time!$C$22 -> 0 | C20: =Time!$D$22 -> 0
A21: =Time!$A$23 -> 0 | B21: =Time!$C$23 -> 0 | C21: =Time!$D$23 -> 0
A22: =Time!$A$24 -> 0 | B22: =Time!$C$24 -> 0 | C22: =Time!$D$24 -> 0
A24: ترکیب عملیات سهم هر نوع از مبلغ کل | G24: ۰۲
A25: =Ops!$A$13 -> 0 | B25: =Ops!$D$13 -> 0
A26: =Ops!$A$14 -> 0 | B26: =Ops!$D$14 -> 0
A27: =Ops!$A$15 -> 0 | B27: =Ops!$D$15 -> 0
A28: =Ops!$A$16 -> 0 | B28: =Ops!$D$16 -> 0
A29: =Ops!$A$17 -> 0 | B29: =Ops!$D$17 -> 0
A30: =Ops!$A$18 -> 0 | B30: =Ops!$D$18 -> 0
A33: مانده بانک‌ها از فایل تراکنش‌ها | G33: ۰۳
A34: بانک | B34: دریافت | C34: پرداخت | D34: مانده
A35: =Banks!$A$13 -> 0 | B35: =Banks!$B$13 -> 0 | C35: =Banks!$C$13 -> 0 | D35: =Banks!$D$13 -> 0
A36: =Banks!$A$14 -> 0 | B36: =Banks!$B$14 -> 0 | C36: =Banks!$C$14 -> 0 | D36: =Banks!$D$14 -> 0
A37: =Banks!$A$15 -> 0 | B37: =Banks!$B$15 -> 0 | C37: =Banks!$C$15 -> 0 | D37: =Banks!$D$15 -> 0
A38: =Banks!$A$16 -> 0 | B38: =Banks!$B$16 -> 0 | C38: =Banks!$C$16 -> 0 | D38: =Banks!$D$16 -> 0
A39: =Banks!$A$17 -> 0 | B39: =Banks!$B$17 -> 0 | C39: =Banks!$C$17 -> 0 | D39: =Banks!$D$17 -> 0
A41: هشدارها مواردی که باید همین امروز بررسی شود | G41: ۰۴
A42: ردیف‌های ناقص باسکول | D42: =SUM(F1!$L$10:$L$1808)-SUM(F1!$M$10:$M$1808) -> 0 | F42: اختلاف بدهکار/بستانکار دفتر
A43: اختلاف پز | D43: =Pos!G8 -> 0 | F43: پز دفتر روزنامه منهای واریز پز به بانک
A44: مانده منفی بانک | D44: =COUNTIF(Banks!$D$13:$D$22,"<0") -> 0 | F44: تعداد حساب‌هایی که مانده منفی دارند
A46: شیت‌های این داشبورد روی هر کارت کلیک کنید | G46: ۰۵
A47: پز و واریزی Pos | C47: بانک‌ها Banks | E47: روند Time
A48: کنترل روزانه پز دفتر روزنامه در برابر واریز پز به بانک | C48: مانده و سهم هر بانک از گردش | E48: وزن و مبلغ ماه به ماه
...

Sheet Pos
A2: مازندشت · سورتینگ و بسته‌بندی مرکبات · MAZANDASHT · CITRUS SORTING & PACKING
A3: کنترل پز روزانه و واریز آن به بانک
A4: پز ثبت‌شده در دفتر روزنامه ↔ واریزی همان روز به حساب بانکی ↔ سایر واریزها
A7: پز دفتر روزنامه | C7: واریز پز به بانک | E7: سایر واریزها | G7: اختلاف
A8: =SUM($C$13:$C$52) -> 0 | C8: =SUM($D$13:$D$52) -> 0 | E8: =SUM($E$13:$E$52) -> 0 | G8: =SUM($F$13:$F$52) -> 0
A12: تاریخ Date | B12: تاریخ واریز Deposit | C12: پز دفتر Journal POS | D12: واریز پز به بانک POS bank | E12: سایر واریزها Other | F12: اختلاف Diff | G12: وضعیت Status
A13: 1405/07/01 | C13: =IF($A13="","",SUMIFS(F1!$L$10:$L$1808,F1!$A$10:$A$1808,$A13,F1!$D$10:$D$1808,"X011",F1!$N$10:$N$1808,"پوز")) -> 0 | D13: =IF($A13="","",SUMIFS(F2!$I$10:$I$289,F2!$A$10:$A$289,IF($B13="",$A13,$B13),F2!$D$10:$D$289,"BN*",F2!$G$10:$G$289,"واریز پز باسکول (۲۰۰۶)")) -> 0 | E13: =IF($A13="","",SUMIFS(F2!$I$10:$I$289,F2!$A$10:$A$289,IF($B13="",$A13,$B13),F2!$D$10:$D$289,"BN*",F2!$G$10:$G$289,"تسویه دریافت (واسط)")) -> 0 | F13: =IF($A13="","",$C13-$D13) -> 0 | G13: =IF($A13="","",IF(ABS($F13)<=1000,"✓ تراز","⚠ بررسی شود")) -> 0
A14: 1405/07/02 | C14: =IF($A14="","",SUMIFS(F1!$L$10:$L$1808,F1!$A$10:$A$1808,$A14,F1!$D$10:$D$1808,"X011",F1!$N$10:$N$1808,"پوز")) -> 0 | D14: =IF($A14="","",SUMIFS(F2!$I$10:$I$289,F2!$A$10:$A$289,IF($B14="",$A14,$B14),F2!$D$10:$D$289,"BN*",F2!$G$10:$G$289,"واریز پز باسکول (۲۰۰۶)")) -> 0 | E14: =IF($A14="","",SUMIFS(F2!$I$10:$I$289,F2!$A$10:$A$289,IF($B14="",$A14,$B14),F2!$D$10:$D$289,"BN*",F2!$G$10:$G$289,"تسویه دریافت (واسط)")) -> 0 | F14: =IF($A14="","",$C14-$D14) -> 0 | G14: =IF($A14="","",IF(ABS($F14)<=1000,"✓ تراز","⚠ بررسی شود")) -> 0
A15: 1405/07/03 | C15: =IF($A15="","",SUMIFS(F1!$L$10:$L$1808,F1!$A$10:$A$1808,$A15,F1!$D$10:$D$1808,"X011",F1!$N$10:$N$1808,"پوز")) -> 0 | D15: =IF($A15="","",SUMIFS(F2!$I$10:$I$289,F2!$A$10:$A$289,IF($B15="",$A15,$B15),F2!$D$10:$D$289,"BN*",F2!$G$10:$G$289,"واریز پز باسکول (۲۰۰۶)")) -> 0 | E15: =IF($A15="","",SUMIFS(F2!$I$10:$I$289,F2!$A$10:$A$289,IF($B15="",$A15,$B15),F2!$D$10:$D$289,"BN*",F2!$G$10:$G$289,"تسویه دریافت (واسط)")) -> 0 | F15: =IF($A15="","",$C15-$D15) -> 0 | G15: =IF($A15="","",IF(ABS($F15)<=1000,"✓ تراز","⚠ بررسی شود")) -> 0
A16: 1405/07/04 | C16: =IF($A16="","",SUMIFS(F1!$L$10:$L$1808,F1!$A$10:$A$1808,$A16,F1!$D$10:$D$1808,"X011",F1!$N$10:$N$1808,"پوز")) -> 0 | D16: =IF($A16="","",SUMIFS(F2!$I$10:$I$289,F2!$A$10:$A$289,IF($B16="",$A16,$B16),F2!$D$10:$D$289,"BN*",F2!$G$10:$G$289,"واریز پز باسکول (۲۰۰۶)")) -> 0 | E16: =IF($A16="","",SUMIFS(F2!$I$10:$I$289,F2!$A$10:$A$289,IF($B16="",$A16,$B16),F2!$D$10:$D$289,"BN*",F2!$G$10:$G$289,"تسویه دریافت (واسط)")) -> 0 | F16: =IF($A16="","",$C16-$D16) -> 0 | G16: =IF($A16="","",IF(ABS($F16)<=1000,"✓ تراز","⚠ بررسی شود")) -> 0
A17: 1405/07/05 | C17: =IF($A17="","",SUMIFS(F1!$L$10:$L$1808,F1!$A$10:$A$1808,$A17,F1!$D$10:$D$1808,"X011",F1!$N$10:$N$1808,"پوز")) -> 0 | D17: =IF($A17="","",SUMIFS(F2!$I$10:$I$289,F2!$A$10:$A$289,IF($B17="",$A17,$B17),F2!$D$10:$D$289,"BN*",F2!$G$10:$G$289,"واریز پز باسکول (۲۰۰۶)")) -> 0 | E17: =IF($A17="","",SUMIFS(F2!$I$10:$I$289,F2!$A$10:$A$289,IF($B17="",$A17,$B17),F2!$D$10:$D$289,"BN*",F2!$G$10:$G$289,"تسویه دریافت (واسط)")) -> 0 | F17: =IF($A17="","",$C17-$D17) -> 0 | G17: =IF($A17="","",IF(ABS($F17)<=1000,"✓ تراز","⚠ بررسی شود")) -> 0
A18: 1405/07/06 | C18: =IF($A18="","",SUMIFS(F1!$L$10:$L$1808,F1!$A$10:$A$1808,$A18,F1!$D$10:$D$1808,"X011",F1!$N$10:$N$1808,"پوز")) -> 0 | D18: =IF($A18="","",SUMIFS(F2!$I$10:$I$289,F2!$A$10:$A$289,IF($B18="",$A18,$B18),F2!$D$10:$D$289,"BN*",F2!$G$10:$G$289,"واریز پز باسکول (۲۰۰۶)")) -> 0 | E18: =IF($A18="","",SUMIFS(F2!$I$10:$I$289,F2!$A$10:$A$289,IF($B18="",$A18,$B18),F2!$D$10:$D$289,"BN*",F2!$G$10:$G$289,"تسویه دریافت (واسط)")) -> 0 | F18: =IF($A18="","",$C18-$D18) -> 0 | G18: =IF($A18="","",IF(ABS($F18)<=1000,"✓ تراز","⚠ بررسی شود")) -> 0
A19: 1405/07/07 | C19: =IF($A19="","",SUMIFS(F1!$L$10:$L$1808,F1!$A$10:$A$1808,$A19,F1!$D$10:$D$1808,"X011",F1!$N$10:$N$1808,"پوز")) -> 0 | D19: =IF($A19="","",SUMIFS(F2!$I$10:$I$289,F2!$A$10:$A$289,IF($B19="",$A19,$B19),F2!$D$10:$D$289,"BN*",F2!$G$10:$G$289,"واریز پز باسکول (۲۰۰۶)")) -> 0 | E19: =IF($A19="","",SUMIFS(F2!$I$10:$I$289,F2!$A$10:$A$289,IF($B19="",$A19,$B19),F2!$D$10:$D$289,"BN*",F2!$G$10:$G$289,"تسویه دریافت (واسط)")) -> 0 | F19: =IF($A19="","",$C19-$D19) -> 0 | G19: =IF($A19="","",IF(ABS($F19)<=1000,"✓ تراز","⚠ بررسی شود")) -> 0
A20: 1405/07/08 | C20: =IF($A20="","",SUMIFS(F1!$L$10:$L$1808,F1!$A$10:$A$1808,$A20,F1!$D$10:$D$1808,"X011",F1!$N$10:$N$1808,"پوز")) -> 0 | D20: =IF($A20="","",SUMIFS(F2!$I$10:$I$289,F2!$A$10:$A$289,IF($B20="",$A20,$B20),F2!$D$10:$D$289,"BN*",F2!$G$10:$G$289,"واریز پز باسکول (۲۰۰۶)")) -> 0 | E20: =IF($A20="","",SUMIFS(F2!$I$10:$I$289,F2!$A$10:$A$289,IF($B20="",$A20,$B20),F2!$D$10:$D$289,"BN*",F2!$G$10:$G$289,"تسویه دریافت (واسط)")) -> 0 | F20: =IF($A20="","",$C20-$D20) -> 0 | G20: =IF($A20="","",IF(ABS($F20)<=1000,"✓ تراز","⚠ بررسی شود")) -> 0
A21: 1405/07/09 | C21: =IF($A21="","",SUMIFS(F1!$L$10:$L$1808,F1!$A$10:$A$1808,$A21,F1!$D$10:$D$1808,"X011",F1!$N$10:$N$1808,"پوز")) -> 0 | D21: =IF($A21="","",SUMIFS(F2!$I$10:$I$289,F2!$A$10:$A$289,IF($B21="",$A21,$B21),F2!$D$10:$D$289,"BN*",F2!$G$10:$G$289,"واریز پز باسکول (۲۰۰۶)")) -> 0 | E21: =IF($A21="","",SUMIFS(F2!$I$10:$I$289,F2!$A$10:$A$289,IF($B21="",$A21,$B21),F2!$D$10:$D$289,"BN*",F2!$G$10:$G$289,"تسویه دریافت (واسط)")) -> 0 | F21: =IF($A21="","",$C21-$D21) -> 0 | G21: =IF($A21="","",IF(ABS($F21)<=1000,"✓ تراز","⚠ بررسی شود")) -> 0
A22: 1405/07/10 | C22: =IF($A22="","",SUMIFS(F1!$L$10:$L$1808,F1!$A$10:$A$1808,$A22,F1!$D$10:$D$1808,"X011",F1!$N$10:$N$1808,"پوز")) -> 0 | D22: =IF($A22="","",SUMIFS(F2!$I$10:$I$289,F2!$A$10:$A$289,IF($B22="",$A22,$B22),F2!$D$10:$D$289,"BN*",F2!$G$10:$G$289,"واریز پز باسکول (۲۰۰۶)")) -> 0 | E22: =IF($A22="","",SUMIFS(F2!$I$10:$I$289,F2!$A$10:$A$289,IF($B22="",$A22,$B22),F2!$D$10:$D$289,"BN*",F2!$G$10:$G$289,"تسویه دریافت (واسط)")) -> 0 | F22: =IF($A22="","",$C22-$D22) -> 0 | G22: =IF($A22="","",IF(ABS($F22)<=1000,"✓ تراز","⚠ بررسی شود")) -> 0
A23: 1405/07/11 | C23: =IF($A23="","",SUMIFS(F1!$L$10:$L$1808,F1!$A$10:$A$1808,$A23,F1!$D$10:$D$1808,"X011",F1!$N$10:$N$1808,"پوز")) -> 0 | D23: =IF($A23="","",SUMIFS(F2!$I$10:$I$289,F2!$A$10:$A$289,IF($B23="",$A23,$B23),F2!$D$10:$D$289,"BN*",F2!$G$10:$G$289,"واریز پز باسکول (۲۰۰۶)")) -> 0 | E23: =IF($A23="","",SUMIFS(F2!$I$10:$I$289,F2!$A$10:$A$289,IF($B23="",$A23,$B23),F2!$D$10:$D$289,"BN*",F2!$G$10:$G$289,"تسویه دریافت (واسط)")) -> 0 | F23: =IF($A23="","",$C23-$D23) -> 0 | G23: =IF($A23="","",IF(ABS($F23)<=1000,"✓ تراز","⚠ بررسی شود")) -> 0
A24: 1405/07/12 | C24: =IF($A24="","",SUMIFS(F1!$L$10:$L$1808,F1!$A$10:$A$1808,$A24,F1!$D$10:$D$1808,"X011",F1!$N$10:$N$1808,"پوز")) -> 0 | D24: =IF($A24="","",SUMIFS(F2!$I$10:$I$289,F2!$A$10:$A$289,IF($B24="",$A24,$B24),F2!$D$10:$D$289,"BN*",F2!$G$10:$G$289,"واریز پز باسکول (۲۰۰۶)")) -> 0 | E24: =IF($A24="","",SUMIFS(F2!$I$10:$I$289,F2!$A$10:$A$289,IF($B24="",$A24,$B24),F2!$D$10:$D$289,"BN*",F2!$G$10:$G$289,"تسویه دریافت (واسط)")) -> 0 | F24: =IF($A24="","",$C24-$D24) -> 0 | G24: =IF($A24="","",IF(ABS($F24)<=1000,"✓ تراز","⚠ بررسی شود")) -> 0
C25: =IF($A25="","",SUMIFS(F1!$L$10:$L$1808,F1!$A$10:$A$1808,$A25,F1!$D$10:$D$1808,"X011",F1!$N$10:$N$1808,"پوز")) -> 0 | D25: =IF($A25="","",SUMIFS(F2!$I$10:$I$289,F2!$A$10:$A$289,IF($B25="",$A25,$B25),F2!$D$10:$D$289,"BN*",F2!$G$10:$G$289,"واریز پز باسکول (۲۰۰۶)")) -> 0 | E25: =IF($A25="","",SUMIFS(F2!$I$10:$I$289,F2!$A$10:$A$289,IF($B25="",$A25,$B25),F2!$D$10:$D$289,"BN*",F2!$G$10:$G$289,"تسویه دریافت (واسط)")) -> 0 | F25: =IF($A25="","",$C25-$D25) -> 0 | G25: =IF($A25="","",IF(ABS($F25)<=1000,"✓ تراز","⚠ بررسی شود")) -> 0
C26: =IF($A26="","",SUMIFS(F1!$L$10:$L$1808,F1!$A$10:$A$1808,$A26,F1!$D$10:$D$1808,"X011",F1!$N$10:$N$1808,"پوز")) -> 0 | D26: =IF($A26="","",SUMIFS(F2!$I$10:$I$289,F2!$A$10:$A$289,IF($B26="",$A26,$B26),F2!$D$10:$D$289,"BN*",F2!$G$10:$G$289,"واریز پز باسکول (۲۰۰۶)")) -> 0 | E26: =IF($A26="","",SUMIFS(F2!$I$10:$I$289,F2!$A$10:$A$289,IF($B26="",$A26,$B26),F2!$D$10:$D$289,"BN*",F2!$G$10:$G$289,"تسویه دریافت (واسط)")) -> 0 | F26: =IF($A26="","",$C26-$D26) -> 0 | G26: =IF($A26="","",IF(ABS($F26)<=1000,"✓ تراز","⚠ بررسی شود")) -> 0
C27: =IF($A27="","",SUMIFS(F1!$L$10:$L$1808,F1!$A$10:$A$1808,$A27,F1!$D$10:$D$1808,"X011",F1!$N$10:$N$1808,"پوز")) -> 0 | D27: =IF($A27="","",SUMIFS(F2!$I$10:$I$289,F2!$A$10:$A$289,IF($B27="",$A27,$B27),F2!$D$10:$D$289,"BN*",F2!$G$10:$G$289,"واریز پز باسکول (۲۰۰۶)")) -> 0 | E27: =IF($A27="","",SUMIFS(F2!$I$10:$I$289,F2!$A$10:$A$289,IF($B27="",$A27,$B27),F2!$D$10:$D$289,"BN*",F2!$G$10:$G$289,"تسویه دریافت (واسط)")) -> 0 | F27: =IF($A27="","",$C27-$D27) -> 0 | G27: =IF($A27="","",IF(ABS($F27)<=1000,"✓ تراز","⚠ بررسی شود")) -> 0
C28: =IF($A28="","",SUMIFS(F1!$L$10:$L$1808,F1!$A$10:$A$1808,$A28,F1!$D$10:$D$1808,"X011",F1!$N$10:$N$1808,"پوز")) -> 0 | D28: =IF($A28="","",SUMIFS(F2!$I$10:$I$289,F2!$A$10:$A$289,IF($B28="",$A28,$B28),F2!$D$10:$D$289,"BN*",F2!$G$10:$G$289,"واریز پز باسکول (۲۰۰۶)")) -> 0 | E28: =IF($A28="","",SUMIFS(F2!$I$10:$I$289,F2!$A$10:$A$289,IF($B28="",$A28,$B28),F2!$D$10:$D$289,"BN*",F2!$G$10:$G$289,"تسویه دریافت (واسط)")) -> 0 | F28: =IF($A28="","",$C28-$D28) -> 0 | G28: =IF($A28="","",IF(ABS($F28)<=1000,"✓ تراز","⚠ بررسی شود")) -> 0
C29: =IF($A29="","",SUMIFS(F1!$L$10:$L$1808,F1!$A$10:$A$1808,$A29,F1!$D$10:$D$1808,"X011",F1!$N$10:$N$1808,"پوز")) -> 0 | D29: =IF($A29="","",SUMIFS(F2!$I$10:$I$289,F2!$A$10:$A$289,IF($B29="",$A29,$B29),F2!$D$10:$D$289,"BN*",F2!$G$10:$G$289,"واریز پز باسکول (۲۰۰۶)")) -> 0 | E29: =IF($A29="","",SUMIFS(F2!$I$10:$I$289,F2!$A$10:$A$289,IF($B29="",$A29,$B29),F2!$D$10:$D$289,"BN*",F2!$G$10:$G$289,"تسویه دریافت (واسط)")) -> 0 | F29: =IF($A29="","",$C29-$D29) -> 0 | G29: =IF($A29="","",IF(ABS($F29)<=1000,"✓ تراز","⚠ بررسی شود")) -> 0
C30: =IF($A30="","",SUMIFS(F1!$L$10:$L$1808,F1!$A$10:$A$1808,$A30,F1!$D$10:$D$1808,"X011",F1!$N$10:$N$1808,"پوز")) -> 0 | D30: =IF($A30="","",SUMIFS(F2!$I$10:$I$289,F2!$A$10:$A$289,IF($B30="",$A30,$B30),F2!$D$10:$D$289,"BN*",F2!$G$10:$G$289,"واریز پز باسکول (۲۰۰۶)")) -> 0 | E30: =IF($A30="","",SUMIFS(F2!$I$10:$I$289,F2!$A$10:$A$289,IF($B30="",$A30,$B30),F2!$D$10:$D$289,"BN*",F2!$G$10:$G$289,"تسویه دریافت (واسط)")) -> 0 | F30: =IF($A30="","",$C30-$D30) -> 0 | G30: =IF($A30="","",IF(ABS($F30)<=1000,"✓ تراز","⚠ بررسی شود")) -> 0
C31: =IF($A31="","",SUMIFS(F1!$L$10:$L$1808,F1!$A$10:$A$1808,$A31,F1!$D$10:$D$1808,"X011",F1!$N$10:$N$1808,"پوز")) -> 0 | D31: =IF($A31="","",SUMIFS(F2!$I$10:$I$289,F2!$A$10:$A$289,IF($B31="",$A31,$B31),F2!$D$10:$D$289,"BN*",F2!$G$10:$G$289,"واریز پز باسکول (۲۰۰۶)")) -> 0 | E31: =IF($A31="","",SUMIFS(F2!$I$10:$I$289,F2!$A$10:$A$289,IF($B31="",$A31,$B31),F2!$D$10:$D$289,"BN*",F2!$G$10:$G$289,"تسویه دریافت (واسط)")) -> 0 | F31: =IF($A31="","",$C31-$D31) -> 0 | G31: =IF($A31="","",IF(ABS($F31)<=1000,"✓ تراز","⚠ بررسی شود")) -> 0
C32: =IF($A32="","",SUMIFS(F1!$L$10:$L$1808,F1!$A$10:$A$1808,$A32,F1!$D$10:$D$1808,"X011",F1!$N$10:$N$1808,"پوز")) -> 0 | D32: =IF($A32="","",SUMIFS(F2!$I$10:$I$289,F2!$A$10:$A$289,IF($B32="",$A32,$B32),F2!$D$10:$D$289,"BN*",F2!$G$10:$G$289,"واریز پز باسکول (۲۰۰۶)")) -> 0 | E32: =IF($A32="","",SUMIFS(F2!$I$10:$I$289,F2!$A$10:$A$289,IF($B32="",$A32,$B32),F2!$D$10:$D$289,"BN*",F2!$G$10:$G$289,"تسویه دریافت (واسط)")) -> 0 | F32: =IF($A32="","",$C32-$D32) -> 0 | G32: =IF($A32="","",IF(ABS($F32)<=1000,"✓ تراز","⚠ بررسی شود")) -> 0
C33: =IF($A33="","",SUMIFS(F1!$L$10:$L$1808,F1!$A$10:$A$1808,$A33,F1!$D$10:$D$1808,"X011",F1!$N$10:$N$1808,"پوز")) -> 0 | D33: =IF($A33="","",SUMIFS(F2!$I$10:$I$289,F2!$A$10:$A$289,IF($B33="",$A33,$B33),F2!$D$10:$D$289,"BN*",F2!$G$10:$G$289,"واریز پز باسکول (۲۰۰۶)")) -> 0 | E33: =IF($A33="","",SUMIFS(F2!$I$10:$I$289,F2!$A$10:$A$289,IF($B33="",$A33,$B33),F2!$D$10:$D$289,"BN*",F2!$G$10:$G$289,"تسویه دریافت (واسط)")) -> 0 | F33: =IF($A33="","",$C33-$D33) -> 0 | G33: =IF($A33="","",IF(ABS($F33)<=1000,"✓ تراز","⚠ بررسی شود")) -> 0
C34: =IF($A34="","",SUMIFS(F1!$L$10:$L$1808,F1!$A$10:$A$1808,$A34,F1!$D$10:$D$1808,"X011",F1!$N$10:$N$1808,"پوز")) -> 0 | D34: =IF($A34="","",SUMIFS(F2!$I$10:$I$289,F2!$A$10:$A$289,IF($B34="",$A34,$B34),F2!$D$10:$D$289,"BN*",F2!$G$10:$G$289,"واریز پز باسکول (۲۰۰۶)")) -> 0 | E34: =IF($A34="","",SUMIFS(F2!$I$10:$I$289,F2!$A$10:$A$289,IF($B34="",$A34,$B34),F2!$D$10:$D$289,"BN*",F2!$G$10:$G$289,"تسویه دریافت (واسط)")) -> 0 | F34: =IF($A34="","",$C34-$D34) -> 0 | G34: =IF($A34="","",IF(ABS($F34)<=1000,"✓ تراز","⚠ بررسی شود")) -> 0
C35: =IF($A35="","",SUMIFS(F1!$L$10:$L$1808,F1!$A$10:$A$1808,$A35,F1!$D$10:$D$1808,"X011",F1!$N$10:$N$1808,"پوز")) -> 0 | D35: =IF($A35="","",SUMIFS(F2!$I$10:$I$289,F2!$A$10:$A$289,IF($B35="",$A35,$B35),F2!$D$10:$D$289,"BN*",F2!$G$10:$G$289,"واریز پز باسکول (۲۰۰۶)")) -> 0 | E35: =IF($A35="","",SUMIFS(F2!$I$10:$I$289,F2!$A$10:$A$289,IF($B35="",$A35,$B35),F2!$D$10:$D$289,"BN*",F2!$G$10:$G$289,"تسویه دریافت (واسط)")) -> 0 | F35: =IF($A35="","",$C35-$D35) -> 0 | G35: =IF($A35="","",IF(ABS($F35)<=1000,"✓ تراز","⚠ بررسی شود")) -> 0
C36: =IF($A36="","",SUMIFS(F1!$L$10:$L$1808,F1!$A$10:$A$1808,$A36,F1!$D$10:$D$1808,"X011",F1!$N$10:$N$1808,"پوز")) -> 0 | D36: =IF($A36="","",SUMIFS(F2!$I$10:$I$289,F2!$A$10:$A$289,IF($B36="",$A36,$B36),F2!$D$10:$D$289,"BN*",F2!$G$10:$G$289,"واریز پز باسکول (۲۰۰۶)")) -> 0 | E36: =IF($A36="","",SUMIFS(F2!$I$10:$I$289,F2!$A$10:$A$289,IF($B36="",$A36,$B36),F2!$D$10:$D$289,"BN*",F2!$G$10:$G$289,"تسویه دریافت (واسط)")) -> 0 | F36: =IF($A36="","",$C36-$D36) -> 0 | G36: =IF($A36="","",IF(ABS($F36)<=1000,"✓ تراز","⚠ بررسی شود")) -> 0
... C52: =IF($A52="","",SUMIFS(F1!$L$10:$L$1808,F1!$A$10:$A$1808,$A52,F1!$D$10:$D$1808,"X011",F1!$N$10:$N$1808,"پوز")) -> 0 | D52: =IF($A52="","",SUMIFS(F2!$I$10:$I$289,F2!$A$10:$A$289,IF($B52="",$A52,$B52),F2!$D$10:$D$289,"BN*",F2!$G$10:$G$289,"واریز پز باسکول (۲۰۰۶)")) -> 0 | E52: =IF($A52="","",SUMIFS(F2!$I$10:$I$289,F2!$A$10:$A$289,IF($B52="",$A52,$B52),F2!$D$10:$D$289,"BN*",F2!$G$10:$G$289,"تسویه دریافت (واسط)")) -> 0 | F52: =IF($A52="","",$C52-$D52) -> 0 | G52: =IF($A52="","",IF(ABS($F52)<=1000,"✓ تراز","⚠ بررسی شود")) -> 0
A54: اختلاف بیش از ۱٬۰۰۰ ریال با ⚠ نمایش داده می‌شود. علت‌های رایج: واریزی پز در 02_Bank ثبت نشده، یا مبلغ پز در دفتر روزنامه اشتباه است. اعداد این نسخه نمونه‌اند.

Sheet Banks
A2: مازندشت · سورتینگ و بسته‌بندی مرکبات · MAZANDASHT · CITRUS SORTING & PACKING
A3: وضعیت بانک‌ها
A4: مانده هر حساب از دفتر تراکنش‌های بانکی + سهم از کل
A7: جمع مانده | C7: جمع دریافت | E7: جمع پرداخت | G7: خالص
A8: =SUM($D$13:$D$22) -> 0 | C8: =SUM($B$13:$B$22) -> 0 | E8: =SUM($C$13:$C$22) -> 0 | G8: =$C$8-$E$8 -> 0
A12: بانک Bank | B12: دریافت In | C12: پرداخت Out | D12: مانده Balance | E12: سهم Share | F12: مانده اولیه Opening | G12: حساب Acct
A13: صادرات ۹۰۰۹ — جاری اصلی | B13: =SUMIF(F2!$D$10:$D$289,"BN01",F2!$I$10:$I$289) -> 0 | C13: =SUMIF(F2!$D$10:$D$289,"BN01",F2!$J$10:$J$289) -> 0 | D13: =$F13+$B13-$C13 -> 0 | E13: =IFERROR($D13/SUM($D$13:$D$22),0) -> 0 | F13: 500000000 | G13: BN01
A14: صادرات ۲۰۰۶ — پوز باسکول | B14: =SUMIF(F2!$D$10:$D$289,"BN02",F2!$I$10:$I$289) -> 0 | C14: =SUMIF(F2!$D$10:$D$289,"BN02",F2!$J$10:$J$289) -> 0 | D14: =$F14+$B14-$C14 -> 0 | E14: =IFERROR($D14/SUM($D$13:$D$22),0) -> 0 | F14: 0 | G14: BN02
A15: ملت | B15: =SUMIF(F2!$D$10:$D$289,"BN03",F2!$I$10:$I$289) -> 0 | C15: =SUMIF(F2!$D$10:$D$289,"BN03",F2!$J$10:$J$289) -> 0 | D15: =$F15+$B15-$C15 -> 0 | E15: =IFERROR($D15/SUM($D$13:$D$22),0) -> 0 | F15: 0 | G15: BN03
A16: کشاورزی | B16: =SUMIF(F2!$D$10:$D$289,"BN04",F2!$I$10:$I$289) -> 0 | C16: =SUMIF(F2!$D$10:$D$289,"BN04",F2!$J$10:$J$289) -> 0 | D16: =$F16+$B16-$C16 -> 0 | E16: =IFERROR($D16/SUM($D$13:$D$22),0) -> 0 | F16: 0 | G16: BN04
A17: سپه | B17: =SUMIF(F2!$D$10:$D$289,"BN05",F2!$I$10:$I$289) -> 0 | C17: =SUMIF(F2!$D$10:$D$289,"BN05",F2!$J$10:$J$289) -> 0 | D17: =$F17+$B17-$C17 -> 0 | E17: =IFERROR($D17/SUM($D$13:$D$22),0) -> 0 | F17: 0 | G17: BN05
A18: مهر ایران | B18: =SUMIF(F2!$D$10:$D$289,"BN06",F2!$I$10:$I$289) -> 0 | C18: =SUMIF(F2!$D$10:$D$289,"BN06",F2!$J$10:$J$289) -> 0 | D18: =$F18+$B18-$C18 -> 0 | E18: =IFERROR($D18/SUM($D$13:$D$22),0) -> 0 | F18: 0 | G18: BN06
A19: تجارت | B19: =SUMIF(F2!$D$10:$D$289,"BN07",F2!$I$10:$I$289) -> 0 | C19: =SUMIF(F2!$D$10:$D$289,"BN07",F2!$J$10:$J$289) -> 0 | D19: =$F19+$B19-$C19 -> 0 | E19: =IFERROR($D19/SUM($D$13:$D$22),0) -> 0 | F19: 0 | G19: BN07
A20: پاسارگاد | B20: =SUMIF(F2!$D$10:$D$289,"BN08",F2!$I$10:$I$289) -> 0 | C20: =SUMIF(F2!$D$10:$D$289,"BN08",F2!$J$10:$J$289) -> 0 | D20: =$F20+$B20-$C20 -> 0 | E20: =IFERROR($D20/SUM($D$13:$D$22),0) -> 0 | F20: 0 | G20: BN08
A21: رفاه | B21: =SUMIF(F2!$D$10:$D$289,"BN09",F2!$I$10:$I$289) -> 0 | C21: =SUMIF(F2!$D$10:$D$289,"BN09",F2!$J$10:$J$289) -> 0 | D21: =$F21+$B21-$C21 -> 0 | E21: =IFERROR($D21/SUM($D$13:$D$22),0) -> 0 | F21: 0 | G21: BN09
A22: قرض‌الحسنه | B22: =SUMIF(F2!$D$10:$D$289,"BN10",F2!$I$10:$I$289) -> 0 | C22: =SUMIF(F2!$D$10:$D$289,"BN10",F2!$J$10:$J$289) -> 0 | D22: =$F22+$B22-$C22 -> 0 | E22: =IFERROR($D22/SUM($D$13:$D$22),0) -> 0 | F22: 0 | G22: BN10

Sheet Time
A2: مازندشت · سورتینگ و بسته‌بندی مرکبات · MAZANDASHT · CITRUS SORTING & PACKING
A3: روند ماهانه عملیات
A4: وزن، مبلغ و گردش هر ماه شمسی · از دفتر ثبت روزانه
A7: کل وزن (kg) | C7: کل مبلغ | E7: کل بدهکار | G7: کل بستانکار
A8: =SUM($C$13:$C$24) -> 0 | C8: =SUM($D$13:$D$24) -> 0 | E8: =SUM($E$13:$E$24) -> 0 | G8: =SUM($F$13:$F$24) -> 0
A12: ماه Month | B12: تعداد گردش Count | C12: وزن (kg) Weight | D12: مبلغ Amount | E12: بدهکار Debit | F12: بستانکار Credit | G12: خالص Net
A13: 1 | B13: =COUNTIF(F1!$P$10:$P$1808,$A13) -> 0 | C13: =SUMIF(F1!$P$10:$P$1808,$A13,F1!$H$10:$H$1808) -> 0 | D13: =SUMIF(F1!$P$10:$P$1808,$A13,F1!$K$10:$K$1808) -> 0 | E13: =SUMIF(F1!$P$10:$P$1808,$A13,F1!$L$10:$L$1808) -> 0 | F13: =SUMIF(F1!$P$10:$P$1808,$A13,F1!$M$10:$M$1808) -> 0 | G13: =$E13-$F13 -> 0
A14: 2 | B14: =COUNTIF(F1!$P$10:$P$1808,$A14) -> 0 | C14: =SUMIF(F1!$P$10:$P$1808,$A14,F1!$H$10:$H$1808) -> 0 | D14: =SUMIF(F1!$P$10:$P$1808,$A14,F1!$K$10:$K$1808) -> 0 | E14: =SUMIF(F1!$P$10:$P$1808,$A14,F1!$L$10:$L$1808) -> 0 | F14: =SUMIF(F1!$P$10:$P$1808,$A14,F1!$M$10:$M$1808) -> 0 | G14: =$E14-$F14 -> 0
A15: 3 | B15: =COUNTIF(F1!$P$10:$P$1808,$A15) -> 0 | C15: =SUMIF(F1!$P$10:$P$1808,$A15,F1!$H$10:$H$1808) -> 0 | D15: =SUMIF(F1!$P$10:$P$1808,$A15,F1!$K$10:$K$1808) -> 0 | E15: =SUMIF(F1!$P$10:$P$1808,$A15,F1!$L$10:$L$1808) -> 0 | F15: =SUMIF(F1!$P$10:$P$1808,$A15,F1!$M$10:$M$1808) -> 0 | G15: =$E15-$F15 -> 0
A16: 4 | B16: =COUNTIF(F1!$P$10:$P$1808,$A16) -> 0 | C16: =SUMIF(F1!$P$10:$P$1808,$A16,F1!$H$10:$H$1808) -> 0 | D16: =SUMIF(F1!$P$10:$P$1808,$A16,F1!$K$10:$K$1808) -> 0 | E16: =SUMIF(F1!$P$10:$P$1808,$A16,F1!$L$10:$L$1808) -> 0 | F16: =SUMIF(F1!$P$10:$P$1808,$A16,F1!$M$10:$M$1808) -> 0 | G16: =$E16-$F16 -> 0
A17: 5 | B17: =COUNTIF(F1!$P$10:$P$1808,$A17) -> 0 | C17: =SUMIF(F1!$P$10:$P$1808,$A17,F1!$H$10:$H$1808) -> 0 | D17: =SUMIF(F1!$P$10:$P$1808,$A17,F1!$K$10:$K$1808) -> 0 | E17: =SUMIF(F1!$P$10:$P$1808,$A17,F1!$L$10:$L$1808) -> 0 | F17: =SUMIF(F1!$P$10:$P$1808,$A17,F1!$M$10:$M$1808) -> 0 | G17: =$E17-$F17 -> 0
A18: 6 | B18: =COUNTIF(F1!$P$10:$P$1808,$A18) -> 0 | C18: =SUMIF(F1!$P$10:$P$1808,$A18,F1!$H$10:$H$1808) -> 0 | D18: =SUMIF(F1!$P$10:$P$1808,$A18,F1!$K$10:$K$1808) -> 0 | E18: =SUMIF(F1!$P$10:$P$1808,$A18,F1!$L$10:$L$1808) -> 0 | F18: =SUMIF(F1!$P$10:$P$1808,$A18,F1!$M$10:$M$1808) -> 0 | G18: =$E18-$F18 -> 0
A19: 7 | B19: =COUNTIF(F1!$P$10:$P$1808,$A19) -> 0 | C19: =SUMIF(F1!$P$10:$P$1808,$A19,F1!$H$10:$H$1808) -> 0 | D19: =SUMIF(F1!$P$10:$P$1808,$A19,F1!$K$10:$K$1808) -> 0 | E19: =SUMIF(F1!$P$10:$P$1808,$A19,F1!$L$10:$L$1808) -> 0 | F19: =SUMIF(F1!$P$10:$P$1808,$A19,F1!$M$10:$M$1808) -> 0 | G19: =$E19-$F19 -> 0
A20: 8 | B20: =COUNTIF(F1!$P$10:$P$1808,$A20) -> 0 | C20: =SUMIF(F1!$P$10:$P$1808,$A20,F1!$H$10:$H$1808) -> 0 | D20: =SUMIF(F1!$P$10:$P$1808,$A20,F1!$K$10:$K$1808) -> 0 | E20: =SUMIF(F1!$P$10:$P$1808,$A20,F1!$L$10:$L$1808) -> 0 | F20: =SUMIF(F1!$P$10:$P$1808,$A20,F1!$M$10:$M$1808) -> 0 | G20: =$E20-$F20 -> 0
A21: 9 | B21: =COUNTIF(F1!$P$10:$P$1808,$A21) -> 0 | C21: =SUMIF(F1!$P$10:$P$1808,$A21,F1!$H$10:$H$1808) -> 0 | D21: =SUMIF(F1!$P$10:$P$1808,$A21,F1!$K$10:$K$1808) -> 0 | E21: =SUMIF(F1!$P$10:$P$1808,$A21,F1!$L$10:$L$1808) -> 0 | F21: =SUMIF(F1!$P$10:$P$1808,$A21,F1!$M$10:$M$1808) -> 0 | G21: =$E21-$F21 -> 0
A22: 10 | B22: =COUNTIF(F1!$P$10:$P$1808,$A22) -> 0 | C22: =SUMIF(F1!$P$10:$P$1808,$A22,F1!$H$10:$H$1808) -> 0 | D22: =SUMIF(F1!$P$10:$P$1808,$A22,F1!$K$10:$K$1808) -> 0 | E22: =SUMIF(F1!$P$10:$P$1808,$A22,F1!$L$10:$L$1808) -> 0 | F22: =SUMIF(F1!$P$10:$P$1808,$A22,F1!$M$10:$M$1808) -> 0 | G22: =$E22-$F22 -> 0
A23: 11 | B23: =COUNTIF(F1!$P$10:$P$1808,$A23) -> 0 | C23: =SUMIF(F1!$P$10:$P$1808,$A23,F1!$H$10:$H$1808) -> 0 | D23: =SUMIF(F1!$P$10:$P$1808,$A23,F1!$K$10:$K$1808) -> 0 | E23: =SUMIF(F1!$P$10:$P$1808,$A23,F1!$L$10:$L$1808) -> 0 | F23: =SUMIF(F1!$P$10:$P$1808,$A23,F1!$M$10:$M$1808) -> 0 | G23: =$E23-$F23 -> 0
A24: 12 | B24: =COUNTIF(F1!$P$10:$P$1808,$A24) -> 0 | C24: =SUMIF(F1!$P$10:$P$1808,$A24,F1!$H$10:$H$1808) -> 0 | D24: =SUMIF(F1!$P$10:$P$1808,$A24,F1!$K$10:$K$1808) -> 0 | E24: =SUMIF(F1!$P$10:$P$1808,$A24,F1!$L$10:$L$1808) -> 0 | F24: =SUMIF(F1!$P$10:$P$1808,$A24,F1!$M$10:$M$1808) -> 0 | G24: =$E24-$F24 -> 0

Sheet Ops
A2: مازندشت · سورتینگ و بسته‌بندی مرکبات · MAZANDASHT · CITRUS SORTING & PACKING
A3: تحلیل عملیات
A4: کدام نوع عملیات چقدر وزن و مبلغ جابه‌جا کرده است؟
A7: انواع عملیات | C7: بیشترین وزن | E7: بیشترین مبلغ | G7: ناترازها
A8: =19 -> 0 | C8: =MAX($C$13:$C$28) -> 0 | E8: =MAX($E$13:$E$28) -> 0 | G8: =COUNTIF(F1!$L$10:$L$1808,">0")-COUNTIF(F1!$M$10:$M$1808,">0") -> 0
A12: نوع عملیات Operation | B12: تعداد Count | C12: وزن (kg) Weight | D12: مبلغ Amount | E12: بدهکار Debit | F12: بستانکار Credit | G12: سهم مبلغ Share
A13: خرید مرکبات | B13: =COUNTIF(F1!$N$10:$N$1808,$A13) -> 0 | C13: =SUMIF(F1!$N$10:$N$1808,$A13,F1!$I$10:$I$1808) -> 0 | D13: =SUMIF(F1!$N$10:$N$1808,$A13,F1!$K$10:$K$1808) -> 0 | E13: =SUMIF(F1!$N$10:$N$1808,$A13,F1!$L$10:$L$1808) -> 0 | F13: =SUMIF(F1!$N$10:$N$1808,$A13,F1!$M$10:$M$1808) -> 0 | G13: =IFERROR($D13/SUM($D$13:$D$28),0) -> 0
A14: فروش بار (بارفروش) | B14: =COUNTIF(F1!$N$10:$N$1808,$A14) -> 0 | C14: =SUMIF(F1!$N$10:$N$1808,$A14,F1!$I$10:$I$1808) -> 0 | D14: =SUMIF(F1!$N$10:$N$1808,$A14,F1!$K$10:$K$1808) -> 0 | E14: =SUMIF(F1!$N$10:$N$1808,$A14,F1!$L$10:$L$1808) -> 0 | F14: =SUMIF(F1!$N$10:$N$1808,$A14,F1!$M$10:$M$1808) -> 0 | G14: =IFERROR($D14/SUM($D$13:$D$28),0) -> 0
A15: فروش متفرقه / صادراتی | B15: =COUNTIF(F1!$N$10:$N$1808,$A15) -> 0 | C15: =SUMIF(F1!$N$10:$N$1808,$A15,F1!$I$10:$I$1808) -> 0 | D15: =SUMIF(F1!$N$10:$N$1808,$A15,F1!$K$10:$K$1808) -> 0 | E15: =SUMIF(F1!$N$10:$N$1808,$A15,F1!$L$10:$L$1808) -> 0 | F15: =SUMIF(F1!$N$10:$N$1808,$A15,F1!$M$10:$M$1808) -> 0 | G15: =IFERROR($D15/SUM($D$13:$D$28),0) -> 0
A16: آبگیری | B16: =COUNTIF(F1!$N$10:$N$1808,$A16) -> 0 | C16: =SUMIF(F1!$N$10:$N$1808,$A16,F1!$I$10:$I$1808) -> 0 | D16: =SUMIF(F1!$N$10:$N$1808,$A16,F1!$K$10:$K$1808) -> 0 | E16: =SUMIF(F1!$N$10:$N$1808,$A16,F1!$L$10:$L$1808) -> 0 | F16: =SUMIF(F1!$N$10:$N$1808,$A16,F1!$M$10:$M$1808) -> 0 | G16: =IFERROR($D16/SUM($D$13:$D$28),0) -> 0
A17: انعام مصطفی | B17: =COUNTIF(F1!$N$10:$N$1808,$A17) -> 0 | C17: =SUMIF(F1!$N$10:$N$1808,$A17,F1!$I$10:$I$1808) -> 0 | D17: =SUMIF(F1!$N$10:$N$1808,$A17,F1!$K$10:$K$1808) -> 0 | E17: =SUMIF(F1!$N$10:$N$1808,$A17,F1!$L$10:$L$1808) -> 0 | F17: =SUMIF(F1!$N$10:$N$1808,$A17,F1!$M$10:$M$1808) -> 0 | G17: =IFERROR($D17/SUM($D$13:$D$28),0) -> 0
A18: باسکول دیگران | B18: =COUNTIF(F1!$N$10:$N$1808,$A18) -> 0 | C18: =SUMIF(F1!$N$10:$N$1808,$A18,F1!$I$10:$I$1808) -> 0 | D18: =SUMIF(F1!$N$10:$N$1808,$A18,F1!$K$10:$K$1808) -> 0 | E18: =SUMIF(F1!$N$10:$N$1808,$A18,F1!$L$10:$L$1808) -> 0 | F18: =SUMIF(F1!$N$10:$N$1808,$A18,F1!$M$10:$M$1808) -> 0 | G18: =IFERROR($D18/SUM($D$13:$D$28),0) -> 0
A19: درآمد پوز باسکول (بدون طرف) | B19: =COUNTIF(F1!$N$10:$N$1808,$A19) -> 0 | C19: =SUMIF(F1!$N$10:$N$1808,$A19,F1!$I$10:$I$1808) -> 0 | D19: =SUMIF(F1!$N$10:$N$1808,$A19,F1!$K$10:$K$1808) -> 0 | E19: =SUMIF(F1!$N$10:$N$1808,$A19,F1!$L$10:$L$1808) -> 0 | F19: =SUMIF(F1!$N$10:$N$1808,$A19,F1!$M$10:$M$1808) -> 0 | G19: =IFERROR($D19/SUM($D$13:$D$28),0) -> 0
A20: مرجوعی خرید | B20: =COUNTIF(F1!$N$10:$N$1808,$A20) -> 0 | C20: =SUMIF(F1!$N$10:$N$1808,$A20,F1!$I$10:$I$1808) -> 0 | D20: =SUMIF(F1!$N$10:$N$1808,$A20,F1!$K$10:$K$1808) -> 0 | E20: =SUMIF(F1!$N$10:$N$1808,$A20,F1!$L$10:$L$1808) -> 0 | F20: =SUMIF(F1!$N$10:$N$1808,$A20,F1!$M$10:$M$1808) -> 0 | G20: =IFERROR($D20/SUM($D$13:$D$28),0) -> 0
A21: مرجوعی فروش | B21: =COUNTIF(F1!$N$10:$N$1808,$A21) -> 0 | C21: =SUMIF(F1!$N$10:$N$1808,$A21,F1!$I$10:$I$1808) -> 0 | D21: =SUMIF(F1!$N$10:$N$1808,$A21,F1!$K$10:$K$1808) -> 0 | E21: =SUMIF(F1!$N$10:$N$1808,$A21,F1!$L$10:$L$1808) -> 0 | F21: =SUMIF(F1!$N$10:$N$1808,$A21,F1!$M$10:$M$1808) -> 0 | G21: =IFERROR($D21/SUM($D$13:$D$28),0) -> 0
A22: ضایعات / افت انبار | B22: =COUNTIF(F1!$N$10:$N$1808,$A22) -> 0 | C22: =SUMIF(F1!$N$10:$N$1808,$A22,F1!$I$10:$I$1808) -> 0 | D22: =SUMIF(F1!$N$10:$N$1808,$A22,F1!$K$10:$K$1808) -> 0 | E22: =SUMIF(F1!$N$10:$N$1808,$A22,F1!$L$10:$L$1808) -> 0 | F22: =SUMIF(F1!$N$10:$N$1808,$A22,F1!$M$10:$M$1808) -> 0 | G22: =IFERROR($D22/SUM($D$13:$D$28),0) -> 0
A23: انتقال بین انبار | B23: =COUNTIF(F1!$N$10:$N$1808,$A23) -> 0 | C23: =SUMIF(F1!$N$10:$N$1808,$A23,F1!$I$10:$I$1808) -> 0 | D23: =SUMIF(F1!$N$10:$N$1808,$A23,F1!$K$10:$K$1808) -> 0 | E23: =SUMIF(F1!$N$10:$N$1808,$A23,F1!$L$10:$L$1808) -> 0 | F23: =SUMIF(F1!$N$10:$N$1808,$A23,F1!$M$10:$M$1808) -> 0 | G23: =IFERROR($D23/SUM($D$13:$D$28),0) -> 0
A24: سایر ورود | B24: =COUNTIF(F1!$N$10:$N$1808,$A24) -> 0 | C24: =SUMIF(F1!$N$10:$N$1808,$A24,F1!$I$10:$I$1808) -> 0 | D24: =SUMIF(F1!$N$10:$N$1808,$A24,F1!$K$10:$K$1808) -> 0 | E24: =SUMIF(F1!$N$10:$N$1808,$A24,F1!$L$10:$L$1808) -> 0 | F24: =SUMIF(F1!$N$10:$N$1808,$A24,F1!$M$10:$M$1808) -> 0 | G24: =IFERROR($D24/SUM($D$13:$D$28),0) -> 0
... A28: فروش سبد | B28: =COUNTIF(F1!$N$10:$N$1808,$A28) -> 0 | C28: =SUMIF(F1!$N$10:$N$1808,$A28,F1!$I$10:$I$1808) -> 0 | D28: =SUMIF(F1!$N$10:$N$1808,$A28,F1!$K$10:$K$1808) -> 0 | E28: =SUMIF(F1!$N$10:$N$1808,$A28,F1!$L$10:$L$1808) -> 0 | F28: =SUMIF(F1!$N$10:$N$1808,$A28,F1!$M$10:$M$1808) -> 0 | G28: =IFERROR($D28/SUM($D$13:$D$28),0) -> 0

Sheet Parties
A2: مازندشت · سورتینگ و بسته‌بندی مرکبات · MAZANDASHT · CITRUS SORTING & PACKING
A3: طرف حساب‌ها
A4: باغداران، بارفروشان و باسکول‌های دیگران · بدهکار، بستانکار و مانده
A12: کد Code | B12: نام Name | C12: گروه Group | D12: بدهکار Debit | E12: بستانکار Credit | F12: مانده Balance
A13: C001 | B13: زینب زاهدی | C13: باغدار | D13: =SUMIF(F1!$D$10:$D$1808,$A13,F1!$L$10:$L$1808) -> 0 | E13: =SUMIF(F1!$D$10:$D$1808,$A13,F1!$M$10:$M$1808) -> 0 | F13: =$D13-$E13 -> 0
A14: C002 | B14: سید عباس موسوی | C14: باغدار | D14: =SUMIF(F1!$D$10:$D$1808,$A14,F1!$L$10:$L$1808) -> 0 | E14: =SUMIF(F1!$D$10:$D$1808,$A14,F1!$M$10:$M$1808) -> 0 | F14: =$D14-$E14 -> 0
A15: C003 | B15: حاج احمد عیسی پور | C15: باغدار | D15: =SUMIF(F1!$D$10:$D$1808,$A15,F1!$L$10:$L$1808) -> 0 | E15: =SUMIF(F1!$D$10:$D$1808,$A15,F1!$M$10:$M$1808) -> 0 | F15: =$D15-$E15 -> 0
A16: C004 | B16: امید زاهدی | C16: باغدار | D16: =SUMIF(F1!$D$10:$D$1808,$A16,F1!$L$10:$L$1808) -> 0 | E16: =SUMIF(F1!$D$10:$D$1808,$A16,F1!$M$10:$M$1808) -> 0 | F16: =$D16-$E16 -> 0
A17: C005 | B17: بار شخصی قاسم زاهدی | C17: باغدار | D17: =SUMIF(F1!$D$10:$D$1808,$A17,F1!$L$10:$L$1808) -> 0 | E17: =SUMIF(F1!$D$10:$D$1808,$A17,F1!$M$10:$M$1808) -> 0 | F17: =$D17-$E17 -> 0
A18: C006 | B18: هوشنگ عیسی پور | C18: باغدار | D18: =SUMIF(F1!$D$10:$D$1808,$A18,F1!$L$10:$L$1808) -> 0 | E18: =SUMIF(F1!$D$10:$D$1808,$A18,F1!$M$10:$M$1808) -> 0 | F18: =$D18-$E18 -> 0
A19: C007 | B19: علی آهنگر | C19: باغدار | D19: =SUMIF(F1!$D$10:$D$1808,$A19,F1!$L$10:$L$1808) -> 0 | E19: =SUMIF(F1!$D$10:$D$1808,$A19,F1!$M$10:$M$1808) -> 0 | F19: =$D19-$E19 -> 0
A20: C008 | B20: صفدر مسلمی | C20: باغدار | D20: =SUMIF(F1!$D$10:$D$1808,$A20,F1!$L$10:$L$1808) -> 0 | E20: =SUMIF(F1!$D$10:$D$1808,$A20,F1!$M$10:$M$1808) -> 0 | F20: =$D20-$E20 -> 0
A21: C009 | B21: همایون بابایی | C21: باغدار | D21: =SUMIF(F1!$D$10:$D$1808,$A21,F1!$L$10:$L$1808) -> 0 | E21: =SUMIF(F1!$D$10:$D$1808,$A21,F1!$M$10:$M$1808) -> 0 | F21: =$D21-$E21 -> 0
A22: C010 | B22: دبیر فرجی | C22: باغدار | D22: =SUMIF(F1!$D$10:$D$1808,$A22,F1!$L$10:$L$1808) -> 0 | E22: =SUMIF(F1!$D$10:$D$1808,$A22,F1!$M$10:$M$1808) -> 0 | F22: =$D22-$E22 -> 0
A23: SL001 | B23: قم — سید حسین حسینی | C23: بارفروش | D23: =SUMIF(F1!$D$10:$D$1808,$A23,F1!$L$10:$L$1808) -> 0 | E23: =SUMIF(F1!$D$10:$D$1808,$A23,F1!$M$10:$M$1808) -> 0 | F23: =$D23-$E23 -> 0
A24: SL002 | B24: مشهد — محمد توکلی | C24: بارفروش | D24: =SUMIF(F1!$D$10:$D$1808,$A24,F1!$L$10:$L$1808) -> 0 | E24: =SUMIF(F1!$D$10:$D$1808,$A24,F1!$M$10:$M$1808) -> 0 | F24: =$D24-$E24 -> 0
... A28: BD001 | B28: باسکول میدان بار (نمونه) | C28: باسکول دیگران | D28: =SUMIF(F1!$D$10:$D$1808,$A28,F1!$L$10:$L$1808) -> 0 | E28: =SUMIF(F1!$D$10:$D$1808,$A28,F1!$M$10:$M$1808) -> 0 | F28: =$D28-$E28 -> 0

Sheet F1
A9: تاریخ | B9: سند | C9: منبع | D9: حساب | E9: شرح | F9: محصول | G9: سبد | H9: وزن باسکول | I9: وزن خالص | J9: فی | K9: مبلغ | L9: بدهکار | M9: بستانکار | N9: عملیات | O9: گروه | P9: ماه
A10: ='[01_Entry.xlsx]Book'!A10 -> 1405/07/01 | B10: ='[01_Entry.xlsx]Book'!B10 -> BS-001 | C10: ='[01_Entry.xlsx]Book'!C10 -> باسکول | D10: ='[01_Entry.xlsx]Book'!D10 -> C001 | F10: ='[01_Entry.xlsx]Book'!F10 -> نارنگی پیچ | G10: ='[01_Entry.xlsx]Book'!G10 -> 139 | H10: ='[01_Entry.xlsx]Book'!H10 -> 2290 | I10: ='[01_Entry.xlsx]Book'!I10 -> 2005.641 | J10: ='[01_Entry.xlsx]Book'!J10 -> 32000 | K10: ='[01_Entry.xlsx]Book'!K10 -> 64181000 | L10: ='[01_Entry.xlsx]Book'!L10 -> 0 | M10: ='[01_Entry.xlsx]Book'!M10 -> 64181000 | ... O10: ='[01_Entry.xlsx]Book'!O10 -> باغدار | P10: =IF($A10="","",IFERROR(VALUE(MID($A10,6,2)),"")) -> 7
A11: ='[01_Entry.xlsx]Book'!A11 -> 1405/07/01 | B11: ='[01_Entry.xlsx]Book'!B11 -> BS-001 | C11: ='[01_Entry.xlsx]Book'!C11 -> باسکول | D11: ='[01_Entry.xlsx]Book'!D11 -> X004 | E11: ='[01_Entry.xlsx]Book'!E11 -> مقابل: خرید مرکبات | G11: ='[01_Entry.xlsx]Book'!G11 -> 0 | H11: ='[01_Entry.xlsx]Book'!H11 -> 0 | I11: ='[01_Entry.xlsx]Book'!I11 -> 0 | K11: ='[01_Entry.xlsx]Book'!K11 -> 64181000 | L11: ='[01_Entry.xlsx]Book'!L11 -> 64181000 | M11: ='[01_Entry.xlsx]Book'!M11 -> 0 | N11: ='[01_Entry.xlsx]Book'!N11 -> مقابل | O11: ='[01_Entry.xlsx]Book'!O11 -> سایر حساب | P11: =IF($A11="","",IFERROR(VALUE(MID($A11,6,2)),"")) -> 7
G12: ='[01_Entry.xlsx]Book'!G12 -> 0 | H12: ='[01_Entry.xlsx]Book'!H12 -> 0 | I12: ='[01_Entry.xlsx]Book'!I12 -> 0 | K12: ='[01_Entry.xlsx]Book'!K12 -> 0 | L12: ='[01_Entry.xlsx]Book'!L12 -> 0 | M12: ='[01_Entry.xlsx]Book'!M12 -> 0 | P12: =IF($A12="","",IFERROR(VALUE(MID($A12,6,2)),""))
G13: ='[01_Entry.xlsx]Book'!G13 -> 0 | H13: ='[01_Entry.xlsx]Book'!H13 -> 0 | I13: ='[01_Entry.xlsx]Book'!I13 -> 0 | K13: ='[01_Entry.xlsx]Book'!K13 -> 0 | L13: ='[01_Entry.xlsx]Book'!L13 -> 0 | M13: ='[01_Entry.xlsx]Book'!M13 -> 0 | P13: =IF($A13="","",IFERROR(VALUE(MID($A13,6,2)),""))
A14: ='[01_Entry.xlsx]Book'!A14 -> 1405/07/01 | B14: ='[01_Entry.xlsx]Book'!B14 -> BS-002 | C14: ='[01_Entry.xlsx]Book'!C14 -> باسکول | D14: ='[01_Entry.xlsx]Book'!D14 -> C003 | F14: ='[01_Entry.xlsx]Book'!F14 -> پرتقال تامسون | G14: ='[01_Entry.xlsx]Book'!G14 -> 53 | H14: ='[01_Entry.xlsx]Book'!H14 -> 910 | I14: ='[01_Entry.xlsx]Book'!I14 -> 822.195 | J14: ='[01_Entry.xlsx]Book'!J14 -> 35000 | K14: ='[01_Entry.xlsx]Book'!K14 -> 28777000 | L14: ='[01_Entry.xlsx]Book'!L14 -> 0 | M14: ='[01_Entry.xlsx]Book'!M14 -> 28777000 | ... O14: ='[01_Entry.xlsx]Book'!O14 -> باغدار | P14: =IF($A14="","",IFERROR(VALUE(MID($A14,6,2)),"")) -> 7
A15: ='[01_Entry.xlsx]Book'!A15 -> 1405/07/01 | B15: ='[01_Entry.xlsx]Book'!B15 -> BS-002 | C15: ='[01_Entry.xlsx]Book'!C15 -> باسکول | D15: ='[01_Entry.xlsx]Book'!D15 -> X004 | E15: ='[01_Entry.xlsx]Book'!E15 -> مقابل: خرید مرکبات | G15: ='[01_Entry.xlsx]Book'!G15 -> 0 | H15: ='[01_Entry.xlsx]Book'!H15 -> 0 | I15: ='[01_Entry.xlsx]Book'!I15 -> 0 | K15: ='[01_Entry.xlsx]Book'!K15 -> 28777000 | L15: ='[01_Entry.xlsx]Book'!L15 -> 28777000 | M15: ='[01_Entry.xlsx]Book'!M15 -> 0 | N15: ='[01_Entry.xlsx]Book'!N15 -> مقابل | O15: ='[01_Entry.xlsx]Book'!O15 -> سایر حساب | P15: =IF($A15="","",IFERROR(VALUE(MID($A15,6,2)),"")) -> 7
G16: ='[01_Entry.xlsx]Book'!G16 -> 0 | H16: ='[01_Entry.xlsx]Book'!H16 -> 0 | I16: ='[01_Entry.xlsx]Book'!I16 -> 0 | K16: ='[01_Entry.xlsx]Book'!K16 -> 0 | L16: ='[01_Entry.xlsx]Book'!L16 -> 0 | M16: ='[01_Entry.xlsx]Book'!M16 -> 0 | P16: =IF($A16="","",IFERROR(VALUE(MID($A16,6,2)),""))
G17: ='[01_Entry.xlsx]Book'!G17 -> 0 | H17: ='[01_Entry.xlsx]Book'!H17 -> 0 | I17: ='[01_Entry.xlsx]Book'!I17 -> 0 | K17: ='[01_Entry.xlsx]Book'!K17 -> 0 | L17: ='[01_Entry.xlsx]Book'!L17 -> 0 | M17: ='[01_Entry.xlsx]Book'!M17 -> 0 | P17: =IF($A17="","",IFERROR(VALUE(MID($A17,6,2)),""))
A18: ='[01_Entry.xlsx]Book'!A18 -> 1405/07/02 | B18: ='[01_Entry.xlsx]Book'!B18 -> BS-003 | C18: ='[01_Entry.xlsx]Book'!C18 -> باسکول | D18: ='[01_Entry.xlsx]Book'!D18 -> C006 | E18: ='[01_Entry.xlsx]Book'!E18 -> کرایه حمل ۵۰۰٬۰۰۰ | F18: ='[01_Entry.xlsx]Book'!F18 -> نارنگی اونشو | G18: ='[01_Entry.xlsx]Book'!G18 -> 85 | H18: ='[01_Entry.xlsx]Book'!H18 -> 1385 | ... O18: ='[01_Entry.xlsx]Book'!O18 -> باغدار | P18: =IF($A18="","",IFERROR(VALUE(MID($A18,6,2)),"")) -> 7
A19: ='[01_Entry.xlsx]Book'!A19 -> 1405/07/02 | B19: ='[01_Entry.xlsx]Book'!B19 -> BS-003 | C19: ='[01_Entry.xlsx]Book'!C19 -> باسکول | D19: ='[01_Entry.xlsx]Book'!D19 -> X004 | E19: ='[01_Entry.xlsx]Book'!E19 -> مقابل: خرید مرکبات | G19: ='[01_Entry.xlsx]Book'!G19 -> 0 | H19: ='[01_Entry.xlsx]Book'!H19 -> 0 | I19: ='[01_Entry.xlsx]Book'!I19 -> 0 | K19: ='[01_Entry.xlsx]Book'!K19 -> 37848000 | L19: ='[01_Entry.xlsx]Book'!L19 -> 37848000 | M19: ='[01_Entry.xlsx]Book'!M19 -> 0 | N19: ='[01_Entry.xlsx]Book'!N19 -> مقابل | O19: ='[01_Entry.xlsx]Book'!O19 -> سایر حساب | P19: =IF($A19="","",IFERROR(VALUE(MID($A19,6,2)),"")) -> 7
G20: ='[01_Entry.xlsx]Book'!G20 -> 0 | H20: ='[01_Entry.xlsx]Book'!H20 -> 0 | I20: ='[01_Entry.xlsx]Book'!I20 -> 0 | K20: ='[01_Entry.xlsx]Book'!K20 -> 0 | L20: ='[01_Entry.xlsx]Book'!L20 -> 0 | M20: ='[01_Entry.xlsx]Book'!M20 -> 0 | P20: =IF($A20="","",IFERROR(VALUE(MID($A20,6,2)),""))
G21: ='[01_Entry.xlsx]Book'!G21 -> 0 | H21: ='[01_Entry.xlsx]Book'!H21 -> 0 | I21: ='[01_Entry.xlsx]Book'!I21 -> 0 | K21: ='[01_Entry.xlsx]Book'!K21 -> 0 | L21: ='[01_Entry.xlsx]Book'!L21 -> 0 | M21: ='[01_Entry.xlsx]Book'!M21 -> 0 | P21: =IF($A21="","",IFERROR(VALUE(MID($A21,6,2)),""))
A22: ='[01_Entry.xlsx]Book'!A22 -> 1405/07/02 | B22: ='[01_Entry.xlsx]Book'!B22 -> BS-004 | C22: ='[01_Entry.xlsx]Book'!C22 -> باسکول | D22: ='[01_Entry.xlsx]Book'!D22 -> C002 | F22: ='[01_Entry.xlsx]Book'!F22 -> پرتقال خونی | G22: ='[01_Entry.xlsx]Book'!G22 -> 36 | H22: ='[01_Entry.xlsx]Book'!H22 -> 605 | I22: ='[01_Entry.xlsx]Book'!I22 -> 531.234 | J22: ='[01_Entry.xlsx]Book'!J22 -> 38000 | K22: ='[01_Entry.xlsx]Book'!K22 -> 20187000 | L22: ='[01_Entry.xlsx]Book'!L22 -> 0 | M22: ='[01_Entry.xlsx]Book'!M22 -> 20187000 | ... O22: ='[01_Entry.xlsx]Book'!O22 -> باغدار | P22: =IF($A22="","",IFERROR(VALUE(MID($A22,6,2)),"")) -> 7
A23: ='[01_Entry.xlsx]Book'!A23 -> 1405/07/02 | B23: ='[01_Entry.xlsx]Book'!B23 -> BS-004 | C23: ='[01_Entry.xlsx]Book'!C23 -> باسکول | D23: ='[01_Entry.xlsx]Book'!D23 -> X004 | E23: ='[01_Entry.xlsx]Book'!E23 -> مقابل: خرید مرکبات | G23: ='[01_Entry.xlsx]Book'!G23 -> 0 | H23: ='[01_Entry.xlsx]Book'!H23 -> 0 | I23: ='[01_Entry.xlsx]Book'!I23 -> 0 | K23: ='[01_Entry.xlsx]Book'!K23 -> 20187000 | L23: ='[01_Entry.xlsx]Book'!L23 -> 20187000 | M23: ='[01_Entry.xlsx]Book'!M23 -> 0 | N23: ='[01_Entry.xlsx]Book'!N23 -> مقابل | O23: ='[01_Entry.xlsx]Book'!O23 -> سایر حساب | P23: =IF($A23="","",IFERROR(VALUE(MID($A23,6,2)),"")) -> 7
G24: ='[01_Entry.xlsx]Book'!G24 -> 0 | H24: ='[01_Entry.xlsx]Book'!H24 -> 0 | I24: ='[01_Entry.xlsx]Book'!I24 -> 0 | K24: ='[01_Entry.xlsx]Book'!K24 -> 0 | L24: ='[01_Entry.xlsx]Book'!L24 -> 0 | M24: ='[01_Entry.xlsx]Book'!M24 -> 0 | P24: =IF($A24="","",IFERROR(VALUE(MID($A24,6,2)),""))
G25: ='[01_Entry.xlsx]Book'!G25 -> 0 | H25: ='[01_Entry.xlsx]Book'!H25 -> 0 | I25: ='[01_Entry.xlsx]Book'!I25 -> 0 | K25: ='[01_Entry.xlsx]Book'!K25 -> 0 | L25: ='[01_Entry.xlsx]Book'!L25 -> 0 | M25: ='[01_Entry.xlsx]Book'!M25 -> 0 | P25: =IF($A25="","",IFERROR(VALUE(MID($A25,6,2)),""))
A26: ='[01_Entry.xlsx]Book'!A26 -> 1405/07/03 | B26: ='[01_Entry.xlsx]Book'!B26 -> BS-005 | C26: ='[01_Entry.xlsx]Book'!C26 -> باسکول | D26: ='[01_Entry.xlsx]Book'!D26 -> C008 | F26: ='[01_Entry.xlsx]Book'!F26 -> نارنگی ژاپنی | G26: ='[01_Entry.xlsx]Book'!G26 -> 108 | H26: ='[01_Entry.xlsx]Book'!H26 -> 1762 | I26: ='[01_Entry.xlsx]Book'!I26 -> 1551.924 | J26: ='[01_Entry.xlsx]Book'!J26 -> 31000 | K26: ='[01_Entry.xlsx]Book'!K26 -> 48110000 | L26: ='[01_Entry.xlsx]Book'!L26 -> 0 | M26: ='[01_Entry.xlsx]Book'!M26 -> 48110000 | ... O26: ='[01_Entry.xlsx]Book'!O26 -> باغدار | P26: =IF($A26="","",IFERROR(VALUE(MID($A26,6,2)),"")) -> 7
A27: ='[01_Entry.xlsx]Book'!A27 -> 1405/07/03 | B27: ='[01_Entry.xlsx]Book'!B27 -> BS-005 | C27: ='[01_Entry.xlsx]Book'!C27 -> باسکول | D27: ='[01_Entry.xlsx]Book'!D27 -> X004 | E27: ='[01_Entry.xlsx]Book'!E27 -> مقابل: خرید مرکبات | G27: ='[01_Entry.xlsx]Book'!G27 -> 0 | H27: ='[01_Entry.xlsx]Book'!H27 -> 0 | I27: ='[01_Entry.xlsx]Book'!I27 -> 0 | K27: ='[01_Entry.xlsx]Book'!K27 -> 48110000 | L27: ='[01_Entry.xlsx]Book'!L27 -> 48110000 | M27: ='[01_Entry.xlsx]Book'!M27 -> 0 | N27: ='[01_Entry.xlsx]Book'!N27 -> مقابل | O27: ='[01_Entry.xlsx]Book'!O27 -> سایر حساب | P27: =IF($A27="","",IFERROR(VALUE(MID($A27,6,2)),"")) -> 7
G28: ='[01_Entry.xlsx]Book'!G28 -> 0 | H28: ='[01_Entry.xlsx]Book'!H28 -> 0 | I28: ='[01_Entry.xlsx]Book'!I28 -> 0 | K28: ='[01_Entry.xlsx]Book'!K28 -> 0 | L28: ='[01_Entry.xlsx]Book'!L28 -> 0 | M28: ='[01_Entry.xlsx]Book'!M28 -> 0 | P28: =IF($A28="","",IFERROR(VALUE(MID($A28,6,2)),""))
G29: ='[01_Entry.xlsx]Book'!G29 -> 0 | H29: ='[01_Entry.xlsx]Book'!H29 -> 0 | I29: ='[01_Entry.xlsx]Book'!I29 -> 0 | K29: ='[01_Entry.xlsx]Book'!K29 -> 0 | L29: ='[01_Entry.xlsx]Book'!L29 -> 0 | M29: ='[01_Entry.xlsx]Book'!M29 -> 0 | P29: =IF($A29="","",IFERROR(VALUE(MID($A29,6,2)),""))
A30: ='[01_Entry.xlsx]Book'!A30 -> 1405/07/03 | B30: ='[01_Entry.xlsx]Book'!B30 -> BS-006 | C30: ='[01_Entry.xlsx]Book'!C30 -> باسکول | D30: ='[01_Entry.xlsx]Book'!D30 -> SL001 | E30: ='[01_Entry.xlsx]Book'!E30 -> هزینه باسکول پوز | F30: ='[01_Entry.xlsx]Book'!F30 -> پرتقال تامسون | G30: ='[01_Entry.xlsx]Book'!G30 -> 0 | H30: ='[01_Entry.xlsx]Book'!H30 -> 2500 | ... O30: ='[01_Entry.xlsx]Book'!O30 -> بارفروش | P30: =IF($A30="","",IFERROR(VALUE(MID($A30,6,2)),"")) -> 7
A31: ='[01_Entry.xlsx]Book'!A31 -> 1405/07/03 | B31: ='[01_Entry.xlsx]Book'!B31 -> BS-006 | C31: ='[01_Entry.xlsx]Book'!C31 -> باسکول | D31: ='[01_Entry.xlsx]Book'!D31 -> X006 | E31: ='[01_Entry.xlsx]Book'!E31 -> مقابل: فروش بار (بارفروش) | G31: ='[01_Entry.xlsx]Book'!G31 -> 0 | H31: ='[01_Entry.xlsx]Book'!H31 -> 0 | I31: ='[01_Entry.xlsx]Book'!I31 -> 0 | K31: ='[01_Entry.xlsx]Book'!K31 -> 145000000 | L31: ='[01_Entry.xlsx]Book'!L31 -> 0 | M31: ='[01_Entry.xlsx]Book'!M31 -> 145000000 | N31: ='[01_Entry.xlsx]Book'!N31 -> مقابل | O31: ='[01_Entry.xlsx]Book'!O31 -> سایر حساب | P31: =IF($A31="","",IFERROR(VALUE(MID($A31,6,2)),"")) -> 7
A32: ='[01_Entry.xlsx]Book'!A32 -> 1405/07/03 | B32: ='[01_Entry.xlsx]Book'!B32 -> BS-006 | C32: ='[01_Entry.xlsx]Book'!C32 -> باسکول | D32: ='[01_Entry.xlsx]Book'!D32 -> X011 | E32: ='[01_Entry.xlsx]Book'!E32 -> پوز باسکول — فروش بار (بارفروش) | G32: ='[01_Entry.xlsx]Book'!G32 -> 0 | H32: ='[01_Entry.xlsx]Book'!H32 -> 0 | I32: ='[01_Entry.xlsx]Book'!I32 -> 0 | K32: ='[01_Entry.xlsx]Book'!K32 -> 120000 | L32: ='[01_Entry.xlsx]Book'!L32 -> 120000 | M32: ='[01_Entry.xlsx]Book'!M32 -> 0 | N32: ='[01_Entry.xlsx]Book'!N32 -> پوز | O32: ='[01_Entry.xlsx]Book'!O32 -> سایر حساب | P32: =IF($A32="","",IFERROR(VALUE(MID($A32,6,2)),"")) -> 7
A33: ='[01_Entry.xlsx]Book'!A33 -> 1405/07/03 | B33: ='[01_Entry.xlsx]Book'!B33 -> BS-006 | C33: ='[01_Entry.xlsx]Book'!C33 -> باسکول | D33: ='[01_Entry.xlsx]Book'!D33 -> X002 | E33: ='[01_Entry.xlsx]Book'!E33 -> مقابل پوز — فروش بار (بارفروش) | G33: ='[01_Entry.xlsx]Book'!G33 -> 0 | H33: ='[01_Entry.xlsx]Book'!H33 -> 0 | I33: ='[01_Entry.xlsx]Book'!I33 -> 0 | K33: ='[01_Entry.xlsx]Book'!K33 -> 120000 | L33: ='[01_Entry.xlsx]Book'!L33 -> 0 | M33: ='[01_Entry.xlsx]Book'!M33 -> 120000 | N33: ='[01_Entry.xlsx]Book'!N33 -> مقابل پوز | O33: ='[01_Entry.xlsx]Book'!O33 -> سایر حساب | P33: =IF($A33="","",IFERROR(VALUE(MID($A33,6,2)),"")) -> 7
A34: ='[01_Entry.xlsx]Book'!A34 -> 1405/07/04 | B34: ='[01_Entry.xlsx]Book'!B34 -> BS-007 | C34: ='[01_Entry.xlsx]Book'!C34 -> باسکول | D34: ='[01_Entry.xlsx]Book'!D34 -> C004 | F34: ='[01_Entry.xlsx]Book'!F34 -> نارنگی پیچ | G34: ='[01_Entry.xlsx]Book'!G34 -> 38 | H34: ='[01_Entry.xlsx]Book'!H34 -> 640 | I34: ='[01_Entry.xlsx]Book'!I34 -> 577.17 | J34: ='[01_Entry.xlsx]Book'!J34 -> 33000 | K34: ='[01_Entry.xlsx]Book'!K34 -> 19047000 | L34: ='[01_Entry.xlsx]Book'!L34 -> 0 | M34: ='[01_Entry.xlsx]Book'!M34 -> 19047000 | ... O34: ='[01_Entry.xlsx]Book'!O34 -> باغدار | P34: =IF($A34="","",IFERROR(VALUE(MID($A34,6,2)),"")) -> 7
A35: ='[01_Entry.xlsx]Book'!A35 -> 1405/07/04 | B35: ='[01_Entry.xlsx]Book'!B35 -> BS-007 | C35: ='[01_Entry.xlsx]Book'!C35 -> باسکول | D35: ='[01_Entry.xlsx]Book'!D35 -> X004 | E35: ='[01_Entry.xlsx]Book'!E35 -> مقابل: خرید مرکبات | G35: ='[01_Entry.xlsx]Book'!G35 -> 0 | H35: ='[01_Entry.xlsx]Book'!H35 -> 0 | I35: ='[01_Entry.xlsx]Book'!I35 -> 0 | K35: ='[01_Entry.xlsx]Book'!K35 -> 19047000 | L35: ='[01_Entry.xlsx]Book'!L35 -> 19047000 | M35: ='[01_Entry.xlsx]Book'!M35 -> 0 | N35: ='[01_Entry.xlsx]Book'!N35 -> مقابل | O35: ='[01_Entry.xlsx]Book'!O35 -> سایر حساب | P35: =IF($A35="","",IFERROR(VALUE(MID($A35,6,2)),"")) -> 7
G36: ='[01_Entry.xlsx]Book'!G36 -> 0 | H36: ='[01_Entry.xlsx]Book'!H36 -> 0 | I36: ='[01_Entry.xlsx]Book'!I36 -> 0 | K36: ='[01_Entry.xlsx]Book'!K36 -> 0 | L36: ='[01_Entry.xlsx]Book'!L36 -> 0 | M36: ='[01_Entry.xlsx]Book'!M36 -> 0 | P36: =IF($A36="","",IFERROR(VALUE(MID($A36,6,2)),""))
G37: ='[01_Entry.xlsx]Book'!G37 -> 0 | H37: ='[01_Entry.xlsx]Book'!H37 -> 0 | I37: ='[01_Entry.xlsx]Book'!I37 -> 0 | K37: ='[01_Entry.xlsx]Book'!K37 -> 0 | L37: ='[01_Entry.xlsx]Book'!L37 -> 0 | M37: ='[01_Entry.xlsx]Book'!M37 -> 0 | P37: =IF($A37="","",IFERROR(VALUE(MID($A37,6,2)),""))
A38: ='[01_Entry.xlsx]Book'!A38 -> 1405/07/04 | B38: ='[01_Entry.xlsx]Book'!B38 -> BS-008 | C38: ='[01_Entry.xlsx]Book'!C38 -> باسکول | D38: ='[01_Entry.xlsx]Book'!D38 -> SL002 | E38: ='[01_Entry.xlsx]Book'!E38 -> هزینه باسکول پوز | F38: ='[01_Entry.xlsx]Book'!F38 -> نارنگی اونشو | G38: ='[01_Entry.xlsx]Book'!G38 -> 0 | H38: ='[01_Entry.xlsx]Book'!H38 -> 1800 | ... O38: ='[01_Entry.xlsx]Book'!O38 -> بارفروش | P38: =IF($A38="","",IFERROR(VALUE(MID($A38,6,2)),"")) -> 7
A39: ='[01_Entry.xlsx]Book'!A39 -> 1405/07/04 | B39: ='[01_Entry.xlsx]Book'!B39 -> BS-008 | C39: ='[01_Entry.xlsx]Book'!C39 -> باسکول | D39: ='[01_Entry.xlsx]Book'!D39 -> X006 | E39: ='[01_Entry.xlsx]Book'!E39 -> مقابل: فروش بار (بارفروش) | G39: ='[01_Entry.xlsx]Book'!G39 -> 0 | H39: ='[01_Entry.xlsx]Book'!H39 -> 0 | I39: ='[01_Entry.xlsx]Book'!I39 -> 0 | K39: ='[01_Entry.xlsx]Book'!K39 -> 93600000 | L39: ='[01_Entry.xlsx]Book'!L39 -> 0 | M39: ='[01_Entry.xlsx]Book'!M39 -> 93600000 | N39: ='[01_Entry.xlsx]Book'!N39 -> مقابل | O39: ='[01_Entry.xlsx]Book'!O39 -> سایر حساب | P39: =IF($A39="","",IFERROR(VALUE(MID($A39,6,2)),"")) -> 7
A40: ='[01_Entry.xlsx]Book'!A40 -> 1405/07/04 | B40: ='[01_Entry.xlsx]Book'!B40 -> BS-008 | C40: ='[01_Entry.xlsx]Book'!C40 -> باسکول | D40: ='[01_Entry.xlsx]Book'!D40 -> X011 | E40: ='[01_Entry.xlsx]Book'!E40 -> پوز باسکول — فروش بار (بارفروش) | G40: ='[01_Entry.xlsx]Book'!G40 -> 0 | H40: ='[01_Entry.xlsx]Book'!H40 -> 0 | I40: ='[01_Entry.xlsx]Book'!I40 -> 0 | K40: ='[01_Entry.xlsx]Book'!K40 -> 90000 | L40: ='[01_Entry.xlsx]Book'!L40 -> 90000 | M40: ='[01_Entry.xlsx]Book'!M40 -> 0 | N40: ='[01_Entry.xlsx]Book'!N40 -> پوز | O40: ='[01_Entry.xlsx]Book'!O40 -> سایر حساب | P40: =IF($A40="","",IFERROR(VALUE(MID($A40,6,2)),"")) -> 7
A41: ='[01_Entry.xlsx]Book'!A41 -> 1405/07/04 | B41: ='[01_Entry.xlsx]Book'!B41 -> BS-008 | C41: ='[01_Entry.xlsx]Book'!C41 -> باسکول | D41: ='[01_Entry.xlsx]Book'!D41 -> X002 | E41: ='[01_Entry.xlsx]Book'!E41 -> مقابل پوز — فروش بار (بارفروش) | G41: ='[01_Entry.xlsx]Book'!G41 -> 0 | H41: ='[01_Entry.xlsx]Book'!H41 -> 0 | I41: ='[01_Entry.xlsx]Book'!I41 -> 0 | K41: ='[01_Entry.xlsx]Book'!K41 -> 90000 | L41: ='[01_Entry.xlsx]Book'!L41 -> 0 | M41: ='[01_Entry.xlsx]Book'!M41 -> 90000 | N41: ='[01_Entry.xlsx]Book'!N41 -> مقابل پوز | O41: ='[01_Entry.xlsx]Book'!O41 -> سایر حساب | P41: =IF($A41="","",IFERROR(VALUE(MID($A41,6,2)),"")) -> 7
A42: ='[01_Entry.xlsx]Book'!A42 -> 1405/07/05 | B42: ='[01_Entry.xlsx]Book'!B42 -> BS-009 | C42: ='[01_Entry.xlsx]Book'!C42 -> باسکول | D42: ='[01_Entry.xlsx]Book'!D42 -> C007 | E42: ='[01_Entry.xlsx]Book'!E42 -> آبگیری — طرف حساب بستانکار | F42: ='[01_Entry.xlsx]Book'!F42 -> نارنگی پیچ | G42: ='[01_Entry.xlsx]Book'!G42 -> 0 | H42: ='[01_Entry.xlsx]Book'!H42 -> 800 | I42: ='[01_Entry.xlsx]Book'!I42 -> 800 | K42: ='[01_Entry.xlsx]Book'!K42 -> 12000000 | L42: ='[01_Entry.xlsx]Book'!L42 -> 0 | M42: ='[01_Entry.xlsx]Book'!M42 -> 12000000 | N42: ='[01_Entry.xlsx]Book'!N42 -> آبگیری | O42: ='[01_Entry.xlsx]Book'!O42 -> باغدار | P42: =IF($A42="","",IFERROR(VALUE(MID($A42,6,2)),"")) -> 7
A43: ='[01_Entry.xlsx]Book'!A43 -> 1405/07/05 | B43: ='[01_Entry.xlsx]Book'!B43 -> BS-009 | C43: ='[01_Entry.xlsx]Book'!C43 -> باسکول | D43: ='[01_Entry.xlsx]Book'!D43 -> X008 | E43: ='[01_Entry.xlsx]Book'!E43 -> مقابل: آبگیری | G43: ='[01_Entry.xlsx]Book'!G43 -> 0 | H43: ='[01_Entry.xlsx]Book'!H43 -> 0 | I43: ='[01_Entry.xlsx]Book'!I43 -> 0 | K43: ='[01_Entry.xlsx]Book'!K43 -> 12000000 | L43: ='[01_Entry.xlsx]Book'!L43 -> 12000000 | M43: ='[01_Entry.xlsx]Book'!M43 -> 0 | N43: ='[01_Entry.xlsx]Book'!N43 -> مقابل | O43: ='[01_Entry.xlsx]Book'!O43 -> سایر حساب | P43: =IF($A43="","",IFERROR(VALUE(MID($A43,6,2)),"")) -> 7
G44: ='[01_Entry.xlsx]Book'!G44 -> 0 | H44: ='[01_Entry.xlsx]Book'!H44 -> 0 | I44: ='[01_Entry.xlsx]Book'!I44 -> 0 | K44: ='[01_Entry.xlsx]Book'!K44 -> 0 | L44: ='[01_Entry.xlsx]Book'!L44 -> 0 | M44: ='[01_Entry.xlsx]Book'!M44 -> 0 | P44: =IF($A44="","",IFERROR(VALUE(MID($A44,6,2)),""))
G45: ='[01_Entry.xlsx]Book'!G45 -> 0 | H45: ='[01_Entry.xlsx]Book'!H45 -> 0 | I45: ='[01_Entry.xlsx]Book'!I45 -> 0 | K45: ='[01_Entry.xlsx]Book'!K45 -> 0 | L45: ='[01_Entry.xlsx]Book'!L45 -> 0 | M45: ='[01_Entry.xlsx]Book'!M45 -> 0 | P45: =IF($A45="","",IFERROR(VALUE(MID($A45,6,2)),""))
A46: ='[01_Entry.xlsx]Book'!A46 -> 1405/07/05 | B46: ='[01_Entry.xlsx]Book'!B46 -> BS-010 | C46: ='[01_Entry.xlsx]Book'!C46 -> باسکول | D46: ='[01_Entry.xlsx]Book'!D46 -> X011 | E46: ='[01_Entry.xlsx]Book'!E46 -> انعام از پوز باسکول | G46: ='[01_Entry.xlsx]Book'!G46 -> 0 | H46: ='[01_Entry.xlsx]Book'!H46 -> 0 | I46: ='[01_Entry.xlsx]Book'!I46 -> 0 | K46: ='[01_Entry.xlsx]Book'!K46 -> 500000 | L46: ='[01_Entry.xlsx]Book'!L46 -> 0 | M46: ='[01_Entry.xlsx]Book'!M46 -> 500000 | N46: ='[01_Entry.xlsx]Book'!N46 -> انعام مصطفی | O46: ='[01_Entry.xlsx]Book'!O46 -> سایر حساب | P46: =IF($A46="","",IFERROR(VALUE(MID($A46,6,2)),"")) -> 7
A47: ='[01_Entry.xlsx]Book'!A47 -> 1405/07/05 | B47: ='[01_Entry.xlsx]Book'!B47 -> BS-010 | C47: ='[01_Entry.xlsx]Book'!C47 -> باسکول | D47: ='[01_Entry.xlsx]Book'!D47 -> X001 | E47: ='[01_Entry.xlsx]Book'!E47 -> مقابل: انعام مصطفی | G47: ='[01_Entry.xlsx]Book'!G47 -> 0 | H47: ='[01_Entry.xlsx]Book'!H47 -> 0 | I47: ='[01_Entry.xlsx]Book'!I47 -> 0 | K47: ='[01_Entry.xlsx]Book'!K47 -> 500000 | L47: ='[01_Entry.xlsx]Book'!L47 -> 500000 | M47: ='[01_Entry.xlsx]Book'!M47 -> 0 | N47: ='[01_Entry.xlsx]Book'!N47 -> مقابل | O47: ='[01_Entry.xlsx]Book'!O47 -> سایر حساب | P47: =IF($A47="","",IFERROR(VALUE(MID($A47,6,2)),"")) -> 7
G48: ='[01_Entry.xlsx]Book'!G48 -> 0 | H48: ='[01_Entry.xlsx]Book'!H48 -> 0 | I48: ='[01_Entry.xlsx]Book'!I48 -> 0 | K48: ='[01_Entry.xlsx]Book'!K48 -> 0 | L48: ='[01_Entry.xlsx]Book'!L48 -> 0 | M48: ='[01_Entry.xlsx]Book'!M48 -> 0 | P48: =IF($A48="","",IFERROR(VALUE(MID($A48,6,2)),""))
...

Sheet F2
A9: تاریخ | B9: سند | C9: منبع | D9: حساب | E9: نام | F9: گروه | G9: عملیات | H9: بانک | I9: بدهکار | J9: بستانکار | K9: ماه | L9: شرح
A10: ='[02_Bank.xlsx]Post'!A13 -> 1405/07/03 | B10: ='[02_Bank.xlsx]Post'!B13 -> JB-BS-006 | C10: ='[02_Bank.xlsx]Post'!C13 -> تراکنش بانکی | D10: ='[02_Bank.xlsx]Post'!D13 -> BN02 | E10: ='[02_Bank.xlsx]Post'!E13 -> صادرات ۲۰۰۶ — پوز باسکول | F10: ='[02_Bank.xlsx]Post'!F13 -> بانک و صندوق | G10: ='[02_Bank.xlsx]Post'!G13 -> واریز پز باسکول (۲۰۰۶) | H10: ='[02_Bank.xlsx]Post'!H13 -> BN02 | ... L10: ='[02_Bank.xlsx]Post'!L13 -> پوز باسکول — فروش بار (بارفروش)
A11: ='[02_Bank.xlsx]Post'!A14 -> 1405/07/03 | B11: ='[02_Bank.xlsx]Post'!B14 -> JB-BS-006 | C11: ='[02_Bank.xlsx]Post'!C14 -> تراکنش بانکی | D11: ='[02_Bank.xlsx]Post'!D14 -> X011 | E11: ='[02_Bank.xlsx]Post'!E14 -> حساب واسط بانک و پز (در راه) | F11: ='[02_Bank.xlsx]Post'!F14 -> سایر حساب | G11: ='[02_Bank.xlsx]Post'!G14 -> واریز پز باسکول (۲۰۰۶) | H11: ='[02_Bank.xlsx]Post'!H14 -> BN02 | ... L11: ='[02_Bank.xlsx]Post'!L14 -> طرف مقابل — پوز باسکول — فروش بار (بارفروش)
A12: ='[02_Bank.xlsx]Post'!A15 -> 1405/07/04 | B12: ='[02_Bank.xlsx]Post'!B15 -> JB-BS-008 | C12: ='[02_Bank.xlsx]Post'!C15 -> تراکنش بانکی | D12: ='[02_Bank.xlsx]Post'!D15 -> BN02 | E12: ='[02_Bank.xlsx]Post'!E15 -> صادرات ۲۰۰۶ — پوز باسکول | F12: ='[02_Bank.xlsx]Post'!F15 -> بانک و صندوق | G12: ='[02_Bank.xlsx]Post'!G15 -> واریز پز باسکول (۲۰۰۶) | H12: ='[02_Bank.xlsx]Post'!H15 -> BN02 | ... L12: ='[02_Bank.xlsx]Post'!L15 -> پوز باسکول — فروش بار (بارفروش)
A13: ='[02_Bank.xlsx]Post'!A16 -> 1405/07/04 | B13: ='[02_Bank.xlsx]Post'!B16 -> JB-BS-008 | C13: ='[02_Bank.xlsx]Post'!C16 -> تراکنش بانکی | D13: ='[02_Bank.xlsx]Post'!D16 -> X011 | E13: ='[02_Bank.xlsx]Post'!E16 -> حساب واسط بانک و پز (در راه) | F13: ='[02_Bank.xlsx]Post'!F16 -> سایر حساب | G13: ='[02_Bank.xlsx]Post'!G16 -> واریز پز باسکول (۲۰۰۶) | H13: ='[02_Bank.xlsx]Post'!H16 -> BN02 | ... L13: ='[02_Bank.xlsx]Post'!L16 -> طرف مقابل — پوز باسکول — فروش بار (بارفروش)
A14: ='[02_Bank.xlsx]Post'!A17 -> 1405/07/05 | B14: ='[02_Bank.xlsx]Post'!B17 -> JB-BS-010 | C14: ='[02_Bank.xlsx]Post'!C17 -> تراکنش بانکی | D14: ='[02_Bank.xlsx]Post'!D17 -> BN02 | E14: ='[02_Bank.xlsx]Post'!E17 -> صادرات ۲۰۰۶ — پوز باسکول | F14: ='[02_Bank.xlsx]Post'!F17 -> بانک و صندوق | G14: ='[02_Bank.xlsx]Post'!G17 -> تسویه پرداخت (واسط) | H14: ='[02_Bank.xlsx]Post'!H17 -> BN02 | ... L14: ='[02_Bank.xlsx]Post'!L17 -> انعام از پوز باسکول
A15: ='[02_Bank.xlsx]Post'!A18 -> 1405/07/05 | B15: ='[02_Bank.xlsx]Post'!B18 -> JB-BS-010 | C15: ='[02_Bank.xlsx]Post'!C18 -> تراکنش بانکی | D15: ='[02_Bank.xlsx]Post'!D18 -> X011 | E15: ='[02_Bank.xlsx]Post'!E18 -> حساب واسط بانک و پز (در راه) | F15: ='[02_Bank.xlsx]Post'!F18 -> سایر حساب | G15: ='[02_Bank.xlsx]Post'!G18 -> تسویه پرداخت (واسط) | H15: ='[02_Bank.xlsx]Post'!H18 -> BN02 | ... L15: ='[02_Bank.xlsx]Post'!L18 -> طرف مقابل — انعام از پوز باسکول
A16: ='[02_Bank.xlsx]Post'!A19 -> 1405/07/06 | B16: ='[02_Bank.xlsx]Post'!B19 -> JB-RV-001 | C16: ='[02_Bank.xlsx]Post'!C19 -> تراکنش بانکی | D16: ='[02_Bank.xlsx]Post'!D19 -> BN01 | E16: ='[02_Bank.xlsx]Post'!E19 -> صادرات ۹۰۰۹ — جاری اصلی | F16: ='[02_Bank.xlsx]Post'!F19 -> بانک و صندوق | G16: ='[02_Bank.xlsx]Post'!G19 -> تسویه دریافت (واسط) | H16: ='[02_Bank.xlsx]Post'!H19 -> BN01 | ... L16: ='[02_Bank.xlsx]Post'!L19 -> تسویه بار
A17: ='[02_Bank.xlsx]Post'!A20 -> 1405/07/06 | B17: ='[02_Bank.xlsx]Post'!B20 -> JB-RV-001 | C17: ='[02_Bank.xlsx]Post'!C20 -> تراکنش بانکی | D17: ='[02_Bank.xlsx]Post'!D20 -> X011 | E17: ='[02_Bank.xlsx]Post'!E20 -> حساب واسط بانک و پز (در راه) | F17: ='[02_Bank.xlsx]Post'!F20 -> سایر حساب | G17: ='[02_Bank.xlsx]Post'!G20 -> تسویه دریافت (واسط) | H17: ='[02_Bank.xlsx]Post'!H20 -> BN01 | ... L17: ='[02_Bank.xlsx]Post'!L20 -> طرف مقابل — تسویه بار
A18: ='[02_Bank.xlsx]Post'!A21 -> 1405/07/08 | B18: ='[02_Bank.xlsx]Post'!B21 -> JB-PV-003 | C18: ='[02_Bank.xlsx]Post'!C21 -> تراکنش بانکی | D18: ='[02_Bank.xlsx]Post'!D21 -> BN02 | E18: ='[02_Bank.xlsx]Post'!E21 -> صادرات ۲۰۰۶ — پوز باسکول | F18: ='[02_Bank.xlsx]Post'!F21 -> بانک و صندوق | G18: ='[02_Bank.xlsx]Post'!G21 -> تسویه پرداخت (واسط) | H18: ='[02_Bank.xlsx]Post'!H21 -> BN02 | ... L18: ='[02_Bank.xlsx]Post'!L21 -> پرداخت از واسط
A19: ='[02_Bank.xlsx]Post'!A22 -> 1405/07/08 | B19: ='[02_Bank.xlsx]Post'!B22 -> JB-PV-003 | C19: ='[02_Bank.xlsx]Post'!C22 -> تراکنش بانکی | D19: ='[02_Bank.xlsx]Post'!D22 -> X011 | E19: ='[02_Bank.xlsx]Post'!E22 -> حساب واسط بانک و پز (در راه) | F19: ='[02_Bank.xlsx]Post'!F22 -> سایر حساب | G19: ='[02_Bank.xlsx]Post'!G22 -> تسویه پرداخت (واسط) | H19: ='[02_Bank.xlsx]Post'!H22 -> BN02 | ... L19: ='[02_Bank.xlsx]Post'!L22 -> طرف مقابل — پرداخت از واسط
A20: ='[02_Bank.xlsx]Post'!A23 -> 1405/07/09 | B20: ='[02_Bank.xlsx]Post'!B23 -> JB-RV-002 | C20: ='[02_Bank.xlsx]Post'!C23 -> تراکنش بانکی | D20: ='[02_Bank.xlsx]Post'!D23 -> BN02 | E20: ='[02_Bank.xlsx]Post'!E23 -> صادرات ۲۰۰۶ — پوز باسکول | F20: ='[02_Bank.xlsx]Post'!F23 -> بانک و صندوق | G20: ='[02_Bank.xlsx]Post'!G23 -> تسویه دریافت (واسط) | H20: ='[02_Bank.xlsx]Post'!H23 -> BN02 | ... L20: ='[02_Bank.xlsx]Post'!L23 -> واریز از واسط
A21: ='[02_Bank.xlsx]Post'!A24 -> 1405/07/09 | B21: ='[02_Bank.xlsx]Post'!B24 -> JB-RV-002 | C21: ='[02_Bank.xlsx]Post'!C24 -> تراکنش بانکی | D21: ='[02_Bank.xlsx]Post'!D24 -> X011 | E21: ='[02_Bank.xlsx]Post'!E24 -> حساب واسط بانک و پز (در راه) | F21: ='[02_Bank.xlsx]Post'!F24 -> سایر حساب | G21: ='[02_Bank.xlsx]Post'!G24 -> تسویه دریافت (واسط) | H21: ='[02_Bank.xlsx]Post'!H24 -> BN02 | ... L21: ='[02_Bank.xlsx]Post'!L24 -> طرف مقابل — واریز از واسط
... A33: ='[02_Bank.xlsx]Post'!A36 -> 1405/07/13 | B33: ='[02_Bank.xlsx]Post'!B36 -> TB-901 | C33: ='[02_Bank.xlsx]Post'!C36 -> تراکنش بانکی | D33: ='[02_Bank.xlsx]Post'!D36 -> BN03 | E33: ='[02_Bank.xlsx]Post'!E36 -> بانک ملت | F33: ='[02_Bank.xlsx]Post'!F36 -> بانک و صندوق | G33: ='[02_Bank.xlsx]Post'!G36 -> انتقال داخلی بین بانک‌ها | H33: ='[02_Bank.xlsx]Post'!H36 -> BN01 | ... L33: ='[02_Bank.xlsx]Post'!L36 -> طرف مقابل — انتقال به حساب ملت
I34: ='[02_Bank.xlsx]Post'!I37 -> 0 | J34: ='[02_Bank.xlsx]Post'!J37 -> 0 | K34: ='[02_Bank.xlsx]Post'!K37 -> 0
I35: ='[02_Bank.xlsx]Post'!I38 -> 0 | J35: ='[02_Bank.xlsx]Post'!J38 -> 0 | K35: ='[02_Bank.xlsx]Post'!K38 -> 0
I36: ='[02_Bank.xlsx]Post'!I39 -> 0 | J36: ='[02_Bank.xlsx]Post'!J39 -> 0 | K36: ='[02_Bank.xlsx]Post'!K39 -> 0
I37: ='[02_Bank.xlsx]Post'!I40 -> 0 | J37: ='[02_Bank.xlsx]Post'!J40 -> 0 | K37: ='[02_Bank.xlsx]Post'!K40 -> 0
I38: ='[02_Bank.xlsx]Post'!I41 -> 0 | J38: ='[02_Bank.xlsx]Post'!J41 -> 0 | K38: ='[02_Bank.xlsx]Post'!K41 -> 0
I39: ='[02_Bank.xlsx]Post'!I42 -> 0 | J39: ='[02_Bank.xlsx]Post'!J42 -> 0 | K39: ='[02_Bank.xlsx]Post'!K42 -> 0
I40: ='[02_Bank.xlsx]Post'!I43 -> 0 | J40: ='[02_Bank.xlsx]Post'!J43 -> 0 | K40: ='[02_Bank.xlsx]Post'!K43 -> 0
I41: ='[02_Bank.xlsx]Post'!I44 -> 0 | J41: ='[02_Bank.xlsx]Post'!J44 -> 0 | K41: ='[02_Bank.xlsx]Post'!K44 -> 0
I42: ='[02_Bank.xlsx]Post'!I45 -> 0 | J42: ='[02_Bank.xlsx]Post'!J45 -> 0 | K42: ='[02_Bank.xlsx]Post'!K45 -> 0
I43: ='[02_Bank.xlsx]Post'!I46 -> 0 | J43: ='[02_Bank.xlsx]Post'!J46 -> 0 | K43: ='[02_Bank.xlsx]Post'!K46 -> 0
I44: ='[02_Bank.xlsx]Post'!I47 -> 0 | J44: ='[02_Bank.xlsx]Post'!J47 -> 0 | K44: ='[02_Bank.xlsx]Post'!K47 -> 0
I45: ='[02_Bank.xlsx]Post'!I48 -> 0 | J45: ='[02_Bank.xlsx]Post'!J48 -> 0 | K45: ='[02_Bank.xlsx]Post'!K48 -> 0
... I289: ='[02_Bank.xlsx]Post'!I292 -> 0 | J289: ='[02_Bank.xlsx]Post'!J292 -> 0 | K289: ='[02_Bank.xlsx]Post'!K292 -> 0

Sheet Sync
A1: مرجع قفل‌شده — کپی از فایل مادر و طرف حساب‌های کلیدی
A2: این شیت فقط برای نمایش است؛ تغییر در آن مجاز نیست.
A6: بانک | B6: حساب | D6: باغدار | E6: بارفروش | F6: باسکول دیگران
A7: صادرات ۹۰۰۹ — جاری اصلی | B7: BN01 | D7: C001 – زینب زاهدی | E7: SL001 – قم — سید حسین حسینی | F7: BD001 – باسکول میدان بار (نمونه)
A8: صادرات ۲۰۰۶ — پوز باسکول | B8: BN02 | D8: C002 – سید عباس موسوی | E8: SL002 – مشهد — محمد توکلی
A9: ملت | B9: BN03 | D9: C003 – حاج احمد عیسی پور | E9: SL003 – اراک — پوریا خوش‌نمکیان
A10: کشاورزی | B10: BN04 | D10: C004 – امید زاهدی | E10: SL004 – تبریز — نورزاده
A11: سپه | B11: BN05 | D11: C005 – بار شخصی قاسم زاهدی | E11: SL005 – زنجان — خانی
A12: مهر ایران | B12: BN06 | D12: C006 – هوشنگ عیسی پور
A13: تجارت | B13: BN07 | D13: C007 – علی آهنگر
A14: پاسارگاد | B14: BN08 | D14: C008 – صفدر مسلمی
A15: رفاه | B15: BN09 | D15: C009 – همایون بابایی
A16: قرض‌الحسنه | B16: BN10 | D16: C010 – دبیر فرجی

Sheet Help
A2: مازندشت · سورتینگ و بسته‌بندی مرکبات · MAZANDASHT · CITRUS SORTING & PACKING
A3: راهنمای داشبورد
A4: این فایل چه می‌خواند، چگونه به‌روز می‌شود و هر نمودار چه می‌گوید
A7: داشبورد از کجا می‌خواند؟ | G7: ۰۱
A8: داشبورد به دو فایل کنار خودش وصل است: دفتر ثبت روزانه (01_Entry → شیت Book) و دفتر تراکنش‌های بانکی (02_Bank → شیت Post). دو شیت مخفی F1 و F2 همین دو منبع را آینه می‌کنند.
