Workbook
Name AcctCodes: Sync!$B$10:$B$259
Name AcctTbl: Sync!$B$10:$G$259
Name BankCodes: Sync!$AK$10:$AK$19
Name BankTbl: Sync!$AK$10:$AN$19
Name BasketCodeCol: Sync!$Z$10:$Z$21
Name BasketTbl: Sync!$Y$10:$AF$21
Name GroupTbl: Sync!$AR$10:$AS$51
Name ListAllCodes: OFFSET(Sync!$B$10,0,0,MAX(COUNTIF(Sync!$C$10:$C$259,"?*"),1),1)
Name ListBanks: OFFSET(Sync!$AL$10,0,0,MAX(COUNTIF(Sync!$AL$10:$AL$19,"?*"),1),1)
Name ListBasketOps: OFFSET(Sync!$AW$10,0,0,MAX(COUNTIF(Sync!$AW$10:$AW$14,"?*"),1),1)
Name ListBaskets: OFFSET(Sync!$Y$10,0,0,MAX(COUNTIF(Sync!$Y$10:$Y$21,"?*"),1),1)
Name ListBasketSellerCodes: OFFSET(Sync!$B$72,0,0,MAX(COUNTIF(Sync!$C$72:$C$74,"?*"),1),1)
Name ListBaskolOps: OFFSET(Sync!$AZ$10,0,0,MAX(COUNTIF(Sync!$AZ$10:$AZ$23,"?*"),1),1)
Name ListCategories: OFFSET(Sync!$CB$10,0,0,MAX(COUNTIF(Sync!$CB$10:$CB$29,"?*"),1),1)
Name ListChequeStatus: OFFSET(Sync!$CG$10,0,0,MAX(COUNTIF(Sync!$CG$10:$CG$29,"?*"),1),1)
Name ListColorKeys: OFFSET(Sync!$CP$10,0,0,MAX(COUNTIF(Sync!$CP$10:$CP$29,"?*"),1),1)
Name ListDirections: OFFSET(Sync!$CC$10,0,0,MAX(COUNTIF(Sync!$CC$10:$CC$29,"?*"),1),1)
Name ListGroups: Sync!$AU$10:$AU$19
Name ListGrowerCodes: OFFSET(Sync!$B$10,0,0,MAX(COUNTIF(Sync!$C$10:$C$66,"?*"),1),1)
Name ListInclude: OFFSET(Sync!$CH$10,0,0,MAX(COUNTIF(Sync!$CH$10:$CH$29,"?*"),1),1)
Name ListLoadBuyerCodes: OFFSET(Sync!$B$67,0,0,MAX(COUNTIF(Sync!$C$67:$C$71,"?*"),1),1)
Name ListManualRoles: OFFSET(Sync!$CI$10,0,0,MAX(COUNTIF(Sync!$CI$10:$CI$29,"?*"),1),1)
Name ListOpCategories: OFFSET(Sync!$CL$10,0,0,MAX(COUNTIF(Sync!$CL$10:$CL$29,"?*"),1),1)
Name ListOps: OFFSET(Sync!$I$10,0,0,MAX(COUNTIF(Sync!$I$10:$I$33,"?*"),1),1)
Name ListOtherScaleCodes: Sync!$AX$10:$AX$29
Name ListPartyBasis: OFFSET(Sync!$CO$10,0,0,MAX(COUNTIF(Sync!$CO$10:$CO$29,"?*"),1),1)
Name ListPartyTypes: OFFSET(Sync!$CE$10,0,0,MAX(COUNTIF(Sync!$CE$10:$CE$29,"?*"),1),1)
Name ListPayMethods: OFFSET(Sync!$CF$10,0,0,MAX(COUNTIF(Sync!$CF$10:$CF$29,"?*"),1),1)
Name ListPosEffects: OFFSET(Sync!$CJ$10,0,0,MAX(COUNTIF(Sync!$CJ$10:$CJ$29,"?*"),1),1)
Name ListProducts: OFFSET(Sync!$AH$10,0,0,MAX(COUNTIF(Sync!$AH$10:$AH$29,"?*"),1),1)
Name ListReportSheets: OFFSET(Sync!$CN$10,0,0,MAX(COUNTIF(Sync!$CN$10:$CN$29,"?*"),1),1)
Name ListSeasons: OFFSET(Sync!$CQ$10,0,0,MAX(COUNTIF(Sync!$CQ$10:$CQ$29,"?*"),1),1)
Name ListSides: OFFSET(Sync!$CK$10,0,0,MAX(COUNTIF(Sync!$CK$10:$CK$29,"?*"),1),1)
Name ListStatus: OFFSET(Sync!$CM$10,0,0,MAX(COUNTIF(Sync!$CM$10:$CM$29,"?*"),1),1)
Name ListSubgroups: OFFSET(Sync!$AR$10,0,0,MAX(COUNTIF(Sync!$AS$10:$AS$51,"?*"),1),1)
Name ListTxnDirections: OFFSET(Sync!$CR$10,0,0,MAX(COUNTIF(Sync!$CR$10:$CR$29,"?*"),1),1)
Name ListUnits: OFFSET(Sync!$CA$10,0,0,MAX(COUNTIF(Sync!$CA$10:$CA$29,"?*"),1),1)
Name ListYesNo: OFFSET(Sync!$CD$10,0,0,MAX(COUNTIF(Sync!$CD$10:$CD$29,"?*"),1),1)
Name OpTbl: Sync!$I$10:$W$33
Name ParamTbl: Sync!$AO$10:$AP$21
Name ProductTbl: Sync!$AH$10:$AI$29

Sheet Home
A1: مازندشت — سورتینگ و بسته‌بندی مرکبات | G1: MAZANDASHT · CITRUS SORTING & PACKING
A2: نمونه ساده — کل چرخه در یک صفحه
A3: ۸ ردیف نمونه که خرید، فروش، باسکول دیگران، انعام، سبد و آبگیری را نشان می‌دهد
A5: ۰۱ | B5: این فایل برای چه کسی است؟ — اگر تازه با سیستم آشنا می‌شوید، از این‌جا شروع کنید
A6: ۱ | B6: شیت ثبت
B7: ۸ ردیف نمونه با همه نوع عملیات. هر ردیف را باز کنید و ببینید چه ستون‌هایی پر شده.
A8: ۲ | B8: شیت خلاصه
B9: جمع بدهکار و بستانکار هر گروه و موجودی سبد؛ همان نتیجه‌ای که در فایل اصلی می‌بینید.
A10: ۳ | B10: شیت Sync
B11: داده‌های ثابت (حساب‌ها، عملیات، سبدها) که همه کشوها از آن می‌آید.
A12: ۴ | B12: فایل اصلی
B13: وقتی منطق را فهمیدید، سراغ 01_Register.xlsx بروید؛ همان ساختار با ظرفیت ۳۰۰ توزین.
A15: ثبت نمونه | D15: خلاصه | G15: راهنما
A16: ۸ ردیف با همه نوع عملیات | D16: جمع‌ها و موجودی سبد | G16: توضیح قدم‌به‌قدم
A21: اعداد این فایل نمونه‌اند و به فایل‌های دیگر وصل نیستند؛ برای کار واقعی از ثبت روزانه استفاده کنید.

Sheet Register
A1: مازندشت — سورتینگ و بسته‌بندی مرکبات | I1: MAZANDASHT · CITRUS SORTING & PACKING
A2: ثبت نمونه
A3: ۸ ردیف: از خرید باغدار تا فروش بار، باسکول دیگران، انعام، سبد و آبگیری
A4: راهنما | B4: ورود دستی | C4: خودکار | D4: ورود | E4: خروج | F4: هشدار | G4: ستون‌های زرد = ورود شما | ستون‌های خاکستری = محاسبه خودکار | روی سرستون‌ها بایستید تا راهنما باز شود
A5: جمع مبلغ | E5: جمع بدهکار | I5: جمع بستانکار | M5: وضعیت
A6: =SUM($K$10:$K$17) -> 0 | E6: =SUM($M$10:$M$17) -> 0 | I6: =SUM($N$10:$N$17) -> 0 | M6: =IF(ROUND($M$7-$N$7,0)=0,"✓ تراز","⚠ ناتراز") -> 0
A9: تاریخ | B9: ساعت | C9: سند | D9: نوع عملیات | E9: کد حساب | F9: نام حساب | G9: محصول | H9: سبد | I9: وزن باسکول | J9: تعداد | K9: فی | L9: مبلغ | M9: بدهکار | N9: بستانکار
A10: 1405/07/01 | B10: 07:45 | C10: SM-01 | D10: خرید مرکبات | E10: C001 | F10: =IF($E10="","",IFERROR(VLOOKUP($E10,AcctTbl,2,0),"کد ناشناخته")) -> 0 | G10: نارنگی پیچ | H10: BK03 – ۹ک مشکی | I10: 2290 | J10: 139 | K10: 32000 | L10: =IF($M10+$N10=0,0,$M10+$N10) -> 0 | M10: =IF($D10="","",IF(OR($D10="خرید مرکبات",$D10="باسکول دیگران"),$K10,IF($D10="فروش بار (بارفروش)",$K10,0))) -> 0 | N10: =IF($D10="","",IF(OR($D10="خرید مرکبات",$D10="فروش بار (بارفروش)",$D10="انعام مصطفی"),$K10,0)) -> 0
A11: 1405/07/01 | B11: 09:10 | C11: SM-02 | D11: خرید مرکبات | E11: C003 | F11: =IF($E11="","",IFERROR(VLOOKUP($E11,AcctTbl,2,0),"کد ناشناخته")) -> 0 | G11: پرتقال تامسون | H11: BK01 – ۶ک مشکی | I11: 910 | J11: 53 | K11: 35000 | L11: =IF($M11+$N11=0,0,$M11+$N11) -> 0 | M11: =IF($D11="","",IF(OR($D11="خرید مرکبات",$D11="باسکول دیگران"),$K11,IF($D11="فروش بار (بارفروش)",$K11,0))) -> 0 | N11: =IF($D11="","",IF(OR($D11="خرید مرکبات",$D11="فروش بار (بارفروش)",$D11="انعام مصطفی"),$K11,0)) -> 0
A12: 1405/07/02 | B12: 08:20 | C12: SM-03 | D12: خرید مرکبات | E12: C006 | F12: =IF($E12="","",IFERROR(VLOOKUP($E12,AcctTbl,2,0),"کد ناشناخته")) -> 0 | G12: نارنگی اونشو | H12: BK01 – ۶ک مشکی | I12: 1385 | J12: 85 | K12: 30000 | L12: =IF($M12+$N12=0,0,$M12+$N12) -> 0 | M12: =IF($D12="","",IF(OR($D12="خرید مرکبات",$D12="باسکول دیگران"),$K12,IF($D12="فروش بار (بارفروش)",$K12,0))) -> 0 | N12: =IF($D12="","",IF(OR($D12="خرید مرکبات",$D12="فروش بار (بارفروش)",$D12="انعام مصطفی"),$K12,0)) -> 0
A13: 1405/07/03 | B13: 10:15 | C13: SM-04 | D13: فروش بار (بارفروش) | E13: SL001 | F13: =IF($E13="","",IFERROR(VLOOKUP($E13,AcctTbl,2,0),"کد ناشناخته")) -> 0 | G13: پرتقال تامسون | H13: BK03 – ۹ک مشکی | I13: 2500 | J13: 120 | K13: 58000 | L13: =IF($M13+$N13=0,0,$M13+$N13) -> 0 | M13: =IF($D13="","",IF(OR($D13="خرید مرکبات",$D13="باسکول دیگران"),$K13,IF($D13="فروش بار (بارفروش)",$K13,0))) -> 0 | N13: =IF($D13="","",IF(OR($D13="خرید مرکبات",$D13="فروش بار (بارفروش)",$D13="انعام مصطفی"),$K13,0)) -> 0
A14: 1405/07/04 | B14: 11:00 | C14: SM-05 | D14: باسکول دیگران | E14: BD001 | F14: =IF($E14="","",IFERROR(VLOOKUP($E14,AcctTbl,2,0),"کد ناشناخته")) -> 0 | L14: =IF($M14+$N14=0,0,$M14+$N14) -> 0 | M14: =IF($D14="","",IF(OR($D14="خرید مرکبات",$D14="باسکول دیگران"),$K14,IF($D14="فروش بار (بارفروش)",$K14,0))) -> 0 | N14: =IF($D14="","",IF(OR($D14="خرید مرکبات",$D14="فروش بار (بارفروش)",$D14="انعام مصطفی"),$K14,0)) -> 0
A15: 1405/07/05 | B15: 12:30 | C15: SM-06 | D15: انعام مصطفی | F15: =IF($E15="","",IFERROR(VLOOKUP($E15,AcctTbl,2,0),"کد ناشناخته")) -> 0 | L15: =IF($M15+$N15=0,0,$M15+$N15) -> 0 | M15: =IF($D15="","",IF(OR($D15="خرید مرکبات",$D15="باسکول دیگران"),$K15,IF($D15="فروش بار (بارفروش)",$K15,0))) -> 0 | N15: =IF($D15="","",IF(OR($D15="خرید مرکبات",$D15="فروش بار (بارفروش)",$D15="انعام مصطفی"),$K15,0)) -> 0
A16: 1405/07/06 | B16: 09:00 | C16: SM-07 | D16: خرید سبد | E16: S001 | F16: =IF($E16="","",IFERROR(VLOOKUP($E16,AcctTbl,2,0),"کد ناشناخته")) -> 0 | H16: BK01 – ۶ک مشکی | J16: 500 | K16: 45000 | L16: =IF($M16+$N16=0,0,$M16+$N16) -> 0 | M16: =IF($D16="","",IF(OR($D16="خرید مرکبات",$D16="باسکول دیگران"),$K16,IF($D16="فروش بار (بارفروش)",$K16,0))) -> 0 | N16: =IF($D16="","",IF(OR($D16="خرید مرکبات",$D16="فروش بار (بارفروش)",$D16="انعام مصطفی"),$K16,0)) -> 0
A17: 1405/07/07 | B17: 14:00 | C17: SM-08 | D17: آبگیری | E17: C002 | F17: =IF($E17="","",IFERROR(VLOOKUP($E17,AcctTbl,2,0),"کد ناشناخته")) -> 0 | G17: پرتقال خونی | I17: 605 | L17: =IF($M17+$N17=0,0,$M17+$N17) -> 0 | M17: =IF($D17="","",IF(OR($D17="خرید مرکبات",$D17="باسکول دیگران"),$K17,IF($D17="فروش بار (بارفروش)",$K17,0))) -> 0 | N17: =IF($D17="","",IF(OR($D17="خرید مرکبات",$D17="فروش بار (بارفروش)",$D17="انعام مصطفی"),$K17,0)) -> 0
A18: جمع | L18: =SUM(L10:L17) -> 0 | M18: =SUM(M10:M17) -> 0 | N18: =SUM(N10:N17) -> 0
A20: این جدول عمداً ساده است: دو ستون بدهکار/بستانکار با قاعده‌های ثابت پر می‌شوند. در فایل اصلی همین کار را جدول عملیات INFO انجام می‌دهد.

Sheet Summary
A1: مازندشت — سورتینگ و بسته‌بندی مرکبات | B1: MAZANDASHT · CITRUS SORTING & PACKING
A2: خلاصه نمونه
A3: جمع هر نوع عملیات و مانده ساده · همان منطق فایل اصلی، در مقیاس کوچک
A4: راهنما | B4: ورود دستی | C4: خودکار | D4: ورود | E4: خروج | F4: هشدار
A5: جمع بدهکار | C5: جمع بستانکار | E5: اختلاف
A6: =Register!$M$18 -> 0 | C6: =Register!$N$18 -> 0 | E6: =Register!$M$18-Register!$N$18 -> 0
A10: نوع عملیات | B10: تعداد | C10: مبلغ | D10: اثر روی حساب طرف | E10: توضیح کوتاه
A11: خرید مرکبات | B11: =COUNTIF(Register!$D$10:$D$17,$A11) -> 0 | C11: =SUMIF(Register!$D$10:$D$17,$A11,Register!$K$10:$K$17) -> 0 | D11: بستانکار باغدار؛ بدهکار موجودی مرکبات | E11: =IF($B11=0,"—","ثبت شده") -> 0
A12: فروش بار (بارفروش) | B12: =COUNTIF(Register!$D$10:$D$17,$A12) -> 0 | C12: =SUMIF(Register!$D$10:$D$17,$A12,Register!$K$10:$K$17) -> 0 | D12: بدهکار بارفروش؛ بستانکار فروش | E12: =IF($B12=0,"—","ثبت شده") -> 0
A13: باسکول دیگران | B13: =COUNTIF(Register!$D$10:$D$17,$A13) -> 0 | C13: =SUMIF(Register!$D$10:$D$17,$A13,Register!$K$10:$K$17) -> 0 | D13: بدهکار طرف؛ بستانکار درآمد باسکول | E13: =IF($B13=0,"—","ثبت شده") -> 0
A14: انعام مصطفی | B14: =COUNTIF(Register!$D$10:$D$17,$A14) -> 0 | C14: =SUMIF(Register!$D$10:$D$17,$A14,Register!$K$10:$K$17) -> 0 | D14: بستانکار مصطفی؛ بدهکار پوز ۲۰۰۶ | E14: =IF($B14=0,"—","ثبت شده") -> 0
A15: خرید سبد | B15: =COUNTIF(Register!$D$10:$D$17,$A15) -> 0 | C15: =SUMIF(Register!$D$10:$D$17,$A15,Register!$K$10:$K$17) -> 0 | D15: بستانکار فروشنده سبد؛ بدهکار موجودی سبد | E15: =IF($B15=0,"—","ثبت شده") -> 0
A16: آبگیری | B16: =COUNTIF(Register!$D$10:$D$17,$A16) -> 0 | C16: =SUMIF(Register!$D$10:$D$17,$A16,Register!$K$10:$K$17) -> 0 | D16: بدهکار طرف؛ بستانکار درآمد آبگیری | E16: =IF($B16=0,"—","ثبت شده") -> 0

Sheet Sync
A1: داده‌های ثابت — کپی کامل از INFO.xlsx (بدون وابستگی)
A2: این شیت فقط نمایش است و قفل شده. همه کشوها و فرمول‌ها از همین‌جا می‌خوانند؛ برای تغییر، INFO.xlsx را ویرایش کنید و سپس این فایل را (با اسکریپت ساخت یا کپی ستون‌ها) دوباره همگام کنید. هیچ فرمولی به فایل مادر وابسته نیست، پس فایل همیشه سالم باز می‌شود. — در فایل نمونه، داده‌ها ثابت و ساده هستند.
A3: MAZANDASHT · INFO MASTER DATA (READ ONLY)
B8: حساب‌ها — کد، نام، گروه، زیرگروه، نوع و مانده اولیه | I8: عملیات — قاعده بدهکار/بستانکار | Y8: سبدها — برچسب، کد، نام، تار، ظرفیت، خرید، فروش، موجودی | AH8: محصولات | AK8: بانک‌ها — کد، عنوان، مانده، حساب معین | AO8: پارامترها | AR8: گروه‌ها و زیرگروه‌ها | AU8: گروه‌های اصلی | AW8: عملیات سبد | AX8: باسکول دیگران | AZ8: عملیات باسکول
B9: ACCOUNTS | I9: OPERATIONS | Y9: BASKETS | AH9: PRODUCTS | AK9: BANKS | AO9: PARAMS | AR9: GROUPS | AU9: GROUP LIST | AW9: BASKET OPS | AX9: OTHER SCALES | AZ9: BASKOL OPS
B10: C001 | C10: زینب زاهدی | D10: باغدار | E10: عمده | F10: طرف حساب | G10: 0 | I10: خرید مرکبات | J10: ورود | K10: خرید | L10: بله | M10: بله | N10: وزن | O10: بستانکار | P10: X004 | Q10: بدهکار | R10: افزودن | S10: — | W10: بله | Y10: BK01 – ۶ک مشکی | Z10: BK01 | AA10: ۶ک مشکی | AB10: 1.5 | AC10: 6 | AD10: 45000 | AE10: 55000 | AF10: 1200 | AH10: پرتقال تامسون | AI10: پرتقال | AK10: BANK01 | AL10: صادرات ۹۰۰۹ — جاری اصلی | AM10: 500000000 | AN10: BN01 | AO10: P01 | AP10: 1.5 | AR10: باغدار | AS10: سردرختی | AU10: باغدار | AW10: خرید سبد | AX10: BD001 | AZ10: خرید مرکبات | CA10: کیلوگرم | CB10: پرتقال | CC10: ورود | CD10: بله | CE10: طرف حساب | CF10: نقد | CG10: در جریان | CH10: ☑ | CI10: افزودن | CJ10: بدهکار | CK10: بدهکار | CL10: خرید | CM10: ✓ | CN10: Growers | CO10: وزن | CP10: mint | CQ10: بهار | CR10: پرداخت
B11: C002 | C11: سید عباس موسوی | D11: باغدار | E11: صادراتی | F11: طرف حساب | G11: 0 | I11: فروش بار (بارفروش) | J11: خروج | K11: فروش | L11: بله | M11: بله | N11: وزن | O11: بدهکار | P11: X006 | Q11: بستانکار | R11: پوز | S11: بدهکار | T11: BANK02 | U11: X002 | W11: بله | Y11: BK02 – درب‌۶ک | Z11: BK02 | AA11: درب‌۶ک | AB11: 1.5 | AC11: 6 | AD11: 48000 | AE11: 58000 | AF11: 400 | AH11: پرتقال خونی | AI11: پرتقال | AK11: BANK02 | AL11: صادرات ۲۰۰۶ — پوز باسکول | AM11: 0 | AN11: BN02 | AO11: P02 | AP11: 1 | AR11: باغدار | AS11: انباری | AU11: بارفروش | AW11: فروش سبد | AX11: BD002 | AZ11: فروش بار (بارفروش) | CA11: سبد | CB11: نارنگی | CC11: خروج | CD11: خیر | CE11: معین | CF11: چک | CG11: پاس شده | CH11: ☐ | CI11: پوز | CJ11: بستانکار | CK11: بستانکار | CL11: فروش | CM11: ⚠ | CN11: LoadBuyers | CO11: مبلغ | CP11: sky | CQ11: تابستان | CR11: دریافت
B12: C003 | C12: حاج احمد عیسی پور | D12: باغدار | E12: خرده‌فروش | F12: طرف حساب | G12: 0 | I12: فروش متفرقه / صادراتی | J12: خروج | K12: فروش | L12: بله | M12: بله | N12: وزن | O12: بدهکار | P12: X006 | Q12: بستانکار | R12: پوز | S12: بدهکار | T12: BANK02 | U12: X002 | W12: بله | Y12: BK03 – ۹ک مشکی | Z12: BK03 | AA12: ۹ک مشکی | AB12: 1.9 | AC12: 9 | AD12: 62000 | AE12: 75000 | AF12: 800 | AH12: پرتقال کاراکارا | AI12: پرتقال | AK12: BANK03 | AL12: ملت | AM12: 0 | AN12: BN03 | AO12: P03 | AP12: 1000 | AR12: باغدار | AS12: عمده | AU12: فروشنده سبد | AW12: مرجوعی خرید سبد | AX12: BD003 | AZ12: فروش متفرقه / صادراتی | CA12: جعبه | CB12: لیمو | CC12: — | CF12: انتقال بانکی | CG12: برگشتی | CI12: هیچ | CJ12: — | CK12: خودکار | CL12: آبگیری | CN12: BasketSellers | CO12: هیچ | CP12: lavender | CQ12: پاییز
B13: C004 | C13: امید زاهدی | D13: باغدار | F13: طرف حساب | G13: 0 | I13: آبگیری | J13: خروج | K13: آبگیری | L13: بله | M13: بله | N13: مبلغ | O13: خودکار | P13: X008 | Q13: خودکار | R13: هیچ | S13: — | W13: بله | Y13: BK04 – ریلی کوچک آبی | Z13: BK04 | AA13: ریلی کوچک آبی | AB13: 1.3 | AC13: 5 | AD13: 40000 | AE13: 50000 | AF13: 300 | AH13: پرتقال بیروتی | AI13: پرتقال | AK13: BANK04 | AL13: کشاورزی | AM13: 0 | AN13: BN04 | AO13: P04 | AP13: 1405 | AR13: باغدار | AS13: خرده‌فروش | AU13: تأمین‌کننده | AW13: مرجوعی فروش سبد | AX13: BD004 | AZ13: آبگیری | CA13: تن | CB13: گریپ‌فرویت | CF13: کارت/پوز | CG13: باطل | CI13: — | CK13: — | CL13: انعام | CN13: Suppliers | CO13: — | CP13: rose | CQ13: زمستان
B14: C005 | C14: بار شخصی قاسم زاهدی | D14: باغدار | F14: طرف حساب | G14: 0 | I14: انعام مصطفی | J14: — | K14: انعام | L14: خیر | M14: خیر | N14: مبلغ | O14: بستانکار | P14: BANK02 | Q14: بدهکار | R14: هیچ | S14: — | V14: X001 | W14: بله | Y14: BK05 – تک‌رج آبی بزرگ | Z14: BK05 | AA14: تک‌رج آبی بزرگ | AB14: 2 | AC14: 10 | AD14: 70000 | AE14: 85000 | AF14: 250 | AH14: پرتقال یافا | AI14: پرتقال | AK14: BANK05 | AL14: سپه | AM14: 0 | AN14: BN05 | AO14: P05 | AP14: 100 | AR14: باغدار | AS14: صادراتی | AU14: کارمند | AW14: انتقال سبد بین انبار | AX14: BD005 | AZ14: انعام مصطفی | CA14: عدد | CB14: سایر | CF14: پاس چک | CL14: باسکول دیگران | CN14: Staff | CP14: sand
B15: C006 | C15: هوشنگ عیسی پور | D15: باغدار | F15: طرف حساب | G15: 0 | I15: باسکول دیگران | J15: — | K15: باسکول دیگران | L15: خیر | M15: بله | N15: مبلغ | O15: بدهکار | P15: X002 | Q15: بستانکار | R15: هیچ | S15: — | W15: بله | Y15: BK06 – آبی ۲۵×۲۰ | Z15: BK06 | AA15: آبی ۲۵×۲۰ | AB15: 1.1 | AC15: 4 | AD15: 35000 | AE15: 45000 | AF15: 150 | AH15: نارنگی پیچ | AI15: نارنگی | AK15: BANK06 | AL15: مهر ایران | AM15: 0 | AN15: BN06 | AO15: P06 | AP15: 0 | AR15: باغدار | AS15: میدان بار | AU15: سایر حساب | AX15: BD006 | AZ15: باسکول دیگران | CA15: ریال | CF15: انتقال داخلی | CL15: درآمد | CN15: Other | CP15: grey
B16: C007 | C16: علی آهنگر | D16: باغدار | F16: طرف حساب | G16: 0 | I16: درآمد پوز باسکول (بدون طرف) | J16: — | K16: درآمد | L16: خیر | M16: خیر | N16: مبلغ | O16: — | Q16: — | R16: پوز | S16: بدهکار | T16: BANK02 | U16: X002 | W16: بله | Y16: BK07 – ۸ک مشکی | Z16: BK07 | AA16: ۸ک مشکی | AB16: 1.8 | AC16: 8 | AD16: 58000 | AE16: 70000 | AF16: 200 | AH16: نارنگی ژاپنی | AI16: نارنگی | AK16: BANK07 | AL16: تجارت | AM16: 0 | AN16: BN07 | AO16: P07 | AP16: خرید- | AR16: بارفروش | AS16: میدان بار شهرستان | AU16: باسکول دیگران | AX16: BD007 | AZ16: درآمد پوز باسکول (بدون طرف) | CL16: هزینه | CN16: OtherScales | CP16: teal
B17: C008 | C17: صفدر مسلمی | D17: باغدار | F17: طرف حساب | G17: 0 | I17: مرجوعی خرید | J17: خروج | K17: خرید | L17: بله | M17: بله | N17: وزن | O17: بدهکار | P17: X004 | Q17: بستانکار | R17: افزودن | S17: — | W17: بله | Y17: BK08 – | Z17: BK08 | AB17: 1.5 | AC17: 6 | AD17: 0 | AE17: 0 | AF17: 0 | AH17: نارنگی اونشو | AI17: نارنگی | AK17: BANK08 | AL17: پاسارگاد | AM17: 0 | AN17: BN08 | AO17: P08 | AP17: فروش- | AR17: بارفروش | AS17: حجره‌دار | AU17: دارایی ثابت | AX17: BD008 | AZ17: مرجوعی خرید | CL17: انتقال | CN17: Assets | CP17: peach
B18: C009 | C18: همایون بابایی | D18: باغدار | F18: طرف حساب | G18: 0 | I18: مرجوعی فروش | J18: ورود | K18: فروش | L18: بله | M18: بله | N18: وزن | O18: بستانکار | P18: X006 | Q18: بدهکار | R18: هیچ | S18: — | W18: بله | Y18: BK09 – | Z18: BK09 | AB18: 1.5 | AC18: 6 | AD18: 0 | AE18: 0 | AF18: 0 | AH18: نارنگی یافا | AI18: نارنگی | AK18: BANK09 | AL18: رفاه | AM18: 0 | AN18: BN09 | AO18: P09 | AP18: 500000000 | AR18: بارفروش | AS18: صادراتی | AU18: وام و تسهیلات | AX18: BD009 | AZ18: مرجوعی فروش | CL18: سایر | CN18: Liabilities
B19: C010 | C19: دبیر فرجی | D19: باغدار | F19: طرف حساب | G19: 0 | I19: ضایعات / افت انبار | J19: خروج | K19: هزینه | L19: بله | M19: بله | N19: وزن | O19: بستانکار | P19: X009 | Q19: بدهکار | R19: هیچ | S19: — | V19: X004 | W19: بله | Y19: BK10 – | Z19: BK10 | AB19: 1.5 | AC19: 6 | AD19: 0 | AE19: 0 | AF19: 0 | AH19: لیمو شیرین | AI19: لیمو | AK19: BANK10 | AL19: قرض‌الحسنه | AM19: 0 | AN19: BN10 | AO19: P10 | AP19: 30 | AR19: بارفروش | AS19: واسطه | AU19: سرمایه و آورده صاحبان | AX19: BD010 | AZ19: ضایعات / افت انبار | CL19: تعدیل | CN19: Equity
B20: C011 | C20: محمود علیجانی | D20: باغدار | F20: طرف حساب | G20: 0 | I20: انتقال بین انبار | J20: خروج | K20: انتقال | L20: بله | M20: خیر | N20: هیچ | O20: — | Q20: — | R20: هیچ | S20: — | W20: بله | Y20: BK11 – | Z20: BK11 | AB20: 1.5 | AC20: 6 | AD20: 0 | AE20: 0 | AF20: 0 | AH20: لیمو ترش | AI20: لیمو | AO20: P11 | AP20: ریال | AR20: بارفروش | AS20: نقدی | AU20: بانک و صندوق | AX20: BD011 | AZ20: انتقال بین انبار
B21: C012 | C21: افشین بشتکار | D21: باغدار | F21: طرف حساب | G21: 0 | I21: سایر ورود | J21: ورود | K21: سایر | L21: بله | M21: بله | N21: وزن | O21: بستانکار | P21: X011 | Q21: بدهکار | R21: افزودن | S21: — | W21: بله | Y21: BK12 – | Z21: BK12 | AB21: 1.5 | AC21: 6 | AD21: 0 | AE21: 0 | AF21: 0 | AH21: کامکوات | AI21: سایر | AO21: P12 | AP21: خیر | AR21: فروشنده سبد | AS21: سبد پلاستیکی | AX21: BD012 | AZ21: سایر ورود
B22: C013 | C22: میرقربان موسویان | D22: باغدار | F22: طرف حساب | G22: 0 | I22: سایر خروج | J22: خروج | K22: سایر | L22: بله | M22: بله | N22: وزن | O22: بدهکار | P22: X011 | Q22: بستانکار | R22: هیچ | S22: — | W22: بله | AH22: گریپ‌فرویت | AI22: گریپ‌فرویت | AR22: فروشنده سبد | AS22: سبد چوبی | AX22: BD013 | AZ22: سایر خروج
B23: C014 | C23: باباجانی (تراجیکلا) | D23: باغدار | F23: طرف حساب | G23: 0 | I23: هزینه باسکول نقدی (درآمد) | J23: — | K23: درآمد | L23: خیر | M23: خیر | N23: مبلغ | O23: — | Q23: — | R23: پوز | S23: بدهکار | T23: BANK02 | U23: X002 | W23: بله | AH23: خرمالو | AI23: سایر | AR23: فروشنده سبد | AS23: سبد مقوایی | AX23: BD014 | AZ23: هزینه باسکول نقدی (درآمد)
B24: C015 | C24: کاظم میرزازاده | D24: باغدار | F24: طرف حساب | G24: 0 | I24: خرید سبد | J24: ورود | K24: خرید | L24: خیر | M24: بله | N24: مبلغ | O24: بستانکار | P24: X005 | Q24: بدهکار | R24: هیچ | S24: — | W24: خیر | AH24: نارنج | AI24: سایر | AR24: فروشنده سبد | AS24: سایر | AX24: BD015
B25: C016 | C25: علی جانبرارپور | D25: باغدار | F25: طرف حساب | G25: 0 | I25: فروش سبد | J25: خروج | K25: فروش | L25: خیر | M25: بله | N25: مبلغ | O25: بدهکار | P25: X007 | Q25: بستانکار | R25: هیچ | S25: — | W25: خیر | AR25: تأمین‌کننده | AS25: مواد بسته‌بندی | AX25: BD016
B26: C017 | C26: لیلا محمودنیا | D26: باغدار | F26: طرف حساب | G26: 0 | I26: مرجوعی خرید سبد | J26: خروج | K26: خرید | L26: خیر | M26: بله | N26: مبلغ | O26: بدهکار | P26: X005 | Q26: بستانکار | R26: هیچ | S26: — | W26: خیر | AR26: تأمین‌کننده | AS26: واکس و رنگ | AX26: BD017
B27: C018 | C27: اسماعیل خانیا | D27: باغدار | F27: طرف حساب | G27: 0 | I27: مرجوعی فروش سبد | J27: ورود | K27: فروش | L27: خیر | M27: بله | N27: مبلغ | O27: بستانکار | P27: X007 | Q27: بدهکار | R27: هیچ | S27: — | W27: خیر | AR27: تأمین‌کننده | AS27: حمل‌ونقل | AX27: BD018
B28: C019 | C28: یوسف یوسف نژاد | D28: باغدار | F28: طرف حساب | G28: 0 | I28: انتقال سبد بین انبار | J28: خروج | K28: انتقال | L28: خیر | M28: خیر | N28: هیچ | O28: — | Q28: — | R28: هیچ | S28: — | W28: خیر | AR28: تأمین‌کننده | AS28: خدمات | AX28: BD019
B29: C020 | C29: علی نوایی | D29: باغدار | F29: طرف حساب | G29: 0 | AR29: کارمند | AS29: مدیرعامل | AX29: BD020
B30: C021 | C30: دومیری | D30: باغدار | F30: طرف حساب | G30: 0 | AR30: کارمند | AS30: حسابدار
B31: C022 | C31: شمسعلی علیجانی | D31: باغدار | F31: طرف حساب | G31: 0 | AR31: کارمند | AS31: فروشنده
B32: C023 | C32: یوسف نیا (موزیج) | D32: باغدار | F32: طرف حساب | G32: 0 | AR32: کارمند | AS32: انباردار
B33: C024 | C33: کاظم ذبیح پور | D33: باغدار | F33: طرف حساب | G33: 0 | AR33: کارمند | AS33: سرپرست خط
B34: C025 | C34: علی غلام رضاپور | D34: باغدار | F34: طرف حساب | G34: 0 | AR34: کارمند | AS34: کارگر
B35: C026 | C35: حسین شکرالله نیا | D35: باغدار | F35: طرف حساب | G35: 0 | AR35: سایر حساب | AS35: صندوق
B36: C027 | C36: سید مهدی حسینی (دوست حاج هوشنگ) | D36: باغدار | F36: طرف حساب | G36: 0 | AR36: سایر حساب | AS36: موجودی
B37: C028 | C37: آقای عزیزی | D37: باغدار | F37: طرف حساب | G37: 0 | AR37: سایر حساب | AS37: درآمد
B38: C029 | C38: آقای حبیبی (بانک صادرات) | D38: باغدار | F38: طرف حساب | G38: 0 | AR38: سایر حساب | AS38: هزینه
B39: C030 | C39: محمد علی اصغرزاده | D39: باغدار | F39: طرف حساب | G39: 0 | AR39: سایر حساب | AS39: انعام و پاداش
B40: C031 | C40: فغان پور | D40: باغدار | F40: طرف حساب | G40: 0 | AR40: سایر حساب | AS40: چک پرداختی
B41: C032 | C41: عباس پور (بهنمیر) | D41: باغدار | F41: طرف حساب | G41: 0 | AR41: سایر حساب | AS41: حساب واسط
... B51: C042 | C51: مغداد طلایی | D51: باغدار | F51: طرف حساب | G51: 0 | AR51: سرمایه و آورده صاحبان | AS51: برداشت سرمایه
B52: C043 | C52: سید عبدالله میراقازاده | D52: باغدار | F52: طرف حساب | G52: 0
B53: C044 | C53: رجب پور | D53: باغدار | F53: طرف حساب | G53: 0
...

Sheet Help
A1: مازندشت — سورتینگ و بسته‌بندی مرکبات | E1: MAZANDASHT · CITRUS SORTING & PACKING
A2: راهنمای نمونه
A3: منطق سیستم در ۵ جمله
A4: راهنما | B4: ورود دستی | C4: خودکار | D4: ورود | E4: خروج | F4: هشدار | G4: ستون‌های زرد = ورود شما | ستون‌های خاکستری = محاسبه خودکار | روی سرستون‌ها بایستید تا راهنما باز شود
B11: • | C11: ۱. وزن خالص
A12: وزن باسکول منهای (تعداد سبد × وزن تار سبد). برای خرید، ۱٪ افت هم کم می‌شود.
B14: • | C14: ۲. مبلغ
A15: وزن خالص × فی خرید، گرد شده به هزار ریال. اگر مبلغ دستی وارد شود، همان ملاک است.
B17: • | C17: ۳. خرید
A18: باغدار بستانکار می‌شود (پول طلب دارد)؛ موجودی مرکبات بدهکار می‌شود.
B20: • | C20: ۴. فروش
A21: بارفروش بدهکار می‌شود؛ مبلغی که پوز باسکول می‌گیرد به حساب پوز ۲۰۰۶ می‌رود و روی حساب بارفروش اثر ندارد.
B23: • | C23: ۵. باسکول دیگران و انعام
A24: باسکول دیگران: طرف حساب بدهکار، درآمد باسکول بستانکار. انعام مصطفی: مصطفی بستانکار، پوز ۲۰۰۶ بدهکار.
A27: برای کار واقعی: 01_Register.xlsx را باز کنید؛ همان قواعد با جدول عملیات INFO اجرا می‌شود.
