Workbook
Name AcctCodes: Accounts!$A$10:$A$259
Name AcctTbl: Accounts!$A$10:$J$259
Name BankTbl: Banks!$A$10:$G$19
Name BasketTbl: Baskets!$B$10:$F$21
Name GroupTbl: Groups!$A$10:$F$52
Name ListAllCodes: OFFSET(Accounts!$A$10,0,0,MAX(COUNTIF(Accounts!$D$10:$D$259,"?*"),1),1)
Name ListBanks: OFFSET(Banks!$B$10,0,0,MAX(COUNTIF(Banks!$B$10:$B$19,"?*"),1),1)
Name ListBasketOps: OFFSET(Ops!$B$24,0,0,MAX(COUNTIF(Ops!$B$24:$B$33,"?*"),1),1)
Name ListBaskets: OFFSET(Baskets!$B$10,0,0,MAX(COUNTIF(Baskets!$B$10:$B$21,"?*"),1),1)
Name ListCategories: OFFSET(Lists!$B$10,0,0,MAX(COUNTIF(Lists!$B$10:$B$29,"?*"),1),1)
Name ListChequeStatus: OFFSET(Lists!$G$10,0,0,MAX(COUNTIF(Lists!$G$10:$G$29,"?*"),1),1)
Name ListColorKeys: OFFSET(Lists!$P$10,0,0,MAX(COUNTIF(Lists!$P$10:$P$29,"?*"),1),1)
Name ListDirections: OFFSET(Lists!$C$10,0,0,MAX(COUNTIF(Lists!$C$10:$C$29,"?*"),1),1)
Name ListGroups: Groups!$H$10:$H$19
Name ListInclude: OFFSET(Lists!$H$10,0,0,MAX(COUNTIF(Lists!$H$10:$H$29,"?*"),1),1)
Name ListManualRoles: OFFSET(Lists!$I$10,0,0,MAX(COUNTIF(Lists!$I$10:$I$29,"?*"),1),1)
Name ListOpCategories: OFFSET(Lists!$L$10,0,0,MAX(COUNTIF(Lists!$L$10:$L$29,"?*"),1),1)
Name ListOps: OFFSET(Ops!$B$10,0,0,MAX(COUNTIF(Ops!$B$10:$B$33,"?*"),1),1)
Name ListPartyBasis: OFFSET(Lists!$O$10,0,0,MAX(COUNTIF(Lists!$O$10:$O$29,"?*"),1),1)
Name ListPartyTypes: OFFSET(Lists!$E$10,0,0,MAX(COUNTIF(Lists!$E$10:$E$29,"?*"),1),1)
Name ListPayMethods: OFFSET(Lists!$F$10,0,0,MAX(COUNTIF(Lists!$F$10:$F$29,"?*"),1),1)
Name ListPosEffects: OFFSET(Lists!$J$10,0,0,MAX(COUNTIF(Lists!$J$10:$J$29,"?*"),1),1)
Name ListProducts: OFFSET(Products!$B$10,0,0,MAX(COUNTIF(Products!$B$10:$B$29,"?*"),1),1)
Name ListReportSheets: OFFSET(Lists!$N$10,0,0,MAX(COUNTIF(Lists!$N$10:$N$29,"?*"),1),1)
Name ListSeasons: OFFSET(Lists!$Q$10,0,0,MAX(COUNTIF(Lists!$Q$10:$Q$29,"?*"),1),1)
Name ListSides: OFFSET(Lists!$K$10,0,0,MAX(COUNTIF(Lists!$K$10:$K$29,"?*"),1),1)
Name ListStatus: OFFSET(Lists!$M$10,0,0,MAX(COUNTIF(Lists!$M$10:$M$29,"?*"),1),1)
Name ListSubgroups: OFFSET(Groups!$B$10,0,0,MAX(COUNTIF(Groups!$B$10:$B$52,"?*"),1),1)
Name ListTxnDirections: OFFSET(Lists!$R$10,0,0,MAX(COUNTIF(Lists!$R$10:$R$29,"?*"),1),1)
Name ListUnits: OFFSET(Lists!$A$10,0,0,MAX(COUNTIF(Lists!$A$10:$A$29,"?*"),1),1)
Name ListYesNo: OFFSET(Lists!$D$10,0,0,MAX(COUNTIF(Lists!$D$10:$D$29,"?*"),1),1)
Name OpTbl: Ops!$A$10:$S$33
Name ParamTbl: Params!$A$10:$E$21
Name ProductTbl: Products!$B$10:$D$29

Sheet Home
A1: مازندشت — سورتینگ و بسته‌بندی مرکبات | G1: MAZANDASHT · CITRUS SORTING & PACKING
A2: مازندشت · سامانه یکپارچه سورتینگ و بسته‌بندی مرکبات
A3: فایل مادر (INFO) — مرکز تعریف حساب‌ها، عملیات، سبدها، بانک‌ها و پارامترها · نسخه ۰۱ · Excel 2013
A5: حساب‌های تعریف‌شده | C5: عملیات باسکول | E5: انواع سبد | G5: محصولات | I5: بانک‌ها
A6: =COUNTIF(Accounts!$D$10:$D$259,"?*") -> 0 | C6: =COUNTIF(Ops!$B$10:$B$33,"?*") -> 0 | E6: =COUNTIF(Baskets!$B$10:$B$21,"?*") -> 0 | G6: =COUNTIF(Products!$B$10:$B$29,"?*") -> 0 | I6: =COUNTIF(Banks!$A$10:$A$19,"?*") -> 0
A8: ۰۱ | B8: فایل‌های سامانه — روی هر کارت کلیک کنید — همه فایل‌ها باید در یک پوشه باشند
A10: INFO · فایل مادر — همین فایل | C10: ۰۱ ثبت · ثبت روزانه عملیات | E10: ۰۲ گزارش · گزارش‌های مدیریتی | G10: ۰۳ فاکتور · فاکتور چاپی
A11: حساب‌ها، عملیات، سبدها، بانک‌ها، پارامترها | C11: باسکول، سبد، پرداخت‌ها، گزارش جامع | E11: باغداران، بارفروشان، فروشندگان سبد، دفتر کل | G11: صورت‌حساب خریدار/باغدار با تیک انتخاب ردیف
A12: INFO.xlsx | C12: 01_Register.xlsx | E12: 02_Reports.xlsx | G12: 03_Invoice.xlsx
A13: ۰۴ ترازنامه · ترازنامه و حسابرسی | C13: ۰۵ بانک · بانک و چک | E13: ۰۶ بارفروشان · کارت بارفروشان | G13: ۰۷ نمونه · ثبت ساده — نسخه نمونه
A14: تراز ۴ و ۶ ستونه، حسابرسی، ترازبانک | C14: تراکنش بانکی، دفتر چک، مغایرت‌گیری | E14: ریز بار ارسالی و تسویه هر بارفروش | G14: کدگذاری ساده‌شده برای شروع سریع
A15: 04_Balance.xlsx | C15: 05_Bank.xlsx | E15: 06_LoadBuyers.xlsx | G15: 07_Sample.xlsx
A23: ۰۲ | B23: جریان داده — چه کسی از چه کسی می‌خواند — فلش‌ها جهت جریان اطلاعات را نشان می‌دهند
A24: INFO | B24: ← | C24: ۰۱ ثبت | D24: ← | E24: ۰۲ گزارش
A25: تعریف‌ها | C25: ورود اطلاعات | E25: گزارش
A27: ۰۱ ثبت ← INFO | D27: کد و نام حساب‌ها، عملیات و قواعد، وزن سبد، بانک‌ها، پارامترها
A28: ۰۲ گزارش ← ۰۱ ثبت + INFO | D28: ریز باسکول، سبد و پرداخت‌ها؛ نام و گروه از INFO
A29: ۰۳ فاکتور ← ۰۱ ثبت + INFO | D29: مانده و ریز گردش هر حساب؛ تیک انتخاب ردیف
A30: ۰۴ ترازنامه ← ۰۱ ثبت + ۰۲ + ۰۵ | D30: گردش حساب‌ها، بانک‌ها، موجودی سبد و مرکبات
A31: ۰۵ بانک ← INFO + ۰۱ ثبت | D31: بانک‌ها و شماره چک‌ها؛ تطبیق با پرداخت‌ها
A32: ۰۶ بارفروشان ← ۰۱ ثبت + ۰۵ | D32: بار خروجی بارفروش + تسویه‌ها + هزینه باسکول
A34: ۰۳ | B34: قواعد طلایی — هر روز یک بار بخوانید
A35: 1 | B35: کدها را تغییر ندهید؛ عنوان‌ها را آزادانه عوض کنید. سیستم با «کد» کار می‌کند، نه با عنوان.
A36: 2 | B36: ردیف تازه = ردیف خالی بعدی؛ کدها از قبل درج شده‌اند. بین ردیف‌ها ردیف خالی نگذارید.
A37: 3 | B37: برای حذف یک حساب، محتوای سلول‌ها را پاک کنید (Delete)؛ خودِ ردیف را حذف نکنید.
A38: 4 | B38: همه فایل‌ها همیشه در یک پوشه باشند؛ مسیر لینک‌ها نسبی است.
A39: 5 | B39: بعد از هر تغییر در INFO، فایل‌های دیگر را باز کنید و Data ← Edit Links ← Update Values بزنید.
A40: 6 | B40: تاریخ‌ها شمسی با قالب 1405/07/10؛ ساعت با قالب 09:30. اعداد را با ارقام لاتین وارد کنید.
A41: 7 | B41: قبل از هر ماه، از کل پوشه یک نسخه پشتیبان بگیرید (فایل را با تاریخ در نام کپی کنید).
A42: 8 | B42: اگر فرمولی «#NAME?» داد، یعنی فایل INFO بسته یا جابه‌جا شده است؛ ابتدا لینک را Update کنید.
A44: راهنمای کامل سامانه — روی این نوار کلیک کنید

Sheet Company
A1: مازندشت — سورتینگ و بسته‌بندی مرکبات | G1: MAZANDASHT · CITRUS SORTING & PACKING
A2: مشخصات شرکت
A3: این مقادیر منبع سرصفحه و گزارش‌های همه فایل‌ها هستند
A5: ۰۱ | B5: اطلاعات هویتی و تماس — ستون‌های زرد قابل ویرایش‌اند
A7: نام کامل شرکت | C7: سورتینگ و بسته‌بندی مرکبات مازندشت | H7: در سرصفحه همه فایل‌ها استفاده می‌شود
A8: برند | C8: مازندشت | H8: نام کوتاه روی فاکتور و گزارش
A9: زمینه فعالیت | C9: سورتینگ، بسته‌بندی و بازرگانی مرکبات
A10: نشانی | C10: باغدشت، بخش مرکزی، شهرستان قائم‌شهر، استان مازندران، ایران
A11: تلفن ثابت | C11: 011-42116449
A12: تلفن همراه | C12: 0911-116-5751
A13: مدیرعامل | C13: قاسم زاهدی تیر
A14: سال مالی | C14: 1405 | H14: برای گزارش‌های ماهانه
A15: شروع سال مالی | C15: 1405/01/01 | H15: تاریخ شمسی
A16: واحد پول | C16: ریال | H16: ریال یا تومان — در همه فرمول‌ها یکسان
A17: یادداشت | C17: این اطلاعات به‌صورت خودکار در سرصفحه فایل‌های دیگر تکرار می‌شود.
A19: ۰۲ | B19: لوگو و سرصفحه — جای لوگو در همه فایل‌ها یکسان است
A20: جای لوگو Insert ← Picture (یکبار در هر فایل) | D20: سرصفحه همه فایل‌ها از همین مشخصات ساخته می‌شود: نام شرکت، نشانی، تلفن و سال مالی. برای تغییر، فقط همین شیت را ویرایش کنید و در فایل‌های دیگر Edit Links → Update Values بزنید. لوگو را می‌توانید در همین کادر درج کنید؛ فایل مادر مرجع ظاهر همه فایل‌هاست.

Sheet Params
A1: مازندشت — سورتینگ و بسته‌بندی مرکبات | B1: MAZANDASHT · CITRUS SORTING & PACKING
A2: پارامترهای محاسباتی
A3: منبع فرمول‌های همه فایل‌ها — مقدار زرد را تغییر دهید، همه‌جا خودکار به‌روز می‌شود
A4: راهنما | B4: ورود دستی | C4: خودکار | D4: ورود | E4: خروج
A5: سال مالی | C5: درصد افت خرید | E5: وزن سبد پیش‌فرض
A6: =IFERROR(VLOOKUP("P04",$A$10:$E$21,3,0),"") -> 0 | C6: =IFERROR(VLOOKUP("P02",$A$10:$E$21,3,0),0) -> 0 | E6: =IFERROR(VLOOKUP("P01",$A$10:$E$21,3,0),0) -> 0
A8: کد | B8: نام پارامتر | C8: مقدار | D8: واحد | E8: توضیح
A9: Code | B9: Parameter | C9: Value | D9: Unit | E9: Note
A10: P01 | B10: وزن سبد پیش‌فرض | C10: 1.5 | D10: کیلوگرم | E10: اگر نوع سبد انتخاب نشود، وزن تار این عدد است
A11: P02 | B11: درصد افت خرید | C11: 1 | D11: درصد | E11: از وزن خالص خرید مرکبات کسر می‌شود
A12: P03 | B12: واحد رند کردن مبلغ | C12: 1000 | D12: ریال | E12: مبلغ نهایی به نزدیک‌ترین مضرب این عدد رند می‌شود
A13: P04 | B13: سال مالی | C13: 1405 | D13: سال | E13: برای گزارش‌های ماهانه
A14: P05 | B14: حد هشدار موجودی سبد | C14: 100 | D14: عدد | E14: کمتر از این تعداد، هشدار موجودی
A15: P06 | B15: درصد کارمزد پوز | C15: 0 | D15: درصد | E15: در صورت کسر کارمزد از واریزی پوز
A16: P07 | B16: پیش‌شماره فاکتور خرید | C16: خرید- | D16: متن
A17: P08 | B17: پیش‌شماره فاکتور فروش | C17: فروش- | D17: متن
A18: P09 | B18: سقف اعتبار پیش‌فرض بارفروش | C18: 500000000 | D18: ریال | E18: برای هشدار اعتباری
A19: P10 | B19: مهلت چک | C19: 30 | D19: روز
A20: P11 | B20: واحد پول | C20: ریال | D20: متن
A21: P12 | B21: نمایش ردیف‌های صفر در ترازنامه | C21: خیر | D21: بله/خیر

Sheet Groups
A1: مازندشت — سورتینگ و بسته‌بندی مرکبات | F1: MAZANDASHT · CITRUS SORTING & PACKING
A2: گروه‌ها و زیرگروه‌های حساب
A3: هر گروه، پیشوند کد، شیت گزارش و رنگ اختصاصی خود را دارد — منبع کشوهای شیت حساب‌ها
A4: راهنما | B4: ورود دستی | C4: خودکار | D4: ورود | E4: خروج | F4: هشدار | G4: ستون‌های زرد = ورود شما | ستون‌های خاکستری = محاسبه خودکار | روی سرستون‌ها بایستید تا راهنما باز شود
A5: گروه‌های اصلی | D5: زیرگروه‌ها | G5: زیرگروه باغدار | J5: گروه‌های گزارشی
A6: 10 | D6: =COUNTIF($B$10:$B$52,"?*") -> 0 | G6: =COUNTIF($B$10:$B$52,"سردرختی")+COUNTIF($B$10:$B$52,"انباری") -> 0 | J6: =SUMPRODUCT(1/COUNTIF($D$10:$D$52,$D$10:$D$52)) -> 0
A8: گروه اصلی | B8: زیرگروه | C8: پیشوند کد | D8: شیت گزارش | E8: رنگ | F8: توضیح | H8: گروه‌های اصلی (منبع کشو)
A9: Group | B9: Subgroup | C9: Prefix | D9: Report Sheet | E9: Color | F9: Note
A10: باغدار | B10: سردرختی | C10: C | D10: Growers | E10: mint | F10: مرکبات سردرختی تحویل باغ | H10: باغدار
A11: باغدار | B11: انباری | C11: C | D11: Growers | E11: mint | F11: مرکبات تحویل انبار | H11: بارفروش
A12: باغدار | B12: عمده | C12: C | D12: Growers | E12: mint | H12: فروشنده سبد
A13: باغدار | B13: خرده‌فروش | C13: C | D13: Growers | E13: mint | H13: تأمین‌کننده
A14: باغدار | B14: صادراتی | C14: C | D14: Growers | E14: mint | H14: کارمند
A15: باغدار | B15: میدان بار | C15: C | D15: Growers | E15: mint | H15: سایر حساب
A16: بارفروش | B16: میدان بار شهرستان | C16: SL | D16: LoadBuyers | E16: sky | F16: خریدار بار در شهرستان | H16: باسکول دیگران
A17: بارفروش | B17: حجره‌دار | C17: SL | D17: LoadBuyers | E17: sky | H17: دارایی ثابت
A18: بارفروش | B18: صادراتی | C18: SL | D18: LoadBuyers | E18: sky | H18: وام و تسهیلات
A19: بارفروش | B19: واسطه | C19: SL | D19: LoadBuyers | E19: sky | H19: سرمایه و آورده صاحبان
A20: بارفروش | B20: نقدی | C20: SL | D20: LoadBuyers | E20: sky | H20: بانک و صندوق
A21: فروشنده سبد | B21: سبد پلاستیکی | C21: S | D21: BasketSellers | E21: lavender
A22: فروشنده سبد | B22: سبد چوبی | C22: S | D22: BasketSellers | E22: lavender
A23: فروشنده سبد | B23: سبد مقوایی | C23: S | D23: BasketSellers | E23: lavender
A24: فروشنده سبد | B24: سایر | C24: S | D24: BasketSellers | E24: lavender
A25: تأمین‌کننده | B25: مواد بسته‌بندی | C25: S | D25: Suppliers | E25: peach
A26: تأمین‌کننده | B26: واکس و رنگ | C26: S | D26: Suppliers | E26: peach
A27: تأمین‌کننده | B27: حمل‌ونقل | C27: S | D27: Suppliers | E27: peach
A28: تأمین‌کننده | B28: خدمات | C28: S | D28: Suppliers | E28: peach
A29: کارمند | B29: مدیرعامل | C29: E | D29: Staff | E29: sand
A30: کارمند | B30: حسابدار | C30: E | D30: Staff | E30: sand
A31: کارمند | B31: فروشنده | C31: E | D31: Staff | E31: sand
A32: کارمند | B32: انباردار | C32: E | D32: Staff | E32: sand
... A34: کارمند | B34: کارگر | C34: E | D34: Staff | E34: sand
A35: سایر حساب | B35: صندوق | C35: X | D35: Other | E35: grey | F35: حساب معین
A36: سایر حساب | B36: موجودی | C36: X | D36: Other | E36: grey | F36: حساب معین
A37: سایر حساب | B37: درآمد | C37: X | D37: Other | E37: grey | F37: حساب معین
A38: سایر حساب | B38: هزینه | C38: X | D38: Other | E38: grey | F38: حساب معین
A39: سایر حساب | B39: انعام و پاداش | C39: X | D39: Other | E39: grey | F39: طرف حساب انعام مصطفی
A40: سایر حساب | B40: چک پرداختی | C40: X | D40: Other | E40: grey | F40: حساب معین چک‌های در جریان
A41: سایر حساب | B41: حساب واسط | C41: X | D41: Other | E41: grey | F41: حساب معین عملیات متفرقه
A42: سایر حساب | B42: مالیات | C42: X | D42: Other | E42: grey
...

Sheet Accounts
A1: مازندشت — سورتینگ و بسته‌بندی مرکبات | I1: MAZANDASHT · CITRUS SORTING & PACKING
A2: دفتر حساب‌ها — همه صاحبان حساب در یک‌جا
A3: باغدار، بارفروش، فروشنده سبد، تأمین‌کننده، کارمند، باسکول دیگران و حساب‌های معین · کدها ثابت‌اند
A4: راهنما | B4: ورود دستی | C4: خودکار | D4: ورود | E4: خروج | F4: هشدار | G4: ستون‌های زرد = ورود شما | ستون‌های خاکستری = محاسبه خودکار | روی سرستون‌ها بایستید تا راهنما باز شود
A5: حساب‌های تعریف‌شده | D5: باغداران | G5: بارفروشان | J5: فروشندگان سبد | M5: مانده بدهکار افتتاحیه
A6: =COUNTIF($D$10:$D$259,"?*") -> 0 | D6: =COUNTIF($B$10:$B$259,"باغدار") -> 0 | G6: =COUNTIF($B$10:$B$259,"بارفروش") -> 0 | J6: =COUNTIF($B$10:$B$259,"فروشنده سبد") -> 0 | M6: =SUMIF($H$10:$H$259,">0") -> 0
A8: کد حساب | B8: گروه (ماهیت) | C8: زیرگروه | D8: نام صاحب حساب | E8: تلفن | F8: همراه | G8: نشانی | H8: مانده اولیه | I8: نوع حساب | J8: فعال | K8: گروه کد (خودکار) | L8: توضیحات | M8: بررسی
A9: Code | B9: Group | C9: Subgroup | D9: Account Holder | E9: Phone | F9: Mobile | G9: Address | H9: Opening | I9: Type | J9: Active | K9: Code Group | L9: Notes | M9: Check
A10: C001 | B10: باغدار | C10: عمده | D10: زینب زاهدی | E10: 011-33330001 | F10: 09110000001 | G10: بابل — میدان مرکبات | H10: 0 | I10: طرف حساب | J10: بله | K10: =IF($A10="","",IF(LEFT($A10,3)="CAP","سرمایه و آورده صاحبان",IF(LEFT($A10,2)="SL","بارفروش",IF(LEFT($A10,2)="BD","باسکول دیگران",IF(LEFT($A10,1)="C","باغدار",IF(LEFT($A10,1)="S","فروشنده سبد/تأمین‌کننده",IF(LEFT($A10,1)="E","کارمند",IF(LEFT($A10,1)="X","سایر حساب",IF(LEFT($A10,1)="F","دارایی ثابت",IF(LEFT($A10,1)="L","وام و تسهیلات","")))))))))) -> Format(font_name='B Nazanin', font_size=9.5, bold=0, italic=0, underline=0, font_color=Color(value=0x6B7A76, type=RGB, is_automatic=False), num_format='General', text_h_align=3, text_v_align=2, fg_color=None, bg_color=Color(value=0xF6F5F0, type=RGB, is_automatic=False), pattern=0, locked=1, hidden=0) | L10: نمونه — ویرایش کنید | M10: =IF(OR($B10="",$A10=""),"",IF(OR($B10=$K10,AND(LEFT($A10,1)="S",OR($B10="فروشنده سبد",$B10="تأمین‌کننده")),AND(LEFT($A10,2)="BD",$B10="باسکول دیگران")),"✓","⚠")) -> Format(font_name='Tahoma', font_size=10, bold=True, italic=0, underline=0, font_color=Color(value=0x6B7A76, type=RGB, is_automatic=False), num_format='General', text_h_align=2, text_v_align=2, fg_color=None, bg_color=Color(value=0xF6F5F0, type=RGB, is_automatic=False), pattern=0, locked=1, hidden=0)
A11: C002 | B11: باغدار | C11: صادراتی | D11: سید عباس موسوی | E11: 011-33330002 | F11: 09110000002 | G11: ساری — شهرک صنعتی | H11: 0 | I11: طرف حساب | J11: بله | K11: =IF($A11="","",IF(LEFT($A11,3)="CAP","سرمایه و آورده صاحبان",IF(LEFT($A11,2)="SL","بارفروش",IF(LEFT($A11,2)="BD","باسکول دیگران",IF(LEFT($A11,1)="C","باغدار",IF(LEFT($A11,1)="S","فروشنده سبد/تأمین‌کننده",IF(LEFT($A11,1)="E","کارمند",IF(LEFT($A11,1)="X","سایر حساب",IF(LEFT($A11,1)="F","دارایی ثابت",IF(LEFT($A11,1)="L","وام و تسهیلات","")))))))))) -> Format(font_name='B Nazanin', font_size=9.5, bold=0, italic=0, underline=0, font_color=Color(value=0x6B7A76, type=RGB, is_automatic=False), num_format='General', text_h_align=3, text_v_align=2, fg_color=None, bg_color=Color(value=0xF6F5F0, type=RGB, is_automatic=False), pattern=0, locked=1, hidden=0) | L11: نمونه | M11: =IF(OR($B11="",$A11=""),"",IF(OR($B11=$K11,AND(LEFT($A11,1)="S",OR($B11="فروشنده سبد",$B11="تأمین‌کننده")),AND(LEFT($A11,2)="BD",$B11="باسکول دیگران")),"✓","⚠")) -> Format(font_name='Tahoma', font_size=10, bold=True, italic=0, underline=0, font_color=Color(value=0x6B7A76, type=RGB, is_automatic=False), num_format='General', text_h_align=2, text_v_align=2, fg_color=None, bg_color=Color(value=0xF6F5F0, type=RGB, is_automatic=False), pattern=0, locked=1, hidden=0)
A12: C003 | B12: باغدار | C12: خرده‌فروش | D12: حاج احمد عیسی پور | E12: 011-33330003 | F12: 09110000003 | G12: قائم‌شهر — خیابان طالب آملی | H12: 0 | I12: طرف حساب | J12: بله | K12: =IF($A12="","",IF(LEFT($A12,3)="CAP","سرمایه و آورده صاحبان",IF(LEFT($A12,2)="SL","بارفروش",IF(LEFT($A12,2)="BD","باسکول دیگران",IF(LEFT($A12,1)="C","باغدار",IF(LEFT($A12,1)="S","فروشنده سبد/تأمین‌کننده",IF(LEFT($A12,1)="E","کارمند",IF(LEFT($A12,1)="X","سایر حساب",IF(LEFT($A12,1)="F","دارایی ثابت",IF(LEFT($A12,1)="L","وام و تسهیلات","")))))))))) -> Format(font_name='B Nazanin', font_size=9.5, bold=0, italic=0, underline=0, font_color=Color(value=0x6B7A76, type=RGB, is_automatic=False), num_format='General', text_h_align=3, text_v_align=2, fg_color=None, bg_color=Color(value=0xF6F5F0, type=RGB, is_automatic=False), pattern=0, locked=1, hidden=0) | L12: نمونه | M12: =IF(OR($B12="",$A12=""),"",IF(OR($B12=$K12,AND(LEFT($A12,1)="S",OR($B12="فروشنده سبد",$B12="تأمین‌کننده")),AND(LEFT($A12,2)="BD",$B12="باسکول دیگران")),"✓","⚠")) -> Format(font_name='Tahoma', font_size=10, bold=True, italic=0, underline=0, font_color=Color(value=0x6B7A76, type=RGB, is_automatic=False), num_format='General', text_h_align=2, text_v_align=2, fg_color=None, bg_color=Color(value=0xF6F5F0, type=RGB, is_automatic=False), pattern=0, locked=1, hidden=0)
A13: C004 | B13: باغدار | D13: امید زاهدی | H13: 0 | I13: طرف حساب | J13: بله | K13: =IF($A13="","",IF(LEFT($A13,3)="CAP","سرمایه و آورده صاحبان",IF(LEFT($A13,2)="SL","بارفروش",IF(LEFT($A13,2)="BD","باسکول دیگران",IF(LEFT($A13,1)="C","باغدار",IF(LEFT($A13,1)="S","فروشنده سبد/تأمین‌کننده",IF(LEFT($A13,1)="E","کارمند",IF(LEFT($A13,1)="X","سایر حساب",IF(LEFT($A13,1)="F","دارایی ثابت",IF(LEFT($A13,1)="L","وام و تسهیلات","")))))))))) -> Format(font_name='B Nazanin', font_size=9.5, bold=0, italic=0, underline=0, font_color=Color(value=0x6B7A76, type=RGB, is_automatic=False), num_format='General', text_h_align=3, text_v_align=2, fg_color=None, bg_color=Color(value=0xF6F5F0, type=RGB, is_automatic=False), pattern=0, locked=1, hidden=0) | M13: =IF(OR($B13="",$A13=""),"",IF(OR($B13=$K13,AND(LEFT($A13,1)="S",OR($B13="فروشنده سبد",$B13="تأمین‌کننده")),AND(LEFT($A13,2)="BD",$B13="باسکول دیگران")),"✓","⚠")) -> Format(font_name='Tahoma', font_size=10, bold=True, italic=0, underline=0, font_color=Color(value=0x6B7A76, type=RGB, is_automatic=False), num_format='General', text_h_align=2, text_v_align=2, fg_color=None, bg_color=Color(value=0xF6F5F0, type=RGB, is_automatic=False), pattern=0, locked=1, hidden=0)
A14: C005 | B14: باغدار | D14: بار شخصی قاسم زاهدی | H14: 0 | I14: طرف حساب | J14: بله | K14: =IF($A14="","",IF(LEFT($A14,3)="CAP","سرمایه و آورده صاحبان",IF(LEFT($A14,2)="SL","بارفروش",IF(LEFT($A14,2)="BD","باسکول دیگران",IF(LEFT($A14,1)="C","باغدار",IF(LEFT($A14,1)="S","فروشنده سبد/تأمین‌کننده",IF(LEFT($A14,1)="E","کارمند",IF(LEFT($A14,1)="X","سایر حساب",IF(LEFT($A14,1)="F","دارایی ثابت",IF(LEFT($A14,1)="L","وام و تسهیلات","")))))))))) -> Format(font_name='B Nazanin', font_size=9.5, bold=0, italic=0, underline=0, font_color=Color(value=0x6B7A76, type=RGB, is_automatic=False), num_format='General', text_h_align=3, text_v_align=2, fg_color=None, bg_color=Color(value=0xF6F5F0, type=RGB, is_automatic=False), pattern=0, locked=1, hidden=0) | M14: =IF(OR($B14="",$A14=""),"",IF(OR($B14=$K14,AND(LEFT($A14,1)="S",OR($B14="فروشنده سبد",$B14="تأمین‌کننده")),AND(LEFT($A14,2)="BD",$B14="باسکول دیگران")),"✓","⚠")) -> Format(font_name='Tahoma', font_size=10, bold=True, italic=0, underline=0, font_color=Color(value=0x6B7A76, type=RGB, is_automatic=False), num_format='General', text_h_align=2, text_v_align=2, fg_color=None, bg_color=Color(value=0xF6F5F0, type=RGB, is_automatic=False), pattern=0, locked=1, hidden=0)
A15: C006 | B15: باغدار | D15: هوشنگ عیسی پور | H15: 0 | I15: طرف حساب | J15: بله | K15: =IF($A15="","",IF(LEFT($A15,3)="CAP","سرمایه و آورده صاحبان",IF(LEFT($A15,2)="SL","بارفروش",IF(LEFT($A15,2)="BD","باسکول دیگران",IF(LEFT($A15,1)="C","باغدار",IF(LEFT($A15,1)="S","فروشنده سبد/تأمین‌کننده",IF(LEFT($A15,1)="E","کارمند",IF(LEFT($A15,1)="X","سایر حساب",IF(LEFT($A15,1)="F","دارایی ثابت",IF(LEFT($A15,1)="L","وام و تسهیلات","")))))))))) -> Format(font_name='B Nazanin', font_size=9.5, bold=0, italic=0, underline=0, font_color=Color(value=0x6B7A76, type=RGB, is_automatic=False), num_format='General', text_h_align=3, text_v_align=2, fg_color=None, bg_color=Color(value=0xF6F5F0, type=RGB, is_automatic=False), pattern=0, locked=1, hidden=0) | M15: =IF(OR($B15="",$A15=""),"",IF(OR($B15=$K15,AND(LEFT($A15,1)="S",OR($B15="فروشنده سبد",$B15="تأمین‌کننده")),AND(LEFT($A15,2)="BD",$B15="باسکول دیگران")),"✓","⚠")) -> Format(font_name='Tahoma', font_size=10, bold=True, italic=0, underline=0, font_color=Color(value=0x6B7A76, type=RGB, is_automatic=False), num_format='General', text_h_align=2, text_v_align=2, fg_color=None, bg_color=Color(value=0xF6F5F0, type=RGB, is_automatic=False), pattern=0, locked=1, hidden=0)
A16: C007 | B16: باغدار | D16: علی آهنگر | H16: 0 | I16: طرف حساب | J16: بله | K16: =IF($A16="","",IF(LEFT($A16,3)="CAP","سرمایه و آورده صاحبان",IF(LEFT($A16,2)="SL","بارفروش",IF(LEFT($A16,2)="BD","باسکول دیگران",IF(LEFT($A16,1)="C","باغدار",IF(LEFT($A16,1)="S","فروشنده سبد/تأمین‌کننده",IF(LEFT($A16,1)="E","کارمند",IF(LEFT($A16,1)="X","سایر حساب",IF(LEFT($A16,1)="F","دارایی ثابت",IF(LEFT($A16,1)="L","وام و تسهیلات","")))))))))) -> Format(font_name='B Nazanin', font_size=9.5, bold=0, italic=0, underline=0, font_color=Color(value=0x6B7A76, type=RGB, is_automatic=False), num_format='General', text_h_align=3, text_v_align=2, fg_color=None, bg_color=Color(value=0xF6F5F0, type=RGB, is_automatic=False), pattern=0, locked=1, hidden=0) | M16: =IF(OR($B16="",$A16=""),"",IF(OR($B16=$K16,AND(LEFT($A16,1)="S",OR($B16="فروشنده سبد",$B16="تأمین‌کننده")),AND(LEFT($A16,2)="BD",$B16="باسکول دیگران")),"✓","⚠")) -> Format(font_name='Tahoma', font_size=10, bold=True, italic=0, underline=0, font_color=Color(value=0x6B7A76, type=RGB, is_automatic=False), num_format='General', text_h_align=2, text_v_align=2, fg_color=None, bg_color=Color(value=0xF6F5F0, type=RGB, is_automatic=False), pattern=0, locked=1, hidden=0)
A17: C008 | B17: باغدار | D17: صفدر مسلمی | H17: 0 | I17: طرف حساب | J17: بله | K17: =IF($A17="","",IF(LEFT($A17,3)="CAP","سرمایه و آورده صاحبان",IF(LEFT($A17,2)="SL","بارفروش",IF(LEFT($A17,2)="BD","باسکول دیگران",IF(LEFT($A17,1)="C","باغدار",IF(LEFT($A17,1)="S","فروشنده سبد/تأمین‌کننده",IF(LEFT($A17,1)="E","کارمند",IF(LEFT($A17,1)="X","سایر حساب",IF(LEFT($A17,1)="F","دارایی ثابت",IF(LEFT($A17,1)="L","وام و تسهیلات","")))))))))) -> Format(font_name='B Nazanin', font_size=9.5, bold=0, italic=0, underline=0, font_color=Color(value=0x6B7A76, type=RGB, is_automatic=False), num_format='General', text_h_align=3, text_v_align=2, fg_color=None, bg_color=Color(value=0xF6F5F0, type=RGB, is_automatic=False), pattern=0, locked=1, hidden=0) | M17: =IF(OR($B17="",$A17=""),"",IF(OR($B17=$K17,AND(LEFT($A17,1)="S",OR($B17="فروشنده سبد",$B17="تأمین‌کننده")),AND(LEFT($A17,2)="BD",$B17="باسکول دیگران")),"✓","⚠")) -> Format(font_name='Tahoma', font_size=10, bold=True, italic=0, underline=0, font_color=Color(value=0x6B7A76, type=RGB, is_automatic=False), num_format='General', text_h_align=2, text_v_align=2, fg_color=None, bg_color=Color(value=0xF6F5F0, type=RGB, is_automatic=False), pattern=0, locked=1, hidden=0)
A18: C009 | B18: باغدار | D18: همایون بابایی | H18: 0 | I18: طرف حساب | J18: بله | K18: =IF($A18="","",IF(LEFT($A18,3)="CAP","سرمایه و آورده صاحبان",IF(LEFT($A18,2)="SL","بارفروش",IF(LEFT($A18,2)="BD","باسکول دیگران",IF(LEFT($A18,1)="C","باغدار",IF(LEFT($A18,1)="S","فروشنده سبد/تأمین‌کننده",IF(LEFT($A18,1)="E","کارمند",IF(LEFT($A18,1)="X","سایر حساب",IF(LEFT($A18,1)="F","دارایی ثابت",IF(LEFT($A18,1)="L","وام و تسهیلات","")))))))))) -> Format(font_name='B Nazanin', font_size=9.5, bold=0, italic=0, underline=0, font_color=Color(value=0x6B7A76, type=RGB, is_automatic=False), num_format='General', text_h_align=3, text_v_align=2, fg_color=None, bg_color=Color(value=0xF6F5F0, type=RGB, is_automatic=False), pattern=0, locked=1, hidden=0) | M18: =IF(OR($B18="",$A18=""),"",IF(OR($B18=$K18,AND(LEFT($A18,1)="S",OR($B18="فروشنده سبد",$B18="تأمین‌کننده")),AND(LEFT($A18,2)="BD",$B18="باسکول دیگران")),"✓","⚠")) -> Format(font_name='Tahoma', font_size=10, bold=True, italic=0, underline=0, font_color=Color(value=0x6B7A76, type=RGB, is_automatic=False), num_format='General', text_h_align=2, text_v_align=2, fg_color=None, bg_color=Color(value=0xF6F5F0, type=RGB, is_automatic=False), pattern=0, locked=1, hidden=0)
A19: C010 | B19: باغدار | D19: دبیر فرجی | H19: 0 | I19: طرف حساب | J19: بله | K19: =IF($A19="","",IF(LEFT($A19,3)="CAP","سرمایه و آورده صاحبان",IF(LEFT($A19,2)="SL","بارفروش",IF(LEFT($A19,2)="BD","باسکول دیگران",IF(LEFT($A19,1)="C","باغدار",IF(LEFT($A19,1)="S","فروشنده سبد/تأمین‌کننده",IF(LEFT($A19,1)="E","کارمند",IF(LEFT($A19,1)="X","سایر حساب",IF(LEFT($A19,1)="F","دارایی ثابت",IF(LEFT($A19,1)="L","وام و تسهیلات","")))))))))) -> Format(font_name='B Nazanin', font_size=9.5, bold=0, italic=0, underline=0, font_color=Color(value=0x6B7A76, type=RGB, is_automatic=False), num_format='General', text_h_align=3, text_v_align=2, fg_color=None, bg_color=Color(value=0xF6F5F0, type=RGB, is_automatic=False), pattern=0, locked=1, hidden=0) | M19: =IF(OR($B19="",$A19=""),"",IF(OR($B19=$K19,AND(LEFT($A19,1)="S",OR($B19="فروشنده سبد",$B19="تأمین‌کننده")),AND(LEFT($A19,2)="BD",$B19="باسکول دیگران")),"✓","⚠")) -> Format(font_name='Tahoma', font_size=10, bold=True, italic=0, underline=0, font_color=Color(value=0x6B7A76, type=RGB, is_automatic=False), num_format='General', text_h_align=2, text_v_align=2, fg_color=None, bg_color=Color(value=0xF6F5F0, type=RGB, is_automatic=False), pattern=0, locked=1, hidden=0)
A20: C011 | B20: باغدار | D20: محمود علیجانی | H20: 0 | I20: طرف حساب | J20: بله | K20: =IF($A20="","",IF(LEFT($A20,3)="CAP","سرمایه و آورده صاحبان",IF(LEFT($A20,2)="SL","بارفروش",IF(LEFT($A20,2)="BD","باسکول دیگران",IF(LEFT($A20,1)="C","باغدار",IF(LEFT($A20,1)="S","فروشنده سبد/تأمین‌کننده",IF(LEFT($A20,1)="E","کارمند",IF(LEFT($A20,1)="X","سایر حساب",IF(LEFT($A20,1)="F","دارایی ثابت",IF(LEFT($A20,1)="L","وام و تسهیلات","")))))))))) -> Format(font_name='B Nazanin', font_size=9.5, bold=0, italic=0, underline=0, font_color=Color(value=0x6B7A76, type=RGB, is_automatic=False), num_format='General', text_h_align=3, text_v_align=2, fg_color=None, bg_color=Color(value=0xF6F5F0, type=RGB, is_automatic=False), pattern=0, locked=1, hidden=0) | M20: =IF(OR($B20="",$A20=""),"",IF(OR($B20=$K20,AND(LEFT($A20,1)="S",OR($B20="فروشنده سبد",$B20="تأمین‌کننده")),AND(LEFT($A20,2)="BD",$B20="باسکول دیگران")),"✓","⚠")) -> Format(font_name='Tahoma', font_size=10, bold=True, italic=0, underline=0, font_color=Color(value=0x6B7A76, type=RGB, is_automatic=False), num_format='General', text_h_align=2, text_v_align=2, fg_color=None, bg_color=Color(value=0xF6F5F0, type=RGB, is_automatic=False), pattern=0, locked=1, hidden=0)
A21: C012 | B21: باغدار | D21: افشین بشتکار | H21: 0 | I21: طرف حساب | J21: بله | K21: =IF($A21="","",IF(LEFT($A21,3)="CAP","سرمایه و آورده صاحبان",IF(LEFT($A21,2)="SL","بارفروش",IF(LEFT($A21,2)="BD","باسکول دیگران",IF(LEFT($A21,1)="C","باغدار",IF(LEFT($A21,1)="S","فروشنده سبد/تأمین‌کننده",IF(LEFT($A21,1)="E","کارمند",IF(LEFT($A21,1)="X","سایر حساب",IF(LEFT($A21,1)="F","دارایی ثابت",IF(LEFT($A21,1)="L","وام و تسهیلات","")))))))))) -> Format(font_name='B Nazanin', font_size=9.5, bold=0, italic=0, underline=0, font_color=Color(value=0x6B7A76, type=RGB, is_automatic=False), num_format='General', text_h_align=3, text_v_align=2, fg_color=None, bg_color=Color(value=0xF6F5F0, type=RGB, is_automatic=False), pattern=0, locked=1, hidden=0) | M21: =IF(OR($B21="",$A21=""),"",IF(OR($B21=$K21,AND(LEFT($A21,1)="S",OR($B21="فروشنده سبد",$B21="تأمین‌کننده")),AND(LEFT($A21,2)="BD",$B21="باسکول دیگران")),"✓","⚠")) -> Format(font_name='Tahoma', font_size=10, bold=True, italic=0, underline=0, font_color=Color(value=0x6B7A76, type=RGB, is_automatic=False), num_format='General', text_h_align=2, text_v_align=2, fg_color=None, bg_color=Color(value=0xF6F5F0, type=RGB, is_automatic=False), pattern=0, locked=1, hidden=0)
A22: C013 | B22: باغدار | D22: میرقربان موسویان | H22: 0 | I22: طرف حساب | J22: بله | K22: =IF($A22="","",IF(LEFT($A22,3)="CAP","سرمایه و آورده صاحبان",IF(LEFT($A22,2)="SL","بارفروش",IF(LEFT($A22,2)="BD","باسکول دیگران",IF(LEFT($A22,1)="C","باغدار",IF(LEFT($A22,1)="S","فروشنده سبد/تأمین‌کننده",IF(LEFT($A22,1)="E","کارمند",IF(LEFT($A22,1)="X","سایر حساب",IF(LEFT($A22,1)="F","دارایی ثابت",IF(LEFT($A22,1)="L","وام و تسهیلات","")))))))))) -> Format(font_name='B Nazanin', font_size=9.5, bold=0, italic=0, underline=0, font_color=Color(value=0x6B7A76, type=RGB, is_automatic=False), num_format='General', text_h_align=3, text_v_align=2, fg_color=None, bg_color=Color(value=0xF6F5F0, type=RGB, is_automatic=False), pattern=0, locked=1, hidden=0) | M22: =IF(OR($B22="",$A22=""),"",IF(OR($B22=$K22,AND(LEFT($A22,1)="S",OR($B22="فروشنده سبد",$B22="تأمین‌کننده")),AND(LEFT($A22,2)="BD",$B22="باسکول دیگران")),"✓","⚠")) -> Format(font_name='Tahoma', font_size=10, bold=True, italic=0, underline=0, font_color=Color(value=0x6B7A76, type=RGB, is_automatic=False), num_format='General', text_h_align=2, text_v_align=2, fg_color=None, bg_color=Color(value=0xF6F5F0, type=RGB, is_automatic=False), pattern=0, locked=1, hidden=0)
A23: C014 | B23: باغدار | D23: باباجانی (تراجیکلا) | H23: 0 | I23: طرف حساب | J23: بله | K23: =IF($A23="","",IF(LEFT($A23,3)="CAP","سرمایه و آورده صاحبان",IF(LEFT($A23,2)="SL","بارفروش",IF(LEFT($A23,2)="BD","باسکول دیگران",IF(LEFT($A23,1)="C","باغدار",IF(LEFT($A23,1)="S","فروشنده سبد/تأمین‌کننده",IF(LEFT($A23,1)="E","کارمند",IF(LEFT($A23,1)="X","سایر حساب",IF(LEFT($A23,1)="F","دارایی ثابت",IF(LEFT($A23,1)="L","وام و تسهیلات","")))))))))) -> Format(font_name='B Nazanin', font_size=9.5, bold=0, italic=0, underline=0, font_color=Color(value=0x6B7A76, type=RGB, is_automatic=False), num_format='General', text_h_align=3, text_v_align=2, fg_color=None, bg_color=Color(value=0xF6F5F0, type=RGB, is_automatic=False), pattern=0, locked=1, hidden=0) | M23: =IF(OR($B23="",$A23=""),"",IF(OR($B23=$K23,AND(LEFT($A23,1)="S",OR($B23="فروشنده سبد",$B23="تأمین‌کننده")),AND(LEFT($A23,2)="BD",$B23="باسکول دیگران")),"✓","⚠")) -> Format(font_name='Tahoma', font_size=10, bold=True, italic=0, underline=0, font_color=Color(value=0x6B7A76, type=RGB, is_automatic=False), num_format='General', text_h_align=2, text_v_align=2, fg_color=None, bg_color=Color(value=0xF6F5F0, type=RGB, is_automatic=False), pattern=0, locked=1, hidden=0)
A24: C015 | B24: باغدار | D24: کاظم میرزازاده | H24: 0 | I24: طرف حساب | J24: بله | K24: =IF($A24="","",IF(LEFT($A24,3)="CAP","سرمایه و آورده صاحبان",IF(LEFT($A24,2)="SL","بارفروش",IF(LEFT($A24,2)="BD","باسکول دیگران",IF(LEFT($A24,1)="C","باغدار",IF(LEFT($A24,1)="S","فروشنده سبد/تأمین‌کننده",IF(LEFT($A24,1)="E","کارمند",IF(LEFT($A24,1)="X","سایر حساب",IF(LEFT($A24,1)="F","دارایی ثابت",IF(LEFT($A24,1)="L","وام و تسهیلات","")))))))))) -> Format(font_name='B Nazanin', font_size=9.5, bold=0, italic=0, underline=0, font_color=Color(value=0x6B7A76, type=RGB, is_automatic=False), num_format='General', text_h_align=3, text_v_align=2, fg_color=None, bg_color=Color(value=0xF6F5F0, type=RGB, is_automatic=False), pattern=0, locked=1, hidden=0) | M24: =IF(OR($B24="",$A24=""),"",IF(OR($B24=$K24,AND(LEFT($A24,1)="S",OR($B24="فروشنده سبد",$B24="تأمین‌کننده")),AND(LEFT($A24,2)="BD",$B24="باسکول دیگران")),"✓","⚠")) -> Format(font_name='Tahoma', font_size=10, bold=True, italic=0, underline=0, font_color=Color(value=0x6B7A76, type=RGB, is_automatic=False), num_format='General', text_h_align=2, text_v_align=2, fg_color=None, bg_color=Color(value=0xF6F5F0, type=RGB, is_automatic=False), pattern=0, locked=1, hidden=0)
... A66: C057 | B66: باغدار | D66: کبری اصغرنیا | H66: 0 | I66: طرف حساب | J66: بله | K66: =IF($A66="","",IF(LEFT($A66,3)="CAP","سرمایه و آورده صاحبان",IF(LEFT($A66,2)="SL","بارفروش",IF(LEFT($A66,2)="BD","باسکول دیگران",IF(LEFT($A66,1)="C","باغدار",IF(LEFT($A66,1)="S","فروشنده سبد/تأمین‌کننده",IF(LEFT($A66,1)="E","کارمند",IF(LEFT($A66,1)="X","سایر حساب",IF(LEFT($A66,1)="F","دارایی ثابت",IF(LEFT($A66,1)="L","وام و تسهیلات","")))))))))) -> Format(font_name='B Nazanin', font_size=9.5, bold=0, italic=0, underline=0, font_color=Color(value=0x6B7A76, type=RGB, is_automatic=False), num_format='General', text_h_align=3, text_v_align=2, fg_color=None, bg_color=Color(value=0xF6F5F0, type=RGB, is_automatic=False), pattern=0, locked=1, hidden=0) | M66: =IF(OR($B66="",$A66=""),"",IF(OR($B66=$K66,AND(LEFT($A66,1)="S",OR($B66="فروشنده سبد",$B66="تأمین‌کننده")),AND(LEFT($A66,2)="BD",$B66="باسکول دیگران")),"✓","⚠")) -> Format(font_name='Tahoma', font_size=10, bold=True, italic=0, underline=0, font_color=Color(value=0x6B7A76, type=RGB, is_automatic=False), num_format='General', text_h_align=2, text_v_align=2, fg_color=None, bg_color=Color(value=0xF6F5F0, type=RGB, is_automatic=False), pattern=0, locked=1, hidden=0)
A67: SL001 | B67: بارفروش | C67: میدان بار شهرستان | D67: قم — سید حسین حسینی | F67: 9125528445 | G67: قم، میدان تره‌بار، بلوک ۴، غرفه ۲۲ | H67: 0 | I67: طرف حساب | J67: بله | K67: =IF($A67="","",IF(LEFT($A67,3)="CAP","سرمایه و آورده صاحبان",IF(LEFT($A67,2)="SL","بارفروش",IF(LEFT($A67,2)="BD","باسکول دیگران",IF(LEFT($A67,1)="C","باغدار",IF(LEFT($A67,1)="S","فروشنده سبد/تأمین‌کننده",IF(LEFT($A67,1)="E","کارمند",IF(LEFT($A67,1)="X","سایر حساب",IF(LEFT($A67,1)="F","دارایی ثابت",IF(LEFT($A67,1)="L","وام و تسهیلات","")))))))))) -> Format(font_name='B Nazanin', font_size=9.5, bold=0, italic=0, underline=0, font_color=Color(value=0x6B7A76, type=RGB, is_automatic=False), num_format='General', text_h_align=3, text_v_align=2, fg_color=None, bg_color=Color(value=0xF6F5F0, type=RGB, is_automatic=False), pattern=0, locked=1, hidden=0) | L67: خریدار بار — فروش خروجی باسکول | M67: =IF(OR($B67="",$A67=""),"",IF(OR($B67=$K67,AND(LEFT($A67,1)="S",OR($B67="فروشنده سبد",$B67="تأمین‌کننده")),AND(LEFT($A67,2)="BD",$B67="باسکول دیگران")),"✓","⚠")) -> Format(font_name='Tahoma', font_size=10, bold=True, italic=0, underline=0, font_color=Color(value=0x6B7A76, type=RGB, is_automatic=False), num_format='General', text_h_align=2, text_v_align=2, fg_color=None, bg_color=Color(value=0xF6F5F0, type=RGB, is_automatic=False), pattern=0, locked=1, hidden=0)
A68: SL002 | B68: بارفروش | C68: میدان بار شهرستان | D68: مشهد — محمد توکلی | F68: 9154018185 | G68: مشهد، میدان بار سپاد، تالار ۶، حجره ۱۵ | H68: 0 | I68: طرف حساب | J68: بله | K68: =IF($A68="","",IF(LEFT($A68,3)="CAP","سرمایه و آورده صاحبان",IF(LEFT($A68,2)="SL","بارفروش",IF(LEFT($A68,2)="BD","باسکول دیگران",IF(LEFT($A68,1)="C","باغدار",IF(LEFT($A68,1)="S","فروشنده سبد/تأمین‌کننده",IF(LEFT($A68,1)="E","کارمند",IF(LEFT($A68,1)="X","سایر حساب",IF(LEFT($A68,1)="F","دارایی ثابت",IF(LEFT($A68,1)="L","وام و تسهیلات","")))))))))) -> Format(font_name='B Nazanin', font_size=9.5, bold=0, italic=0, underline=0, font_color=Color(value=0x6B7A76, type=RGB, is_automatic=False), num_format='General', text_h_align=3, text_v_align=2, fg_color=None, bg_color=Color(value=0xF6F5F0, type=RGB, is_automatic=False), pattern=0, locked=1, hidden=0) | L68: خریدار بار — فروش خروجی باسکول | M68: =IF(OR($B68="",$A68=""),"",IF(OR($B68=$K68,AND(LEFT($A68,1)="S",OR($B68="فروشنده سبد",$B68="تأمین‌کننده")),AND(LEFT($A68,2)="BD",$B68="باسکول دیگران")),"✓","⚠")) -> Format(font_name='Tahoma', font_size=10, bold=True, italic=0, underline=0, font_color=Color(value=0x6B7A76, type=RGB, is_automatic=False), num_format='General', text_h_align=2, text_v_align=2, fg_color=None, bg_color=Color(value=0xF6F5F0, type=RGB, is_automatic=False), pattern=0, locked=1, hidden=0)
A69: SL003 | B69: بارفروش | C69: میدان بار شهرستان | D69: اراک — پوریا خوش‌نمکیان | F69: 9369182495 | G69: اراک، میدان بار، فاز ۲، سالن شهید رجایی، حجره ۶ | H69: 0 | I69: طرف حساب | J69: بله | K69: =IF($A69="","",IF(LEFT($A69,3)="CAP","سرمایه و آورده صاحبان",IF(LEFT($A69,2)="SL","بارفروش",IF(LEFT($A69,2)="BD","باسکول دیگران",IF(LEFT($A69,1)="C","باغدار",IF(LEFT($A69,1)="S","فروشنده سبد/تأمین‌کننده",IF(LEFT($A69,1)="E","کارمند",IF(LEFT($A69,1)="X","سایر حساب",IF(LEFT($A69,1)="F","دارایی ثابت",IF(LEFT($A69,1)="L","وام و تسهیلات","")))))))))) -> Format(font_name='B Nazanin', font_size=9.5, bold=0, italic=0, underline=0, font_color=Color(value=0x6B7A76, type=RGB, is_automatic=False), num_format='General', text_h_align=3, text_v_align=2, fg_color=None, bg_color=Color(value=0xF6F5F0, type=RGB, is_automatic=False), pattern=0, locked=1, hidden=0) | L69: خریدار بار — فروش خروجی باسکول | M69: =IF(OR($B69="",$A69=""),"",IF(OR($B69=$K69,AND(LEFT($A69,1)="S",OR($B69="فروشنده سبد",$B69="تأمین‌کننده")),AND(LEFT($A69,2)="BD",$B69="باسکول دیگران")),"✓","⚠")) -> Format(font_name='Tahoma', font_size=10, bold=True, italic=0, underline=0, font_color=Color(value=0x6B7A76, type=RGB, is_automatic=False), num_format='General', text_h_align=2, text_v_align=2, fg_color=None, bg_color=Color(value=0xF6F5F0, type=RGB, is_automatic=False), pattern=0, locked=1, hidden=0)
A70: SL004 | B70: بارفروش | C70: میدان بار شهرستان | D70: تبریز — نورزاده | H70: 0 | I70: طرف حساب | J70: بله | K70: =IF($A70="","",IF(LEFT($A70,3)="CAP","سرمایه و آورده صاحبان",IF(LEFT($A70,2)="SL","بارفروش",IF(LEFT($A70,2)="BD","باسکول دیگران",IF(LEFT($A70,1)="C","باغدار",IF(LEFT($A70,1)="S","فروشنده سبد/تأمین‌کننده",IF(LEFT($A70,1)="E","کارمند",IF(LEFT($A70,1)="X","سایر حساب",IF(LEFT($A70,1)="F","دارایی ثابت",IF(LEFT($A70,1)="L","وام و تسهیلات","")))))))))) -> Format(font_name='B Nazanin', font_size=9.5, bold=0, italic=0, underline=0, font_color=Color(value=0x6B7A76, type=RGB, is_automatic=False), num_format='General', text_h_align=3, text_v_align=2, fg_color=None, bg_color=Color(value=0xF6F5F0, type=RGB, is_automatic=False), pattern=0, locked=1, hidden=0) | L70: خریدار بار — فروش خروجی باسکول | M70: =IF(OR($B70="",$A70=""),"",IF(OR($B70=$K70,AND(LEFT($A70,1)="S",OR($B70="فروشنده سبد",$B70="تأمین‌کننده")),AND(LEFT($A70,2)="BD",$B70="باسکول دیگران")),"✓","⚠")) -> Format(font_name='Tahoma', font_size=10, bold=True, italic=0, underline=0, font_color=Color(value=0x6B7A76, type=RGB, is_automatic=False), num_format='General', text_h_align=2, text_v_align=2, fg_color=None, bg_color=Color(value=0xF6F5F0, type=RGB, is_automatic=False), pattern=0, locked=1, hidden=0)
A71: SL005 | B71: بارفروش | C71: میدان بار شهرستان | D71: زنجان — خانی | H71: 0 | I71: طرف حساب | J71: بله | K71: =IF($A71="","",IF(LEFT($A71,3)="CAP","سرمایه و آورده صاحبان",IF(LEFT($A71,2)="SL","بارفروش",IF(LEFT($A71,2)="BD","باسکول دیگران",IF(LEFT($A71,1)="C","باغدار",IF(LEFT($A71,1)="S","فروشنده سبد/تأمین‌کننده",IF(LEFT($A71,1)="E","کارمند",IF(LEFT($A71,1)="X","سایر حساب",IF(LEFT($A71,1)="F","دارایی ثابت",IF(LEFT($A71,1)="L","وام و تسهیلات","")))))))))) -> Format(font_name='B Nazanin', font_size=9.5, bold=0, italic=0, underline=0, font_color=Color(value=0x6B7A76, type=RGB, is_automatic=False), num_format='General', text_h_align=3, text_v_align=2, fg_color=None, bg_color=Color(value=0xF6F5F0, type=RGB, is_automatic=False), pattern=0, locked=1, hidden=0) | L71: خریدار بار — فروش خروجی باسکول | M71: =IF(OR($B71="",$A71=""),"",IF(OR($B71=$K71,AND(LEFT($A71,1)="S",OR($B71="فروشنده سبد",$B71="تأمین‌کننده")),AND(LEFT($A71,2)="BD",$B71="باسکول دیگران")),"✓","⚠")) -> Format(font_name='Tahoma', font_size=10, bold=True, italic=0, underline=0, font_color=Color(value=0x6B7A76, type=RGB, is_automatic=False), num_format='General', text_h_align=2, text_v_align=2, fg_color=None, bg_color=Color(value=0xF6F5F0, type=RGB, is_automatic=False), pattern=0, locked=1, hidden=0)
A72: S001 | B72: فروشنده سبد | C72: سبد پلاستیکی | D72: حسن کوچک‌زاده | E72: 011-44440001 | F72: 09110000004 | G72: باغدشت | H72: 0 | I72: طرف حساب | J72: بله | K72: =IF($A72="","",IF(LEFT($A72,3)="CAP","سرمایه و آورده صاحبان",IF(LEFT($A72,2)="SL","بارفروش",IF(LEFT($A72,2)="BD","باسکول دیگران",IF(LEFT($A72,1)="C","باغدار",IF(LEFT($A72,1)="S","فروشنده سبد/تأمین‌کننده",IF(LEFT($A72,1)="E","کارمند",IF(LEFT($A72,1)="X","سایر حساب",IF(LEFT($A72,1)="F","دارایی ثابت",IF(LEFT($A72,1)="L","وام و تسهیلات","")))))))))) -> Format(font_name='B Nazanin', font_size=9.5, bold=0, italic=0, underline=0, font_color=Color(value=0x6B7A76, type=RGB, is_automatic=False), num_format='General', text_h_align=3, text_v_align=2, fg_color=None, bg_color=Color(value=0xF6F5F0, type=RGB, is_automatic=False), pattern=0, locked=1, hidden=0) | L72: خرید سبد از باغ | M72: =IF(OR($B72="",$A72=""),"",IF(OR($B72=$K72,AND(LEFT($A72,1)="S",OR($B72="فروشنده سبد",$B72="تأمین‌کننده")),AND(LEFT($A72,2)="BD",$B72="باسکول دیگران")),"✓","⚠")) -> Format(font_name='Tahoma', font_size=10, bold=True, italic=0, underline=0, font_color=Color(value=0x6B7A76, type=RGB, is_automatic=False), num_format='General', text_h_align=2, text_v_align=2, fg_color=None, bg_color=Color(value=0xF6F5F0, type=RGB, is_automatic=False), pattern=0, locked=1, hidden=0)
A73: S002 | B73: فروشنده سبد | C73: سبد پلاستیکی | D73: سید محمد موسویان | E73: 011-44440002 | F73: 09110000005 | G73: قائم‌شهر — میدان بار | H73: 0 | I73: طرف حساب | J73: بله | K73: =IF($A73="","",IF(LEFT($A73,3)="CAP","سرمایه و آورده صاحبان",IF(LEFT($A73,2)="SL","بارفروش",IF(LEFT($A73,2)="BD","باسکول دیگران",IF(LEFT($A73,1)="C","باغدار",IF(LEFT($A73,1)="S","فروشنده سبد/تأمین‌کننده",IF(LEFT($A73,1)="E","کارمند",IF(LEFT($A73,1)="X","سایر حساب",IF(LEFT($A73,1)="F","دارایی ثابت",IF(LEFT($A73,1)="L","وام و تسهیلات","")))))))))) -> Format(font_name='B Nazanin', font_size=9.5, bold=0, italic=0, underline=0, font_color=Color(value=0x6B7A76, type=RGB, is_automatic=False), num_format='General', text_h_align=3, text_v_align=2, fg_color=None, bg_color=Color(value=0xF6F5F0, type=RGB, is_automatic=False), pattern=0, locked=1, hidden=0) | L73: خرید سبد از میدان بار | M73: =IF(OR($B73="",$A73=""),"",IF(OR($B73=$K73,AND(LEFT($A73,1)="S",OR($B73="فروشنده سبد",$B73="تأمین‌کننده")),AND(LEFT($A73,2)="BD",$B73="باسکول دیگران")),"✓","⚠")) -> Format(font_name='Tahoma', font_size=10, bold=True, italic=0, underline=0, font_color=Color(value=0x6B7A76, type=RGB, is_automatic=False), num_format='General', text_h_align=2, text_v_align=2, fg_color=None, bg_color=Color(value=0xF6F5F0, type=RGB, is_automatic=False), pattern=0, locked=1, hidden=0)
A74: S003 | B74: فروشنده سبد | C74: سبد پلاستیکی | D74: سید ربیع موسویان | H74: 0 | I74: طرف حساب | J74: بله | K74: =IF($A74="","",IF(LEFT($A74,3)="CAP","سرمایه و آورده صاحبان",IF(LEFT($A74,2)="SL","بارفروش",IF(LEFT($A74,2)="BD","باسکول دیگران",IF(LEFT($A74,1)="C","باغدار",IF(LEFT($A74,1)="S","فروشنده سبد/تأمین‌کننده",IF(LEFT($A74,1)="E","کارمند",IF(LEFT($A74,1)="X","سایر حساب",IF(LEFT($A74,1)="F","دارایی ثابت",IF(LEFT($A74,1)="L","وام و تسهیلات","")))))))))) -> Format(font_name='B Nazanin', font_size=9.5, bold=0, italic=0, underline=0, font_color=Color(value=0x6B7A76, type=RGB, is_automatic=False), num_format='General', text_h_align=3, text_v_align=2, fg_color=None, bg_color=Color(value=0xF6F5F0, type=RGB, is_automatic=False), pattern=0, locked=1, hidden=0) | M74: =IF(OR($B74="",$A74=""),"",IF(OR($B74=$K74,AND(LEFT($A74,1)="S",OR($B74="فروشنده سبد",$B74="تأمین‌کننده")),AND(LEFT($A74,2)="BD",$B74="باسکول دیگران")),"✓","⚠")) -> Format(font_name='Tahoma', font_size=10, bold=True, italic=0, underline=0, font_color=Color(value=0x6B7A76, type=RGB, is_automatic=False), num_format='General', text_h_align=2, text_v_align=2, fg_color=None, bg_color=Color(value=0xF6F5F0, type=RGB, is_automatic=False), pattern=0, locked=1, hidden=0)
A75: E001 | B75: کارمند | C75: مدیرعامل | D75: قاسم زاهدی تیر | F75: 09110000010 | G75: قائم‌شهر | H75: 0 | I75: طرف حساب | J75: بله | K75: =IF($A75="","",IF(LEFT($A75,3)="CAP","سرمایه و آورده صاحبان",IF(LEFT($A75,2)="SL","بارفروش",IF(LEFT($A75,2)="BD","باسکول دیگران",IF(LEFT($A75,1)="C","باغدار",IF(LEFT($A75,1)="S","فروشنده سبد/تأمین‌کننده",IF(LEFT($A75,1)="E","کارمند",IF(LEFT($A75,1)="X","سایر حساب",IF(LEFT($A75,1)="F","دارایی ثابت",IF(LEFT($A75,1)="L","وام و تسهیلات","")))))))))) -> Format(font_name='B Nazanin', font_size=9.5, bold=0, italic=0, underline=0, font_color=Color(value=0x6B7A76, type=RGB, is_automatic=False), num_format='General', text_h_align=3, text_v_align=2, fg_color=None, bg_color=Color(value=0xF6F5F0, type=RGB, is_automatic=False), pattern=0, locked=1, hidden=0) | L75: مدیرعامل شرکت | M75: =IF(OR($B75="",$A75=""),"",IF(OR($B75=$K75,AND(LEFT($A75,1)="S",OR($B75="فروشنده سبد",$B75="تأمین‌کننده")),AND(LEFT($A75,2)="BD",$B75="باسکول دیگران")),"✓","⚠")) -> Format(font_name='Tahoma', font_size=10, bold=True, italic=0, underline=0, font_color=Color(value=0x6B7A76, type=RGB, is_automatic=False), num_format='General', text_h_align=2, text_v_align=2, fg_color=None, bg_color=Color(value=0xF6F5F0, type=RGB, is_automatic=False), pattern=0, locked=1, hidden=0)
A76: E002 | B76: کارمند | C76: حسابدار | D76: (نام حسابدار) | F76: 09110000011 | G76: قائم‌شهر | H76: 0 | I76: طرف حساب | J76: بله | K76: =IF($A76="","",IF(LEFT($A76,3)="CAP","سرمایه و آورده صاحبان",IF(LEFT($A76,2)="SL","بارفروش",IF(LEFT($A76,2)="BD","باسکول دیگران",IF(LEFT($A76,1)="C","باغدار",IF(LEFT($A76,1)="S","فروشنده سبد/تأمین‌کننده",IF(LEFT($A76,1)="E","کارمند",IF(LEFT($A76,1)="X","سایر حساب",IF(LEFT($A76,1)="F","دارایی ثابت",IF(LEFT($A76,1)="L","وام و تسهیلات","")))))))))) -> Format(font_name='B Nazanin', font_size=9.5, bold=0, italic=0, underline=0, font_color=Color(value=0x6B7A76, type=RGB, is_automatic=False), num_format='General', text_h_align=3, text_v_align=2, fg_color=None, bg_color=Color(value=0xF6F5F0, type=RGB, is_automatic=False), pattern=0, locked=1, hidden=0) | M76: =IF(OR($B76="",$A76=""),"",IF(OR($B76=$K76,AND(LEFT($A76,1)="S",OR($B76="فروشنده سبد",$B76="تأمین‌کننده")),AND(LEFT($A76,2)="BD",$B76="باسکول دیگران")),"✓","⚠")) -> Format(font_name='Tahoma', font_size=10, bold=True, italic=0, underline=0, font_color=Color(value=0x6B7A76, type=RGB, is_automatic=False), num_format='General', text_h_align=2, text_v_align=2, fg_color=None, bg_color=Color(value=0xF6F5F0, type=RGB, is_automatic=False), pattern=0, locked=1, hidden=0)
A77: E003 | B77: کارمند | C77: فروشنده | D77: (نام فروشنده ۱) | F77: 09110000012 | G77: قائم‌شهر | H77: 0 | I77: طرف حساب | J77: بله | K77: =IF($A77="","",IF(LEFT($A77,3)="CAP","سرمایه و آورده صاحبان",IF(LEFT($A77,2)="SL","بارفروش",IF(LEFT($A77,2)="BD","باسکول دیگران",IF(LEFT($A77,1)="C","باغدار",IF(LEFT($A77,1)="S","فروشنده سبد/تأمین‌کننده",IF(LEFT($A77,1)="E","کارمند",IF(LEFT($A77,1)="X","سایر حساب",IF(LEFT($A77,1)="F","دارایی ثابت",IF(LEFT($A77,1)="L","وام و تسهیلات","")))))))))) -> Format(font_name='B Nazanin', font_size=9.5, bold=0, italic=0, underline=0, font_color=Color(value=0x6B7A76, type=RGB, is_automatic=False), num_format='General', text_h_align=3, text_v_align=2, fg_color=None, bg_color=Color(value=0xF6F5F0, type=RGB, is_automatic=False), pattern=0, locked=1, hidden=0) | M77: =IF(OR($B77="",$A77=""),"",IF(OR($B77=$K77,AND(LEFT($A77,1)="S",OR($B77="فروشنده سبد",$B77="تأمین‌کننده")),AND(LEFT($A77,2)="BD",$B77="باسکول دیگران")),"✓","⚠")) -> Format(font_name='Tahoma', font_size=10, bold=True, italic=0, underline=0, font_color=Color(value=0x6B7A76, type=RGB, is_automatic=False), num_format='General', text_h_align=2, text_v_align=2, fg_color=None, bg_color=Color(value=0xF6F5F0, type=RGB, is_automatic=False), pattern=0, locked=1, hidden=0)
A78: E004 | B78: کارمند | C78: انباردار | D78: (نام انباردار) | F78: 09110000013 | G78: قائم‌شهر | H78: 0 | I78: طرف حساب | J78: بله | K78: =IF($A78="","",IF(LEFT($A78,3)="CAP","سرمایه و آورده صاحبان",IF(LEFT($A78,2)="SL","بارفروش",IF(LEFT($A78,2)="BD","باسکول دیگران",IF(LEFT($A78,1)="C","باغدار",IF(LEFT($A78,1)="S","فروشنده سبد/تأمین‌کننده",IF(LEFT($A78,1)="E","کارمند",IF(LEFT($A78,1)="X","سایر حساب",IF(LEFT($A78,1)="F","دارایی ثابت",IF(LEFT($A78,1)="L","وام و تسهیلات","")))))))))) -> Format(font_name='B Nazanin', font_size=9.5, bold=0, italic=0, underline=0, font_color=Color(value=0x6B7A76, type=RGB, is_automatic=False), num_format='General', text_h_align=3, text_v_align=2, fg_color=None, bg_color=Color(value=0xF6F5F0, type=RGB, is_automatic=False), pattern=0, locked=1, hidden=0) | M78: =IF(OR($B78="",$A78=""),"",IF(OR($B78=$K78,AND(LEFT($A78,1)="S",OR($B78="فروشنده سبد",$B78="تأمین‌کننده")),AND(LEFT($A78,2)="BD",$B78="باسکول دیگران")),"✓","⚠")) -> Format(font_name='Tahoma', font_size=10, bold=True, italic=0, underline=0, font_color=Color(value=0x6B7A76, type=RGB, is_automatic=False), num_format='General', text_h_align=2, text_v_align=2, fg_color=None, bg_color=Color(value=0xF6F5F0, type=RGB, is_automatic=False), pattern=0, locked=1, hidden=0)
A79: E005 | B79: کارمند | C79: سرپرست خط | D79: رضا کاظمی (نمونه) | F79: 09110000014 | G79: قائم‌شهر | H79: 0 | I79: طرف حساب | J79: بله | K79: =IF($A79="","",IF(LEFT($A79,3)="CAP","سرمایه و آورده صاحبان",IF(LEFT($A79,2)="SL","بارفروش",IF(LEFT($A79,2)="BD","باسکول دیگران",IF(LEFT($A79,1)="C","باغدار",IF(LEFT($A79,1)="S","فروشنده سبد/تأمین‌کننده",IF(LEFT($A79,1)="E","کارمند",IF(LEFT($A79,1)="X","سایر حساب",IF(LEFT($A79,1)="F","دارایی ثابت",IF(LEFT($A79,1)="L","وام و تسهیلات","")))))))))) -> Format(font_name='B Nazanin', font_size=9.5, bold=0, italic=0, underline=0, font_color=Color(value=0x6B7A76, type=RGB, is_automatic=False), num_format='General', text_h_align=3, text_v_align=2, fg_color=None, bg_color=Color(value=0xF6F5F0, type=RGB, is_automatic=False), pattern=0, locked=1, hidden=0) | L79: نمونه — گروه سالن ۱ | M79: =IF(OR($B79="",$A79=""),"",IF(OR($B79=$K79,AND(LEFT($A79,1)="S",OR($B79="فروشنده سبد",$B79="تأمین‌کننده")),AND(LEFT($A79,2)="BD",$B79="باسکول دیگران")),"✓","⚠")) -> Format(font_name='Tahoma', font_size=10, bold=True, italic=0, underline=0, font_color=Color(value=0x6B7A76, type=RGB, is_automatic=False), num_format='General', text_h_align=2, text_v_align=2, fg_color=None, bg_color=Color(value=0xF6F5F0, type=RGB, is_automatic=False), pattern=0, locked=1, hidden=0)
A80: E006 | B80: کارمند | C80: کارگر | D80: علی احمدی (نمونه) | F80: 09110000015 | G80: قائم‌شهر | H80: 0 | I80: طرف حساب | J80: بله | K80: =IF($A80="","",IF(LEFT($A80,3)="CAP","سرمایه و آورده صاحبان",IF(LEFT($A80,2)="SL","بارفروش",IF(LEFT($A80,2)="BD","باسکول دیگران",IF(LEFT($A80,1)="C","باغدار",IF(LEFT($A80,1)="S","فروشنده سبد/تأمین‌کننده",IF(LEFT($A80,1)="E","کارمند",IF(LEFT($A80,1)="X","سایر حساب",IF(LEFT($A80,1)="F","دارایی ثابت",IF(LEFT($A80,1)="L","وام و تسهیلات","")))))))))) -> Format(font_name='B Nazanin', font_size=9.5, bold=0, italic=0, underline=0, font_color=Color(value=0x6B7A76, type=RGB, is_automatic=False), num_format='General', text_h_align=3, text_v_align=2, fg_color=None, bg_color=Color(value=0xF6F5F0, type=RGB, is_automatic=False), pattern=0, locked=1, hidden=0) | L80: نمونه — گروه سالن ۱ | M80: =IF(OR($B80="",$A80=""),"",IF(OR($B80=$K80,AND(LEFT($A80,1)="S",OR($B80="فروشنده سبد",$B80="تأمین‌کننده")),AND(LEFT($A80,2)="BD",$B80="باسکول دیگران")),"✓","⚠")) -> Format(font_name='Tahoma', font_size=10, bold=True, italic=0, underline=0, font_color=Color(value=0x6B7A76, type=RGB, is_automatic=False), num_format='General', text_h_align=2, text_v_align=2, fg_color=None, bg_color=Color(value=0xF6F5F0, type=RGB, is_automatic=False), pattern=0, locked=1, hidden=0)
A81: X001 | B81: سایر حساب | C81: انعام و پاداش | D81: انعام مصطفی | H81: 0 | I81: طرف حساب | J81: بله | K81: =IF($A81="","",IF(LEFT($A81,3)="CAP","سرمایه و آورده صاحبان",IF(LEFT($A81,2)="SL","بارفروش",IF(LEFT($A81,2)="BD","باسکول دیگران",IF(LEFT($A81,1)="C","باغدار",IF(LEFT($A81,1)="S","فروشنده سبد/تأمین‌کننده",IF(LEFT($A81,1)="E","کارمند",IF(LEFT($A81,1)="X","سایر حساب",IF(LEFT($A81,1)="F","دارایی ثابت",IF(LEFT($A81,1)="L","وام و تسهیلات","")))))))))) -> Format(font_name='B Nazanin', font_size=9.5, bold=0, italic=0, underline=0, font_color=Color(value=0x6B7A76, type=RGB, is_automatic=False), num_format='General', text_h_align=3, text_v_align=2, fg_color=None, bg_color=Color(value=0xF6F5F0, type=RGB, is_automatic=False), pattern=0, locked=1, hidden=0) | L81: حساب شخصی انعام مصطفی — پول‌های پوز باسکول برای او بستانکار می‌شود | M81: =IF(OR($B81="",$A81=""),"",IF(OR($B81=$K81,AND(LEFT($A81,1)="S",OR($B81="فروشنده سبد",$B81="تأمین‌کننده")),AND(LEFT($A81,2)="BD",$B81="باسکول دیگران")),"✓","⚠")) -> Format(font_name='Tahoma', font_size=10, bold=True, italic=0, underline=0, font_color=Color(value=0x6B7A76, type=RGB, is_automatic=False), num_format='General', text_h_align=2, text_v_align=2, fg_color=None, bg_color=Color(value=0xF6F5F0, type=RGB, is_automatic=False), pattern=0, locked=1, hidden=0)
A82: X002 | B82: سایر حساب | C82: درآمد باسکول | D82: درآمد باسکول (احمد زاهدی) | H82: 0 | I82: معین | J82: بله | K82: =IF($A82="","",IF(LEFT($A82,3)="CAP","سرمایه و آورده صاحبان",IF(LEFT($A82,2)="SL","بارفروش",IF(LEFT($A82,2)="BD","باسکول دیگران",IF(LEFT($A82,1)="C","باغدار",IF(LEFT($A82,1)="S","فروشنده سبد/تأمین‌کننده",IF(LEFT($A82,1)="E","کارمند",IF(LEFT($A82,1)="X","سایر حساب",IF(LEFT($A82,1)="F","دارایی ثابت",IF(LEFT($A82,1)="L","وام و تسهیلات","")))))))))) -> Format(font_name='B Nazanin', font_size=9.5, bold=0, italic=0, underline=0, font_color=Color(value=0x6B7A76, type=RGB, is_automatic=False), num_format='General', text_h_align=3, text_v_align=2, fg_color=None, bg_color=Color(value=0xF6F5F0, type=RGB, is_automatic=False), pattern=0, locked=1, hidden=0) | L82: درآمد هزینه باسکول و پوز — حساب درآمدی | M82: =IF(OR($B82="",$A82=""),"",IF(OR($B82=$K82,AND(LEFT($A82,1)="S",OR($B82="فروشنده سبد",$B82="تأمین‌کننده")),AND(LEFT($A82,2)="BD",$B82="باسکول دیگران")),"✓","⚠")) -> Format(font_name='Tahoma', font_size=10, bold=True, italic=0, underline=0, font_color=Color(value=0x6B7A76, type=RGB, is_automatic=False), num_format='General', text_h_align=2, text_v_align=2, fg_color=None, bg_color=Color(value=0xF6F5F0, type=RGB, is_automatic=False), pattern=0, locked=1, hidden=0)
...

Sheet Ops
A1: مازندشت — سورتینگ و بسته‌بندی مرکبات | O1: MAZANDASHT · CITRUS SORTING & PACKING
A2: قواعد عملیات — موتور بدهکار/بستانکار سامانه
A3: هر عملیات یک جهت، یک دسته، الزامات و سمت‌های حساب دارد · تغییر این شیت، رفتار همه فایل‌ها را عوض می‌کند
A4: راهنما | B4: ورود دستی | C4: خودکار | D4: ورود | E4: خروج | F4: هشدار | G4: ستون‌های زرد = ورود شما | ستون‌های خاکستری = محاسبه خودکار | روی سرستون‌ها بایستید تا راهنما باز شود
A5: عملیات تعریف‌شده | E5: عملیات فعال | I5: در کشوی باسکول | M5: عملیات سبد | Q5: عملیات پوز
A6: =COUNTIF($B$10:$B$33,"?*") -> 0 | E6: =COUNTIF($S$10:$S$33,"بله") -> 0 | I6: =COUNTIF($P$10:$P$33,"بله") -> 0 | M6: =COUNTIF($B$10:$B$33,"*سبد*") -> 0 | Q6: =COUNTIF($L$10:$L$33,"بدهکار")+COUNTIF($L$10:$L$33,"بستانکار") -> 0
A7: شناسه عملیات | C7: جهت و دسته | E7: الزامات و طرف حساب | I7: حساب معین | K7: مبلغ دستی و پوز | O7: طرف ثابت | P7: نمایش | R7: توضیح / فعال
A8: کد | B8: عنوان عملیات | C8: جهت | D8: دسته | E8: وزن لازم؟ | F8: حساب طرف؟ | G8: مبنای مبلغ طرف | H8: سمت حساب طرف | I8: حساب معین | J8: سمت معین | K8: نقش مبلغ دستی | L8: اثر پوز | M8: بانک پوز | N8: حساب مقابل پوز | O8: حساب طرف ثابت | P8: در باسکول؟ | Q8: رنگ | R8: توضیح و قاعده | S8: فعال
A9: Code | B9: Operation | C9: Direction | D9: Category | E9: Weight? | F9: Party? | G9: Party Basis | H9: Party Side | I9: Ledger | J9: Ledger Side | K9: Manual Role | L9: POS Effect | M9: POS Bank | N9: POS Counter | O9: Fixed Party | P9: In Baskol | Q9: Color | R9: Rule | S9: Active
A10: OP01 | B10: خرید مرکبات | C10: ورود | D10: خرید | E10: بله | F10: بله | G10: وزن | H10: بستانکار | I10: X004 | J10: بدهکار | K10: افزودن | L10: — | P10: بله | Q10: mint | R10: بدهکار: موجودی مرکبات | بستانکار: حساب باغدار. مبلغ ستون «مبلغ دستی» به بستانکاری باغدار اضافه می‌شود (کرایه/سایر). | S10: بله
A11: OP02 | B11: فروش بار (بارفروش) | C11: خروج | D11: فروش | E11: بله | F11: بله | G11: وزن | H11: بدهکار | I11: X006 | J11: بستانکار | K11: پوز | L11: بدهکار | M11: BANK02 | N11: X002 | P11: بله | Q11: sky | R11: بدهکار: حساب بارفروش | بستانکار: فروش مرکبات. مبلغ ستون «پوز/دستی» فقط هزینه باسکول است: بدهکار صادرات ۲۰۰۶ / بستانکار درآمد باسکول؛ به حساب بارفروش کاری ندارد. | S11: بله
A12: OP03 | B12: فروش متفرقه / صادراتی | C12: خروج | D12: فروش | E12: بله | F12: بله | G12: وزن | H12: بدهکار | I12: X006 | J12: بستانکار | K12: پوز | L12: بدهکار | M12: BANK02 | N12: X002 | P12: بله | Q12: sky | R12: مانند فروش بار؛ برای حجره‌دار و صادراتی. | S12: بله
A13: OP04 | B13: آبگیری | C13: خروج | D13: آبگیری | E13: بله | F13: بله | G13: مبلغ | H13: خودکار | I13: X008 | J13: خودکار | K13: هیچ | L13: — | P13: بله | Q13: lavender | R13: هم وزن و هم مبلغ وارد می‌شود. سمت حساب را خودتان (بدهکار/بستانکار) در ستون «سمت حساب» انتخاب کنید؛ طرف مقابل حساب درآمد آبگیری است. | S13: بله
A14: OP05 | B14: انعام مصطفی | C14: — | D14: انعام | E14: خیر | F14: خیر | G14: مبلغ | H14: بستانکار | I14: BANK02 | J14: بدهکار | K14: هیچ | L14: — | O14: X001 | P14: بله | Q14: rose | R14: فقط مبلغ. بدهکار: صادرات ۲۰۰۶ (پوز باسکول) | بستانکار: انعام مصطفی. با هر انتقال/پرداخت به ایشان در شیت Payment تسویه می‌شود. | S14: بله
A15: OP06 | B15: باسکول دیگران | C15: — | D15: باسکول دیگران | E15: خیر | F15: بله | G15: مبلغ | H15: بدهکار | I15: X002 | J15: بستانکار | K15: هیچ | L15: — | P15: بله | Q15: sand | R15: فقط مبلغ. بدهکار: حساب صاحب باسکول دیگر (گروه باسکول دیگران) | بستانکار: درآمد باسکول. | S15: بله
A16: OP07 | B16: درآمد پوز باسکول (بدون طرف) | C16: — | D16: درآمد | E16: خیر | F16: خیر | G16: مبلغ | H16: — | J16: — | K16: پوز | L16: بدهکار | M16: BANK02 | N16: X002 | P16: بله | Q16: sand | R16: فقط مبلغ. بدهکار: صادرات ۲۰۰۶ | بستانکار: درآمد باسکول. برای هزینه باسکول نقدی/POS بدون بار. | S16: بله
A17: OP08 | B17: مرجوعی خرید | C17: خروج | D17: خرید | E17: بله | F17: بله | G17: وزن | H17: بدهکار | I17: X004 | J17: بستانکار | K17: افزودن | L17: — | P17: بله | Q17: grey | R17: برگشت بار به باغدار: بدهکار باغدار | بستانکار موجودی مرکبات. | S17: بله
A18: OP09 | B18: مرجوعی فروش | C18: ورود | D18: فروش | E18: بله | F18: بله | G18: وزن | H18: بستانکار | I18: X006 | J18: بدهکار | K18: هیچ | L18: — | P18: بله | Q18: grey | R18: برگشت بار از بارفروش: بستانکار بارفروش | بدهکار فروش مرکبات. | S18: بله
A19: OP10 | B19: ضایعات / افت انبار | C19: خروج | D19: هزینه | E19: بله | F19: بله | G19: وزن | H19: بستانکار | I19: X009 | J19: بدهکار | K19: هیچ | L19: — | O19: X004 | P19: بله | Q19: grey | R19: فقط وزن و فی. طرف حساب ثابت = موجودی مرکبات (بستانکار) | هزینه ضایعات (بدهکار). | S19: بله
A20: OP11 | B20: انتقال بین انبار | C20: خروج | D20: انتقال | E20: بله | F20: خیر | G20: هیچ | H20: — | J20: — | K20: هیچ | L20: — | P20: بله | Q20: teal | R20: فقط برای کنترل فیزیکی؛ سند مالی ندارد. | S20: بله
A21: OP12 | B21: سایر ورود | C21: ورود | D21: سایر | E21: بله | F21: بله | G21: وزن | H21: بستانکار | I21: X011 | J21: بدهکار | K21: افزودن | L21: — | P21: بله | Q21: sand | R21: ورود متفرقه با طرف حساب؛ به حساب واسط می‌رود تا بعداً طبقه‌بندی شود. | S21: بله
A22: OP13 | B22: سایر خروج | C22: خروج | D22: سایر | E22: بله | F22: بله | G22: وزن | H22: بدهکار | I22: X011 | J22: بستانکار | K22: هیچ | L22: — | P22: بله | Q22: sand | R22: خروج متفرقه با طرف حساب؛ به حساب واسط می‌رود. | S22: بله
A23: OP14 | B23: هزینه باسکول نقدی (درآمد) | C23: — | D23: درآمد | E23: خیر | F23: خیر | G23: مبلغ | H23: — | J23: — | K23: پوز | L23: بدهکار | M23: BANK02 | N23: X002 | P23: بله | Q23: sand | R23: دریافت هزینه باسکول از مشتری بدون بار؛ بدهکار صادرات ۲۰۰۶ / بستانکار درآمد باسکول. | S23: بله
A24: OP15 | B24: خرید سبد | C24: ورود | D24: خرید | E24: خیر | F24: بله | G24: مبلغ | H24: بستانکار | I24: X005 | J24: بدهکار | K24: هیچ | L24: — | P24: خیر | Q24: lavender | R24: خرید سبد از فروشنده سبد: بدهکار موجودی سبد | بستانکار فروشنده سبد. | S24: بله
A25: OP16 | B25: فروش سبد | C25: خروج | D25: فروش | E25: خیر | F25: بله | G25: مبلغ | H25: بدهکار | I25: X007 | J25: بستانکار | K25: هیچ | L25: — | P25: خیر | Q25: lavender | R25: فروش سبد: بدهکار خریدار | بستانکار درآمد فروش سبد. | S25: بله
A26: OP17 | B26: مرجوعی خرید سبد | C26: خروج | D26: خرید | E26: خیر | F26: بله | G26: مبلغ | H26: بدهکار | I26: X005 | J26: بستانکار | K26: هیچ | L26: — | P26: خیر | Q26: lavender | R26: برگشت سبد به فروشنده: بدهکار فروشنده | بستانکار موجودی سبد. | S26: بله
A27: OP18 | B27: مرجوعی فروش سبد | C27: ورود | D27: فروش | E27: خیر | F27: بله | G27: مبلغ | H27: بستانکار | I27: X007 | J27: بدهکار | K27: هیچ | L27: — | P27: خیر | Q27: lavender | R27: برگشت سبد از خریدار: بستانکار خریدار | بدهکار فروش سبد. | S27: بله
